Workbook
Name Ccy: MAIN!$C$6
Name circ: MAIN!$C$9
Name CoName: MAIN!$C$4
Name g: #REF!
Name IQ_CH: 110000
Name IQ_CQ: 5000
Name IQ_CY: 10000
Name IQ_DAILY: 500000
Name IQ_FH: 100000
Name IQ_FQ: 500
Name IQ_FY: 1000
Name IQ_LTM: 2000
Name IQ_MONTH: 15000
Name IQ_NTM: 6000
Name IQ_WEEK: 50000
Name IQ_YTD: 3000
Name OpCase: [1]DCF!$E$98
Name ScenarioREV: Assumptions!$D$4
Name TTS: #REF!
Name Units: MAIN!$C$7

Sheet MAIN
A1: =CoName -> Darden Restaurants Inc
A2: Model Details
B4: Company name | C4: Darden Restaurants Inc | E4: Current Stock Price | F4: 183 | H4: Operating Case One | I4: Terminal Mult | J4: Perpetuity | K4: DDM | L4: Average
B5: Latest BS date | C5: 247.43 | E5: Diluted s/o | F5: 116.313 | H5: Implied Price | I5: ='DCF Model'!G18 -> 265.91277 | J5: ='DCF Model'!C18 -> 209.24271 | K5: ='DCF Model'!K11 -> 167.70763 | L5: =AVERAGE(I5:K5) -> 214.2877
B6: Currency | C6: USD | E6: Mkt Cap | F6: =F5*F4 -> 21285.279 | H6: Difference | I6: =I5/$F$4-1 -> 0.45307523 | J6: =J5/$F$4-1 -> 0.14340276 | K6: =K5/$F$4-1 -> -0.083564844 | L6: =L5/$F$4-1 -> 0.17097105
B7: Units | C7: m | E7: Cash | F7: 211
B8: Analyst name | C8: Alan Chen | E8: Debt | F8: =142+2135.1+3878.3 -> 6155.4
B9: Circular switch | C9: 0 | E9: EV | F9: =F6-F7+F8 -> 27229.679

Sheet Quarterly Projections

Sheet Assumptions
A1: =CoName -> Darden Restaurants Inc | C1: Hist. | D1: Hist. | E1: Hist. | F1: Proj. | G1: Proj. | H1: Proj. | I1: Proj. | J1: Proj.
A2: * | B2: Income Statement | C2: 2022 | D2: =C2+1 -> 2023 | E2: =D2+1 -> 2024 | F2: =E2+1 -> 2025 | G2: =F2+1 -> 2026 | H2: =G2+1 -> 2027 | I2: =H2+1 -> 2028 | J2: =I2+1 -> 2029
B4: Operating Case | D4: 1
D5: Variance
B6: Street Case | D6: 0 | F6: 0.082 | G6: 0.037 | H6: 0.05 | I6: 0.055 | J6: 0.05
B7: Optimistic Case | D7: 0.025 | F7: =F6+$D$7 -> 0.107 | G7: =G6+$D$7 -> 0.062 | H7: =H6+$D$7 -> 0.075 | I7: =I6+$D$7 -> 0.08 | J7: =J6+$D$7 -> 0.075
B8: Pessimistic Case | D8: -0.025 | F8: =F6+$D$8 -> 0.057 | G8: =G6+$D$8 -> 0.012 | H8: =H6+$D$8 -> 0.025 | I8: =I6+$D$8 -> 0.03 | J8: =J6+$D$8 -> 0.025
B10: Revenue Growth | D10: =IncState!D16/IncState!C16-1 -> 0.086023761 | E10: =IncState!E16/IncState!D16-1 -> 0.060289728 | F10: =CHOOSE(ScenarioREV,F6,F7,F8) -> 0.082 | G10: =CHOOSE(ScenarioREV,G6,G7,G8) -> 0.037 | H10: =CHOOSE(ScenarioREV,H6,H7,H8) -> 0.05 | I10: =CHOOSE(ScenarioREV,I6,I7,I8) -> 0.055 | J10: =CHOOSE(ScenarioREV,J6,J7,J8) -> 0.05
B11: COGS % of sales | C11: =IncState!C17/IncState!C16 -> 0.7988806 | D11: =IncState!D17/IncState!D16 -> 0.78625988 | E11: =IncState!E17/IncState!E16 -> 0.78118195 | F11: =E11-0.005 -> 0.77618195 | G11: =F11-0.005 -> 0.77118195 | H11: =G11-0.005 -> 0.76618195 | I11: =H11-0.005 -> 0.76118195 | J11: =I11-0.005 -> 0.75618195
B12: SG&A % of sales | C12: =IncState!C18/IncState!C16 -> 0.087539808 | D12: =IncState!D18/IncState!D16 -> 0.097269535 | E12: =IncState!E18/IncState!E16 -> 0.1019401 | F12: =E12 -> 0.1019401 | G12: =F12+0.0025 -> 0.1044401 | H12: =G12+0.0025 -> 0.1069401 | I12: =H12+0.0025 -> 0.1094401 | J12: =I12+0.0025 -> 0.1119401
B13: Amortization $ Amt | C13: =IncState!C22 -> 0 | D13: =IncState!D22 -> 0 | E13: =IncState!E22 -> 0 | F13: =E13 -> 0 | G13: =F13 -> 0 | H13: =G13 -> 0 | I13: =H13 -> 0 | J13: =I13 -> 0
B14: Non recurring income / (expense) | C14: =IncState!C25 -> 10.6 | D14: =IncState!D25 -> -12.4 | E14: =IncState!E25 -> -49.2 | F14: 0 | G14: 0 | H14: 0 | I14: 0 | J14: 0
B15: Other Income / (expense) | C15: =IncState!C26 -> 0 | D15: =IncState!D26 -> 0 | E15: =IncState!E26 -> 0 | F15: 0 | G15: 0 | H15: 0 | I15: 0 | J15: 0
B16: Effective tax rate | C16: =IncState!C33/IncState!C31 -> 0.12343454 | D16: =IncState!D33/IncState!D31 -> 0.12200252 | E16: =IncState!E33/IncState!E31 -> 0.11472372 | F16: 0.21 | G16: =F16 -> 0.21 | H16: =G16 -> 0.21 | I16: =H16 -> 0.21 | J16: =I16 -> 0.21
B17: Dividend Payout Rate | C17: =IncState!C35 -> 4.8383921 | D17: =IncState!D35 -> 5.2410342 | E17: =IncState!E35 -> 5.5957447 | F17: =E17+(E17-D17) -> 5.9504552 | G17: =F17+(F17-E17) -> 6.3051657 | H17: =G17+(G17-F17) -> 6.6598761 | I17: =H17+(H17-G17) -> 7.0145866 | J17: =I17+(I17-H17) -> 7.3692971
B18: Basic WASO | C18: =IncState!C38 -> 121.9 | D18: =IncState!D38 -> 119.9 | E18: =IncState!E38 -> 117.5 | F18: =E18 -> 117.5 | G18: =F18 -> 117.5 | H18: =G18 -> 117.5 | I18: =H18 -> 117.5 | J18: =I18 -> 117.5
B19: Diluted WASO | C19: =IncState!C39 -> 122.9 | D19: =IncState!D39 -> 120.8 | E19: =IncState!E39 -> 118.4 | F19: =E19 -> 118.4 | G19: =F19 -> 118.4 | H19: =G19 -> 118.4 | I19: =H19 -> 118.4 | J19: =I19 -> 118.4
A21: * | B21: Debt | C21: =C2 -> 2022 | D21: =D2 -> 2023 | E21: =E2 -> 2024 | F21: =F2 -> 2025 | G21: =G2 -> 2026 | H21: =H2 -> 2027 | I21: =I2 -> 2028 | J21: =J2 -> 2029
B23: Interest rate on Revolver | E23: =E24+1% -> 0.0586 | F23: =E23 -> 0.0586 | G23: =F23 -> 0.0586 | H23: =G23 -> 0.0586 | I23: =H23 -> 0.0586 | J23: =I23 -> 0.0586
B24: Interest rate on long-term debt | E24: 0.0486 | F24: =E24 -> 0.0486 | G24: =F24 -> 0.0486 | H24: =G24 -> 0.0486 | I24: =H24 -> 0.0486 | J24: =I24 -> 0.0486
B25: Interest rate on cash | E25: 0.04 | F25: =E25 -> 0.04 | G25: =F25 -> 0.04 | H25: =G25 -> 0.04 | I25: =H25 -> 0.04 | J25: =I25 -> 0.04
B27: Issuance of long-term debt | F27: 0 | G27: 0 | H27: 0 | I27: 0 | J27: 0
B28: Repayment of long-term debt | F28: 0 | G28: 0 | H28: 0 | I28: 0 | J28: 0
A30: * | B30: Calcs | C30: =C21 -> 2022 | D30: =D21 -> 2023 | E30: =E21 -> 2024 | F30: =F21 -> 2025 | G30: =G21 -> 2026 | H30: =H21 -> 2027 | I30: =I21 -> 2028 | J30: =J21 -> 2029
B32: CapEx % of Sales | C32: =564.9/IncState!C16 -> 0.053862583 | D32: =601.2/IncState!D16 -> 0.052783143 | E32: =644.6/IncState!E16 -> 0.053375508 | F32: =AVERAGE(C32:E32) -> 0.053340412 | G32: =F32 -> 0.053340412 | H32: =G32 -> 0.053340412 | I32: =H32 -> 0.053340412 | J32: =I32 -> 0.053340412
B33: Depreciation % of beginning PP&E | D33: =IncState!D21/BalSheet!C23 -> 0.064783772 | E33: =IncState!E21/BalSheet!D23 -> 0.067786592 | F33: =E33 -> 0.067786592 | G33: =F33 -> 0.067786592 | H33: =G33 -> 0.067786592 | I33: =H33 -> 0.067786592 | J33: =I33 -> 0.067786592
B34: Share issuance / (repurchases) | F34: 0 | G34: 0 | H34: 0 | I34: 0 | J34: 0
A36: * | B36: Shareholder information | C36: =C30 -> 2022 | D36: =D30 -> 2023 | E36: =E30 -> 2024 | F36: =F30 -> 2025 | G36: =G30 -> 2026 | H36: =H30 -> 2027 | I36: =I30 -> 2028 | J36: =J30 -> 2029
B38: =B17 -> Dividend Payout Rate | C38: =C17 -> 4.8383921 | D38: =D17 -> 5.2410342 | E38: =E17 -> 5.5957447 | F38: =F17 -> 5.9504552 | G38: =G17 -> 6.3051657 | H38: =H17 -> 6.6598761 | I38: =I17 -> 7.0145866 | J38: =J17 -> 7.3692971
B39: Basic WASO | C39: =C18 -> 121.9 | D39: =D18 -> 119.9 | E39: =E18 -> 117.5 | F39: =F18 -> 117.5 | G39: =G18 -> 117.5 | H39: =H18 -> 117.5 | I39: =I18 -> 117.5 | J39: =J18 -> 117.5
B40: Diluted WASO | C40: =C19 -> 122.9 | D40: =D19 -> 120.8 | E40: =E19 -> 118.4 | F40: =F19 -> 118.4 | G40: =G19 -> 118.4 | H40: =H19 -> 118.4 | I40: =I19 -> 118.4 | J40: =J19 -> 118.4
A42: * | B42: Balance Sheet - Assets | C42: =C36 -> 2022 | D42: =D36 -> 2023 | E42: =E36 -> 2024 | F42: =F36 -> 2025 | G42: =G36 -> 2026 | H42: =H36 -> 2027 | I42: =I36 -> 2028 | J42: =J36 -> 2029
B44: Operating Cash % of sales | C44: =BalSheet!C16/IncState!C16 -> 0.01 | D44: =BalSheet!D16/IncState!D16 -> 0.01 | E44: =BalSheet!E16/IncState!E16 -> 0.01 | F44: =E44 -> 0.01 | G44: =F44 -> 0.01 | H44: =G44 -> 0.01 | I44: =H44 -> 0.01 | J44: =I44 -> 0.01
B45: Accounts receivable % of sales | C45: =BalSheet!C18/IncState!C16 -> 0.0076469803 | D45: =BalSheet!D18/IncState!D16 -> 0.0069446883 | E45: =BalSheet!E18/IncState!E16 -> 0.0077670224 | F45: =E45 -> 0.0077670224 | G45: =F45 -> 0.0077670224 | H45: =G45 -> 0.0077670224 | I45: =H45 -> 0.0077670224 | J45: =I45 -> 0.0077670224
B46: Inventories % of COGS | C46: =BalSheet!C19/IncState!C17 -> 0.034361759 | D46: =BalSheet!D19/IncState!D17 -> 0.032438166 | E46: =BalSheet!E19/IncState!E17 -> 0.033029118 | F46: =E46 -> 0.033029118 | G46: =F46 -> 0.033029118 | H46: =G46 -> 0.033029118 | I46: =H46 -> 0.033029118 | J46: =I46 -> 0.033029118
B47: Other current assets % of sales | C47: =BalSheet!C20/IncState!C16 -> 0.024962337 | D47: =BalSheet!D20/IncState!D16 -> 0.022686567 | E47: =BalSheet!E20/IncState!E16 -> 0.024203632 | F47: =E47 -> 0.024203632 | G47: =F47 -> 0.024203632 | H47: =G47 -> 0.024203632 | I47: =H47 -> 0.024203632 | J47: =I47 -> 0.024203632
B49: Other long-term assets % of sales | C49: =BalSheet!C25/IncState!C16 -> 0.028709548 | D49: =BalSheet!D25/IncState!D16 -> 0.030517998 | E49: =BalSheet!E25/IncState!E16 -> 0.030769995 | F49: =E49 -> 0.030769995 | G49: =F49 -> 0.030769995 | H49: =G49 -> 0.030769995 | I49: =H49 -> 0.030769995 | J49: =I49 -> 0.030769995
A51: * | B51: Balance Sheet - Liabilities | C51: =C42 -> 2022 | D51: =D42 -> 2023 | E51: =E42 -> 2024 | F51: =F42 -> 2025 | G51: =G42 -> 2026 | H51: =H42 -> 2027 | I51: =I42 -> 2028 | J51: =J42 -> 2029
B53: Accounts payable % of COGS | C53: =BalSheet!C31/IncState!C17 -> 0.072447335 | D53: =BalSheet!D31/IncState!D17 -> 0.066517782 | E53: =BalSheet!E31/IncState!E17 -> 0.069089791 | F53: =E53 -> 0.069089791 | G53: =F53 -> 0.069089791 | H53: =G53 -> 0.069089791 | I53: =H53 -> 0.069089791 | J53: =I53 -> 0.069089791
B54: Other current liabilities % of sales | C54: =BalSheet!C32/IncState!C16 -> 0.12685215 | D54: =BalSheet!D32/IncState!D16 -> 0.13257243 | E54: =BalSheet!E32/IncState!E16 -> 0.13213047 | F54: =E54 -> 0.13213047 | G54: =F54 -> 0.13213047 | H54: =G54 -> 0.13213047 | I54: =H54 -> 0.13213047 | J54: =I54 -> 0.13213047
...

Sheet Calcs
A1: =CoName -> Darden Restaurants Inc | C1: Hist. | D1: Hist. | E1: Hist. | F1: Proj. | G1: Proj. | H1: Proj. | I1: Proj. | J1: Proj.
A2: Net PP&E | C2: 2022 | D2: =C2+1 -> 2023 | E2: =D2+1 -> 2024 | F2: =E2+1 -> 2025 | G2: =F2+1 -> 2026 | H2: =G2+1 -> 2027 | I2: =H2+1 -> 2028 | J2: =I2+1 -> 2029
B3: Capital expenditure % of sales | F3: =Assumptions!F32 -> 0.053340412 | G3: =Assumptions!G32 -> 0.053340412 | H3: =Assumptions!H32 -> 0.053340412 | I3: =Assumptions!I32 -> 0.053340412 | J3: =Assumptions!J32 -> 0.053340412
B4: Depreciation % of PP&E | F4: =Assumptions!F33 -> 0.067786592 | G4: =F4 -> 0.067786592 | H4: =G4 -> 0.067786592 | I4: =H4 -> 0.067786592 | J4: =I4 -> 0.067786592
B6: Beginning PP&E | F6: =E9 -> 8271.9 | G6: =F9 -> 8408.1747 | H6: =G9 -> 8561.0007 | I6: =H9 -> 8739.6066 | J6: =I9 -> 8947.8463
B7: Capex | F7: =F3*IncState!F16 -> 696.99859 | G7: =G3*IncState!G16 -> 722.78754 | H7: =H3*IncState!H16 -> 758.92692 | I7: =I3*IncState!I16 -> 800.6679 | J7: =J3*IncState!J16 -> 840.70129
B8: Depreciation | F8: =F6*F4 -> 560.72391 | G8: =G6*G4 -> 569.96151 | H8: =H6*H4 -> 580.32107 | I8: =I6*I4 -> 592.42815 | J8: =J6*J4 -> 606.54401
B9: Ending PP&E | E9: =BalSheet!E23 -> 8271.9 | F9: =F6+F7-F8 -> 8408.1747 | G9: =G6+G7-G8 -> 8561.0007 | H9: =H6+H7-H8 -> 8739.6066 | I9: =I6+I7-I8 -> 8947.8463 | J9: =J6+J7-J8 -> 9182.0036
A10: Equity | C10: =C2 -> 2022 | D10: =D2 -> 2023 | E10: =E2 -> 2024 | F10: =F2 -> 2025 | G10: =G2 -> 2026 | H10: =H2 -> 2027 | I10: =I2 -> 2028 | J10: =J2 -> 2029
B11: Share issuance/(repurchases) | F11: =Assumptions!F34 -> 0 | G11: =Assumptions!G34 -> 0 | H11: =Assumptions!H34 -> 0 | I11: =Assumptions!I34 -> 0 | J11: =Assumptions!J34 -> 0
B13: Beginning balance | F13: =E17 -> 2311.3 | G13: =F17 -> 2870.2581 | H13: =G17 -> 3460.8509 | I13: =H17 -> 4104.4381 | J13: =I17 -> 4814.4293
B14: Net income | F14: =IncState!F34 -> 1258.1366 | G14: =IncState!G34 -> 1331.4498 | H14: =IncState!H34 -> 1426.1226 | I14: =IncState!I34 -> 1534.2051 | J14: =IncState!J34 -> 1642.0435
B15: Dividends paid | F15: =-IncState!F36 -> -699.17848 | G15: =-IncState!G36 -> -740.85696 | H15: =-IncState!H36 -> -782.53545 | I15: =-IncState!I36 -> -824.21393 | J15: =-IncState!J36 -> -865.89241
B16: Share issuance / (repurchase) | F16: =F11 -> 0 | G16: =G11 -> 0 | H16: =H11 -> 0 | I16: =I11 -> 0 | J16: =J11 -> 0
B17: Ending balance | E17: =BalSheet!E39 -> 2311.3 | F17: =SUM(F13:F16) -> 2870.2581 | G17: =SUM(G13:G16) -> 3460.8509 | H17: =SUM(H13:H16) -> 4104.4381 | I17: =SUM(I13:I16) -> 4814.4293 | J17: =SUM(J13:J16) -> 5590.5803
A18: OWC | C18: =C10 -> 2022 | D18: =D10 -> 2023 | E18: =E10 -> 2024 | F18: =F10 -> 2025 | G18: =G10 -> 2026 | H18: =H10 -> 2027 | I18: =I10 -> 2028 | J18: =J10 -> 2029
B19: Operating Cash | E19: =BalSheet!E16 -> 120.767 | F19: =BalSheet!F16 -> 130.66989 | G19: =BalSheet!G16 -> 135.50468 | H19: =BalSheet!H16 -> 142.27991 | I19: =BalSheet!I16 -> 150.10531 | J19: =BalSheet!J16 -> 157.61057
B20: =BalSheet!B18 -> Accounts receivable | E20: =BalSheet!E18 -> 93.8 | F20: =BalSheet!F18 -> 101.4916 | G20: =BalSheet!G18 -> 105.24679 | H20: =BalSheet!H18 -> 110.50913 | I20: =BalSheet!I18 -> 116.58713 | J20: =BalSheet!J18 -> 122.41649
B21: =BalSheet!B19 -> Inventories | E21: =BalSheet!E19 -> 311.6 | F21: =BalSheet!F19 -> 334.99324 | G21: =BalSheet!G19 -> 345.15019 | H21: =BalSheet!H19 -> 360.05801 | I21: =BalSheet!I19 -> 377.38228 | J21: =BalSheet!J19 -> 393.64853
B22: Other current assets | E22: =BalSheet!E20 -> 292.3 | F22: =BalSheet!F20 -> 316.2686 | G22: =BalSheet!G20 -> 327.97054 | H22: =BalSheet!H20 -> 344.36907 | I22: =BalSheet!I20 -> 363.30936 | J22: =BalSheet!J20 -> 381.47483
B23: Accounts payables | E23: =BalSheet!E31 -> 651.8 | F23: =BalSheet!F31 -> 700.73362 | G23: =BalSheet!G31 -> 721.97977 | H23: =BalSheet!H31 -> 753.16371 | I23: =BalSheet!I31 -> 789.40235 | J23: =BalSheet!J31 -> 823.42782
B24: Other current liabilities | E24: =BalSheet!E32 -> 1595.7 | F24: =BalSheet!F32 -> 1726.5474 | G24: =BalSheet!G32 -> 1790.4297 | H24: =BalSheet!H32 -> 1879.9511 | I24: =BalSheet!I32 -> 1983.3484 | J24: =BalSheet!J32 -> 2082.5159
A25: * | B25: OWC | E25: =SUM(E19:E22)-SUM(E23:E24) -> -1429.033 | F25: =SUM(F19:F22)-SUM(F23:F24) -> -1543.8577 | G25: =SUM(G19:G22)-SUM(G23:G24) -> -1598.5372 | H25: =SUM(H19:H22)-SUM(H23:H24) -> -1675.8987 | I25: =SUM(I19:I22)-SUM(I23:I24) -> -1765.3667 | J25: =SUM(J19:J22)-SUM(J23:J24) -> -1850.7933
B26: Change in OWC | F26: =E25-F25 -> 114.82468 | G26: =F25-G25 -> 54.679539 | H26: =G25-H25 -> 77.361506 | I26: =H25-I25 -> 89.467981 | J26: =I25-J25 -> 85.426564

Sheet Debt
A1: =CoName -> Darden Restaurants Inc | C1: Hist. | D1: Hist. | E1: Hist. | F1: Proj. | G1: Proj. | H1: Proj. | I1: Proj. | J1: Proj.
A2: Assumptions | C2: 2022 | D2: =C2+1 -> 2023 | E2: =D2+1 -> 2024 | F2: =E2+1 -> 2025 | G2: =F2+1 -> 2026 | H2: =G2+1 -> 2027 | I2: =H2+1 -> 2028 | J2: =I2+1 -> 2029
B4: Interest rate on revolver | F4: =Assumptions!F23 -> 0.0586 | G4: =Assumptions!G23 -> 0.0586 | H4: =Assumptions!H23 -> 0.0586 | I4: =Assumptions!I23 -> 0.0586 | J4: =Assumptions!J23 -> 0.0586
B5: Interest rate on long-term debt | F5: =Assumptions!F24 -> 0.0486 | G5: =Assumptions!G24 -> 0.0486 | H5: =Assumptions!H24 -> 0.0486 | I5: =Assumptions!I24 -> 0.0486 | J5: =Assumptions!J24 -> 0.0486
B6: Interest rate on cash | F6: =Assumptions!F25 -> 0.04 | G6: =Assumptions!G25 -> 0.04 | H6: =Assumptions!H25 -> 0.04 | I6: =Assumptions!I25 -> 0.04 | J6: =Assumptions!J25 -> 0.04
B8: Issuance of long-term debt | F8: =Assumptions!F27 -> 0 | G8: =Assumptions!G27 -> 0 | H8: =Assumptions!H27 -> 0 | I8: =Assumptions!I27 -> 0 | J8: =Assumptions!J27 -> 0
B9: Repayment of long-term debt | F9: =Assumptions!F28 -> 0 | G9: =Assumptions!G28 -> 0 | H9: =Assumptions!H28 -> 0 | I9: =Assumptions!I28 -> 0 | J9: =Assumptions!J28 -> 0
A11: Revolver | C11: =C2 -> 2022 | D11: =D2 -> 2023 | E11: =E2 -> 2024 | F11: =F2 -> 2025 | G11: =G2 -> 2026 | H11: =H2 -> 2027 | I11: =I2 -> 2028 | J11: =J2 -> 2029
B12: Balance | F12: 0 | G12: 0 | H12: 0 | I12: 0 | J12: 0
B13: Interest rate
B14: Interest expense
A16: Long term debt | C16: =C11 -> 2022 | D16: =D11 -> 2023 | E16: =E11 -> 2024 | F16: =F11 -> 2025 | G16: =G11 -> 2026 | H16: =H11 -> 2027 | I16: =I11 -> 2028 | J16: =J11 -> 2029
B17: Beginning balance | F17: =E20 -> 2128.9 | G17: =F20 -> 2128.9 | H17: =G20 -> 2128.9 | I17: =H20 -> 2128.9 | J17: =I20 -> 2128.9
B18: Issuance | F18: =F8 -> 0 | G18: =G8 -> 0 | H18: =H8 -> 0 | I18: =I8 -> 0 | J18: =J8 -> 0
B19: Repayment | F19: =F9 -> 0 | G19: =G9 -> 0 | H19: =H9 -> 0 | I19: =I9 -> 0 | J19: =J9 -> 0
B20: Ending balance | E20: =BalSheet!E35 -> 2128.9 | F20: =SUM(F17:F19) -> 2128.9 | G20: =SUM(G17:G19) -> 2128.9 | H20: =SUM(H17:H19) -> 2128.9 | I20: =SUM(I17:I19) -> 2128.9 | J20: =SUM(J17:J19) -> 2128.9
B21: Interest rate | F21: =F5 -> 0.0486 | G21: =G5 -> 0.0486 | H21: =H5 -> 0.0486 | I21: =I5 -> 0.0486 | J21: =J5 -> 0.0486
B22: Interest expense | F22: =-F21*F20 -> -103.46454 | G22: =-G21*G20 -> -103.46454 | H22: =-H21*H20 -> -103.46454 | I22: =-I21*I20 -> -103.46454 | J22: =-J21*J20 -> -103.46454
A24: Debt summary | C24: =C16 -> 2022 | D24: =D16 -> 2023 | E24: =E16 -> 2024 | F24: =F16 -> 2025 | G24: =G16 -> 2026 | H24: =H16 -> 2027 | I24: =I16 -> 2028 | J24: =J16 -> 2029
B25: Revolver | F25: =F12 -> 0 | G25: =G12 -> 0 | H25: =H12 -> 0 | I25: =I12 -> 0 | J25: =J12 -> 0
B26: Total long term debt | F26: =F20 -> 2128.9 | G26: =G20 -> 2128.9 | H26: =H20 -> 2128.9 | I26: =I20 -> 2128.9 | J26: =J20 -> 2128.9
B27: Total debt | F27: =SUM(F25:F26) -> 2128.9 | G27: =SUM(G25:G26) -> 2128.9 | H27: =SUM(H25:H26) -> 2128.9 | I27: =SUM(I25:I26) -> 2128.9 | J27: =SUM(J25:J26) -> 2128.9
B28: Total interest expense | F28: =F22 -> -103.46454 | G28: =G22 -> -103.46454 | H28: =H22 -> -103.46454 | I28: =I22 -> -103.46454 | J28: =J22 -> -103.46454
A30: Interest income | C30: =C11 -> 2022 | D30: =D11 -> 2023 | E30: =E11 -> 2024 | F30: =F11 -> 2025 | G30: =G11 -> 2026 | H30: =H11 -> 2027 | I30: =I11 -> 2028 | J30: =J11 -> 2029
B31: Excess Cash | F31: =BalSheet!F17 -> 1110.0125 | G31: =BalSheet!G17 -> 1823.7548 | H31: =BalSheet!H17 -> 2676.211 | I31: =BalSheet!I17 -> 3625.6113 | J31: =BalSheet!J17 -> 4596.5597
B32: Interest rate | F32: =F6 -> 0.04 | G32: =G6 -> 0.04 | H32: =H6 -> 0.04 | I32: =I6 -> 0.04 | J32: =J6 -> 0.04
B33: Interest income | F33: =F31*F32 -> 44.4005 | G33: =G31*G32 -> 72.950192 | H33: =H31*H32 -> 107.04844 | I33: =I31*I32 -> 145.02445 | J33: =J31*J32 -> 183.86239

Sheet IncState
A1: =CoName -> Darden Restaurants Inc | C1: Hist. | D1: Hist. | E1: Hist. | F1: Proj. | G1: Proj. | H1: Proj. | I1: Proj. | J1: Proj.
A2: Assumptions | C2: 2022 | D2: =C2+1 -> 2023 | E2: =D2+1 -> 2024 | F2: =E2+1 -> 2025 | G2: =F2+1 -> 2026 | H2: =G2+1 -> 2027 | I2: =H2+1 -> 2028 | J2: =I2+1 -> 2029
B4: Revenue growth | F4: =Assumptions!F10 -> 0.082 | G4: =Assumptions!G10 -> 0.037 | H4: =Assumptions!H10 -> 0.05 | I4: =Assumptions!I10 -> 0.055 | J4: =Assumptions!J10 -> 0.05
B5: Cost of goods sold as % of sales | F5: =Assumptions!F11 -> 0.77618195 | G5: =Assumptions!G11 -> 0.77118195 | H5: =Assumptions!H11 -> 0.76618195 | I5: =Assumptions!I11 -> 0.76118195 | J5: =Assumptions!J11 -> 0.75618195
B6: SG&A % of sales | F6: =Assumptions!F12 -> 0.1019401 | G6: =Assumptions!G12 -> 0.1044401 | H6: =Assumptions!H12 -> 0.1069401 | I6: =Assumptions!I12 -> 0.1094401 | J6: =Assumptions!J12 -> 0.1119401
B7: Amortization amount | F7: =Assumptions!F13 -> 0 | G7: =Assumptions!G13 -> 0 | H7: =Assumptions!H13 -> 0 | I7: =Assumptions!I13 -> 0 | J7: =Assumptions!J13 -> 0
B8: Non recurring items, amount | F8: =Assumptions!F14 -> 0 | G8: =Assumptions!G14 -> 0 | H8: =Assumptions!H14 -> 0 | I8: =Assumptions!I14 -> 0 | J8: =Assumptions!J14 -> 0
B9: Other income (expense), amt | F9: =Assumptions!F15 -> 0 | G9: =Assumptions!G15 -> 0 | H9: =Assumptions!H15 -> 0 | I9: =Assumptions!I15 -> 0 | J9: =Assumptions!J15 -> 0
B10: Effective tax rate | F10: =Assumptions!F16 -> 0.21 | G10: =Assumptions!G16 -> 0.21 | H10: =Assumptions!H16 -> 0.21 | I10: =Assumptions!I16 -> 0.21 | J10: =Assumptions!J16 -> 0.21
B11: Dividend Payout Rate | F11: =Assumptions!F17 -> 5.9504552 | G11: =Assumptions!G17 -> 6.3051657 | H11: =Assumptions!H17 -> 6.6598761 | I11: =Assumptions!I17 -> 7.0145866 | J11: =Assumptions!J17 -> 7.3692971
B12: Basic WASO | F12: =Assumptions!F18 -> 117.5 | G12: =Assumptions!G18 -> 117.5 | H12: =Assumptions!H18 -> 117.5 | I12: =Assumptions!I18 -> 117.5 | J12: =Assumptions!J18 -> 117.5
B13: Diluted WASO | F13: =Assumptions!F19 -> 118.4 | G13: =Assumptions!G19 -> 118.4 | H13: =Assumptions!H19 -> 118.4 | I13: =Assumptions!I19 -> 118.4 | J13: =Assumptions!J19 -> 118.4
A15: Income statement | C15: =C37 -> 44926 | D15: =D37 -> 45291 | E15: =E37 -> 45657 | F15: =F37 -> 46022 | G15: =G37 -> 46022 | H15: =H37 -> 46022 | I15: =I37 -> 46022 | J15: =J37 -> 46022
B16: Revenue | C16: 10487.8 | D16: 11390 | E16: 12076.7 | F16: =E16*(1+F4) -> 13066.989 | G16: =F16*(1+G4) -> 13550.468 | H16: =G16*(1+H4) -> 14227.991 | I16: =H16*(1+I4) -> 15010.531 | J16: =I16*(1+J4) -> 15761.057
B17: COGS | C17: =3355.9+3346.3+1676.3 -> 8378.5 | D17: =3523.9+3619.3+1812.3 -> 8955.5 | E17: =3657+3833.1+1944 -> 9434.1 | F17: =F16*F5 -> 10142.361 | G17: =G16*G5 -> 10449.876 | H17: =H16*H5 -> 10901.23 | I17: =I16*I5 -> 11425.745 | J17: =J16*J5 -> 11918.227
B18: SG&A | C18: =118.3+25.9+386.1+387.8 -> 918.1 | D18: =144.5+24.3+479.2+459.9 -> 1107.9 | E18: =169.9+24.8+520.3+516.1 -> 1231.1 | F18: =F16*F6 -> 1332.0502 | G18: =G16*G6 -> 1415.2122 | H18: =H16*H6 -> 1521.5428 | I18: =I16*I6 -> 1642.754 | J18: =J16*J6 -> 1764.2943
A19: * | B19: EBIT | C19: =C16-SUM(C17:C18) -> 1191.2 | D19: =D16-SUM(D17:D18) -> 1326.6 | E19: =E16-SUM(E17:E18) -> 1411.5 | F19: =F16-SUM(F17:F18) -> 1592.5779 | G19: =G16-SUM(G17:G18) -> 1685.3795 | H19: =H16-SUM(H17:H18) -> 1805.2185 | I19: =I16-SUM(I17:I18) -> 1942.0318 | J19: =J16-SUM(J17:J18) -> 2078.536
B21: Depreciation | C21: 387.8 | D21: 459.9 | E21: 516.1 | F21: =Calcs!F8 -> 560.72391 | G21: =Calcs!G8 -> 569.96151 | H21: =Calcs!H8 -> 580.32107 | I21: =Calcs!I8 -> 592.42815 | J21: =Calcs!J8 -> 606.54401
B22: Amortization | C22: 0 | D22: 0 | E22: 0 | F22: =F7 -> 0 | G22: =G7 -> 0 | H22: =H7 -> 0 | I22: =I7 -> 0 | J22: =J7 -> 0
A23: * | B23: EBITDA | C23: =SUM(C19,C21:C22) -> 1579 | D23: =SUM(D19,D21:D22) -> 1786.5 | E23: =SUM(E19,E21:E22) -> 1927.6 | F23: =SUM(F19,F21:F22) -> 2153.3019 | G23: =SUM(G19,G21:G22) -> 2255.341 | H23: =SUM(H19,H21:H22) -> 2385.5395 | I23: =SUM(I19,I21:I22) -> 2534.4599 | J23: =SUM(J19,J21:J22) -> 2685.08
B25: Non-recurring items | C25: 10.6 | D25: -12.4 | E25: -49.2 | F25: =F8 -> 0 | G25: =G8 -> 0 | H25: =H8 -> 0 | I25: =I8 -> 0 | J25: =J8 -> 0
B26: Other income (expense) | F26: =F9 -> 0 | G26: =G9 -> 0 | H26: =H9 -> 0 | I26: =I9 -> 0 | J26: =J9 -> 0
B28: Interest income | F28: =IF(circ=1,Debt!F33,0) -> 0 | G28: =IF(circ=1,Debt!G33,0) -> 0 | H28: =IF(circ=1,Debt!H33,0) -> 0 | I28: =IF(circ=1,Debt!I33,0) -> 0 | J28: =IF(circ=1,Debt!J33,0) -> 0
B29: Interest expense | C29: -81.3 | D29: -138.1 | E29: -175.1 | F29: =IF(circ=1,Debt!F28,0) -> 0 | G29: =IF(circ=1,Debt!G28,0) -> 0 | H29: =IF(circ=1,Debt!H28,0) -> 0 | I29: =IF(circ=1,Debt!I28,0) -> 0 | J29: =IF(circ=1,Debt!J28,0) -> 0
A31: * | B31: Pretax Income | C31: =C19+SUM(C26:C29) -> 1109.9 | D31: =D19+SUM(D26:D29) -> 1188.5 | E31: =E19+SUM(E25:E29) -> 1187.2 | F31: =F19+SUM(F25:F29) -> 1592.5779 | G31: =G19+SUM(G25:G29) -> 1685.3795 | H31: =H19+SUM(H25:H29) -> 1805.2185 | I31: =I19+SUM(I25:I29) -> 1942.0318 | J31: =J19+SUM(J25:J29) -> 2078.536
B33: Tax expense | C33: 137 | D33: 145 | E33: 136.2 | F33: =F31*F10 -> 334.44137 | G33: =G31*G10 -> 353.9297 | H33: =H31*H10 -> 379.09588 | I33: =I31*I10 -> 407.82668 | J33: =J31*J10 -> 436.49257
A34: * | B34: Net income | C34: =C31-C33 -> 972.9 | D34: =D31-D33 -> 1043.5 | E34: =E31-E33 -> 1051 | F34: =F31-F33 -> 1258.1366 | G34: =G31-G33 -> 1331.4498 | H34: =H31-H33 -> 1426.1226 | I34: =I31-I33 -> 1534.2051 | J34: =J31-J33 -> 1642.0435
B35: Dividend payout rate | C35: =C36/C38 -> 4.8383921 | D35: =D36/D38 -> 5.2410342 | E35: =E36/E38 -> 5.5957447 | F35: =F11 -> 5.9504552 | G35: =G11 -> 6.3051657 | H35: =H11 -> 6.6598761 | I35: =I11 -> 7.0145866 | J35: =J11 -> 7.3692971
B36: Dividends | C36: 589.8 | D36: 628.4 | E36: 657.5 | F36: =F35*F38 -> 699.17848 | G36: =G35*G38 -> 740.85696 | H36: =H35*H38 -> 782.53545 | I36: =I35*I38 -> 824.21393 | J36: =J35*J38 -> 865.89241
A37: Shareholder information | C37: 44926 | D37: 45291 | E37: 45657 | F37: 46022 | G37: 46022 | H37: 46022 | I37: 46022 | J37: 46022
B38: Basic WASO | C38: 121.9 | D38: 119.9 | E38: 117.5 | F38: =F12 -> 117.5 | G38: =G12 -> 117.5 | H38: =H12 -> 117.5 | I38: =I12 -> 117.5 | J38: =J12 -> 117.5
B39: Diluted WASO | C39: 122.9 | D39: 120.8 | E39: 118.4 | F39: =F13 -> 118.4 | G39: =G13 -> 118.4 | H39: =H13 -> 118.4 | I39: =I13 -> 118.4 | J39: =J13 -> 118.4
B40: Basic earnings per share | C40: =C34/C38 -> 7.9811321 | D40: =D34/D38 -> 8.7030859 | E40: =E34/E38 -> 8.9446809 | F40: =F34/F38 -> 10.707545 | G40: =G34/G38 -> 11.331488 | H40: =H34/H38 -> 12.137213 | I40: =I34/I38 -> 13.057065 | J40: =J34/J38 -> 13.974838
A41: * | B41: Diluted earnings per share | C41: =C34/C39 -> 7.916192 | D41: =D34/D39 -> 8.638245 | E41: =E34/E39 -> 8.8766892 | F41: =F34/F39 -> 10.626154 | G41: =G34/G39 -> 11.245353 | H41: =H34/H39 -> 12.044954 | I41: =I34/I39 -> 12.957814 | J41: =J34/J39 -> 13.86861

Sheet BalSheet
A1: =CoName -> Darden Restaurants Inc | C1: Hist. | D1: Hist. | E1: Hist. | F1: Proj. | G1: Proj. | H1: Proj. | I1: Proj. | J1: Proj.
A2: Assumptions | C2: 2022 | D2: =C2+1 -> 2023 | E2: =D2+1 -> 2024 | F2: =E2+1 -> 2025 | G2: =F2+1 -> 2026 | H2: =G2+1 -> 2027 | I2: =H2+1 -> 2028 | J2: =I2+1 -> 2029
B4: Operating Cash % of sales | F4: =Assumptions!F44 -> 0.01 | G4: =F4 -> 0.01 | H4: =G4 -> 0.01 | I4: =H4 -> 0.01 | J4: =I4 -> 0.01
B5: Accounts receivable % of sales | F5: =Assumptions!F45 -> 0.0077670224 | G5: =Assumptions!G45 -> 0.0077670224 | H5: =Assumptions!H45 -> 0.0077670224 | I5: =Assumptions!I45 -> 0.0077670224 | J5: =Assumptions!J45 -> 0.0077670224
B6: Inventories % of COGS | F6: =Assumptions!F46 -> 0.033029118 | G6: =Assumptions!G46 -> 0.033029118 | H6: =Assumptions!H46 -> 0.033029118 | I6: =Assumptions!I46 -> 0.033029118 | J6: =Assumptions!J46 -> 0.033029118
B7: Other current assets % of sales | F7: =Assumptions!F47 -> 0.024203632 | G7: =Assumptions!G47 -> 0.024203632 | H7: =Assumptions!H47 -> 0.024203632 | I7: =Assumptions!I47 -> 0.024203632 | J7: =Assumptions!J47 -> 0.024203632
B9: Other long-term assets % of sales | F9: =Assumptions!F49 -> 0.030769995 | G9: =Assumptions!G49 -> 0.030769995 | H9: =Assumptions!H49 -> 0.030769995 | I9: =Assumptions!I49 -> 0.030769995 | J9: =Assumptions!J49 -> 0.030769995
B11: Accounts payable/Accural % of COGS | F11: =Assumptions!F53 -> 0.069089791 | G11: =Assumptions!G53 -> 0.069089791 | H11: =Assumptions!H53 -> 0.069089791 | I11: =Assumptions!I53 -> 0.069089791 | J11: =Assumptions!J53 -> 0.069089791
B12: Other current liabilities % of sales | F12: =Assumptions!F54 -> 0.13213047 | G12: =Assumptions!G54 -> 0.13213047 | H12: =Assumptions!H54 -> 0.13213047 | I12: =Assumptions!I54 -> 0.13213047 | J12: =Assumptions!J54 -> 0.13213047
B13: Other long-term liabilities % of sales | F13: =Assumptions!F55 -> 0.48848609 | G13: =Assumptions!G55 -> 0.48848609 | H13: =Assumptions!H55 -> 0.48848609 | I13: =Assumptions!I55 -> 0.48848609 | J13: =Assumptions!J55 -> 0.48848609
A15: Balance sheet | C15: =C2 -> 2022 | D15: =D2 -> 2023 | E15: =E2 -> 2024 | F15: =F2 -> 2025 | G15: =G2 -> 2026 | H15: =H2 -> 2027 | I15: =I2 -> 2028 | J15: =J2 -> 2029
B16: Operating Cash | C16: =1%*IncState!C16 -> 104.878 | D16: =1%*IncState!D16 -> 113.9 | E16: =1%*IncState!E16 -> 120.767 | F16: =F4*IncState!F16 -> 130.66989 | G16: =G4*IncState!G16 -> 135.50468 | H16: =H4*IncState!H16 -> 142.27991 | I16: =I4*IncState!I16 -> 150.10531 | J16: =J4*IncState!J16 -> 157.61057
B17: Excess cash | C17: =367.8-C16 -> 262.922 | D17: =194.8-D16 -> 80.9 | E17: =240-E16 -> 119.233 | F17: =MAX(CashFlow!F23,0) -> 1110.0125 | G17: =MAX(CashFlow!G23,0) -> 1823.7548 | H17: =MAX(CashFlow!H23,0) -> 2676.211 | I17: =MAX(CashFlow!I23,0) -> 3625.6113 | J17: =MAX(CashFlow!J23,0) -> 4596.5597
B18: Accounts receivable | C18: 80.2 | D18: 79.1 | E18: 93.8 | F18: =F5*IncState!F16 -> 101.4916 | G18: =G5*IncState!G16 -> 105.24679 | H18: =H5*IncState!H16 -> 110.50913 | I18: =I5*IncState!I16 -> 116.58713 | J18: =J5*IncState!J16 -> 122.41649
B19: Inventories | C19: 287.9 | D19: 290.5 | E19: 311.6 | F19: =F6*IncState!F17 -> 334.99324 | G19: =G6*IncState!G17 -> 345.15019 | H19: =H6*IncState!H17 -> 360.05801 | I19: =I6*IncState!I17 -> 377.38228 | J19: =J6*IncState!J17 -> 393.64853
B20: Other current assets | C20: =107.3+154.5 -> 261.8 | D20: =121.7+136.7 -> 258.4 | E20: =135.6+156.7 -> 292.3 | F20: =F7*IncState!F16 -> 316.2686 | G20: =G7*IncState!G16 -> 327.97054 | H20: =H7*IncState!H16 -> 344.36907 | I20: =I7*IncState!I16 -> 363.30936 | J20: =J7*IncState!J16 -> 381.47483
B21: Total current assets | C21: =SUM(C16:C20) -> 997.7 | D21: =SUM(D16:D20) -> 822.8 | E21: =SUM(E16:E20) -> 937.7 | F21: =SUM(F16:F20) -> 1993.4358 | G21: =SUM(G16:G20) -> 2737.627 | H21: =SUM(H16:H20) -> 3633.4271 | I21: =SUM(I16:I20) -> 4632.9954 | J21: =SUM(J16:J20) -> 5651.7102
B23: Property, plant & equipment, net | C23: =3725.1+3373.9 -> 7099 | D23: =4184.3+3429.3 -> 7613.6 | E23: =4716+3555.9 -> 8271.9 | F23: =Calcs!F9 -> 8408.1747 | G23: =Calcs!G9 -> 8561.0007 | H23: =Calcs!H9 -> 8739.6066 | I23: =Calcs!I9 -> 8947.8463 | J23: =Calcs!J9 -> 9182.0036
B24: Intangible assets | C24: =1037.4+806.3 -> 1843.7 | D24: =1391+1148 -> 2539 | E24: =1659.4+1346.4 -> 3005.8 | F24: =E24-IncState!F22 -> 3005.8 | G24: =F24-IncState!G22 -> 3005.8 | H24: =G24-IncState!H22 -> 3005.8 | I24: =H24-IncState!I22 -> 3005.8 | J24: =I24-IncState!J22 -> 3005.8
B25: Other assets | C25: 301.1 | D25: 347.6 | E25: 371.6 | F25: =F9*IncState!F16 -> 402.0712 | G25: =G9*IncState!G16 -> 416.94783 | H25: =H9*IncState!H16 -> 437.79523 | I25: =I9*IncState!I16 -> 461.87396 | J25: =J9*IncState!J16 -> 484.96766
B26: Total non-current assets | C26: =SUM(C23:C25) -> 9243.8 | D26: =SUM(D23:D25) -> 10500.2 | E26: =SUM(E23:E25) -> 11649.3 | F26: =SUM(F23:F25) -> 11816.046 | G26: =SUM(G23:G25) -> 11983.749 | H26: =SUM(H23:H25) -> 12183.202 | I26: =SUM(I23:I25) -> 12415.52 | J26: =SUM(J23:J25) -> 12672.771
A28: * | B28: TOTAL ASSETS | C28: =SUM(C26,C21) -> 10241.5 | D28: =SUM(D26,D21) -> 11323 | E28: =SUM(E26,E21) -> 12587 | F28: =SUM(F26,F21) -> 13809.482 | G28: =SUM(G26,G21) -> 14721.376 | H28: =SUM(H26,H21) -> 15816.629 | I28: =SUM(I26,I21) -> 17048.516 | J28: =SUM(J26,J21) -> 18324.481
B30: Revolver/Short term debt | C30: 0 | D30: 86.8 | E30: 0 | F30: =MIN(CashFlow!F23,0) -> 0 | G30: =MIN(CashFlow!G23,0) -> 0 | H30: =MIN(CashFlow!H23,0) -> 0 | I30: =MIN(CashFlow!I23,0) -> 0 | J30: =MIN(CashFlow!J23,0) -> 0
B31: Accounts payable/Accurals | C31: =426.2+173+7.8 -> 607 | D31: =399.5+190.1+6.1 -> 595.7 | E31: =439.6+207.5+4.7 -> 651.8 | F31: =F11*IncState!F17 -> 700.73362 | G31: =G11*IncState!G17 -> 721.97977 | H31: =H11*IncState!H17 -> 753.16371 | I31: =I11*IncState!I17 -> 789.40235 | J31: =J11*IncState!J17 -> 823.42782
B32: Other current liabilities | C32: =65.9+512+752.5 -> 1330.4 | D32: =71+591.8+847.2 -> 1510 | E32: =83+599.4+913.3 -> 1595.7 | F32: =F12*IncState!F16 -> 1726.5474 | G32: =G12*IncState!G16 -> 1790.4297 | H32: =H12*IncState!H16 -> 1879.9511 | I32: =I12*IncState!I16 -> 1983.3484 | J32: =J12*IncState!J16 -> 2082.5159
B33: Total current liabilities | C33: =SUM(C30:C32) -> 1937.4 | D33: =SUM(D30:D32) -> 2192.5 | E33: =SUM(E30:E32) -> 2247.5 | F33: =SUM(F30:F32) -> 2427.281 | G33: =SUM(G30:G32) -> 2512.4094 | H33: =SUM(H30:H32) -> 2633.1149 | I33: =SUM(I30:I32) -> 2772.7508 | J33: =SUM(J30:J32) -> 2905.9437
B35: Long-term debt, including current maturities | C35: 884.9 | D35: 1370.4 | E35: 2128.9 | F35: =Debt!F20 -> 2128.9 | G35: =Debt!G20 -> 2128.9 | H35: =Debt!H20 -> 2128.9 | I35: =Debt!I20 -> 2128.9 | J35: =Debt!J20 -> 2128.9
B36: Other long-term liabilities | C36: =142.2+3667.6+1407.9 -> 5217.7 | D36: =232+3704.7+1580.9 -> 5517.6 | E36: =278.8+3816.9+1803.6 -> 5899.3 | F36: =F13*IncState!F16 -> 6383.0426 | G36: =G13*IncState!G16 -> 6619.2152 | H36: =H13*IncState!H16 -> 6950.1759 | I36: =I13*IncState!I16 -> 7332.4356 | J36: =J13*IncState!J16 -> 7699.0574
B37: Total non-current liabilities | C37: =SUM(C35:C36) -> 6102.6 | D37: =SUM(D35:D36) -> 6888 | E37: =SUM(E35:E36) -> 8028.2 | F37: =SUM(F35:F36) -> 8511.9426 | G37: =SUM(G35:G36) -> 8748.1152 | H37: =SUM(H35:H36) -> 9079.0759 | I37: =SUM(I35:I36) -> 9461.3356 | J37: =SUM(J35:J36) -> 9827.9574
B39: Equity | C39: 2201.5 | D39: 2242.5 | E39: 2311.3 | F39: =Calcs!F17 -> 2870.2581 | G39: =Calcs!G17 -> 3460.8509 | H39: =Calcs!H17 -> 4104.4381 | I39: =Calcs!I17 -> 4814.4293 | J39: =Calcs!J17 -> 5590.5803
A40: * | B40: TOTAL LIABILITIES & EQUITY | C40: =SUM(C39,C37,C33) -> 10241.5 | D40: =SUM(D39,D37,D33) -> 11323 | E40: =SUM(E39,E37,E33) -> 12587 | F40: =SUM(F39,F37,F33) -> 13809.482 | G40: =SUM(G39,G37,G33) -> 14721.376 | H40: =SUM(H39,H37,H33) -> 15816.629 | I40: =SUM(I39,I37,I33) -> 17048.516 | J40: =SUM(J39,J37,J33) -> 18324.481
A42: * | B42: Balance check | C42: =C40-C28 -> 0 | D42: =D40-D28 -> 0 | E42: =E40-E28 -> 0 | F42: =F40-F28 -> 0 | G42: =G40-G28 -> 0 | H42: =H40-H28 -> 0 | I42: =I40-I28 -> 0 | J42: =J40-J28 -> 0

Sheet CashFlow
A1: =CoName -> Darden Restaurants Inc | C1: Hist. | D1: Hist. | E1: Hist. | F1: Proj. | G1: Proj. | H1: Proj. | I1: Proj. | J1: Proj.
A2: Cash flow statement | C2: 2022 | D2: =C2+1 -> 2023 | E2: =D2+1 -> 2024 | F2: =E2+1 -> 2025 | G2: =F2+1 -> 2026 | H2: =G2+1 -> 2027 | I2: =H2+1 -> 2028 | J2: =I2+1 -> 2029
B3: Net Income | F3: =IncState!F34 -> 1258.1366 | G3: =IncState!G34 -> 1331.4498 | H3: =IncState!H34 -> 1426.1226 | I3: =IncState!I34 -> 1534.2051 | J3: =IncState!J34 -> 1642.0435
B4: Depreciation | F4: =IncState!F21 -> 560.72391 | G4: =IncState!G21 -> 569.96151 | H4: =IncState!H21 -> 580.32107 | I4: =IncState!I21 -> 592.42815 | J4: =IncState!J21 -> 606.54401
B5: Amortization | F5: =IncState!F22 -> 0 | G5: =IncState!G22 -> 0 | H5: =IncState!H22 -> 0 | I5: =IncState!I22 -> 0 | J5: =IncState!J22 -> 0
B6: (inc) / dec in OWC | F6: =Calcs!F26 -> 114.82468 | G6: =Calcs!G26 -> 54.679539 | H6: =Calcs!H26 -> 77.361506 | I6: =Calcs!I26 -> 89.467981 | J6: =Calcs!J26 -> 85.426564
B7: (inc) / dec in LT assets | F7: =BalSheet!E25-BalSheet!F25 -> -30.4712 | G7: =BalSheet!F25-BalSheet!G25 -> -14.876634 | H7: =BalSheet!G25-BalSheet!H25 -> -20.847392 | I7: =BalSheet!H25-BalSheet!I25 -> -24.078737 | J7: =BalSheet!I25-BalSheet!J25 -> -23.093698
B8: inc / (dec) in LT liabilties | F8: =BalSheet!F36-BalSheet!E36 -> 483.7426 | G8: =BalSheet!G36-BalSheet!F36 -> 236.17258 | H8: =BalSheet!H36-BalSheet!G36 -> 330.96076 | I8: =BalSheet!I36-BalSheet!H36 -> 382.25968 | J8: =BalSheet!J36-BalSheet!I36 -> 366.62178
B9: CFFO | F9: =SUM(F3:F8) -> 2386.9566 | G9: =SUM(G3:G8) -> 2177.3868 | H9: =SUM(H3:H8) -> 2393.9185 | I9: =SUM(I3:I8) -> 2574.2822 | J9: =SUM(J3:J8) -> 2677.5421
B11: Capex | F11: =-Calcs!F7 -> -696.99859 | G11: =-Calcs!G7 -> -722.78754 | H11: =-Calcs!H7 -> -758.92692 | I11: =-Calcs!I7 -> -800.6679 | J11: =-Calcs!J7 -> -840.70129
B12: CFFI | F12: =SUM(F11) -> -696.99859 | G12: =SUM(G11) -> -722.78754 | H12: =SUM(H11) -> -758.92692 | I12: =SUM(I11) -> -800.6679 | J12: =SUM(J11) -> -840.70129
B14: Dividends Paid | F14: =-IncState!F36 -> -699.17848 | G14: =-IncState!G36 -> -740.85696 | H14: =-IncState!H36 -> -782.53545 | I14: =-IncState!I36 -> -824.21393 | J14: =-IncState!J36 -> -865.89241
B15: Debt Issuance / (repayments) | F15: =SUM(Debt!F8:F9) -> 0 | G15: =SUM(Debt!G8:G9) -> 0 | H15: =SUM(Debt!H8:H9) -> 0 | I15: =SUM(Debt!I8:I9) -> 0 | J15: =SUM(Debt!J8:J9) -> 0
B16: Share issuance / (repurchases) | F16: =Calcs!F11 -> 0 | G16: =Calcs!G11 -> 0 | H16: =Calcs!H11 -> 0 | I16: =Calcs!I11 -> 0 | J16: =Calcs!J11 -> 0
B17: CFFF | F17: =SUM(F14:F16) -> -699.17848 | G17: =SUM(G14:G16) -> -740.85696 | H17: =SUM(H14:H16) -> -782.53545 | I17: =SUM(I14:I16) -> -824.21393 | J17: =SUM(J14:J16) -> -865.89241
B19: Net changes in cash | F19: =SUM(F17,F12,F9) -> 990.7795 | G19: =SUM(G17,G12,G9) -> 713.74229 | H19: =SUM(H17,H12,H9) -> 852.45616 | I19: =SUM(I17,I12,I9) -> 949.40036 | J19: =SUM(J17,J12,J9) -> 970.94842
B21: Beginning cash | F21: =BalSheet!E17 -> 119.233 | G21: =BalSheet!F17 -> 1110.0125 | H21: =BalSheet!G17 -> 1823.7548 | I21: =BalSheet!H17 -> 2676.211 | J21: =BalSheet!I17 -> 3625.6113
B22: =B19 -> Net changes in cash | F22: =F19 -> 990.7795 | G22: =G19 -> 713.74229 | H22: =H19 -> 852.45616 | I22: =I19 -> 949.40036 | J22: =J19 -> 970.94842
B23: Ending cash | F23: =SUM(F21:F22) -> 1110.0125 | G23: =SUM(G21:G22) -> 1823.7548 | H23: =SUM(H21:H22) -> 2676.211 | I23: =SUM(I21:I22) -> 3625.6113 | J23: =SUM(J21:J22) -> 4596.5597

Sheet Free Cash Flow
A1: =CoName -> Darden Restaurants Inc | C1: Hist. | D1: Hist. | E1: Hist. | F1: Proj. | G1: Proj. | H1: Proj. | I1: Proj. | J1: Proj.
A2: Free Cash Flows | C2: 2022 | D2: =C2+1 -> 2023 | E2: =D2+1 -> 2024 | F2: =E2+1 -> 2025 | G2: =F2+1 -> 2026 | H2: =G2+1 -> 2027 | I2: =H2+1 -> 2028 | J2: =I2+1 -> 2029
A3: * | B3: Sales | F3: =IncState!F16 -> 13066.989 | G3: =IncState!G16 -> 13550.468 | H3: =IncState!H16 -> 14227.991 | I3: =IncState!I16 -> 15010.531 | J3: =IncState!J16 -> 15761.057
B4: EBIT | F4: =IncState!F19 -> 1592.5779 | G4: =IncState!G19 -> 1685.3795 | H4: =IncState!H19 -> 1805.2185 | I4: =IncState!I19 -> 1942.0318 | J4: =IncState!J19 -> 2078.536
B5: Effective Tax Rate | F5: =Assumptions!F16 -> 0.21 | G5: =Assumptions!G16 -> 0.21 | H5: =Assumptions!H16 -> 0.21 | I5: =Assumptions!I16 -> 0.21 | J5: =Assumptions!J16 -> 0.21
A7: * | B7: NOPAT | F7: =F4*(1-F5) -> 1258.1366 | G7: =G4*(1-G5) -> 1331.4498 | H7: =H4*(1-H5) -> 1426.1226 | I7: =I4*(1-I5) -> 1534.2051 | J7: =J4*(1-J5) -> 1642.0435
B8: Depreciation | F8: =CashFlow!F4 -> 560.72391 | G8: =CashFlow!G4 -> 569.96151 | H8: =CashFlow!H4 -> 580.32107 | I8: =CashFlow!I4 -> 592.42815 | J8: =CashFlow!J4 -> 606.54401
B9: Amortization | F9: =CashFlow!F5 -> 0 | G9: =CashFlow!G5 -> 0 | H9: =CashFlow!H5 -> 0 | I9: =CashFlow!I5 -> 0 | J9: =CashFlow!J5 -> 0
B10: (inc) / dec in OWC | F10: =CashFlow!F6 -> 114.82468 | G10: =CashFlow!G6 -> 54.679539 | H10: =CashFlow!H6 -> 77.361506 | I10: =CashFlow!I6 -> 89.467981 | J10: =CashFlow!J6 -> 85.426564
B11: (inc) / dec in other long-term assets | F11: =CashFlow!F7 -> -30.4712 | G11: =CashFlow!G7 -> -14.876634 | H11: =CashFlow!H7 -> -20.847392 | I11: =CashFlow!I7 -> -24.078737 | J11: =CashFlow!J7 -> -23.093698
B12: inc / (dec) other long-term liabilities | F12: =CashFlow!F8 -> 483.7426 | G12: =CashFlow!G8 -> 236.17258 | H12: =CashFlow!H8 -> 330.96076 | I12: =CashFlow!I8 -> 382.25968 | J12: =CashFlow!J8 -> 366.62178
B13: (Capex) | F13: =CashFlow!F11 -> -696.99859 | G13: =CashFlow!G11 -> -722.78754 | H13: =CashFlow!H11 -> -758.92692 | I13: =CashFlow!I11 -> -800.6679 | J13: =CashFlow!J11 -> -840.70129
A15: * | B15: Free Cash Flow | F15: =SUM(F7:F13) -> 1689.958 | G15: =SUM(G7:G13) -> 1454.5993 | H15: =SUM(H7:H13) -> 1634.9916 | I15: =SUM(I7:I13) -> 1773.6143 | J15: =SUM(J7:J13) -> 1836.8408

Sheet WACC
A1: =CoName -> Darden Restaurants Inc
A3: * | B3: WACC | G3: Comp | H3: Levered beta | I3: Gross debt | J3: Market cap | K3: Debt/Mcap | L3: MTR | M3: Unlevered beta
B4: Tax Rate | E4: =Assumptions!F16 -> 0.21 | L4: =E4 -> 0.21 | M4: =H4/((1+K4*(1-L4))) -> 0
B5: Risk free rate | E5: 0.041 | L5: =L4 -> 0.21 | M5: =H5/((1+K5*(1-L5))) -> 0
B6: Market risk Premium | E6: 0.05 | L6: =L5 -> 0.21 | M6: =H6/((1+K6*(1-L6))) -> 0
B7: Beta | E7: 0.82 | L7: =L6 -> 0.21 | M7: =H7/((1+K7*(1-L7))) -> 0
B8: Cost of Equity | E8: =E5+E6*E7 -> 0.082
B9: % Equity | E9: =1-E10 -> 0.71081422 | G9: Industry beta (average) | M9: =AVERAGE(M4:M7) -> 0
B10: % Debt | E10: =MAIN!F8/MAIN!F6 -> 0.28918578
B11: Cost of debt | E11: =Assumptions!F24 -> 0.0486 | G11: Re-levered beta | M11: =M9*(1+E10*(1-E4)) -> 0
B12: Post tax cost of debt | E12: =E11*(1-E4) -> 0.038394
A13: * | B13: WACC | E13: =WACC!E8*WACC!E9+WACC!E12*WACC!E10 -> 0.069389765
B14: Long Term growth rate | E14: 0.025

Sheet DCF Model
A1: =CoName -> Darden Restaurants Inc | D1: Proj. | E1: Proj. | F1: Proj. | G1: Proj. | H1: Proj.
A2: Discount Model Year count | D2: 0.5 | E2: =D2+1 -> 1.5 | F2: =E2+1 -> 2.5 | G2: =F2+1 -> 3.5 | H2: =G2+1 -> 4.5
B3: Discount Factor | D3: =1/(1+$K$17)^D2 -> 0.96701228 | E3: =1/(1+$K$17)^E2 -> 0.90426551 | F3: =1/(1+$K$17)^F2 -> 0.8455902 | G3: =1/(1+$K$17)^G2 -> 0.79072218 | H3: =1/(1+$K$17)^H2 -> 0.73941439
B4: PV FCF | D4: =D3*'Free Cash Flow'!F15 -> 1634.2101 | E4: =E3*'Free Cash Flow'!G15 -> 1315.3439 | F4: =F3*'Free Cash Flow'!H15 -> 1382.5329 | G4: =G3*'Free Cash Flow'!I15 -> 1402.4362 | H4: =H3*'Free Cash Flow'!J15 -> 1358.1865 | I4: =(H4*(1+K18))/(K17-K18) -> 31361.761
A6: Value Calculation | E6: Multiples Calculation | I6: Dividend Discount Model
B7: Total PV of FCFs | C7: =SUM(D4:H4) -> 7092.7096 | E7: Total PV of FCFs | G7: =C7 -> 7092.7096 | I7: FY Dividend | K7: =IncState!J36 -> 865.89241
B8: PV of TV | C8: =I4*H3 -> 23189.337 | E8: Multiple TV | G8: =G10*H3*IncState!J23 -> 29780.802 | I8: Equity value | K8: =K7/(K17-K18) -> 19506.578
B9: EV | C9: =SUM(C7:C8) -> 30282.047 | E9: EV | G9: =SUM(G7:G8) -> 36873.512
E10: Exit Mult. | G10: 15 | I10: Diluted S/O | K10: =G17 -> 116.313
I11: Implied Share Price | K11: =K8/K10 -> 167.70763
B12: Cash & Cash Equiv | C12: =MAIN!F7 -> 211 | E12: Cash & Cash Equiv | G12: =C12 -> 211
B13: Debt & Claims | C13: =MAIN!F8 -> 6155.4 | E13: Debt & Claims | G13: =C13 -> 6155.4
B14: NCI | C14: 0 | E14: NCI | G14: =C14 -> 0
B15: Equity Value | C15: =C9+C12-SUM(C13:C14) -> 24337.647 | E15: Equity Value | G15: =G9+G12-SUM(G13:G14) -> 30929.112
B17: Diluted S/O | C17: =MAIN!F5 -> 116.313 | E17: Diluted S/O | G17: =C17 -> 116.313 | I17: WACC | K17: =WACC!E13 -> 0.069389765
A18: * | B18: Implied Share Price | C18: =C15/C17 -> 209.24271 | E18: Implied Share Price | G18: =G15/G17 -> 265.91277 | I18: Long Term growth rate | K18: 0.025
A20: Sensitivity analysis
C22: Discount rate variance | E22: 0.005 | H22: Discount rate variance | J22: 0.005
C23: Implied growth rate variance | E23: 0.0025 | H23: TV multiple variance | J23: 1
E25: LTGR | J25: Exit Mult.
C26: =C18 -> 209.24271 | D26: =E26-E23 -> 0.0225 | E26: 0.025 | F26: =E26+E23 -> 0.0275 | H26: =G18 -> 265.91277 | I26: =J26-J23 -> 14 | J26: 15 | K26: =J26+J23 -> 16
C27: =C28+$E$22 -> 0.079389765 | D27: 151.22611 | E27: 158.15089 | F27: 165.74292 | H27: =C27 -> 0.079389765 | I27: 237.68009 | J27: 254.04926 | K27: 270.41843
C28: =C29+$E$22 -> 0.074389765 | D28: 172.32826 | E28: 181.00526 | F28: 190.60752 | H28: =C28 -> 0.074389765 | I28: 243.19226 | J28: 259.90704 | K28: 276.62182
C29: 0.069389765 | D29: 198.15264 | E29: 209.24271 | F29: 221.65649 | H29: =C29 -> 0.069389765 | I29: 248.84342 | J29: 265.91277 | K29: 282.98211
C30: =C29-$E$22 -> 0.064389765 | D30: 230.40647 | E30: 244.93047 | F30: 261.42305 | H30: =C30 -> 0.064389765 | I30: 254.63779 | J30: 272.07094 | K30: 289.50409
C31: =C30-$E$22 -> 0.059389765 | D31: 271.7237 | E31: 291.33932 | F31: 314.03047 | H31: =C31 -> 0.059389765 | I31: 260.57974 | J31: 278.38622 | K31: 296.19269
