Workbook
Name Ccy: MAIN!$C$6
Name circ: MAIN!$C$9
Name CoName: MAIN!$C$4
Name g: #REF!
Name IQ_CH: 110000
Name IQ_CQ: 5000
Name IQ_CY: 10000
Name IQ_DAILY: 500000
Name IQ_FH: 100000
Name IQ_FQ: 500
Name IQ_FY: 1000
Name IQ_LTM: 2000
Name IQ_MONTH: 15000
Name IQ_NTM: 6000
Name IQ_WEEK: 50000
Name IQ_YTD: 3000
Name OpCase: [1]DCF!$E$98
Name ScenarioREV: Assumptions!$D$4
Name TTS: #REF!
Name Units: MAIN!$C$7

Sheet MAIN
A1: =CoName -> McDonald's Corp.
A2: Model Details
B4: Company name | C4: McDonald's Corp. | E4: Current Stock Price | F4: 311.01 | I4: Terminal Mult | J4: Perpetuity | K4: DDM | L4: Comps | M4: Average
B5: Latest BS date | C5: 247.43 | E5: Diluted s/o | F5: 712.15435 | H5: Implied Price | I5: ='DCF Model'!G18 -> 254.81765 | J5: ='DCF Model'!C18 -> 228.96027 | K5: ='DCF Model'!K18 -> 255.49088 | L5: =Comps!I9 -> 213.02645 | M5: =AVERAGE(I5:J5) -> 241.88896
B6: Currency | C6: USD | E6: Mkt Cap | F6: =F5*F4 -> 221487.12 | H6: Difference | I6: =I5/$F$4-1 -> -0.18067699 | J6: =J5/$F$4-1 -> -0.26381702 | K6: =K5/$F$4-1 -> -0.17851234 | L6: =L5/$F$4-1 -> -0.31504952 | M6: =M5/$F$4-1 -> -0.22224701
B7: Units | C7: m | E7: Cash | F7: 2413
B8: Analyst name | C8: Alan Chen | E8: Debt | F8: =1800+39483 -> 41283
B9: Circular switch | C9: 0 | E9: EV | F9: =F6-F7+F8 -> 260357.12

Sheet Quarterly Projections
A1: =CoName -> McDonald's Corp.
A2: Income Statement | C2: Q122 | D2: Q222 | E2: Q322 | F2: Q422 | G2: 2022 | H2: Q123 | I2: Q223 | J2: Q323 | K2: Q423 | L2: 2023 | M2: Q124 | N2: Q224 | O2: Q324 | P2: Q424 | Q2: 2024 | R2: Q125 | S2: Q225 | T2: Q325 | U2: Q425E | V2: 2025E | W2: Q126E | X2: Q226E | Y2: Q326E | Z2: Q426E | AA2: 2026E | AB2: 2027E | AC2: 2028E | AD2: 2029E
B3: Franchised resturants | C3: 3262.8 | D3: 3526.8 | E3: 3671.2 | F3: 3645 | G3: =SUM(C3:F3) -> 14105.8 | H3: 3587.5 | I3: 3933.3 | J3: 4047.1 | K3: 3869 | L3: =SUM(H3:K3) -> 15436.9 | M3: 3723 | N3: 3940 | O3: 4094 | P3: 3958 | Q3: =SUM(M3:P3) -> 15715 | R3: 3661 | S3: 4213 | T3: 4363 | U3: =P3*(1+U4) -> 4218.064 | V3: =SUM(R3:U3) -> 16455.064 | W3: =R3*(1+W4) -> 3931.914 | X3: =S3*(1+X4) -> 4423.65 | Y3: =T3*(1+Y4) -> 4572.424 | Z3: =U3*(1+Z4) -> 4445.8395 | AA3: =SUM(W3:Z3) -> 17373.827 | AB3: =AA3*(1+AB4) -> 18312.014 | AC3: =AB3*(1+AC4) -> 19300.863 | AD3: =AC3*(1+AD4) -> 20343.109
B4: y/y% | C4: n/a | D4: n/a | E4: n/a | F4: n/a | G4: n/a | H4: =H3/C3-1 -> 0.099515753 | I4: =I3/D3-1 -> 0.11526029 | J4: =J3/E3-1 -> 0.10239159 | K4: =K3/F3-1 -> 0.061454047 | L4: =L3/G3-1 -> 0.094365438 | M4: =M3/H3-1 -> 0.037770035 | N4: =N3/I3-1 -> 0.0017034043 | O4: =O3/J3-1 -> 0.011588545 | ... T4: =T3/O3-1 -> 0.065705911 | U4: =T4 -> 0.065705911 | V4: =V3/Q3-1 -> 0.047092841 | W4: 0.074 | X4: 0.05 | Y4: 0.048 | Z4: 0.054 | AA4: =AA3/V3-1 -> 0.055834694 | AB4: =Z4 -> 0.054 | AC4: =AB4 -> 0.054 | AD4: =AC4 -> 0.054
B5: Company owned resturants | C5: 2302.4 | D5: 2112.8 | E5: 2124.8 | F5: 2208.4 | G5: =SUM(C5:F5) -> 8748.4 | H5: 2224.3 | I5: 2487 | J5: 2556.2 | K5: 2474 | L5: =SUM(H5:K5) -> 9741.5 | M5: 2355 | N5: 2461 | O5: 2656 | P5: 2310 | Q5: =SUM(M5:P5) -> 9782 | R5: 2132 | S5: 2458 | T5: 2563 | U5: =P5*(1+U6) -> 2471.7 | V5: =SUM(R5:U5) -> 9624.7 | W5: =R5*(1+W6) -> 2281.24 | X5: =S5*(1+X6) -> 2630.06 | Y5: =T5*(1+Y6) -> 2742.41 | Z5: =U5*(1+Z6) -> 2644.719 | AA5: =SUM(W5:Z5) -> 10298.429 | AB5: =AA5*(1+AB6) -> 11019.319 | AC5: =AB5*(1+AC6) -> 11790.671 | AD5: =AC5*(1+AD6) -> 12616.018
B6: y/y% | C6: n/a | D6: n/a | E6: n/a | F6: n/a | G6: n/a | H6: =H5/C5-1 -> -0.033921126 | I6: =I5/D5-1 -> 0.17711094 | J6: =J5/E5-1 -> 0.20303087 | K6: =K5/F5-1 -> 0.12026807 | L6: =L5/G5-1 -> 0.1135179 | M6: =M5/H5-1 -> 0.058760059 | N6: =N5/I5-1 -> -0.010454363 | O6: =O5/J5-1 -> 0.039042328 | ... T6: =T5/O5-1 -> -0.03501506 | U6: 0.07 | V6: =V5/Q5-1 -> -0.016080556 | W6: 0.07 | X6: =W6 -> 0.07 | Y6: 0.07 | Z6: 0.07 | AA6: =AA5/V5-1 -> 0.07 | AB6: =Z6 -> 0.07 | AC6: =AB6 -> 0.07 | AD6: =AC6 -> 0.07
B7: Other | C7: 100.4 | D7: 78.8 | E7: 76.1 | F7: 73.1 | G7: =SUM(C7:F7) -> 328.4 | H7: 86 | I7: 77.2 | J7: 89 | K7: 63 | L7: =SUM(H7:K7) -> 315.2 | M7: 91 | N7: 89 | O7: 124 | P7: 120 | Q7: =SUM(M7:P7) -> 424 | R7: 162 | S7: 172 | T7: 151 | U7: =T7 -> 151 | V7: =SUM(R7:U7) -> 636 | W7: =U7 -> 151 | X7: =W7*1.05 -> 158.55 | Y7: =X7*1.05 -> 166.4775 | Z7: =Y7*1.05 -> 174.80138 | AA7: =SUM(W7:Z7) -> 650.82888 | AB7: =AA7*1.05 -> 683.37032 | AC7: =AB7*1.05 -> 717.53883 | AD7: =AC7*1.05 -> 753.41578
A8: Revenues | C8: =SUM(C3:C7) -> 5665.6 | D8: =SUM(D3:D7) -> 5718.4 | E8: =SUM(E3:E7) -> 5872.1 | F8: =SUM(F3:F7) -> 5926.5 | G8: =SUM(G3:G7) -> 23182.6 | H8: =SUM(H3:H7) -> 5897.8656 | I8: =SUM(I3:I7) -> 6497.7924 | J8: =SUM(J3:J7) -> 6692.6054 | ... AD8: =SUM(AD3:AD7) -> 33712.668
L9: =L8/G8-1 -> 0.099695801 | Q9: =Q8/L8-1 -> 0.016757571 | V9: =V8/Q8-1 -> 0.030661323 | AA9: =AA8/V8-1 -> 0.060167259 | AB9: =AB8/AA8-1 -> 0.059725443 | AC9: =AC8/AB8-1 -> 0.059782773 | AD9: =AD8/AC8-1 -> 0.059840257
B10: Franchised resturant expenses | C10: 584 | D10: 588.6 | E10: 589 | F10: 588.1 | G10: =SUM(C10:F10) -> 2349.7 | H10: 598.3 | I10: 618.2 | J10: 625.4 | K10: 633 | L10: =SUM(H10:K10) -> 2474.9 | M10: 627 | N10: 629 | O10: 646 | P10: 635 | Q10: =SUM(M10:P10) -> 2537 | R10: 620 | S10: 654 | T10: 666 | U10: =U11*U3 -> 643.87592 | V10: =SUM(R10:U10) -> 2583.8759 | W10: =W11*W3 -> 600.1959 | X10: =X11*X3 -> 675.25806 | Y10: =Y11*Y3 -> 697.968 | Z10: =Z11*Z3 -> 678.64522 | AA10: =SUM(W10:Z10) -> 2652.0672 | AB10: =AB11*AB3 -> 2795.2788 | AC10: =AC11*AC3 -> 2946.2239 | AD10: =AD11*AD3 -> 3105.3199
B11: Margin% | C11: =C10/C3 -> 0.17898737 | D11: =D10/D3 -> 0.1668935 | E11: =E10/E3 -> 0.160438 | F11: =F10/F3 -> 0.16134431 | G11: =G10/G3 -> 0.16657687 | H11: =H10/H3 -> 0.16677352 | I11: =I10/I3 -> 0.15717082 | J11: =J10/J3 -> 0.1545304 | ... T11: =T10/T3 -> 0.15264726 | U11: =T11 -> 0.15264726 | V11: =V10/V3 -> 0.15702618 | W11: 0.15264726 | X11: =W11 -> 0.15264726 | Y11: =X11 -> 0.15264726 | Z11: =Y11 -> 0.15264726 | AA11: =AA10/AA3 -> 0.15264726 | AB11: =AA11 -> 0.15264726 | AC11: =AB11 -> 0.15264726 | AD11: =AC11 -> 0.15264726
B12: Company owned resturant expenses | C12: 1959.2 | D12: 1769.8 | E12: 1779.6 | F12: 1872.3 | G12: =SUM(C12:F12) -> 7380.9 | H12: 1923.1 | I12: 2091.3 | J12: 2135 | K12: 2075 | L12: =SUM(H12:K12) -> 8224.4 | M12: 2035 | N12: 2074 | O12: 2248 | P12: 1977 | Q12: =SUM(M12:P12) -> 8334 | R12: 1859 | S12: 2078 | T12: 2172 | U12: =U5*U13 -> 2094.6283 | V12: =SUM(R12:U12) -> 8203.6283 | W12: =W5*W13 -> 1933.2241 | X12: =X5*X13 -> 2228.8296 | Y12: =Y5*Y13 -> 2324.04 | Z12: =Z5*Z13 -> 2241.2523 | AA12: =SUM(W12:Z12) -> 8727.346 | AB12: =AB5*AB13 -> 9338.2602 | AC12: =AC5*AC13 -> 9991.9384 | AD12: =AD5*AD13 -> 10691.374
B13: Margin% | C13: =C12/C5 -> 0.85093815 | D13: =D12/D5 -> 0.83765619 | E13: =E12/E5 -> 0.83753765 | F13: =F12/F5 -> 0.84780837 | G13: =G12/G5 -> 0.8436857 | H13: =H12/H5 -> 0.86458661 | I13: =I12/I5 -> 0.84089264 | J13: =J12/J5 -> 0.83522416 | ... T13: =T12/T5 -> 0.8474444 | U13: =T13 -> 0.8474444 | V13: =V12/V5 -> 0.85235159 | W13: =U13 -> 0.8474444 | X13: =W13 -> 0.8474444 | Y13: =X13 -> 0.8474444 | Z13: =Y13 -> 0.8474444 | AA13: =AA12/AA5 -> 0.8474444 | AB13: =AA13 -> 0.8474444 | AC13: =AB13 -> 0.8474444 | AD13: =AC13 -> 0.8474444
B14: Other resturant expenses | C14: 72.3 | D14: 57.9 | E14: 57.4 | F14: 57.2 | G14: =SUM(C14:F14) -> 244.8 | H14: 62.8 | I14: 57 | J14: 68 | K14: 45 | L14: =SUM(H14:K14) -> 232.8 | M14: 68 | N14: 69 | O14: 104 | P14: 98 | Q14: =SUM(M14:P14) -> 339 | R14: 140 | S14: 149 | T14: 135 | U14: =T14 -> 135 | V14: =SUM(R14:U14) -> 559 | W14: =U14 -> 135 | X14: =W14*1.05 -> 141.75 | Y14: =X14*1.05 -> 148.8375 | Z14: =Y14*1.05 -> 156.27938 | AA14: =SUM(W14:Z14) -> 581.86687 | AB14: =AA14*1.05 -> 610.96022 | AC14: =AB14*1.05 -> 641.50823 | AD14: =AC14*1.05 -> 673.58364
B15: SG&A | C15: =92.7+584.3+60.5 -> 737.5 | D15: =93+611.2+886.1 -> 1590.3 | E15: =93.3+576.4+12.5 -> 682.2 | F15: =91.4+720.3+14.5 -> 826.2 | G15: =SUM(C15:F15) -> 3836.2 | H15: =99.3+553.3+128.6 -> 781.2 | I15: =95.2+567.5-35.8 -> 626.9 | J15: =97+584-25 -> 656 | K15: =91+731+31 -> 853 | L15: =SUM(H15:K15) -> 2917.1 | M15: =99+622-17 -> 704 | N15: =101+590+107 -> 798 | O15: =111+536+39 -> 686 | P15: =136+664+10 -> 810 | Q15: =SUM(M15:P15) -> 2998 | R15: =107+575+7 -> 689 | S15: =106+595+29 -> 730 | T15: =121+664-37 -> 748 | U15: =U16*U8 -> 723.04236 | V15: =SUM(R15:U15) -> 2890.0424 | W15: =W16*W8 -> 763.71576 | X15: =X16*X8 -> 865.4856 | Y15: =Y16*Y8 -> 897.77154 | Z15: =Z16*Z8 -> 871.85806 | AA15: =SUM(W15:Z15) -> 3398.831 | AB15: =AB16*AB8 -> 3601.8276 | AC15: =AC16*AC8 -> 3817.1549 | AD15: =AD16*AD8 -> 4045.5744
B16: Margin% | C16: =C15/C8 -> 0.13017156 | D16: =D15/D8 -> 0.27810227 | E16: =E15/E8 -> 0.1161765 | F16: =F15/F8 -> 0.13940774 | G16: =G15/G8 -> 0.16547756 | H16: =H15/H8 -> 0.1324547 | I16: =I15/I8 -> 0.096478921 | J16: =J15/J8 -> 0.098018628 | ... T16: =T15/T8 -> 0.10569404 | U16: =T16 -> 0.10569404 | V16: =V15/V8 -> 0.10817729 | W16: 0.12 | X16: =W16 -> 0.12 | Y16: =X16 -> 0.12 | Z16: =Y16 -> 0.12 | AA16: =AA15/AA8 -> 0.12000161 | AB16: =AA16 -> 0.12000161 | AC16: =AB16 -> 0.12000161 | AD16: =AC16 -> 0.12000161
A18: Operating Income | C18: =C8-SUM(C10:C15) -> 2311.5701 | D18: =D8-SUM(D10:D15) -> 1710.7955 | E18: =E8-SUM(E10:E15) -> 2762.902 | F18: =F8-SUM(F10:F15) -> 2581.6908 | G18: =G8-SUM(G10:G15) -> 9369.9897 | H18: =H8-SUM(H10:H15) -> 2531.4342 | I18: =I8-SUM(I10:I15) -> 3103.3943 | J18: =J8-SUM(J10:J15) -> 3207.2157 | ... AD18: =AD8-SUM(AD10:AD15) -> 15195.815
A19: Operating Margin | V19: =V18/V8 -> 0.46707347 | AA19: =AA18/AA8 -> 0.45764938
B20: Interest expense | C20: 287.3 | D20: 290.6 | E20: 306.2 | F20: 322.9 | G20: =SUM(C20:F20) -> 1207 | H20: 329.7 | I20: 330.2 | J20: 341 | K20: 360 | L20: =SUM(H20:K20) -> 1360.9 | M20: 372 | N20: 373 | O20: 381 | P20: 380 | Q20: =SUM(M20:P20) -> 1506 | R20: 376 | S20: 390 | T20: 406 | V20: =SUM(R20:U20) -> 1172 | AA20: =SUM(W20:Z20) -> 0
A21: Pretax Income | C21: =C18-C20 -> 2024.2701 | D21: =D18-D20 -> 1420.1955 | E21: =E18-E20 -> 2456.702 | F21: =F18-F20 -> 2258.7908 | G21: =G18-G20 -> 8162.9897 | H21: =H18-H20 -> 2201.7342 | I21: =I18-I20 -> 2773.1943 | J21: =J18-J20 -> 2866.2157 | ... AD21: =AD18-AD20 -> 15195.815
B22: Tax rate | C22: =C23/C21 -> 0.21578148 | D22: =D23/D21 -> 0.1556828 | E22: =E23/E21 -> 0.2257498 | F22: =F23/F21 -> 0.19280227 | G22: =G23/G21 -> 0.20188682 | H22: =H23/H21 -> 0.2110609 | I22: =I23/I21 -> 0.18256925 | J22: =J23/J21 -> 0.21142861 | ... T22: =T23/T21 -> 0.2275324 | U22: 0.22 | V22: =V23/V21 -> 0.21700741 | W22: 0.22 | X22: 0.22 | Y22: 0.22 | Z22: 0.22 | AA22: =AA23/AA21 -> 0.21995553 | AB22: 0.22 | AC22: 0.22 | AD22: 0.22
B23: Taxes | C23: 436.8 | D23: 221.1 | E23: 554.6 | F23: 435.5 | G23: =SUM(C23:F23) -> 1648 | H23: 464.7 | I23: 506.3 | J23: 606 | K23: 476 | L23: =SUM(H23:K23) -> 2053 | M23: 479 | N23: 533 | O23: 588 | P23: 521 | Q23: =SUM(M23:P23) -> 2121 | R23: 461 | S23: 608 | T23: 671 | U23: =U21*U22 -> 713.53766 | V23: =SUM(R23:U23) -> 2453.5377 | W23: =W21*W22 -> 644.85568 | X23: =X21*X22 -> 726.01246 | Y23: =Y21*Y22 -> 750.59872 | Z23: =Z21*Z22 -> 729.61873 | AA23: =SUM(W23:Z23) -> 2851.0856 | AB23: =AB21*AB22 -> 3006.8501 | AC23: =AC21*AC22 -> 3170.5018 | AD23: =AD21*AD22 -> 3343.0794
A24: Net income | C24: =C21-C23 -> 1587.4701 | D24: =D21-D23 -> 1199.0955 | E24: =E21-E23 -> 1902.102 | F24: =F21-F23 -> 1823.2908 | G24: =G21-G23 -> 6514.9897 | H24: =H21-H23 -> 1737.0342 | I24: =I21-I23 -> 2266.8943 | J24: =J21-J23 -> 2260.2157 | ... AD24: =AD21-AD23 -> 11852.736

Sheet Assumptions
A1: =CoName -> McDonald's Corp. | C1: Hist. | D1: Hist. | E1: Hist. | F1: Proj. | G1: Proj. | H1: Proj. | I1: Proj. | J1: Proj.
A2: * | B2: Income Statement | C2: 2022 | D2: =C2+1 -> 2023 | E2: =D2+1 -> 2024 | F2: =E2+1 -> 2025 | G2: =F2+1 -> 2026 | H2: =G2+1 -> 2027 | I2: =H2+1 -> 2028 | J2: =I2+1 -> 2029
B4: Operating Case | D4: 1
D5: Variance
B6: Street Case | D6: 0 | F6: ='Quarterly Projections'!V9 -> 0.030661323 | G6: ='Quarterly Projections'!AA9 -> 0.060167259 | H6: ='Quarterly Projections'!AB9 -> 0.059725443 | I6: ='Quarterly Projections'!AC9 -> 0.059782773 | J6: ='Quarterly Projections'!AD9 -> 0.059840257
B7: Optimistic Case | D7: 0.025 | F7: =F6+$D$7 -> 0.055661323 | G7: =G6+$D$7 -> 0.085167259 | H7: =H6+$D$7 -> 0.084725443 | I7: =I6+$D$7 -> 0.084782773 | J7: =J6+$D$7 -> 0.084840257
B8: Pessimistic Case | D8: -0.025 | F8: =F6+$D$8 -> 0.0056613231 | G8: =G6+$D$8 -> 0.035167259 | H8: =H6+$D$8 -> 0.034725443 | I8: =I6+$D$8 -> 0.034782773 | J8: =J6+$D$8 -> 0.034840257
B10: Revenue Growth | D10: =IncState!D16/IncState!C16-1 -> 0.099695801 | E10: =IncState!E16/IncState!D16-1 -> 0.016757571 | F10: =CHOOSE(ScenarioREV,F6,F7,F8) -> 0.030661323 | G10: =CHOOSE(ScenarioREV,G6,G7,G8) -> 0.060167259 | H10: =CHOOSE(ScenarioREV,H6,H7,H8) -> 0.059725443 | I10: =CHOOSE(ScenarioREV,I6,I7,I8) -> 0.059782773 | J10: =CHOOSE(ScenarioREV,J6,J7,J8) -> 0.059840257
B11: COGS % of sales | C11: =IncState!C17/IncState!C16 -> 0.58521477 | D11: =IncState!D17/IncState!D16 -> 0.42881393 | E11: =IncState!E17/IncState!E16 -> 0.53504834 | F11: =E11 -> 0.53504834 | G11: =F11 -> 0.53504834 | H11: =G11 -> 0.53504834 | I11: =H11 -> 0.53504834 | J11: =I11 -> 0.53504834
B12: SG&A % of sales | C12: =IncState!C18/IncState!C16 -> 0.16547756 | D12: =IncState!D18/IncState!D16 -> 0.11442386 | E12: =IncState!E18/IncState!E16 -> 0.11565902 | F12: =E12 -> 0.11565902 | G12: =F12 -> 0.11565902 | H12: =G12 -> 0.11565902 | I12: =H12 -> 0.11565902 | J12: =I12 -> 0.11565902
B13: Amortization $ Amt | C13: =IncState!C22 -> 0 | D13: =IncState!D22 -> 0 | E13: =IncState!E22 -> 0 | F13: =E13 -> 0 | G13: =F13 -> 0 | H13: =G13 -> 0 | I13: =H13 -> 0 | J13: =I13 -> 0
B14: Non recurring income / (expense) | C14: =IncState!C25 -> 0 | D14: =IncState!D25 -> 0 | E14: =IncState!E25 -> 0 | F14: 0 | G14: 0 | H14: 0 | I14: 0 | J14: 0
B15: Other Income / (expense) | C15: =IncState!C26 -> 0 | D15: =IncState!D26 -> 0 | E15: =IncState!E26 -> 0 | F15: 0 | G15: 0 | H15: 0 | I15: 0 | J15: 0
B16: Effective tax rate | C16: =IncState!C33/IncState!C31 -> 0.33553221 | D16: =IncState!D33/IncState!D31 -> 0.19515937 | E16: =IncState!E33/IncState!E31 -> 0.27591959 | F16: 0.22 | G16: =F16 -> 0.22 | H16: =G16 -> 0.22 | I16: =H16 -> 0.22 | J16: =I16 -> 0.22
B17: Dividend Payout Rate | C17: =IncState!C35 -> 5.6591989 | D17: =IncState!D35 -> 6.2275038 | E17: =IncState!E35 -> 6.779897 | F17: =E17+(E17-D17) -> 7.3322902 | G17: =F17+(F17-E17) -> 7.8846834 | H17: =G17+(G17-F17) -> 8.4370766 | I17: =H17+(H17-G17) -> 8.9894698 | J17: =I17+(I17-H17) -> 9.541863
B18: Basic WASO | C18: =IncState!C38 -> 736.5 | D18: =IncState!D38 -> 727.9 | E18: =IncState!E38 -> 718.3 | F18: =E18 -> 718.3 | G18: =F18 -> 718.3 | H18: =G18 -> 718.3 | I18: =H18 -> 718.3 | J18: =I18 -> 718.3
B19: Diluted WASO | C19: =IncState!C39 -> 741.3 | D19: =IncState!D39 -> 732.3 | E19: =IncState!E39 -> 721.9 | F19: =E19 -> 721.9 | G19: =F19 -> 721.9 | H19: =G19 -> 721.9 | I19: =H19 -> 721.9 | J19: =I19 -> 721.9
A21: * | B21: Debt | C21: =C2 -> 2022 | D21: =D2 -> 2023 | E21: =E2 -> 2024 | F21: =F2 -> 2025 | G21: =G2 -> 2026 | H21: =H2 -> 2027 | I21: =I2 -> 2028 | J21: =J2 -> 2029
B23: Interest rate on Revolver | E23: =E24+0.04 -> 0.078 | F23: =E23 -> 0.078 | G23: =F23 -> 0.078 | H23: =G23 -> 0.078 | I23: =H23 -> 0.078 | J23: =I23 -> 0.078
B24: Interest rate on long-term debt | E24: 0.038 | F24: 0.05 | G24: =F24 -> 0.05 | H24: =G24 -> 0.05 | I24: =H24 -> 0.05 | J24: =I24 -> 0.05
B25: Interest rate on cash | C25: =IncState!C28/SUM(BalSheet!C17:C18) -> 0.13120211 | D25: =IncState!D28/SUM(BalSheet!D17:D18) -> 0.051539637 | E25: =IncState!E28/SUM(BalSheet!E17:E18) -> 0.1281106 | F25: =AVERAGE(C25:E25) -> 0.10361745 | G25: =F25 -> 0.10361745 | H25: =G25 -> 0.10361745 | I25: =H25 -> 0.10361745 | J25: =I25 -> 0.10361745
B27: Issuance of long-term debt | E27: 0 | F27: 0 | G27: 0 | H27: 0 | I27: 0 | J27: 0
B28: Repayment of long-term debt | E28: 0 | F28: 0 | G28: 0 | H28: 0 | I28: 0 | J28: 0
A30: * | B30: Calcs | C30: =C21 -> 2022 | D30: =D21 -> 2023 | E30: =E21 -> 2024 | F30: =F21 -> 2025 | G30: =G21 -> 2026 | H30: =H21 -> 2027 | I30: =I21 -> 2028 | J30: =J21 -> 2029
B32: CapEx % of Sales | F32: =3200/IncState!F16 -> 0.11977933 | G32: =F32-0.02 -> 0.099779329 | H32: =G32-0.02 -> 0.079779329 | I32: =H32-0.02 -> 0.059779329 | J32: =I32-0.02 -> 0.039779329
B33: Depreciation % of beginning PP&E | D33: =IncState!D21/BalSheet!C24 -> 0.010512035 | E33: =IncState!E21/BalSheet!D24 -> 0.01163396 | F33: =E33 -> 0.01163396 | G33: =F33 -> 0.01163396 | H33: =G33 -> 0.01163396 | I33: =H33 -> 0.01163396 | J33: =I33 -> 0.01163396
B34: Share issuance / (repurchases) | F34: 0 | G34: 0 | H34: 0 | I34: 0 | J34: 0
A36: * | B36: Shareholder information | C36: =C30 -> 2022 | D36: =D30 -> 2023 | E36: =E30 -> 2024 | F36: =F30 -> 2025 | G36: =G30 -> 2026 | H36: =H30 -> 2027 | I36: =I30 -> 2028 | J36: =J30 -> 2029
B38: =B17 -> Dividend Payout Rate | C38: =C17 -> 5.6591989 | D38: =D17 -> 6.2275038 | E38: =E17 -> 6.779897 | F38: =F17 -> 7.3322902 | G38: =G17 -> 7.8846834 | H38: =H17 -> 8.4370766 | I38: =I17 -> 8.9894698 | J38: =J17 -> 9.541863
B39: Basic WASO | C39: =C18 -> 736.5 | D39: =D18 -> 727.9 | E39: =E18 -> 718.3 | F39: =F18 -> 718.3 | G39: =G18 -> 718.3 | H39: =H18 -> 718.3 | I39: =I18 -> 718.3 | J39: =J18 -> 718.3
B40: Diluted WASO | C40: =C19 -> 741.3 | D40: =D19 -> 732.3 | E40: =E19 -> 721.9 | F40: =F19 -> 721.9 | G40: =G19 -> 721.9 | H40: =H19 -> 721.9 | I40: =I19 -> 721.9 | J40: =J19 -> 721.9
A42: * | B42: Balance Sheet - Assets | C42: =C36 -> 2022 | D42: =D36 -> 2023 | E42: =E36 -> 2024 | F42: =F36 -> 2025 | G42: =G36 -> 2026 | H42: =H36 -> 2027 | I42: =I36 -> 2028 | J42: =J36 -> 2029
B44: Operating Cash % of sales | C44: =BalSheet!C17/IncState!C16 -> 0.015 | D44: =BalSheet!D17/IncState!D16 -> 0.015 | E44: =BalSheet!E17/IncState!E16 -> 0.015 | F44: =E44 -> 0.015 | G44: =F44 -> 0.015 | H44: =G44 -> 0.015 | I44: =H44 -> 0.015 | J44: =I44 -> 0.015
B45: Accounts receivable % of sales | C45: =BalSheet!C19/IncState!C16 -> 0.091232217 | D45: =BalSheet!D19/IncState!D16 -> 0.097592326 | E45: =BalSheet!E19/IncState!E16 -> 0.091933103 | F45: =E45 -> 0.091933103 | G45: =F45 -> 0.091933103 | H45: =G45 -> 0.091933103 | I45: =H45 -> 0.091933103 | J45: =I45 -> 0.091933103
B46: Inventories % of COGS | C46: =BalSheet!C20/IncState!C17 -> 0.0038328862 | D46: =BalSheet!D20/IncState!D17 -> 0.0048481079 | E46: =BalSheet!E20/IncState!E17 -> 0.0040377821 | F46: =E46 -> 0.0040377821 | G46: =F46 -> 0.0040377821 | H46: =G46 -> 0.0040377821 | I46: =H46 -> 0.0040377821 | J46: =I46 -> 0.0040377821
B47: Other current assets % of sales | C47: =BalSheet!C21/IncState!C16 -> 0.029047648 | D47: =BalSheet!D21/IncState!D16 -> 0.033969033 | E47: =BalSheet!E21/IncState!E16 -> 0.041433551 | F47: =E47 -> 0.041433551 | G47: =F47 -> 0.041433551 | H47: =G47 -> 0.041433551 | I47: =H47 -> 0.041433551 | J47: =I47 -> 0.041433551
B49: Investments in unconsolidated entities | C49: =BalSheet!C26 -> 1064.5 | D49: =BalSheet!D26 -> 1080 | E49: =BalSheet!E26 -> 2710 | F49: =E49 -> 2710 | G49: =F49 -> 2710 | H49: =G49 -> 2710 | I49: =H49 -> 2710 | J49: =I49 -> 2710
B50: Other long-term assets % of sales | C50: =BalSheet!C27/IncState!C16 -> 0.20304884 | D50: =BalSheet!D27/IncState!D16 -> 0.22036724 | E50: =BalSheet!E27/IncState!E16 -> 0.23513733 | F50: =E50 -> 0.23513733 | G50: =F50 -> 0.23513733 | H50: =G50 -> 0.23513733 | I50: =H50 -> 0.23513733 | J50: =I50 -> 0.23513733
A52: * | B52: Balance Sheet - Liabilities | C52: =C42 -> 2022 | D52: =D42 -> 2023 | E52: =E42 -> 2024 | F52: =F42 -> 2025 | G52: =G42 -> 2026 | H52: =H42 -> 2027 | I52: =I42 -> 2028 | J52: =J42 -> 2029
B54: Accounts payable % of COGS | C54: =BalSheet!C33/IncState!C17 -> 0.072249904 | D54: =BalSheet!D33/IncState!D17 -> 0.10089553 | E54: =BalSheet!E33/IncState!E17 -> 0.074194246 | F54: =E54 -> 0.074194246 | G54: =F54 -> 0.074194246 | H54: =G54 -> 0.074194246 | I54: =H54 -> 0.074194246 | J54: =I54 -> 0.074194246
...

Sheet Calcs
A1: =CoName -> McDonald's Corp. | C1: Hist. | D1: Hist. | E1: Hist. | F1: Proj. | G1: Proj. | H1: Proj. | I1: Proj. | J1: Proj.
A2: Net PP&E | C2: 2022 | D2: =C2+1 -> 2023 | E2: =D2+1 -> 2024 | F2: =E2+1 -> 2025 | G2: =F2+1 -> 2026 | H2: =G2+1 -> 2027 | I2: =H2+1 -> 2028 | J2: =I2+1 -> 2029
B3: Capital expenditure % of sales | F3: =Assumptions!F32 -> 0.11977933 | G3: =Assumptions!G32 -> 0.099779329 | H3: =Assumptions!H32 -> 0.079779329 | I3: =Assumptions!I32 -> 0.059779329 | J3: =Assumptions!J32 -> 0.039779329
B4: Depreciation % of PP&E | F4: =Assumptions!F33 -> 0.01163396 | G4: =F4 -> 0.01163396 | H4: =G4 -> 0.01163396 | I4: =H4 -> 0.01163396 | J4: =I4 -> 0.01163396
B6: Beginning PP&E | F6: =E9 -> 38634 | G6: =F9 -> 41384.534 | H6: =G9 -> 43729.139 | I6: =H9 -> 45614.958 | J6: =I9 -> 46985.808
B7: Capex | F7: =F3*IncState!F16 -> 3200 | G7: =G3*IncState!G16 -> 2826.071 | H7: =H3*IncState!H16 -> 2394.5628 | I7: =I3*IncState!I16 -> 1901.5325 | J7: =J3*IncState!J16 -> 1341.0673
B8: Depreciation | F8: =F6*F4 -> 449.4664 | G8: =G6*G4 -> 481.466 | H8: =H6*H4 -> 508.74304 | I8: =I6*I4 -> 530.68259 | J8: =J6*J4 -> 546.631
B9: Ending PP&E | E9: =BalSheet!E24 -> 38634 | F9: =F6+F7-F8 -> 41384.534 | G9: =G6+G7-G8 -> 43729.139 | H9: =H6+H7-H8 -> 45614.958 | I9: =I6+I7-I8 -> 46985.808 | J9: =J6+J7-J8 -> 47780.245
A10: Equity | C10: =C2 -> 2022 | D10: =D2 -> 2023 | E10: =E2 -> 2024 | F10: =F2 -> 2025 | G10: =G2 -> 2026 | H10: =H2 -> 2027 | I10: =I2 -> 2028 | J10: =J2 -> 2029
B11: Share issuance/(repurchases) | F11: =Assumptions!F34 -> 0 | G11: =Assumptions!G34 -> 0 | H11: =Assumptions!H34 -> 0 | I11: =Assumptions!I34 -> 0 | J11: =Assumptions!J34 -> 0
B13: Beginning balance | F13: =E17 -> -3917 | G13: =F17 -> -1905.1123 | H13: =G17 -> 147.92916 | I13: =H17 -> 2265.0645 | J13: =I17 -> 4474.2886
B14: Net income | F14: =IncState!F34 -> 7278.6718 | G14: =IncState!G34 -> 7716.6095 | H14: =IncState!H34 -> 8177.4874 | I14: =IncState!I34 -> 8666.3603 | J14: =IncState!J34 -> 9184.9575
B15: Dividends paid | F15: =-IncState!F36 -> -5266.784 | G15: =-IncState!G36 -> -5663.5681 | H15: =-IncState!H36 -> -6060.3521 | I15: =-IncState!I36 -> -6457.1361 | J15: =-IncState!J36 -> -6853.9202
B16: Share issuance / (repurchase) | F16: =F11 -> 0 | G16: =G11 -> 0 | H16: =H11 -> 0 | I16: =I11 -> 0 | J16: =J11 -> 0
B17: Ending balance | E17: =BalSheet!E41 -> -3917 | F17: =SUM(F13:F16) -> -1905.1123 | G17: =SUM(G13:G16) -> 147.92916 | H17: =SUM(H13:H16) -> 2265.0645 | I17: =SUM(I13:I16) -> 4474.2886 | J17: =SUM(J13:J16) -> 6805.3259
A18: OWC | C18: =C10 -> 2022 | D18: =D10 -> 2023 | E18: =E10 -> 2024 | F18: =F10 -> 2025 | G18: =G10 -> 2026 | H18: =H10 -> 2027 | I18: =I10 -> 2028 | J18: =J10 -> 2029
B19: Operating Cash | E19: =BalSheet!E17 -> 388.81533 | F19: =BalSheet!F17 -> 400.73693 | G19: =BalSheet!G17 -> 424.84817 | H19: =BalSheet!H17 -> 450.22241 | I19: =BalSheet!I17 -> 477.13796 | J19: =BalSheet!J17 -> 505.69001
B20: =BalSheet!B20 -> Inventories | E20: =BalSheet!E19 -> 2383 | F20: =BalSheet!F19 -> 2456.0659 | G20: =BalSheet!G19 -> 2603.8407 | H20: =BalSheet!H19 -> 2759.3562 | I20: =BalSheet!I19 -> 2924.3182 | J20: =BalSheet!J19 -> 3099.3101
B21: =BalSheet!B19 -> Accounts receivable | E21: =BalSheet!E20 -> 56 | F21: =BalSheet!F20 -> 57.717034 | G21: =BalSheet!G20 -> 61.18971 | H21: =BalSheet!H20 -> 64.844292 | I21: =BalSheet!I20 -> 68.720864 | J21: =BalSheet!J20 -> 72.833138
B22: Other current assets | E22: =BalSheet!E21 -> 1074 | F22: =BalSheet!F21 -> 1106.9303 | G22: =BalSheet!G21 -> 1173.5312 | H22: =BalSheet!H21 -> 1243.6209 | I22: =BalSheet!I21 -> 1317.968 | J22: =BalSheet!J21 -> 1396.8355
B23: Accounts payables | E23: =BalSheet!E33 -> 1029 | F23: =BalSheet!F33 -> 1982.1583 | G23: =BalSheet!G33 -> 2101.4193 | H23: =BalSheet!H33 -> 2226.9275 | I23: =BalSheet!I33 -> 2360.0594 | J23: =BalSheet!J33 -> 2501.286
B24: Other current liabilities | E24: =BalSheet!E34 -> 2951 | F24: =BalSheet!F34 -> 3041.4816 | G24: =BalSheet!G34 -> 3224.4792 | H24: =BalSheet!H34 -> 3417.0626 | I24: =BalSheet!I34 -> 3621.3441 | J24: =BalSheet!J34 -> 3838.0463
A25: * | B25: OWC | E25: =SUM(E19:E22)-SUM(E23:E24) -> -78.184667 | F25: =SUM(F19:F22)-SUM(F23:F24) -> -1002.1897 | G25: =SUM(G19:G22)-SUM(G23:G24) -> -1062.4887 | H25: =SUM(H19:H22)-SUM(H23:H24) -> -1125.9463 | I25: =SUM(I19:I22)-SUM(I23:I24) -> -1193.2585 | J25: =SUM(J19:J22)-SUM(J23:J24) -> -1264.6634
B26: Change in OWC | F26: =E25-F25 -> 924.00502 | G26: =F25-G25 -> 60.299006 | H26: =G25-H25 -> 63.457607 | I26: =H25-I25 -> 67.312192 | J26: =I25-J25 -> 71.404895

Sheet Debt
A1: =CoName -> McDonald's Corp. | C1: Hist. | D1: Hist. | E1: Hist. | F1: Proj. | G1: Proj. | H1: Proj. | I1: Proj. | J1: Proj.
A2: Assumptions | C2: 2022 | D2: =C2+1 -> 2023 | E2: =D2+1 -> 2024 | F2: =E2+1 -> 2025 | G2: =F2+1 -> 2026 | H2: =G2+1 -> 2027 | I2: =H2+1 -> 2028 | J2: =I2+1 -> 2029
B4: Interest rate on revolver | F4: =Assumptions!F23 -> 0.078 | G4: =Assumptions!G23 -> 0.078 | H4: =Assumptions!H23 -> 0.078 | I4: =Assumptions!I23 -> 0.078 | J4: =Assumptions!J23 -> 0.078
B5: Interest rate on long-term debt | F5: =Assumptions!F24 -> 0.05 | G5: =Assumptions!G24 -> 0.05 | H5: =Assumptions!H24 -> 0.05 | I5: =Assumptions!I24 -> 0.05 | J5: =Assumptions!J24 -> 0.05
B6: Interest rate on cash | F6: =Assumptions!F25 -> 0.10361745 | G6: =Assumptions!G25 -> 0.10361745 | H6: =Assumptions!H25 -> 0.10361745 | I6: =Assumptions!I25 -> 0.10361745 | J6: =Assumptions!J25 -> 0.10361745
B8: Issuance of long-term debt | F8: =Assumptions!F27 -> 0 | G8: =Assumptions!G27 -> 0 | H8: =Assumptions!H27 -> 0 | I8: =Assumptions!I27 -> 0 | J8: =Assumptions!J27 -> 0
B9: Repayment of long-term debt | F9: =Assumptions!F28 -> 0 | G9: =Assumptions!G28 -> 0 | H9: =Assumptions!H28 -> 0 | I9: =Assumptions!I28 -> 0 | J9: =Assumptions!J28 -> 0
A11: Revolver | C11: =C2 -> 2022 | D11: =D2 -> 2023 | E11: =E2 -> 2024 | F11: =F2 -> 2025 | G11: =G2 -> 2026 | H11: =H2 -> 2027 | I11: =I2 -> 2028 | J11: =J2 -> 2029
B12: Balance | F12: NO REVOLVER | G12: NO REVOLVER | H12: NO REVOLVER | I12: NO REVOLVER | J12: NO REVOLVER
B13: Interest rate
B14: Interest expense
A16: Long term debt | C16: =C11 -> 2022 | D16: =D11 -> 2023 | E16: =E11 -> 2024 | F16: =F11 -> 2025 | G16: =G11 -> 2026 | H16: =H11 -> 2027 | I16: =I11 -> 2028 | J16: =J11 -> 2029
B17: Beginning balance | F17: =E20 -> 38424 | G17: =F20 -> 38424 | H17: =G20 -> 38424 | I17: =H20 -> 38424 | J17: =I20 -> 38424
B18: Issuance | F18: =F8 -> 0 | G18: =G8 -> 0 | H18: =H8 -> 0 | I18: =I8 -> 0 | J18: =J8 -> 0
B19: Repayment | F19: =F9 -> 0 | G19: =G9 -> 0 | H19: =H9 -> 0 | I19: =I9 -> 0 | J19: =J9 -> 0
B20: Ending balance | E20: =BalSheet!E37 -> 38424 | F20: =SUM(F17:F19) -> 38424 | G20: =SUM(G17:G19) -> 38424 | H20: =SUM(H17:H19) -> 38424 | I20: =SUM(I17:I19) -> 38424 | J20: =SUM(J17:J19) -> 38424
B21: Interest rate | F21: =F5 -> 0.05 | G21: =G5 -> 0.05 | H21: =H5 -> 0.05 | I21: =I5 -> 0.05 | J21: =J5 -> 0.05
B22: Interest expense | F22: =F20*F21 -> 1921.2 | G22: =G20*G21 -> 1921.2 | H22: =H20*H21 -> 1921.2 | I22: =I20*I21 -> 1921.2 | J22: =J20*J21 -> 1921.2
A24: Debt summary | C24: =C16 -> 2022 | D24: =D16 -> 2023 | E24: =E16 -> 2024 | F24: =F16 -> 2025 | G24: =G16 -> 2026 | H24: =H16 -> 2027 | I24: =I16 -> 2028 | J24: =J16 -> 2029
B25: Revolver | F25: =F12 -> NO REVOLVER | G25: =G12 -> NO REVOLVER | H25: =H12 -> NO REVOLVER | I25: =I12 -> NO REVOLVER | J25: =J12 -> NO REVOLVER
B26: Total long term debt | F26: =F20 -> 38424 | G26: =G20 -> 38424 | H26: =H20 -> 38424 | I26: =I20 -> 38424 | J26: =J20 -> 38424
B27: Total debt | F27: =SUM(F25:F26) -> 38424 | G27: =SUM(G25:G26) -> 38424 | H27: =SUM(H25:H26) -> 38424 | I27: =SUM(I25:I26) -> 38424 | J27: =SUM(J25:J26) -> 38424
B28: Total interest expense | F28: =F22 -> 1921.2 | G28: =G22 -> 1921.2 | H28: =H22 -> 1921.2 | I28: =I22 -> 1921.2 | J28: =J22 -> 1921.2
A30: Interest income | C30: =C11 -> 2022 | D30: =D11 -> 2023 | E30: =E11 -> 2024 | F30: =F11 -> 2025 | G30: =G11 -> 2026 | H30: =H11 -> 2027 | I30: =I11 -> 2028 | J30: =J11 -> 2029
B31: Excess Cash | F31: =BalSheet!F18 -> 1206.5538 | G31: =BalSheet!G18 -> 1632.6172 | H31: =BalSheet!H18 -> 2619.1506 | I31: =BalSheet!I18 -> 4258.6167 | J31: =BalSheet!J18 -> 6645.0173
B32: Interest rate | F32: =F6 -> 0.10361745 | G32: =G6 -> 0.10361745 | H32: =H6 -> 0.10361745 | I32: =I6 -> 0.10361745 | J32: =J6 -> 0.10361745
B33: Interest income | F33: =F31*F32 -> 125.02003 | G33: =G31*G32 -> 169.16762 | H33: =H31*H32 -> 271.3897 | I33: =I31*I32 -> 441.26699 | J33: =J31*J32 -> 688.53973

Sheet IncState
A1: =CoName -> McDonald's Corp. | C1: Hist. | D1: Hist. | E1: Hist. | F1: Proj. | G1: Proj. | H1: Proj. | I1: Proj. | J1: Proj.
A2: Assumptions | C2: 2022 | D2: =C2+1 -> 2023 | E2: =D2+1 -> 2024 | F2: =E2+1 -> 2025 | G2: =F2+1 -> 2026 | H2: =G2+1 -> 2027 | I2: =H2+1 -> 2028 | J2: =I2+1 -> 2029
B4: Revenue growth | F4: =Assumptions!F10 -> 0.030661323 | G4: =Assumptions!G10 -> 0.060167259 | H4: =Assumptions!H10 -> 0.059725443 | I4: =Assumptions!I10 -> 0.059782773 | J4: =Assumptions!J10 -> 0.059840257
B5: Cost of goods sold as % of sales | F5: =Assumptions!F11 -> 0.53504834 | G5: =Assumptions!G11 -> 0.53504834 | H5: =Assumptions!H11 -> 0.53504834 | I5: =Assumptions!I11 -> 0.53504834 | J5: =Assumptions!J11 -> 0.53504834
B6: SG&A % of sales | F6: =Assumptions!F12 -> 0.11565902 | G6: =Assumptions!G12 -> 0.11565902 | H6: =Assumptions!H12 -> 0.11565902 | I6: =Assumptions!I12 -> 0.11565902 | J6: =Assumptions!J12 -> 0.11565902
B7: Amortization amount | F7: =Assumptions!F13 -> 0 | G7: =Assumptions!G13 -> 0 | H7: =Assumptions!H13 -> 0 | I7: =Assumptions!I13 -> 0 | J7: =Assumptions!J13 -> 0
B8: Non recurring items, amount | F8: =Assumptions!F14 -> 0 | G8: =Assumptions!G14 -> 0 | H8: =Assumptions!H14 -> 0 | I8: =Assumptions!I14 -> 0 | J8: =Assumptions!J14 -> 0
B9: Other income (expense), amt | F9: =Assumptions!F15 -> 0 | G9: =Assumptions!G15 -> 0 | H9: =Assumptions!H15 -> 0 | I9: =Assumptions!I15 -> 0 | J9: =Assumptions!J15 -> 0
B10: Effective tax rate | F10: =Assumptions!F16 -> 0.22 | G10: =Assumptions!G16 -> 0.22 | H10: =Assumptions!H16 -> 0.22 | I10: =Assumptions!I16 -> 0.22 | J10: =Assumptions!J16 -> 0.22
B11: Dividend Payout Rate | F11: =Assumptions!F17 -> 7.3322902 | G11: =Assumptions!G17 -> 7.8846834 | H11: =Assumptions!H17 -> 8.4370766 | I11: =Assumptions!I17 -> 8.9894698 | J11: =Assumptions!J17 -> 9.541863
B12: Basic WASO | F12: =Assumptions!F18 -> 718.3 | G12: =Assumptions!G18 -> 718.3 | H12: =Assumptions!H18 -> 718.3 | I12: =Assumptions!I18 -> 718.3 | J12: =Assumptions!J18 -> 718.3
B13: Diluted WASO | F13: =Assumptions!F19 -> 721.9 | G13: =Assumptions!G19 -> 721.9 | H13: =Assumptions!H19 -> 721.9 | I13: =Assumptions!I19 -> 721.9 | J13: =Assumptions!J19 -> 721.9
A15: Income statement | C15: =C37 -> 44926 | D15: =D37 -> 45291 | E15: =E37 -> 45657 | F15: =F37 -> 46022 | G15: =G37 -> 46022 | H15: =H37 -> 46022 | I15: =I37 -> 46022 | J15: =J37 -> 46022
B16: Revenue | C16: ='Quarterly Projections'!G8 -> 23182.6 | D16: ='Quarterly Projections'!L8 -> 25493.808 | E16: ='Quarterly Projections'!Q8 -> 25921.022 | F16: =E16*(1+F4) -> 26715.795 | G16: =F16*(1+G4) -> 28323.211 | H16: =G16*(1+H4) -> 30014.827 | I16: =H16*(1+I4) -> 31809.197 | J16: =I16*(1+J4) -> 33712.668
B17: COGS | C17: =SUM('Quarterly Projections'!G10,'Quarterly Projections'!G12,'Quarterly Projections'!G15) -> 13566.8 | D17: =SUM('Quarterly Projections'!L10,'Quarterly Projections'!L12,'Quarterly Projections'!L14) -> 10932.1 | E17: =SUM('Quarterly Projections'!Q10,'Quarterly Projections'!Q12,'Quarterly Projections'!Q15) -> 13869 | F17: =F16*F5 -> 14294.242 | G17: =G16*G5 -> 15154.287 | H17: =H16*H5 -> 16059.384 | I17: =I16*I5 -> 17019.458 | J17: =J16*J5 -> 18037.907
B18: SG&A | C18: =SUM('Quarterly Projections'!G15) -> 3836.2 | D18: ='Quarterly Projections'!L15 -> 2917.1 | E18: ='Quarterly Projections'!Q15 -> 2998 | F18: =F16*F6 -> 3089.9226 | G18: =G16*G6 -> 3275.8348 | H18: =H16*H6 -> 3471.4855 | I18: =I16*I6 -> 3679.0205 | J18: =J16*J6 -> 3899.1741
A19: * | B19: EBIT | C19: =C16-SUM(C17:C18) -> 5779.6 | D19: =D16-SUM(D17:D18) -> 11644.608 | E19: =E16-SUM(E17:E18) -> 9054.0222 | F19: =F16-SUM(F17:F18) -> 9331.6305 | G19: =G16-SUM(G17:G18) -> 9893.0891 | H19: =H16-SUM(H17:H18) -> 10483.958 | I19: =I16-SUM(I17:I18) -> 11110.718 | J19: =J16-SUM(J17:J18) -> 11775.587
B21: Depreciation | C21: 370 | D21: 382 | E21: 447 | F21: =Calcs!F8 -> 449.4664 | G21: =Calcs!G8 -> 481.466 | H21: =Calcs!H8 -> 508.74304 | I21: =Calcs!I8 -> 530.68259 | J21: =Calcs!J8 -> 546.631
B22: Amortization | F22: =F7 -> 0 | G22: =G7 -> 0 | H22: =H7 -> 0 | I22: =I7 -> 0 | J22: =J7 -> 0
A23: * | B23: EBITDA | C23: =SUM(C19,C21:C22) -> 6149.6 | D23: =SUM(D19,D21:D22) -> 12026.608 | E23: =SUM(E19,E21:E22) -> 9501.0222 | F23: =SUM(F19,F21:F22) -> 9781.0969 | G23: =SUM(G19,G21:G22) -> 10374.555 | H23: =SUM(H19,H21:H22) -> 10992.701 | I23: =SUM(I19,I21:I22) -> 11641.401 | J23: =SUM(J19,J21:J22) -> 12322.218
B25: Non-recurring items | C25: 0 | D25: 0 | E25: 0 | F25: =F8 -> 0 | G25: =G8 -> 0 | H25: =H8 -> 0 | I25: =I8 -> 0 | J25: =J8 -> 0
B26: Other income (expense) | C26: 0 | D26: 0 | E26: 0 | F26: =F9 -> 0 | G26: =G9 -> 0 | H26: =H9 -> 0 | I26: =I9 -> 0 | J26: =J9 -> 0
B28: Interest income | C28: 339 | D28: 236 | E28: 139 | F28: =IF(circ=1,Debt!F33,0) -> 0 | G28: =IF(circ=1,Debt!G33,0) -> 0 | H28: =IF(circ=1,Debt!H33,0) -> 0 | I28: =IF(circ=1,Debt!I33,0) -> 0 | J28: =IF(circ=1,Debt!J33,0) -> 0
B29: Interest expense | C29: -1207 | D29: -1361 | E29: -1506 | F29: =IF(circ=1,-Debt!F22,0) -> 0 | G29: =IF(circ=1,-Debt!G22,0) -> 0 | H29: =IF(circ=1,-Debt!H22,0) -> 0 | I29: =IF(circ=1,-Debt!I22,0) -> 0 | J29: =IF(circ=1,-Debt!J22,0) -> 0
A31: * | B31: Pretax Income | C31: =C19+SUM(C26:C29) -> 4911.6 | D31: =D19+SUM(D26:D29) -> 10519.608 | E31: =E19+SUM(E25:E29) -> 7687.0222 | F31: =F19+SUM(F25:F29) -> 9331.6305 | G31: =G19+SUM(G25:G29) -> 9893.0891 | H31: =H19+SUM(H25:H29) -> 10483.958 | I31: =I19+SUM(I25:I29) -> 11110.718 | J31: =J19+SUM(J25:J29) -> 11775.587
B33: Tax expense | C33: ='Quarterly Projections'!G23 -> 1648 | D33: ='Quarterly Projections'!L23 -> 2053 | E33: ='Quarterly Projections'!Q23 -> 2121 | F33: =F31*F10 -> 2052.9587 | G33: =G31*G10 -> 2176.4796 | H33: =H31*H10 -> 2306.4708 | I33: =I31*I10 -> 2444.358 | J33: =J31*J10 -> 2590.629
A34: * | B34: Net income | C34: =C31-C33 -> 3263.6 | D34: =D31-D33 -> 8466.6079 | E34: =E31-E33 -> 5566.0222 | F34: =F31-F33 -> 7278.6718 | G34: =G31-G33 -> 7716.6095 | H34: =H31-H33 -> 8177.4874 | I34: =I31-I33 -> 8666.3603 | J34: =J31-J33 -> 9184.9575
B35: Dividend payout rate | C35: =C36/C38 -> 5.6591989 | D35: =D36/D38 -> 6.2275038 | E35: =E36/E38 -> 6.779897 | F35: =F11 -> 7.3322902 | G35: =G11 -> 7.8846834 | H35: =H11 -> 8.4370766 | I35: =I11 -> 8.9894698 | J35: =J11 -> 9.541863
B36: Dividends | C36: 4168 | D36: 4533 | E36: 4870 | F36: =F35*F38 -> 5266.784 | G36: =G35*G38 -> 5663.5681 | H36: =H35*H38 -> 6060.3521 | I36: =I35*I38 -> 6457.1361 | J36: =J35*J38 -> 6853.9202
A37: Shareholder information | C37: 44926 | D37: 45291 | E37: 45657 | F37: 46022 | G37: 46022 | H37: 46022 | I37: 46022 | J37: 46022
B38: Basic WASO | C38: 736.5 | D38: 727.9 | E38: 718.3 | F38: =F12 -> 718.3 | G38: =G12 -> 718.3 | H38: =H12 -> 718.3 | I38: =I12 -> 718.3 | J38: =J12 -> 718.3
B39: Diluted WASO | C39: 741.3 | D39: 732.3 | E39: 721.9 | F39: =F13 -> 721.9 | G39: =G13 -> 721.9 | H39: =H13 -> 721.9 | I39: =I13 -> 721.9 | J39: =J13 -> 721.9
B40: Basic earnings per share | C40: =C34/C38 -> 4.4312288 | D40: =D34/D38 -> 11.631554 | E40: =E34/E38 -> 7.7488823 | F40: =F34/F38 -> 10.133192 | G40: =G34/G38 -> 10.742878 | H40: =H34/H38 -> 11.384501 | I40: =I34/I38 -> 12.065099 | J40: =J34/J38 -> 12.787077
A41: * | B41: Diluted earnings per share | C41: =C34/C39 -> 4.4025361 | D41: =D34/D39 -> 11.561666 | E41: =E34/E39 -> 7.7102399 | F41: =F34/F39 -> 10.082659 | G41: =G34/G39 -> 10.689305 | H41: =H34/H39 -> 11.327729 | I41: =I34/I39 -> 12.004932 | J41: =J34/J39 -> 12.72331

Sheet BalSheet
A1: =CoName -> McDonald's Corp. | C1: Hist. | D1: Hist. | E1: Hist. | F1: Proj. | G1: Proj. | H1: Proj. | I1: Proj. | J1: Proj.
A2: Assumptions | C2: 2022 | D2: =C2+1 -> 2023 | E2: =D2+1 -> 2024 | F2: =E2+1 -> 2025 | G2: =F2+1 -> 2026 | H2: =G2+1 -> 2027 | I2: =H2+1 -> 2028 | J2: =I2+1 -> 2029
B4: Operating Cash % of sales | F4: =Assumptions!F44 -> 0.015 | G4: =F4 -> 0.015 | H4: =G4 -> 0.015 | I4: =H4 -> 0.015 | J4: =I4 -> 0.015
B5: Accounts receivable % of sales | F5: =Assumptions!F45 -> 0.091933103 | G5: =Assumptions!G45 -> 0.091933103 | H5: =Assumptions!H45 -> 0.091933103 | I5: =Assumptions!I45 -> 0.091933103 | J5: =Assumptions!J45 -> 0.091933103
B6: Inventories % of COGS | F6: =Assumptions!F46 -> 0.0040377821 | G6: =Assumptions!G46 -> 0.0040377821 | H6: =Assumptions!H46 -> 0.0040377821 | I6: =Assumptions!I46 -> 0.0040377821 | J6: =Assumptions!J46 -> 0.0040377821
B7: Other current assets % of sales | F7: =Assumptions!F47 -> 0.041433551 | G7: =Assumptions!G47 -> 0.041433551 | H7: =Assumptions!H47 -> 0.041433551 | I7: =Assumptions!I47 -> 0.041433551 | J7: =Assumptions!J47 -> 0.041433551
B9: Other long-term assets % of sales | F9: =Assumptions!F50 -> 0.23513733 | G9: =Assumptions!G50 -> 0.23513733 | H9: =Assumptions!H50 -> 0.23513733 | I9: =Assumptions!I50 -> 0.23513733 | J9: =Assumptions!J50 -> 0.23513733
B10: Investment in unconsolidated entities $ balance | F10: =Assumptions!F49 -> 2710 | G10: =Assumptions!G49 -> 2710 | H10: =Assumptions!H49 -> 2710 | I10: =Assumptions!I49 -> 2710 | J10: =Assumptions!J49 -> 2710
B12: Accounts payable/Accural % of COGS | F12: =Assumptions!F54 -> 0.074194246 | G12: =Assumptions!G54 -> 0.074194246 | H12: =Assumptions!H54 -> 0.074194246 | I12: =Assumptions!I54 -> 0.074194246 | J12: =Assumptions!J54 -> 0.074194246
B13: Other current liabilities % of sales | F13: =Assumptions!F55 -> 0.11384582 | G13: =Assumptions!G55 -> 0.11384582 | H13: =Assumptions!H55 -> 0.11384582 | I13: =Assumptions!I55 -> 0.11384582 | J13: =Assumptions!J55 -> 0.11384582
B14: Other long-term liabilities % of sales | F14: =Assumptions!F56 -> 0.64407182 | G14: =Assumptions!G56 -> 0.64407182 | H14: =Assumptions!H56 -> 0.64407182 | I14: =Assumptions!I56 -> 0.64407182 | J14: =Assumptions!J56 -> 0.64407182
A16: Balance sheet | C16: =C2 -> 2022 | D16: =D2 -> 2023 | E16: =E2 -> 2024 | F16: =F2 -> 2025 | G16: =G2 -> 2026 | H16: =H2 -> 2027 | I16: =I2 -> 2028 | J16: =J2 -> 2029
B17: Operating Cash | C17: =1.5%*IncState!C16 -> 347.739 | D17: =1.5%*IncState!D16 -> 382.40712 | E17: =1.5%*IncState!E16 -> 388.81533 | F17: =F4*IncState!F16 -> 400.73693 | G17: =G4*IncState!G16 -> 424.84817 | H17: =H4*IncState!H16 -> 450.22241 | I17: =I4*IncState!I16 -> 477.13796 | J17: =J4*IncState!J16 -> 505.69001
B18: Excess cash | C18: =2583.8-C17 -> 2236.061 | D18: =4579-D17 -> 4196.5929 | E18: =1085-E17 -> 696.18467 | F18: =MAX(CashFlow!F23,0) -> 1206.5538 | G18: =MAX(CashFlow!G23,0) -> 1632.6172 | H18: =MAX(CashFlow!H23,0) -> 2619.1506 | I18: =MAX(CashFlow!I23,0) -> 4258.6167 | J18: =MAX(CashFlow!J23,0) -> 6645.0173
B19: Accounts receivable | C19: 2115 | D19: 2488 | E19: 2383 | F19: =F5*IncState!F16 -> 2456.0659 | G19: =G5*IncState!G16 -> 2603.8407 | H19: =H5*IncState!H16 -> 2759.3562 | I19: =I5*IncState!I16 -> 2924.3182 | J19: =J5*IncState!J16 -> 3099.3101
B20: Inventories | C20: 52 | D20: 53 | E20: 56 | F20: =F6*IncState!F17 -> 57.717034 | G20: =G6*IncState!G17 -> 61.18971 | H20: =H6*IncState!H17 -> 64.844292 | I20: =I6*IncState!I17 -> 68.720864 | J20: =J6*IncState!J17 -> 72.833138
B21: Other current assets | C21: 673.4 | D21: 866 | E21: 1074 | F21: =F7*IncState!F16 -> 1106.9303 | G21: =G7*IncState!G16 -> 1173.5312 | H21: =H7*IncState!H16 -> 1243.6209 | I21: =I7*IncState!I16 -> 1317.968 | J21: =J7*IncState!J16 -> 1396.8355
B22: Total current assets | C22: =SUM(C17:C21) -> 5424.2 | D22: =SUM(D17:D21) -> 7986 | E22: =SUM(E17:E21) -> 4598 | F22: =SUM(F17:F21) -> 5228.004 | G22: =SUM(G17:G21) -> 5896.027 | H22: =SUM(H17:H21) -> 7137.1944 | I22: =SUM(I17:I21) -> 9046.7617 | J22: =SUM(J17:J21) -> 11719.686
B24: Property, plant & equipment, net | C24: =12565.7+23773.6 -> 36339.3 | D24: =13514+24908 -> 38422 | E24: =13339+25295 -> 38634 | F24: =Calcs!F9 -> 41384.534 | G24: =Calcs!G9 -> 43729.139 | H24: =Calcs!H9 -> 45614.958 | I24: =Calcs!I9 -> 46985.808 | J24: =Calcs!J9 -> 47780.245
B25: Intangible assets | C25: 2900.4 | D25: 3040 | E25: 3145 | F25: =E25-IncState!F22 -> 3145 | G25: =F25-IncState!G22 -> 3145 | H25: =G25-IncState!H22 -> 3145 | I25: =H25-IncState!I22 -> 3145 | J25: =I25-IncState!J22 -> 3145
B26: Investment in unconsolidated entities | C26: 1064.5 | D26: 1080 | E26: 2710 | F26: =F10 -> 2710 | G26: =G10 -> 2710 | H26: =H10 -> 2710 | I26: =I10 -> 2710 | J26: =J10 -> 2710
B27: Other assets | C27: 4707.2 | D27: 5618 | E27: 6095 | F27: =F9*IncState!F16 -> 6281.8808 | G27: =G9*IncState!G16 -> 6659.8443 | H27: =H9*IncState!H16 -> 7057.6065 | I27: =I9*IncState!I16 -> 7479.5297 | J27: =J9*IncState!J16 -> 7927.1067
B28: Total non-current assets | C28: =SUM(C24:C27) -> 45011.4 | D28: =SUM(D24:D27) -> 48160 | E28: =SUM(E24:E27) -> 50584 | F28: =SUM(F24:F27) -> 53521.414 | G28: =SUM(G24:G27) -> 56243.983 | H28: =SUM(H24:H27) -> 58527.565 | I28: =SUM(I24:I27) -> 60320.338 | J28: =SUM(J24:J27) -> 61562.351
A30: * | B30: TOTAL ASSETS | C30: =SUM(C28,C22) -> 50435.6 | D30: =SUM(D28,D22) -> 56146 | E30: =SUM(E28,E22) -> 55182 | F30: =SUM(F28,F22) -> 58749.418 | G30: =SUM(G28,G22) -> 62140.01 | H30: =SUM(H28,H22) -> 65664.759 | I30: =SUM(I28,I22) -> 69367.1 | J30: =SUM(J28,J22) -> 73282.037
B32: Revolver/Short term debt | C32: 0 | D32: 2192 | E32: 0 | F32: =MIN(CashFlow!F23,0) -> 0 | G32: =MIN(CashFlow!G23,0) -> 0 | H32: =MIN(CashFlow!H23,0) -> 0 | I32: =MIN(CashFlow!I23,0) -> 0 | J32: =MIN(CashFlow!J23,0) -> 0
B33: Accounts payable/Accurals | C33: 980.2 | D33: 1103 | E33: 1029 | F33: =F12*IncState!F16 -> 1982.1583 | G33: =G12*IncState!G16 -> 2101.4193 | H33: =H12*IncState!H16 -> 2226.9275 | I33: =I12*IncState!I16 -> 2360.0594 | J33: =J12*IncState!J16 -> 2501.286
B34: Other current liabilities | C34: =661.1+274.9+255.1+393.4+1237.4 -> 2821.9 | D34: =688+705+268+469+1434 -> 3564 | E34: =636+361+224+482+119+1129 -> 2951 | F34: =F13*IncState!F16 -> 3041.4816 | G34: =G13*IncState!G16 -> 3224.4792 | H34: =H13*IncState!H16 -> 3417.0626 | I34: =I13*IncState!I16 -> 3621.3441 | J34: =J13*IncState!J16 -> 3838.0463
B35: Total current liabilities | C35: =SUM(C32:C34) -> 3802.1 | D35: =SUM(D32:D34) -> 6859 | E35: =SUM(E32:E34) -> 3980 | F35: =SUM(F32:F34) -> 5023.6398 | G35: =SUM(G32:G34) -> 5325.8985 | H35: =SUM(H32:H34) -> 5643.9901 | I35: =SUM(I32:I34) -> 5981.4035 | J35: =SUM(J32:J34) -> 6339.3322
B37: Long-term debt, including current maturities | C37: 35903.5 | D37: 37153 | E37: 38424 | F37: =Debt!F20 -> 38424 | G37: =Debt!G20 -> 38424 | H37: =Debt!H20 -> 38424 | I37: =Debt!I20 -> 38424 | J37: =Debt!J20 -> 38424
B38: Other long-term liabilities | C38: =12134.4+791.9+757.8+1051.8+1997.5 -> 16733.4 | D38: =13058+363+790+950+1681 -> 16842 | E38: =12888+344+778+771+1914 -> 16695 | F38: =F14*IncState!F16 -> 17206.891 | G38: =G14*IncState!G16 -> 18242.182 | H38: =H14*IncState!H16 -> 19331.705 | I38: =I14*IncState!I16 -> 20487.408 | J38: =J14*IncState!J16 -> 21713.379
B39: Total non-current liabilities | C39: =SUM(C37:C38) -> 52636.9 | D39: =SUM(D37:D38) -> 53995 | E39: =SUM(E37:E38) -> 55119 | F39: =SUM(F37:F38) -> 55630.891 | G39: =SUM(G37:G38) -> 56666.182 | H39: =SUM(H37:H38) -> 57755.705 | I39: =SUM(I37:I38) -> 58911.408 | J39: =SUM(J37:J38) -> 60137.379
B41: Equity | C41: -6003.4 | D41: -4708 | E41: -3917 | F41: =Calcs!F17 -> -1905.1123 | G41: =Calcs!G17 -> 147.92916 | H41: =Calcs!H17 -> 2265.0645 | I41: =Calcs!I17 -> 4474.2886 | J41: =Calcs!J17 -> 6805.3259
A42: * | B42: TOTAL LIABILITIES & EQUITY | C42: =SUM(C41,C39,C35) -> 50435.6 | D42: =SUM(D41,D39,D35) -> 56146 | E42: =SUM(E41,E39,E35) -> 55182 | F42: =SUM(F41,F39,F35) -> 58749.418 | G42: =SUM(G41,G39,G35) -> 62140.01 | H42: =SUM(H41,H39,H35) -> 65664.759 | I42: =SUM(I41,I39,I35) -> 69367.1 | J42: =SUM(J41,J39,J35) -> 73282.037
A44: * | B44: Balance check | C44: =C42-C30 -> 0 | D44: =D42-D30 -> 0 | E44: =E42-E30 -> 0 | F44: =F42-F30 -> 0 | G44: =G42-G30 -> 0 | H44: =H42-H30 -> 0 | I44: =I42-I30 -> 0 | J44: =J42-J30 -> 0

Sheet CashFlow
A1: =CoName -> McDonald's Corp. | C1: Hist. | D1: Hist. | E1: Hist. | F1: Proj. | G1: Proj. | H1: Proj. | I1: Proj. | J1: Proj.
A2: Cash flow statement | C2: 2022 | D2: =C2+1 -> 2023 | E2: =D2+1 -> 2024 | F2: =E2+1 -> 2025 | G2: =F2+1 -> 2026 | H2: =G2+1 -> 2027 | I2: =H2+1 -> 2028 | J2: =I2+1 -> 2029
B3: Net Income | F3: =IncState!F34 -> 7278.6718 | G3: =IncState!G34 -> 7716.6095 | H3: =IncState!H34 -> 8177.4874 | I3: =IncState!I34 -> 8666.3603 | J3: =IncState!J34 -> 9184.9575
B4: Depreciation | F4: =IncState!F21 -> 449.4664 | G4: =IncState!G21 -> 481.466 | H4: =IncState!H21 -> 508.74304 | I4: =IncState!I21 -> 530.68259 | J4: =IncState!J21 -> 546.631
B5: Amortization | F5: =IncState!F22 -> 0 | G5: =IncState!G22 -> 0 | H5: =IncState!H22 -> 0 | I5: =IncState!I22 -> 0 | J5: =IncState!J22 -> 0
B6: (inc) / dec in OWC | F6: =Calcs!F26 -> 924.00502 | G6: =Calcs!G26 -> 60.299006 | H6: =Calcs!H26 -> 63.457607 | I6: =Calcs!I26 -> 67.312192 | J6: =Calcs!J26 -> 71.404895
B7: (inc) / dec in LT assets | F7: =BalSheet!E27-BalSheet!F27 -> -186.88076 | G7: =BalSheet!F27-BalSheet!G27 -> -377.96355 | H7: =BalSheet!G27-BalSheet!H27 -> -397.76215 | I7: =BalSheet!H27-BalSheet!I27 -> -421.92328 | J7: =BalSheet!I27-BalSheet!J27 -> -447.57698
B8: inc / (dec) in LT liabilities | F8: =BalSheet!F38-BalSheet!E38 -> 511.89079 | G8: =BalSheet!G38-BalSheet!F38 -> 1035.2915 | H8: =BalSheet!H38-BalSheet!G38 -> 1089.5224 | I8: =BalSheet!I38-BalSheet!H38 -> 1155.7029 | J8: =BalSheet!J38-BalSheet!I38 -> 1225.9717
B9: CFFO | F9: =SUM(F3:F8) -> 8977.1532 | G9: =SUM(G3:G8) -> 8915.7024 | H9: =SUM(H3:H8) -> 9441.4483 | I9: =SUM(I3:I8) -> 9998.1347 | J9: =SUM(J3:J8) -> 10581.388
B11: Capex | F11: =-Calcs!F7 -> -3200 | G11: =-Calcs!G7 -> -2826.071 | H11: =-Calcs!H7 -> -2394.5628 | I11: =-Calcs!I7 -> -1901.5325 | J11: =-Calcs!J7 -> -1341.0673
B12: CFFI | F12: =F11 -> -3200 | G12: =G11 -> -2826.071 | H12: =H11 -> -2394.5628 | I12: =I11 -> -1901.5325 | J12: =J11 -> -1341.0673
B14: Dividends Paid | F14: =-IncState!F36 -> -5266.784 | G14: =-IncState!G36 -> -5663.5681 | H14: =-IncState!H36 -> -6060.3521 | I14: =-IncState!I36 -> -6457.1361 | J14: =-IncState!J36 -> -6853.9202
B15: Share issuance / (repurchases) | F15: =Calcs!F11 -> 0 | G15: =Calcs!G11 -> 0 | H15: =Calcs!H11 -> 0 | I15: =Calcs!I11 -> 0 | J15: =Calcs!J11 -> 0
B16: Debt issuance / (repayments) | F16: =SUM(Debt!F8:F9) -> 0 | G16: =SUM(Debt!G8:G9) -> 0 | H16: =SUM(Debt!H8:H9) -> 0 | I16: =SUM(Debt!I8:I9) -> 0 | J16: =SUM(Debt!J8:J9) -> 0
B17: CFFF | F17: =SUM(F14:F16) -> -5266.784 | G17: =SUM(G14:G16) -> -5663.5681 | H17: =SUM(H14:H16) -> -6060.3521 | I17: =SUM(I14:I16) -> -6457.1361 | J17: =SUM(J14:J16) -> -6853.9202
B19: Net Changes in Cash | F19: =SUM(F17,F12,F9) -> 510.36917 | G19: =SUM(G17,G12,G9) -> 426.06333 | H19: =SUM(H17,H12,H9) -> 986.53341 | I19: =SUM(I17,I12,I9) -> 1639.4661 | J19: =SUM(J17,J12,J9) -> 2386.4007
B21: Beginning Cash | F21: =BalSheet!E18 -> 696.18467 | G21: =BalSheet!F18 -> 1206.5538 | H21: =BalSheet!G18 -> 1632.6172 | I21: =BalSheet!H18 -> 2619.1506 | J21: =BalSheet!I18 -> 4258.6167
B22: =B19 -> Net Changes in Cash | F22: =F19 -> 510.36917 | G22: =G19 -> 426.06333 | H22: =H19 -> 986.53341 | I22: =I19 -> 1639.4661 | J22: =J19 -> 2386.4007
B23: Ending Cash | F23: =SUM(F21:F22) -> 1206.5538 | G23: =SUM(G21:G22) -> 1632.6172 | H23: =SUM(H21:H22) -> 2619.1506 | I23: =SUM(I21:I22) -> 4258.6167 | J23: =SUM(J21:J22) -> 6645.0173

Sheet Free Cash Flow
A1: =CoName -> McDonald's Corp. | C1: Hist. | D1: Hist. | E1: Hist. | F1: Proj. | G1: Proj. | H1: Proj. | I1: Proj. | J1: Proj.
A2: Free Cash Flows | C2: 2022 | D2: =C2+1 -> 2023 | E2: =D2+1 -> 2024 | F2: =E2+1 -> 2025 | G2: =F2+1 -> 2026 | H2: =G2+1 -> 2027 | I2: =H2+1 -> 2028 | J2: =I2+1 -> 2029
A3: * | B3: Sales | F3: =IncState!F16 -> 26715.795 | G3: =IncState!G16 -> 28323.211 | H3: =IncState!H16 -> 30014.827 | I3: =IncState!I16 -> 31809.197 | J3: =IncState!J16 -> 33712.668
B4: EBIT | F4: =IncState!F19 -> 9331.6305 | G4: =IncState!G19 -> 9893.0891 | H4: =IncState!H19 -> 10483.958 | I4: =IncState!I19 -> 11110.718 | J4: =IncState!J19 -> 11775.587
B5: Effective Tax Rate | F5: =Assumptions!F16 -> 0.22 | G5: =Assumptions!G16 -> 0.22 | H5: =Assumptions!H16 -> 0.22 | I5: =Assumptions!I16 -> 0.22 | J5: =Assumptions!J16 -> 0.22
A7: * | B7: NOPAT | F7: =F4*(1-F5) -> 7278.6718 | G7: =G4*(1-G5) -> 7716.6095 | H7: =H4*(1-H5) -> 8177.4874 | I7: =I4*(1-I5) -> 8666.3603 | J7: =J4*(1-J5) -> 9184.9575
B8: Depreciation | F8: =CashFlow!F4 -> 449.4664 | G8: =CashFlow!G4 -> 481.466 | H8: =CashFlow!H4 -> 508.74304 | I8: =CashFlow!I4 -> 530.68259 | J8: =CashFlow!J4 -> 546.631
B9: Amortization | F9: =CashFlow!F5 -> 0 | G9: =CashFlow!G5 -> 0 | H9: =CashFlow!H5 -> 0 | I9: =CashFlow!I5 -> 0 | J9: =CashFlow!J5 -> 0
B10: (inc) / dec in OWC | F10: =CashFlow!F6 -> 924.00502 | G10: =CashFlow!G6 -> 60.299006 | H10: =CashFlow!H6 -> 63.457607 | I10: =CashFlow!I6 -> 67.312192 | J10: =CashFlow!J6 -> 71.404895
B11: (inc) / dec in other long-term assets | F11: =CashFlow!F7 -> -186.88076 | G11: =CashFlow!G7 -> -377.96355 | H11: =CashFlow!H7 -> -397.76215 | I11: =CashFlow!I7 -> -421.92328 | J11: =CashFlow!J7 -> -447.57698
B12: inc / (dec) other long-term liabilities | F12: =CashFlow!F8 -> 511.89079 | G12: =CashFlow!G8 -> 1035.2915 | H12: =CashFlow!H8 -> 1089.5224 | I12: =CashFlow!I8 -> 1155.7029 | J12: =CashFlow!J8 -> 1225.9717
B13: (Capex) | F13: =CashFlow!F12 -> -3200 | G13: =CashFlow!G12 -> -2826.071 | H13: =CashFlow!H12 -> -2394.5628 | I13: =CashFlow!I12 -> -1901.5325 | J13: =CashFlow!J12 -> -1341.0673
A15: * | B15: Free Cash Flow | F15: =SUM(F7:F13) -> 5777.1532 | G15: =SUM(G7:G13) -> 6089.6314 | H15: =SUM(H7:H13) -> 7046.8855 | I15: =SUM(I7:I13) -> 8096.6022 | J15: =SUM(J7:J13) -> 9240.3209

Sheet WACC
A1: =CoName -> McDonald's Corp.
A3: * | B3: WACC | G3: Comp | H3: Levered beta | I3: Gross debt | J3: Market cap | K3: Debt/Mcap | L3: MTR | M3: Unlevered beta
B4: Tax Rate | E4: =Assumptions!F16 -> 0.22 | G4: YUM | H4: 0.67 | I4: =48+11506 -> 11554 | J4: 40220 | K4: =I4/J4 -> 0.28727001 | L4: =E4 -> 0.22 | M4: =H4/((1+K4*(1-L4))) -> 0.54735404
B5: Risk free rate | E5: 0.0415 | G5: QSR | H5: 0.61 | I5: =116+13415 -> 13531 | J5: 33400 | K5: =I5/J5 -> 0.40511976 | L5: =L4 -> 0.22 | M5: =H5/((1+K5*(1-L5))) -> 0.46352816
B6: Market risk Premium | E6: 0.05 | G6: SBUX | H6: 0.98 | I6: =1498.9+14575.9 -> 16074.8 | J6: 96940 | K6: =I6/J6 -> 0.16582216 | L6: =L5 -> 0.22 | M6: =H6/((1+K6*(1-L6))) -> 0.86776249
B7: Beta | E7: =M10*0.66 -> 0.47338941
B8: Cost of Equity | E8: =E5+E6*E7 -> 0.06516947 | G8: Industry beta (average) | M8: =AVERAGE(M4:M6) -> 0.6262149
B9: % Equity | E9: =1-E10 -> 0.81360993
B10: % Debt | E10: =MAIN!F8/MAIN!F6 -> 0.18639007 | G10: Re-levered beta | M10: =M8*(1+E10*(1-E4)) -> 0.71725668
B11: Cost of debt | E11: =Assumptions!F24 -> 0.05
B12: Post tax cost of debt | E12: =E11*(1-E4) -> 0.039
A13: * | B13: WACC | E13: =WACC!E8*WACC!E9+WACC!E12*WACC!E10 -> 0.060291741
B14: Long Term growth rate | E14: 0.025

Sheet DCF Model
A1: =CoName -> McDonald's Corp. | D1: Proj. | E1: Proj. | F1: Proj. | G1: Proj. | H1: Proj.
A2: Discount Model Year count | D2: 0.5 | E2: =D2+1 -> 1.5 | F2: =E2+1 -> 2.5 | G2: =F2+1 -> 3.5 | H2: =G2+1 -> 4.5
B3: Discount Factor | D3: =1/(1+$K$3)^D2 -> 0.97115223 | E3: =1/(1+$K$3)^E2 -> 0.91592926 | F3: =1/(1+$K$3)^F2 -> 0.86384645 | G3: =1/(1+$K$3)^G2 -> 0.81472525 | H3: =1/(1+$K$3)^H2 -> 0.76839724 | I3: WACC | K3: =WACC!E13 -> 0.060291741
B4: PV FCF | D4: =D3*'Free Cash Flow'!F15 -> 5610.4952 | E4: =E3*'Free Cash Flow'!G15 -> 5577.6716 | F4: =F3*'Free Cash Flow'!H15 -> 6087.427 | G4: =G3*'Free Cash Flow'!I15 -> 6596.5063 | H4: =H3*'Free Cash Flow'!J15 -> 7100.2371 | I4: LTGR | K4: 0.0275
H5: =(H4*(1+K4))/(K3-K4) -> 222479.6
A6: Value Calculation | E6: Multiples Calculation
B7: Total PV of FCFs | C7: =SUM(D4:H4) -> 30972.337 | E7: Total PV of FCFs | G7: =C7 -> 30972.337
B8: PV of TV | C8: =H5*H3 -> 170952.71 | E8: Multiple TV | G8: =H3*G10*IncState!J23 -> 189367.16
B9: EV | C9: =SUM(C7:C8) -> 201925.05 | E9: EV | G9: =SUM(G7:G8) -> 220339.5
E10: Implied EBITDA multiple | G10: 20
B12: Cash & Cash Equiv | C12: =MAIN!F7 -> 2413 | E12: Cash & Cash Equiv | G12: =C12 -> 2413
B13: Debt & Claims | C13: =MAIN!F8 -> 41283 | E13: Debt & Claims | G13: =C13 -> 41283 | K13: DDM
B14: NCI | C14: 0 | E14: NCI | G14: =C14 -> 0 | I14: FY Dividends | K14: =IncState!J36 -> 6853.9202
B15: Equity Value | C15: =C9+C12-SUM(C13:C14) -> 163055.05 | E15: Equity Value | G15: =G9+G12-SUM(G13:G14) -> 181469.5 | I15: Equity Value | K15: =K14/(WACC!E8-K4) -> 181948.94
B17: Diluted S/O | C17: =MAIN!F5 -> 712.15435 | E17: Diluted S/O | G17: =C17 -> 712.15435 | I17: Diluted S/O | K17: =G17 -> 712.15435
A18: * | B18: Implied Share Price | C18: =C15/C17 -> 228.96027 | E18: Implied Share Price | G18: =G15/G17 -> 254.81765 | I18: Implied Share Price | K18: =K15/K17 -> 255.49088
A20: Sensitivity analysis
C22: Discount rate variance | E22: 0.005 | J22: Discount rate variance | L22: 0.005
C23: LTGR variance | E23: 0.0025 | J23: TV multiple variance | L23: 2
E26: LTGR | J26: Exit Mult.
C27: =C18 -> 228.96027 | D27: =E27-E23 -> 0.025 | E27: =K4 -> 0.0275 | F27: =E27+E23 -> 0.03 | H27: =G18 -> 254.81765 | I27: =J27-L23 -> 18 | J27: 20 | K27: =J27+L23 -> 22
C28: =C29+$E$22 -> 0.070291741 | D28: 147.18398 | E28: 147.18398 | F28: 156.90376 | H28: =C28 -> 0.070291741 | I28: 217.27173 | J28: 242.76262 | K28: 268.2535
C29: =C30+$E$22 -> 0.065291741 | D29: 175.18806 | E29: 175.18806 | F29: 188.03181 | H29: =C29 -> 0.065291741 | I29: 222.67999 | J29: 248.71371 | K29: 274.74743
C30: 0.060291741 | D30: 211.41289 | E30: 211.41289 | F30: 228.96027 | H30: =C30 -> 0.060291741 | I30: 228.2269 | J30: 254.81765 | K30: 281.40839
C31: =C30-$E$22 -> 0.055291741 | D31: 259.9503 | E31: 259.9503 | F31: 285.00174 | H31: =C31 -> 0.055291741 | I31: 233.91672 | J31: 261.07913 | K31: 288.24154
C32: =C31-$E$22 -> 0.050291741 | D32: 328.12951 | E32: 328.12951 | F32: 366.13244 | H32: =C32 -> 0.050291741 | I32: 239.75386 | J32: 267.50302 | K32: 295.25219

Sheet Comps
B1: =CoName -> McDonald's Corp.
B3: Ticker | C3: EV | D3: P/E | E3: FY P/E | F3: EV/EBITDA | G3: EV/EBIT | H3: EV/R | I3: Delta / Avg
B4: YUM | C4: =40220-1045+WACC!I4 -> 50729 | D4: 28.26 | E4: 23.84 | F4: 18.34 | G4: =C4/2403 -> 21.110695 | H4: 6.41
B5: QSR | C5: =WACC!J5-1206+WACC!I5 -> 45725 | D5: 26.08 | E5: 13.72 | F5: =C5/2950 -> 15.5 | G5: =C5/3170 -> 14.42429 | H5: 4.37
B6: SBUX | C6: =WACC!J6+WACC!I6-247.2 -> 112767.6 | D6: =96940/1856.7 -> 52.210912 | E6: 22.88 | F6: 21.99 | G6: =C6/2936.6 -> 38.400736 | H6: =C6/37184.4 -> 3.0326589
A7: * | B7: Average | D7: =AVERAGE(D4:D6) -> 35.516971 | E7: =AVERAGE(E4:E6) -> 20.146667 | F7: =AVERAGE(F4:F6) -> 18.61 | G7: =AVERAGE(G4:G6) -> 24.64524 | H7: =AVERAGE(H4:H6) -> 4.6042196
B9: McDonalds - Current Price | D9: =(D7*IncState!E34)/MAIN!F5 -> 277.59185 | E9: =(E7*IncState!F34)/MAIN!F5 -> 205.91179 | F9: =(F7*IncState!F23-MAIN!F8+MAIN!F7)/721.2 -> 198.49724 | G9: =(G7*IncState!F19-MAIN!F8+MAIN!F7)/721.2 -> 264.98929 | H9: =(H7*IncState!F16-MAIN!F8+MAIN!F7)/MAIN!F5 -> 118.14207 | I9: =AVERAGE(D9:H9) -> 213.02645
B10: MCD | C10: =MAIN!F9 -> 260357.12 | D10: =MAIN!F6/IncState!E34 -> 39.792713 | E10: =MAIN!F6/IncState!F34 -> 30.429607 | F10: =C10/IncState!F23 -> 26.618397 | G10: =C10/IncState!F19 -> 27.900497 | H10: =C10/IncState!F16 -> 9.745438 | I10: =(SUM(D10:H10)-SUM(D7:H7))/SUM(D7:H7) -> 0.29909804
D11: =(D10-D7)/D7 -> 0.12038591 | E11: =(E10-E7)/E7 -> 0.51040407 | F11: =(F10-F7)/F7 -> 0.43032765 | G11: =(G10-G7)/G7 -> 0.13208459 | H11: =(H10-H7)/H7 -> 1.1166319
