Workbook
Name Ccy: MAIN!$C$6
Name circ: MAIN!$C$9
Name CoName: MAIN!$C$4
Name g: #REF!
Name IQ_CH: 110000
Name IQ_CQ: 5000
Name IQ_CY: 10000
Name IQ_DAILY: 500000
Name IQ_FH: 100000
Name IQ_FQ: 500
Name IQ_FY: 1000
Name IQ_LTM: 2000
Name IQ_MONTH: 15000
Name IQ_NTM: 6000
Name IQ_WEEK: 50000
Name IQ_YTD: 3000
Name OpCase: [1]DCF!$E$98
Name ScenarioREV: Assumptions!$D$4
Name TTS: #REF!
Name Units: MAIN!$C$7

Sheet MAIN
A1: =CoName -> Starbucks Corp.
A2: Model Details
B4: Company name | C4: Starbucks Corp. | E4: Current Stock Price | F4: 85.25 | H4: Recovery Case | I4: Terminal Mult | J4: Perpetuity | K4: DDM | L4: Average
B5: Latest BS date | C5: 247.43 | E5: S/O | F5: 1136.7 | H5: Implied Price | I5: ='DCF Model'!G18 -> 105.51706 | J5: ='DCF Model'!C18 -> 81.535342 | K5: ='DCF Model'!K18 -> 89.323555 | L5: =AVERAGE(I5:J5) -> 93.526203
B6: Currency | C6: USD | E6: Mkt Cap | F6: =F5*F4 -> 96903.675 | H6: Difference | I6: =I5/$F$4-1 -> 0.23773681 | J6: =J5/$F$4-1 -> -0.043573696 | K6: =K5/$F$4-1 -> 0.04778364 | L6: =L5/$F$4-1 -> 0.097081557
B7: Units | C7: m | E7: Cash | F7: =4172.6+333.3 -> 4505.9
B8: Analyst name | C8: Alan Chen | E8: Debt | F8: =14570.9+9070.6 -> 23641.5
B9: Circular switch | C9: 0 | E9: EV | F9: =F6-F7+F8 -> 116039.28

Sheet Quarterly Projections
A1: =CoName -> Starbucks Corp.
A2: Income Statement Projection | C2: Q122 | D2: Q222 | E2: Q322 | F2: Q422 | G2: 2022 | H2: Q123 | I2: Q223 | J2: Q323 | K2: Q423 | L2: 2023 | M2: Q124 | N2: Q224 | O2: Q324 | P2: Q424 | Q2: 2024 | R2: Q125 | S2: Q225 | T2: Q325 | U2: Q425 | V2: 2025 | W2: Q126E | X2: Q226E | Y2: Q326E | Z2: Q426E | AA2: 2026 | AB2: Q127E | AC2: Q227E | AD2: Q327E | AE2: Q427E | AF2: =AA2+1 -> 2027 | AG2: =AF2+1 -> 2028 | AH2: =AG2+1 -> 2029 | AI2: =AH2+1 -> 2030 | AJ2: =AI2+1 -> 2031 | AK2: =AJ2+1 -> 2032
B3: Company-operated stores | C3: 6722.4 | D3: 6276.7 | E3: 6675.5 | F3: 6901.4 | G3: =SUM(C3:F3) -> 26576 | H3: 7083.5 | I3: 7142.3 | J3: 7556.7 | K3: 7679.9 | L3: =SUM(H3:K3) -> 29462.4 | M3: 7755.2 | N3: 7052.6 | O3: 7516 | P3: 7442.1 | Q3: =SUM(M3:P3) -> 29765.9 | R3: 7785.3 | S3: 7285 | T3: 7812.5 | U3: 7862 | V3: =Q51 -> 30688.9 | W3: =R3*(1+W4) -> 8018.859 | X3: =S3*(1+X4) -> 7503.55 | Y3: =T3*(1+Y4) -> 8046.875 | Z3: =U3*(1+Z4) -> 8097.86 | AA3: =SUM(W3:Z3) -> 31667.144 | AB3: =W3*(1+AB4) -> 8339.6134 | AC3: =X3*(1+AC4) -> 7953.763 | AD3: =Y3*(1+AD4) -> 8610.1562 | AE3: =Z3*(1+AE4) -> 8826.6674 | AF3: =SUM(AB3:AE3) -> 33730.2 | AG3: =AF3*(1+AG4) -> 36428.616 | AH3: =AG3*(1+AH4) -> 39707.191 | AI3: =AH3*(1+AI4) -> 43677.911 | AJ3: =AI3*(1+AJ4) -> 48482.481 | AK3: =AJ3*(1+AK4) -> 54300.378
B4: y/y | C4: n/a | D4: n/a | E4: n/a | F4: n/a | G4: n/a | H4: =H3/C3-1 -> 0.053715935 | I4: =I3/D3-1 -> 0.13790686 | J4: =J3/E3-1 -> 0.13200509 | K4: =K3/F3-1 -> 0.1128032 | L4: =L3/G3-1 -> 0.10860927 | M4: =M3/H3-1 -> 0.094826004 | N4: =N3/I3-1 -> -0.01255898 | O4: =O3/J3-1 -> -0.0053859489 | ... V4: =V3/Q3-1 -> 0.031008637 | W4: 0.03 | X4: =W4 -> 0.03 | Y4: =X4 -> 0.03 | Z4: =Y4 -> 0.03 | AA4: =AA3/V3-1 -> 0.031876151 | AB4: 0.04 | AC4: 0.06 | AD4: 0.07 | AE4: 0.09 | AF4: =AF3/AA3-1 -> 0.065148155 | AG4: 0.08 | AH4: =AG4+0.01 -> 0.09 | AI4: =AH4+0.01 -> 0.1 | AJ4: =AI4+0.01 -> 0.11 | AK4: =AJ4+0.01 -> 0.12
B5: Licensed stores | C5: 850.8 | D5: 849.5 | E5: 956.8 | F5: 998.4 | G5: =SUM(C5:F5) -> 3655.5 | H5: 1119.5 | I5: 1069.5 | J5: 1136.2 | K5: 1187.5 | L5: =SUM(H5:K5) -> 4512.7 | M5: 1192.1 | N5: 1054.5 | O5: 1129 | P5: 1129.5 | Q5: =SUM(M5:P5) -> 4505.1 | R5: 1135.7 | S5: 1016 | T5: 1105.6 | U5: 1093 | V5: =SUM(R5:U5) -> 4350.3 | W5: =R5*(1+W6) -> 1124.343 | X5: =S5*(1+X6) -> 1005.84 | Y5: =T5*(1+Y6) -> 1094.544 | Z5: =U5*(1+Z6) -> 1082.07 | AA5: =SUM(W5:Z5) -> 4306.797 | AB5: =W5*(1+AB6) -> 1124.343 | AC5: =X5*(1+AC6) -> 1005.84 | AD5: =Y5*(1+AD6) -> 1094.544 | AE5: =Z5*(1+AE6) -> 1082.07 | AF5: =SUM(AB5:AE5) -> 4306.797 | AG5: =AF5*(1+AG6) -> 4306.797 | AH5: =AG5*(1+AH6) -> 4349.865 | AI5: =AH5*(1+AI6) -> 4436.8623 | AJ5: =AI5*(1+AJ6) -> 4569.9681 | AK5: =AJ5*(1+AK6) -> 4752.7669
B6: y/y | C6: n/a | D6: n/a | E6: n/a | F6: n/a | G6: n/a | H6: =H5/C5-1 -> 0.3158204 | I6: =I5/D5-1 -> 0.25897587 | J6: =J5/E5-1 -> 0.1875 | K6: =K5/F5-1 -> 0.18940304 | L6: =L5/G5-1 -> 0.23449596 | M6: =M5/H5-1 -> 0.06485038 | N6: =N5/I5-1 -> -0.014025245 | O6: =O5/J5-1 -> -0.0063369125 | ... V6: =V5/Q5-1 -> -0.034361057 | W6: -0.01 | X6: -0.01 | Y6: -0.01 | Z6: -0.01 | AA6: =AA5/V5-1 -> -0.01 | AB6: 0 | AC6: 0 | AD6: 0 | AE6: 0 | AF6: =AF5/AA5-1 -> 0 | AG6: =AF6 -> 0 | AH6: =AG6+0.01 -> 0.01 | AI6: =AH6+0.01 -> 0.02 | AJ6: =AI6+0.01 -> 0.03 | AK6: =AJ6+0.01 -> 0.04
B7: Other | C7: 477.2 | D7: 509.4 | E7: 517.8 | F7: 514.4 | G7: =SUM(C7:F7) -> 2018.8 | H7: 510.9 | I7: 508 | J7: 475.4 | K7: 506.2 | L7: =SUM(H7:K7) -> 2000.5 | M7: 478 | N7: 455.9 | O7: 468.9 | P7: 502.4 | Q7: =SUM(M7:P7) -> 1905.2 | R7: 476.8 | S7: 455.9 | T7: 537.9 | U7: 614 | V7: =SUM(R7:U7) -> 2084.6 | W7: =R7*(1+W8) -> 521.69708 | X7: =S7*(1+X8) -> 498.82907 | Y7: =T7*(1+Y8) -> 588.55046 | Z7: =U7*(1+Z8) -> 671.81629 | AA7: =SUM(W7:Z7) -> 2280.8929 | AB7: =W7*(1+AB8) -> 573.86679 | AC7: =X7*(1+AC8) -> 548.71197 | AD7: =Y7*(1+AD8) -> 647.40551 | AE7: =Z7*(1+AE8) -> 738.99792 | AF7: =SUM(AB7:AE7) -> 2508.9822 | AG7: =AF7*(1+AG8) -> 2759.8804 | AH7: =AG7*(1+AH8) -> 3063.4673 | AI7: =AH7*(1+AI8) -> 3431.0833 | AJ7: =AI7*(1+AJ8) -> 3877.1242 | AK7: =AJ7*(1+AK8) -> 4419.9215
B8: y/y | C8: n/a | D8: n/a | E8: n/a | F8: n/a | G8: n/a | H8: =H7/C7-1 -> 0.070620285 | I8: =I7/D7-1 -> -0.0027483314 | J8: =J7/E7-1 -> -0.081884898 | K8: =K7/F7-1 -> -0.015940902 | L8: =L7/G7-1 -> -0.009064791 | M8: =M7/H7-1 -> -0.064396164 | N8: =N7/I7-1 -> -0.10255906 | O8: =O7/J7-1 -> -0.013672697 | ... V8: =V7/Q7-1 -> 0.094163342 | W8: =V8 -> 0.094163342 | X8: =W8 -> 0.094163342 | Y8: =X8 -> 0.094163342 | Z8: =Y8 -> 0.094163342 | AA8: =AA7/V7-1 -> 0.094163342 | AB8: 0.1 | AC8: =AB8 -> 0.1 | AD8: =AC8 -> 0.1 | AE8: =AD8 -> 0.1 | AF8: =AF7/AA7-1 -> 0.1 | AG8: =AF8 -> 0.1 | AH8: =AG8+0.01 -> 0.11 | AI8: =AH8+0.01 -> 0.12 | AJ8: =AI8+0.01 -> 0.13 | AK8: =AJ8+0.01 -> 0.14
A9: Revenues | C9: =SUM(C3:C7) -> 8050.4 | D9: =SUM(D3:D7) -> 7635.6 | E9: =SUM(E3:E7) -> 8150.1 | F9: =SUM(F3:F7) -> 8414.2 | G9: =SUM(G3:G7) -> 32250.3 | H9: =SUM(H3:H7) -> 8714.2695 | I9: =SUM(I3:I7) -> 8720.1969 | J9: =SUM(J3:J7) -> 9168.6195 | ... AK9: =SUM(AK3:AK7) -> 63473.227
B10: y/y | C10: n/a | D10: n/a | E10: n/a | F10: n/a | G10: n/a | H10: =H9/C9-1 -> 0.082464168 | I10: =I9/D9-1 -> 0.14204475 | J10: =J9/E9-1 -> 0.12497019 | K10: =K9/F9-1 -> 0.11405745 | L10: =L9/G9-1 -> 0.11552274 | M10: =M9/H9-1 -> 0.081612135 | N10: =N9/I9-1 -> -0.018029807 | O10: =O9/J9-1 -> -0.0059694077 | ... AF10: =AF9/AA9-1 -> 0.059892752 | AG10: =AG9/AF9-1 -> 0.072740242 | AH10: =AH9/AG9-1 -> 0.083347951 | AI10: =AI9/AH9-1 -> 0.093915406 | AJ10: =AJ9/AI9-1 -> 0.10444534 | AK10: =AK9/AJ9-1 -> 0.11494022
B12: Product distribution costs | C12: 2526.9 | D12: 2465.8 | E12: 2613.6 | F12: 2711 | G12: =SUM(C12:F12) -> 10317.3 | H12: 2810.2 | I12: 2801.7 | J12: 2864.2 | K12: 2933.1 | L12: =SUM(H12:K12) -> 11409.2 | M12: 2980.6 | N12: 2648.7 | O12: 2740.9 | P12: 2910.3 | Q12: =SUM(M12:P12) -> 11280.5 | R12: 2893.7 | S12: 2737.6 | T12: 2955.5 | U12: 3071.4 | V12: =SUM(R12:U12) -> 11658.2 | W12: =W13*W9 -> 3035.1303 | X12: =X13*X9 -> 2828.9093 | Y12: =Y13*Y9 -> 3055.5647 | Z12: =Z13*Z9 -> 3093.807 | AA12: =SUM(W12:Z12) -> 12013.411 | AB12: =AB13*AB9 -> 3152.2529 | AC12: =AC13*AC9 -> 2985.9744 | AD12: =AD13*AD9 -> 3250.9584 | AE12: =AE13*AE9 -> 3343.8031 | AF12: =SUM(AB12:AE12) -> 12732.989 | AG12: =AG13*AG9 -> 13789.676 | AH12: =AH13*AH9 -> 14774.095 | AI12: =AI13*AI9 -> 15981.199 | AJ12: =AJ13*AJ9 -> 17451.106 | AK12: =AK13*AK9 -> 19234.784
B13: Margin % | C13: =C12/C9 -> 0.31388502 | D13: =D12/D9 -> 0.32293467 | E13: =E12/E9 -> 0.32068318 | F13: =F12/F9 -> 0.32219343 | G13: =G12/G9 -> 0.3199133 | H13: =H12/H9 -> 0.32248257 | I13: =I12/I9 -> 0.32128862 | J13: =J12/J9 -> 0.31239163 | ... V13: =V12/V9 -> 0.31403577 | W13: =V13 -> 0.31403577 | X13: =W13 -> 0.31403577 | Y13: =X13 -> 0.31403577 | Z13: =Y13 -> 0.31403577 | AA13: =AA12/AA9 -> 0.31403625 | AB13: =AA13 -> 0.31403625 | AC13: =AB13 -> 0.31403625 | AD13: =AC13 -> 0.31403625 | AE13: =AD13 -> 0.31403625 | AF13: =AF12/AF9 -> 0.31403775 | AG13: =AF13+0.003 -> 0.31703775 | AH13: =AG13-0.0035 -> 0.31353775 | AI13: =AH13-0.0035 -> 0.31003775 | AJ13: =AI13-0.0035 -> 0.30653775 | AK13: =AJ13-0.0035 -> 0.30303775
B14: Store operating expenses | C14: 3400 | D14: 3314.7 | E14: 3302.5 | F14: 3544.7 | G14: =SUM(C14:F14) -> 13561.9 | H14: 3665.3 | I14: 3636 | J14: 3697.6 | K14: 3721.3 | L14: =SUM(H14:K14) -> 14720.2 | M14: 3851.5 | N14: 3724.1 | O14: 3829.1 | P14: 3881.7 | Q14: =SUM(M14:P14) -> 15286.4 | R14: 4203 | S14: 4176 | T14: 4344.8 | U14: 4335 | V14: =SUM(R14:U14) -> 17058.8 | W14: =W15*W9 -> 4441.1385 | X14: =X15*X9 -> 4139.3867 | Y14: =Y15*Y9 -> 4471.039 | Z14: =Z15*Z9 -> 4526.9969 | AA14: =SUM(W14:Z14) -> 17578.561 | AB14: =AB15*AB9 -> 4612.5175 | AC14: =AC15*AC9 -> 4359.703 | AD14: =AD15*AD9 -> 4736.2435 | AE14: =AE15*AE9 -> 4860.8588 | AF14: =SUM(AB14:AE14) -> 18569.323 | AG14: =AG15*AG9 -> 19920.06 | AH14: =AH15*AH9 -> 21391.873 | AI14: =AI15*AI9 -> 23194.716 | AJ14: =AJ15*AJ9 -> 25389.577 | AK14: =AK15*AK9 -> 28053.968
B15: Margin % | C15: =C14/C9 -> 0.42233926 | D15: =D14/D9 -> 0.43411127 | E15: =E14/E9 -> 0.40520975 | F15: =F14/F9 -> 0.42127594 | G15: =G14/G9 -> 0.42052012 | H15: =H14/H9 -> 0.42060898 | I15: =I14/I9 -> 0.41696306 | J15: =J14/J9 -> 0.40328863 | ... V15: =V14/V9 -> 0.45951119 | W15: =V15 -> 0.45951119 | X15: =W15 -> 0.45951119 | Y15: =X15 -> 0.45951119 | Z15: =Y15 -> 0.45951119 | AA15: =AA14/AA9 -> 0.45951189 | AB15: =AA15 -> 0.45951189 | AC15: =AB15-0.001 -> 0.45851189 | AD15: =AC15-0.001 -> 0.45751189 | AE15: =AD15-0.001 -> 0.45651189 | AF15: =AF14/AF9 -> 0.45798112 | AG15: =AF15 -> 0.45798112 | AH15: =AG15-0.004 -> 0.45398112 | AI15: =AH15-0.004 -> 0.44998112 | AJ15: =AI15-0.004 -> 0.44598112 | AK15: =AJ15-0.004 -> 0.44198112
B16: Other operating expenses | C16: 101.7 | D16: 101.7 | E16: 135.1 | F16: 123.1 | G16: =SUM(C16:F16) -> 461.6 | H16: 129.3 | I16: 126.2 | J16: 138.7 | K16: 145.2 | L16: =SUM(H16:K16) -> 539.4 | M16: 150.4 | N16: 132.8 | O16: 143.9 | P16: 138.7 | Q16: =SUM(M16:P16) -> 565.8 | R16: 152.5 | S16: 138.7 | T16: 151.6 | U16: 141.8 | V16: =SUM(R16:U16) -> 584.6 | W16: =W17*W9 -> 152.19649 | X16: =X17*X9 -> 141.85555 | Y16: =Y17*Y9 -> 153.22118 | Z16: =Z17*Z9 -> 155.13884 | AA16: =SUM(W16:Z16) -> 602.41206 | AB16: =AB17*AB9 -> 158.0696 | AC16: =AC17*AC9 -> 149.73157 | AD16: =AD17*AD9 -> 163.01919 | AE16: =AE17*AE9 -> 167.67488 | AF16: =SUM(AB16:AE16) -> 638.49524 | AG16: =AG17*AG9 -> 684.93954 | AH16: =AH17*AH9 -> 553.54535 | AI16: =AI17*AI9 -> 399.34788 | AJ16: =AJ17*AJ9 -> 213.33905 | AK16: =AK17*AK9 -> -16.032615
B17: Margin % | C17: =C16/C9 -> 0.012632913 | D17: =D16/D9 -> 0.013319189 | E17: =E16/E9 -> 0.016576484 | F17: =F16/F9 -> 0.01463003 | G17: =G16/G9 -> 0.014313045 | H17: =H16/H9 -> 0.014837732 | I17: =I16/I9 -> 0.01447215 | J17: =J16/J9 -> 0.015127686 | ... V17: =V16/V9 -> 0.015747312 | W17: =V17 -> 0.015747312 | X17: =W17 -> 0.015747312 | Y17: =X17 -> 0.015747312 | Z17: =Y17 -> 0.015747312 | AA17: =AA16/AA9 -> 0.015747336 | AB17: =AA17 -> 0.015747336 | AC17: =AB17 -> 0.015747336 | AD17: =AC17 -> 0.015747336 | AE17: =AD17 -> 0.015747336 | AF17: =AF16/AF9 -> 0.015747411 | AG17: =AF17 -> 0.015747411 | AH17: =AG17-0.004 -> 0.011747411 | AI17: =AH17-0.004 -> 0.0077474114 | AJ17: =AI17-0.004 -> 0.0037474114 | AK17: =AJ17-0.004 -> -0.00025258862
B18: SG&A expenses | C18: =366+525.8 -> 891.8 | D18: =367.7+481.5 -> 849.2 | E18: =356.8+486.7 -> 843.5 | F18: =357.4+538 -> 895.4 | G18: =SUM(C18:F18) -> 3479.9 | H18: =327.1+580.9 -> 908 | I18: =341.9+620.4 -> 962.3 | J18: =342.2+604.3 -> 946.5 | K18: =351.4+635.8 -> 987.2 | L18: =SUM(H18:K18) -> 3804 | M18: =365.3+648 -> 1013.3 | N18: =371.9+654.6 -> 1026.5 | O18: =380.4+576 -> 956.4 | P18: =395+644.8 -> 1039.8 | Q18: =SUM(M18:P18) -> 4036 | R18: =407.6+665.8 -> 1073.4 | S18: =418.9+632.3 -> 1051.2 | T18: =427.6+677.2 -> 1104.8 | U18: =430.8+642 -> 1072.8 | V18: =SUM(R18:U18) -> 4302.2 | W18: =W19*W9 -> 1120.0475 | X18: =X19*X9 -> 1043.9462 | Y18: =Y19*Y9 -> 1127.5884 | Z18: =Z19*Z9 -> 1141.7008 | AA18: =SUM(W18:Z18) -> 4433.2828 | AB18: =AB19*AB9 -> 1163.269 | AC18: =AC19*AC9 -> 1101.9076 | AD18: =AD19*AD9 -> 1199.6941 | AE18: =AE19*AE9 -> 1233.9563 | AF18: =SUM(AB18:AE18) -> 4698.8269 | AG18: =AG19*AG9 -> 5040.6207 | AH18: =AH19*AH9 -> 5295.824 | AI18: =AI19*AI9 -> 5612.7725 | AJ18: =AJ19*AJ9 -> 5999.7464 | AK18: =AK19*AK9 -> 6689.3586
B19: Margin % | C19: =C18/C9 -> 0.1107771 | D19: =D18/D9 -> 0.11121588 | E19: =E18/E9 -> 0.10349566 | F19: =F18/F9 -> 0.10641535 | G19: =G18/G9 -> 0.10790287 | H19: =H18/H9 -> 0.10419691 | I19: =I18/I9 -> 0.11035301 | J19: =J18/J9 -> 0.10323255 | ... V19: =V18/V9 -> 0.11588793 | W19: =V19 -> 0.11588793 | X19: =W19 -> 0.11588793 | Y19: =X19 -> 0.11588793 | Z19: =Y19 -> 0.11588793 | AA19: =AA18/AA9 -> 0.11588811 | AB19: =AA19 -> 0.11588811 | AC19: =AB19 -> 0.11588811 | AD19: =AC19 -> 0.11588811 | AE19: =AD19 -> 0.11588811 | AF19: =AF18/AF9 -> 0.11588866 | AG19: =AF19 -> 0.11588866 | AH19: =AG19-0.0035 -> 0.11238866 | AI19: =AH19-0.0035 -> 0.10888866 | AJ19: =AI19-0.0035 -> 0.10538866 | AK19: =AJ19 -> 0.10538866
A20: Operating Income | C20: =C9-SUM(C12:C18) -> 1129.2511 | D20: =D9-SUM(D12:D18) -> 903.42963 | E20: =E9-SUM(E12:E18) -> 1254.6575 | F20: =F9-SUM(F12:F18) -> 1139.2419 | G20: =G9-SUM(G12:G18) -> 4428.8453 | H20: =H9-SUM(H12:H18) -> 1200.7116 | I20: =I9-SUM(I12:I18) -> 1193.2442 | J20: =J9-SUM(J12:J18) -> 1520.8887 | ... AK20: =AK9-SUM(AK12:AK18) -> 9510.4041
B21: Margin % | C21: =C20/C9 -> 0.14027267 | D21: =D20/D9 -> 0.11831809 | E21: =E20/E9 -> 0.15394382 | F21: =F20/F9 -> 0.13539515 | G21: =G20/G9 -> 0.13732726 | H21: =H20/H9 -> 0.13778683 | I21: =I20/I9 -> 0.13683684 | J21: =J20/J9 -> 0.16587979 | ... AK21: =AK20/AK9 -> 0.14983332
A23: Company operated stores
B24: Beginning Stores | Q24: 21018 | V24: =Q29 -> 21514 | AA24: =V29 -> 22019.92 | AF24: =AA29 -> 22535.958 | AG24: =AF29 -> 23062.318 | AH24: =AG29 -> 23599.204 | AI24: =AH29 -> 24146.828 | AJ24: =AI29 -> 24705.405 | AK24: =AJ29 -> 25275.153
B25: Openings | Q25: 1261 | V25: =Q25*(1.02) -> 1286.22 | AA25: =V25*(1.02) -> 1311.9444 | AF25: =AA25*(1.02) -> 1338.1833 | AG25: =AF25*(1+0.02) -> 1364.947 | AH25: =AG25*(1+0.02) -> 1392.2459 | AI25: =AH25*(1+0.02) -> 1420.0908 | AJ25: =AI25*(1+0.02) -> 1448.4926
B26: Closings | Q26: -877 | V26: =Q26*(1.02) -> -894.54 | AA26: =V26*(1.02) -> -912.4308 | AF26: =AA26*(1.02) -> -930.67942 | AG26: =AF26*(1+0.02) -> -949.293 | AH26: =AG26*(1+0.02) -> -968.27886 | AI26: =AH26*(1+0.02) -> -987.64444 | AJ26: =AI26*(1+0.02) -> -1007.3973
B27: Transfers | Q27: 112 | V27: =Q27*(1.02) -> 114.24 | AA27: =V27*(1.02) -> 116.5248 | AF27: =AA27*(1.02) -> 118.8553 | AG27: =AF27*(1+0.02) -> 121.2324 | AH27: =AG27*(1+0.02) -> 123.65705 | AI27: =AH27*(1+0.02) -> 126.13019 | AJ27: =AI27*(1+0.02) -> 128.65279
A28: Net change in stores | Q28: =SUM(Q25:Q27) -> 496 | V28: =SUM(V25:V27) -> 505.92 | AA28: =SUM(AA25:AA27) -> 516.0384 | AF28: =SUM(AF25:AF27) -> 526.35917 | AG28: =SUM(AG25:AG27) -> 536.88635 | AH28: =SUM(AH25:AH27) -> 547.62408 | AI28: =SUM(AI25:AI27) -> 558.57656 | AJ28: =SUM(AJ25:AJ27) -> 569.74809
B29: Ending stores | Q29: =SUM(Q28,Q24) -> 21514 | V29: =SUM(V28,V24) -> 22019.92 | AA29: =SUM(AA28,AA24) -> 22535.958 | AF29: =SUM(AF28,AF24) -> 23062.318 | AG29: =SUM(AG28,AG24) -> 23599.204 | AH29: =SUM(AH28,AH24) -> 24146.828 | AI29: =SUM(AI28,AI24) -> 24705.405 | AJ29: =SUM(AJ28,AJ24) -> 25275.153
A31: Licensed Stores
B32: Beginning Stores | Q32: 19181 | V32: =Q37 -> 19476 | AA32: =V37 -> 19776.9 | AF32: =AA37 -> 20083.818 | AG32: =AF37 -> 20396.874 | AH32: =AG37 -> 20716.192 | AI32: =AH37 -> 21041.896 | AJ32: =AI37 -> 21374.114 | AK32: =AJ37 -> 21712.976
B33: Openings | Q33: 1001 | V33: =Q33*(1.02) -> 1021.02 | AA33: =V33*(1.02) -> 1041.4404 | AF33: =AA33*(1.02) -> 1062.2692 | AG33: =AF33*(1+0.02) -> 1083.5146 | AH33: =AG33*(1+0.02) -> 1105.1849 | AI33: =AH33*(1+0.02) -> 1127.2886 | AJ33: =AI33*(1+0.02) -> 1149.8344
B34: Closings | Q34: -594 | V34: =Q34*(1.02) -> -605.88 | AA34: =V34*(1.02) -> -617.9976 | AF34: =AA34*(1.02) -> -630.35755 | AG34: =AF34*(1+0.02) -> -642.9647 | AH34: =AG34*(1+0.02) -> -655.824 | AI34: =AH34*(1+0.02) -> -668.94048 | AJ34: =AI34*(1+0.02) -> -682.31929
B35: Transfers | Q35: -112 | V35: =Q35*(1.02) -> -114.24 | AA35: =V35*(1.02) -> -116.5248 | AF35: =AA35*(1.02) -> -118.8553 | AG35: =AF35*(1+0.02) -> -121.2324 | AH35: =AG35*(1+0.02) -> -123.65705 | AI35: =AH35*(1+0.02) -> -126.13019 | AJ35: =AI35*(1+0.02) -> -128.65279
A36: Net change in stores | Q36: =SUM(Q33:Q35) -> 295 | V36: =SUM(V33:V35) -> 300.9 | AA36: =SUM(AA33:AA35) -> 306.918 | AF36: =SUM(AF33:AF35) -> 313.05636 | AG36: =SUM(AG33:AG35) -> 319.31749 | AH36: =SUM(AH33:AH35) -> 325.70384 | AI36: =SUM(AI33:AI35) -> 332.21791 | AJ36: =SUM(AJ33:AJ35) -> 338.86227
B37: Ending stores | Q37: =SUM(Q36,Q32) -> 19476 | V37: =SUM(V36,V32) -> 19776.9 | AA37: =SUM(AA36,AA32) -> 20083.818 | AF37: =SUM(AF36,AF32) -> 20396.874 | AG37: =SUM(AG36,AG32) -> 20716.192 | AH37: =SUM(AH36,AH32) -> 21041.896 | AI37: =SUM(AI36,AI32) -> 21374.114 | AJ37: =SUM(AJ36,AJ32) -> 21712.976
A39: Comparable Sales Projection
A40: Comps
B41: Company operated comps margin | Q41: -0.01 | R41: =Q41 -> -0.01 | S41: =R41 -> -0.01 | T41: =S41 -> -0.01 | U41: =T41 -> -0.01 | V41: 0 | W41: =V41 -> 0 | X41: =W41 -> 0 | Y41: =X41 -> 0 | Z41: =Y41 -> 0 | AA41: 0.01 | AB41: =AA41 -> 0.01 | AC41: =AB41 -> 0.01 | AD41: =AC41 -> 0.01 | AE41: =AD41 -> 0.01 | AF41: 0.02 | AG41: =AF41+0.0075 -> 0.0275 | AH41: =AG41+0.0075 -> 0.035 | AI41: =AH41+0.0075 -> 0.0425 | AJ41: =AI41+0.0075 -> 0.05
B42: Licensed store comps | Q42: -0.01 | R42: =Q42 -> -0.01 | S42: =R42 -> -0.01 | T42: =S42 -> -0.01 | U42: =T42 -> -0.01 | V42: =V41 -> 0 | W42: =W41 -> 0 | X42: =X41 -> 0 | Y42: =Y41 -> 0 | Z42: =Z41 -> 0 | AA42: =AA41 -> 0.01 | AB42: =AB41 -> 0.01 | AC42: =AC41 -> 0.01 | ... AJ42: =AJ41 -> 0.05
A43: Company operated revenue
B44: Prior year rev | Q44: =Q3 -> 29765.9 | R44: =R3 -> 7785.3 | S44: =S3 -> 7285 | T44: =T3 -> 7812.5 | U44: =U3 -> 7862 | V44: =V3 -> 30688.9 | W44: =W3 -> 8018.859 | X44: =X3 -> 7503.55 | ... AJ44: =AJ3 -> 48482.481
...

Sheet Assumptions
A1: =CoName -> Starbucks Corp. | C1: Hist. | D1: Hist. | E1: Hist. | F1: Proj. | G1: Proj. | H1: Proj. | I1: Proj. | J1: Proj. | K1: Proj. | L1: Proj.
A2: * | B2: Income Statement | C2: 2023 | D2: =C2+1 -> 2024 | E2: =D2+1 -> 2025 | F2: =E2+1 -> 2026 | G2: =F2+1 -> 2027 | H2: =G2+1 -> 2028 | I2: =H2+1 -> 2029 | J2: =I2+1 -> 2030 | K2: =J2+1 -> 2031 | L2: =K2+1 -> 2032
B4: Operating Case | D4: 1
D5: Variance
B6: Revenue Model Case | D6: 0 | F6: ='Quarterly Projections'!AA10 -> 0.030467227 | G6: ='Quarterly Projections'!AF10 -> 0.059892752 | H6: ='Quarterly Projections'!AG10 -> 0.072740242 | I6: ='Quarterly Projections'!AH10 -> 0.083347951 | J6: ='Quarterly Projections'!AI10 -> 0.093915406 | K6: ='Quarterly Projections'!AJ10 -> 0.10444534 | L6: ='Quarterly Projections'!AK10 -> 0.11494022
B7: Comps Model Case | D7: 0.025 | F7: ='Quarterly Projections'!V64 -> 0.0448069 | G7: ='Quarterly Projections'!AA64 -> 0.045256819 | H7: ='Quarterly Projections'!AF64 -> 0.076291 | I7: ='Quarterly Projections'!AG64 -> 0.08736814 | J7: ='Quarterly Projections'!AH64 -> 0.097817079 | K7: ='Quarterly Projections'!AI64 -> 0.10823392 | L7: ='Quarterly Projections'!AJ64 -> 0.1186206
B8: Pessimistic Case | D8: -0.025 | F8: =F6+$D$8 -> 0.0054672268 | G8: =G6+$D$8 -> 0.034892752 | H8: =H6+$D$8 -> 0.047740242 | I8: =I6+$D$8 -> 0.058347951 | J8: =J6+$D$8 -> 0.068915406 | K8: =K6+$D$8 -> 0.079445337 | L8: =L6+$D$8 -> 0.089940221
B10: Revenue Growth | D10: ='Quarterly Projections'!Q10 -> 0.0055666508 | E10: ='Quarterly Projections'!V10 -> 0.02619368 | F10: =CHOOSE(ScenarioREV,F6,F7,F8) -> 0.030467227 | G10: =CHOOSE(ScenarioREV,G6,G7,G8) -> 0.059892752 | H10: =CHOOSE(ScenarioREV,H6,H7,H8) -> 0.072740242 | I10: =CHOOSE(ScenarioREV,I6,I7,I8) -> 0.083347951 | J10: =CHOOSE(ScenarioREV,J6,J7,J8) -> 0.093915406 | K10: =CHOOSE(ScenarioREV,K6,K7,K8) -> 0.10444534 | L10: =CHOOSE(ScenarioREV,L6,L7,L8) -> 0.11494022
B11: COGS % of sales | C11: ='Quarterly Projections'!L13 -> 0.31713415 | D11: ='Quarterly Projections'!Q13 -> 0.31182096 | E11: ='Quarterly Projections'!V13 -> 0.31403577 | F11: ='Quarterly Projections'!AA13 -> 0.31403625 | G11: =F11 -> 0.31403625 | H11: =G11 -> 0.31403625 | I11: =H11 -> 0.31403625 | J11: =I11 -> 0.31403625 | K11: =J11 -> 0.31403625 | L11: =K11 -> 0.31403625
B12: SG&A % of sales | C12: =SUM('Quarterly Projections'!L15,'Quarterly Projections'!L17,'Quarterly Projections'!L19) -> 0.52989855 | D12: =SUM('Quarterly Projections'!Q15,'Quarterly Projections'!Q17,'Quarterly Projections'!Q19) -> 0.5497591 | E12: =SUM('Quarterly Projections'!V15,'Quarterly Projections'!V17,'Quarterly Projections'!V19) -> 0.59114643 | F12: =SUM('Quarterly Projections'!AA15,'Quarterly Projections'!AA17,'Quarterly Projections'!AA19) -> 0.59114733 | G12: =SUM('Quarterly Projections'!AF15,'Quarterly Projections'!AF17,'Quarterly Projections'!AF19) -> 0.58961719 | H12: =SUM('Quarterly Projections'!AG15,'Quarterly Projections'!AG17,'Quarterly Projections'!AG19) -> 0.58961719 | I12: =SUM('Quarterly Projections'!AH15,'Quarterly Projections'!AH17,'Quarterly Projections'!AH19) -> 0.57811719 | J12: =SUM('Quarterly Projections'!AI15,'Quarterly Projections'!AI17,'Quarterly Projections'!AI19) -> 0.56661719 | K12: =SUM('Quarterly Projections'!AJ15,'Quarterly Projections'!AJ17,'Quarterly Projections'!AJ19) -> 0.55511719 | L12: =SUM('Quarterly Projections'!AK15,'Quarterly Projections'!AK17,'Quarterly Projections'!AK19) -> 0.54711719
B13: Amortization $ Amt | C13: =IncState!C22 -> 0 | D13: =IncState!D22 -> 0 | E13: =IncState!E22 -> 0 | F13: =E13 -> 0 | G13: =F13 -> 0 | H13: =G13 -> 0 | I13: =H13 -> 0 | J13: =I13 -> 0 | K13: =J13 -> 0 | L13: =K13 -> 0
B14: Non recurring income / (expense) | C14: =IncState!C25 -> 0 | D14: =IncState!D25 -> 0 | E14: =IncState!E25 -> 0 | F14: 0 | G14: 0 | H14: 0 | I14: 0 | J14: 0 | K14: 0 | L14: 0
B15: Other Income / (expense) | C15: =IncState!C26 -> 0 | D15: =IncState!D26 -> 0 | E15: =IncState!E26 -> 0 | F15: 0 | G15: 0 | H15: 0 | I15: 0 | J15: 0 | K15: 0 | L15: 0
B16: Effective tax rate | C16: =IncState!C33/IncState!C31 -> 0.23592782 | D16: =IncState!D33/IncState!D31 -> 0.28140783 | E16: =IncState!E33/IncState!E31 -> 0.30787491 | F16: 0.19 | G16: =F16+0.01 -> 0.2 | H16: =G16+0.01 -> 0.21 | I16: =H16+0.01 -> 0.22 | J16: =I16 -> 0.22 | K16: =J16 -> 0.22 | L16: =K16 -> 0.22
B17: Dividend Payout Rate | C17: =IncState!C35 -> 1.9621954 | D17: =IncState!D35 -> 2.1198116 | E17: =IncState!E35 -> 2.2799436 | F17: =E17+(E17-D17) -> 2.4400755 | G17: =F17+(F17-E17) -> 2.6002074 | H17: =G17+(G17-F17) -> 2.7603393 | I17: =H17+(H17-G17) -> 2.9204712 | J17: =I17+(I17-H17) -> 3.0806031 | K17: =J17+(J17-I17) -> 3.240735 | L17: =K17+(K17-J17) -> 3.4008669
B18: Basic WASO | C18: =IncState!C38 -> 1153.3 | D18: =IncState!D38 -> 1146.8 | E18: =IncState!E38 -> 1133.8 | F18: =E18 -> 1133.8 | G18: =F18 -> 1133.8 | H18: =G18 -> 1133.8 | I18: =H18 -> 1133.8 | J18: =I18 -> 1133.8 | K18: =J18 -> 1133.8 | L18: =K18 -> 1133.8
B19: Diluted WASO | C19: =IncState!C39 -> 1158.5 | D19: =IncState!D39 -> 1151.3 | E19: =IncState!E39 -> 1137.3 | F19: =E19 -> 1137.3 | G19: =F19 -> 1137.3 | H19: =G19 -> 1137.3 | I19: =H19 -> 1137.3 | J19: =I19 -> 1137.3 | K19: =J19 -> 1137.3 | L19: =K19 -> 1137.3
A21: * | B21: Debt | C21: =C2 -> 2023 | D21: =D2 -> 2024 | E21: =E2 -> 2025 | F21: =F2 -> 2026 | G21: =G2 -> 2027 | H21: =H2 -> 2028 | I21: =I2 -> 2029 | J21: =J2 -> 2030 | ... L21: =L2 -> 2032
B23: Interest rate on Revolver | E23: 0.05848 | F23: =E23 -> 0.05848 | G23: =F23 -> 0.05848 | H23: =G23 -> 0.05848 | I23: =H23 -> 0.05848 | J23: =I23 -> 0.05848 | K23: =J23 -> 0.05848 | L23: =K23 -> 0.05848
B24: Interest rate on long-term debt | E24: 0.0381 | F24: =E24 -> 0.0381 | G24: =F24 -> 0.0381 | H24: =G24 -> 0.0381 | I24: =H24 -> 0.0381 | J24: =I24 -> 0.0381 | K24: =J24 -> 0.0381 | L24: =K24 -> 0.0381
B25: Interest rate on cash | E25: =IncState!E28/SUM(BalSheet!E17:E18) -> 0.037368389 | F25: =E25 -> 0.037368389 | G25: =F25 -> 0.037368389 | H25: =G25 -> 0.037368389 | I25: =H25 -> 0.037368389 | J25: =I25 -> 0.037368389 | K25: =J25 -> 0.037368389 | L25: =K25 -> 0.037368389
B27: Issuance of long-term debt | E27: 0 | F27: 0 | G27: 0 | H27: 0 | I27: 0 | J27: 0 | K27: 0 | L27: 0
B28: Repayment of long-term debt | E28: 0 | F28: 0 | G28: 0 | H28: 0 | I28: 0 | J28: 0 | K28: 0 | L28: 0
A30: * | B30: Calcs | C30: =C21 -> 2023 | D30: =D21 -> 2024 | E30: =E21 -> 2025 | F30: =F21 -> 2026 | G30: =G21 -> 2027 | H30: =H21 -> 2028 | I30: =I21 -> 2029 | J30: =J21 -> 2030 | ... L30: =L21 -> 2032
B32: CapEx % of Sales | C32: =1841.3/IncState!C16 -> 0.051181424 | D32: =2333.6/IncState!D16 -> 0.064506483 | E32: =2777.5/IncState!E16 -> 0.07481724 | F32: =E32+0.001 -> 0.07581724 | G32: =F32+0.001 -> 0.07681724 | H32: =G32+0.001 -> 0.07781724 | I32: =H32+0.001 -> 0.07881724 | J32: =I32+0.001 -> 0.07981724 | K32: =J32+0.001 -> 0.08081724 | L32: =K32+0.001 -> 0.08181724
B33: Depreciation % of beginning PP&E | D33: =IncState!D21/BalSheet!C24 -> 0.093468074 | E33: =IncState!E21/BalSheet!D24 -> 0.095735995 | F33: =E33 -> 0.095735995 | G33: =F33 -> 0.095735995 | H33: =G33 -> 0.095735995 | I33: =H33 -> 0.095735995 | J33: =I33 -> 0.095735995 | K33: =J33 -> 0.095735995 | L33: =K33 -> 0.095735995
B34: Share issuance / (repurchases) | F34: 0 | G34: 0 | H34: 0 | I34: 0 | J34: 0 | K34: 0 | L34: 0
A36: * | B36: Shareholder information | C36: =C30 -> 2023 | D36: =D30 -> 2024 | E36: =E30 -> 2025 | F36: =F30 -> 2026 | G36: =G30 -> 2027 | H36: =H30 -> 2028 | I36: =I30 -> 2029 | J36: =J30 -> 2030 | ... L36: =L30 -> 2032
B38: =B17 -> Dividend Payout Rate | C38: =C17 -> 1.9621954 | D38: =D17 -> 2.1198116 | E38: =E17 -> 2.2799436 | F38: =F17 -> 2.4400755 | G38: =G17 -> 2.6002074 | H38: =H17 -> 2.7603393 | I38: =I17 -> 2.9204712 | ... L38: =L17 -> 3.4008669
B39: Basic WASO | C39: =C18 -> 1153.3 | D39: =D18 -> 1146.8 | E39: =E18 -> 1133.8 | F39: =F18 -> 1133.8 | G39: =G18 -> 1133.8 | H39: =H18 -> 1133.8 | I39: =I18 -> 1133.8 | J39: =J18 -> 1133.8 | ... L39: =L18 -> 1133.8
B40: Diluted WASO | C40: =C19 -> 1158.5 | D40: =D19 -> 1151.3 | E40: =E19 -> 1137.3 | F40: =F19 -> 1137.3 | G40: =G19 -> 1137.3 | H40: =H19 -> 1137.3 | I40: =I19 -> 1137.3 | J40: =J19 -> 1137.3 | ... L40: =L19 -> 1137.3
A42: * | B42: Balance Sheet - Assets | C42: =C36 -> 2023 | D42: =D36 -> 2024 | E42: =E36 -> 2025 | F42: =F36 -> 2026 | G42: =G36 -> 2027 | H42: =H36 -> 2028 | I42: =I36 -> 2029 | J42: =J36 -> 2030 | ... L42: =L36 -> 2032
B44: Operating Cash % of sales | C44: =BalSheet!C17/IncState!C16 -> 0.02 | D44: =BalSheet!D17/IncState!D16 -> 0.02 | E44: =BalSheet!E17/IncState!E16 -> 0.02 | F44: =E44 -> 0.02 | G44: =F44 -> 0.02 | H44: =G44 -> 0.02 | I44: =H44 -> 0.02 | J44: =I44 -> 0.02 | K44: =J44 -> 0.02 | L44: =K44 -> 0.02
B45: Accounts receivable % of sales | C45: =BalSheet!C19/IncState!C16 -> 0.032674612 | D45: =BalSheet!D19/IncState!D16 -> 0.032731457 | E45: =BalSheet!E19/IncState!E16 -> 0.032696009 | F45: =E45 -> 0.032696009 | G45: =F45 -> 0.032696009 | H45: =G45 -> 0.032696009 | I45: =H45 -> 0.032696009 | J45: =I45 -> 0.032696009 | K45: =J45 -> 0.032696009 | L45: =K45 -> 0.032696009
B46: Inventories % of COGS | C46: =BalSheet!C20/IncState!C17 -> 0.19077587 | D46: =BalSheet!D20/IncState!D17 -> 0.16013475 | E46: =BalSheet!E20/IncState!E17 -> 0.15245064 | F46: =E46 -> 0.15245064 | G46: =F46 -> 0.15245064 | H46: =G46 -> 0.15245064 | I46: =H46 -> 0.15245064 | J46: =I46 -> 0.15245064 | K46: =J46 -> 0.15245064 | L46: =K46 -> 0.15245064
B47: Other current assets % of sales | C47: =BalSheet!C21/IncState!C16 -> 0.023576866 | D47: =BalSheet!D21/IncState!D16 -> 0.021046982 | E47: =BalSheet!E21/IncState!E16 -> 0.015356727 | F47: =E47 -> 0.015356727 | G47: =F47 -> 0.015356727 | H47: =G47 -> 0.015356727 | I47: =H47 -> 0.015356727 | J47: =I47 -> 0.015356727 | K47: =J47 -> 0.015356727 | L47: =K47 -> 0.015356727
B49: Investments in unconsolidated entities | C49: =BalSheet!C26 -> 590.3 | D49: =BalSheet!D26 -> 687.3 | E49: =BalSheet!E26 -> 739.9 | F49: =E49 -> 739.9 | G49: =F49 -> 739.9 | H49: =G49 -> 739.9 | I49: =H49 -> 739.9 | J49: =I49 -> 739.9 | K49: =J49 -> 739.9 | L49: =K49 -> 739.9
B50: Other long-term assets % of sales | C50: =BalSheet!C27/IncState!C16 -> 0.065429834 | D50: =BalSheet!D27/IncState!D16 -> 0.064028269 | E50: =BalSheet!E27/IncState!E16 -> 0.064209489 | F50: =E50 -> 0.064209489 | G50: =F50 -> 0.064209489 | H50: =G50 -> 0.064209489 | I50: =H50 -> 0.064209489 | J50: =I50 -> 0.064209489 | K50: =J50 -> 0.064209489 | L50: =K50 -> 0.064209489
A52: * | B52: Balance Sheet - Liabilities | C52: =C42 -> 2023 | D52: =D42 -> 2024 | E52: =E42 -> 2025 | F52: =F42 -> 2026 | G52: =G42 -> 2027 | H52: =H42 -> 2028 | I52: =I42 -> 2029 | J52: =J42 -> 2030 | ... L52: =L42 -> 2032
B54: Accounts payable % of COGS | C54: =BalSheet!C33/IncState!C17 -> 0.3804123 | D54: =BalSheet!D33/IncState!D17 -> 0.40048757 | E54: =BalSheet!E33/IncState!E17 -> 0.39258205 | F54: =E54 -> 0.39258205 | G54: =F54 -> 0.39258205 | H54: =G54 -> 0.39258205 | I54: =H54 -> 0.39258205 | J54: =I54 -> 0.39258205 | K54: =J54 -> 0.39258205 | L54: =K54 -> 0.39258205
...

Sheet Calcs
A1: =CoName -> Starbucks Corp. | C1: Hist. | D1: Hist. | E1: Hist. | F1: Proj. | G1: Proj. | H1: Proj. | I1: Proj. | J1: Proj. | K1: Proj. | L1: Proj.
A2: Net PP&E | C2: 2023 | D2: =C2+1 -> 2024 | E2: =D2+1 -> 2025 | F2: =E2+1 -> 2026 | G2: =F2+1 -> 2027 | H2: =G2+1 -> 2028 | I2: =H2+1 -> 2029 | J2: =I2+1 -> 2030 | K2: =J2+1 -> 2031 | L2: =K2+1 -> 2032
B3: Capital expenditure % of sales | F3: =Assumptions!F32 -> 0.07581724 | G3: =Assumptions!G32 -> 0.07681724 | H3: =Assumptions!H32 -> 0.07781724 | I3: =Assumptions!I32 -> 0.07881724 | J3: =Assumptions!J32 -> 0.07981724 | K3: =Assumptions!K32 -> 0.08081724 | L3: =Assumptions!L32 -> 0.08181724
B4: Depreciation % of PP&E | F4: =Assumptions!F33 -> 0.095735995 | G4: =F4 -> 0.095735995 | H4: =G4 -> 0.095735995 | I4: =H4 -> 0.095735995 | J4: =I4 -> 0.095735995 | K4: =J4 -> 0.095735995 | L4: =K4 -> 0.095735995
B6: Beginning PP&E | F6: =E9 -> 17951.7 | G6: =F9 -> 19133.454 | H6: =G9 -> 20416.329 | I6: =H9 -> 21846.441 | J6: =I9 -> 23468.868 | K6: =J9 -> 25336.31 | L6: =K9 -> 27511.615
B7: Capex | F7: =F3*IncState!F16 -> 2900.3776 | G7: =G3*IncState!G16 -> 3114.6352 | H7: =H3*IncState!H16 -> 3384.6899 | I7: =I3*IncState!I16 -> 3713.9175 | J7: =J3*IncState!J16 -> 4114.2575 | K7: =K3*IncState!K16 -> 4600.9023 | L7: =L3*IncState!L16 -> 5193.2042
B8: Depreciation | F8: =F6*F4 -> 1718.6239 | G8: =G6*G4 -> 1831.7602 | H8: =H6*H4 -> 1954.5775 | I8: =I6*I4 -> 2091.4908 | J8: =J6*J4 -> 2246.8154 | K8: =K6*K4 -> 2425.5968 | L8: =L6*L4 -> 2633.8519
B9: Ending PP&E | E9: =BalSheet!E24 -> 17951.7 | F9: =F6+F7-F8 -> 19133.454 | G9: =G6+G7-G8 -> 20416.329 | H9: =H6+H7-H8 -> 21846.441 | I9: =I6+I7-I8 -> 23468.868 | J9: =J6+J7-J8 -> 25336.31 | K9: =K6+K7-K8 -> 27511.615 | L9: =L6+L7-L8 -> 30070.968
A10: Equity | C10: =C2 -> 2023 | D10: =D2 -> 2024 | E10: =E2 -> 2025 | F10: =F2 -> 2026 | G10: =G2 -> 2027 | H10: =H2 -> 2028 | I10: =I2 -> 2029 | J10: =J2 -> 2030 | ... L10: =L2 -> 2032
B11: Share issuance/(repurchases) | F11: =Assumptions!F34 -> 0 | G11: =Assumptions!G34 -> 0 | H11: =Assumptions!H34 -> 0 | I11: =Assumptions!I34 -> 0 | J11: =Assumptions!J34 -> 0 | K11: =Assumptions!K34 -> 0 | L11: =Assumptions!L34 -> 0
B13: Beginning balance | F13: =E17 -> -7441.6 | G13: =F17 -> -7270.1348 | H13: =G17 -> -7093.0724 | I13: =H17 -> -6912.1477 | J13: =I17 -> -6259.5761 | K13: =J17 -> -4953.9326 | L13: =K17 -> -2818.0134
B14: Net income | F14: =IncState!F34 -> 2938.0227 | G14: =IncState!G34 -> 3125.1775 | H14: =IncState!H34 -> 3310.5974 | I14: =IncState!I34 -> 3963.8018 | J14: =IncState!J34 -> 4798.4313 | K14: =IncState!K34 -> 5810.2645 | L14: =IncState!L34 -> 6874.1706
B15: Dividends paid | F15: =-IncState!F36 -> -2766.5576 | G15: =-IncState!G36 -> -2948.1151 | H15: =-IncState!H36 -> -3129.6727 | I15: =-IncState!I36 -> -3311.2302 | J15: =-IncState!J36 -> -3492.7878 | K15: =-IncState!K36 -> -3674.3453 | L15: =-IncState!L36 -> -3855.9029
B16: Share issuance / (repurchase) | F16: =F11 -> 0 | G16: =G11 -> 0 | H16: =H11 -> 0 | I16: =I11 -> 0 | J16: =J11 -> 0 | K16: =K11 -> 0 | L16: =L11 -> 0
B17: Ending balance | E17: =BalSheet!E41 -> -7441.6 | F17: =SUM(F13:F16) -> -7270.1348 | G17: =SUM(G13:G16) -> -7093.0724 | H17: =SUM(H13:H16) -> -6912.1477 | I17: =SUM(I13:I16) -> -6259.5761 | J17: =SUM(J13:J16) -> -4953.9326 | K17: =SUM(K13:K16) -> -2818.0134 | L17: =SUM(L13:L16) -> 200.25436
A18: OWC | C18: =C10 -> 2023 | D18: =D10 -> 2024 | E18: =E10 -> 2025 | F18: =F10 -> 2026 | G18: =G10 -> 2027 | H18: =H10 -> 2028 | I18: =I10 -> 2029 | J18: =J10 -> 2030 | ... L18: =L10 -> 2032
B19: Operating Cash | E19: =BalSheet!E17 -> 742.47593 | F19: =BalSheet!F17 -> 765.09712 | G19: =BalSheet!G17 -> 810.92089 | H19: =BalSheet!H17 -> 869.90747 | I19: =BalSheet!I17 -> 942.41247 | J19: =BalSheet!J17 -> 1030.9195 | K19: =BalSheet!K17 -> 1138.5943 | L19: =BalSheet!L17 -> 1269.4645
B20: =BalSheet!B20 -> Inventories | E20: =BalSheet!E20 -> 1777.3 | F20: =BalSheet!F20 -> 1831.4522 | G20: =BalSheet!G20 -> 1941.1429 | H20: =BalSheet!H20 -> 2082.3421 | I20: =BalSheet!I20 -> 2255.901 | J20: =BalSheet!J20 -> 2467.7649 | K20: =BalSheet!K20 -> 2725.5114 | L20: =BalSheet!L20 -> 3038.7823
B21: =BalSheet!B19 -> Accounts receivable | E21: =BalSheet!E19 -> 1213.8 | F21: =BalSheet!F19 -> 1250.7811 | G21: =BalSheet!G19 -> 1325.6938 | H21: =BalSheet!H19 -> 1422.1251 | I21: =BalSheet!I19 -> 1540.6563 | J21: =BalSheet!J19 -> 1685.3477 | K21: =BalSheet!K19 -> 1861.3744 | L21: =BalSheet!L19 -> 2075.3212
B22: Other current assets | E22: =BalSheet!E21 -> 570.1 | F22: =BalSheet!F21 -> 587.46937 | G22: =BalSheet!G21 -> 622.65452 | H22: =BalSheet!H21 -> 667.94656 | I22: =BalSheet!I21 -> 723.61854 | J22: =BalSheet!J21 -> 791.57747 | K22: =BalSheet!K21 -> 874.25405 | L22: =BalSheet!L21 -> 974.741
B23: Accounts payables | E23: =BalSheet!E33 -> 4576.8 | F23: =BalSheet!F33 -> 4716.2496 | G23: =BalSheet!G33 -> 4998.7187 | H23: =BalSheet!H33 -> 5362.3267 | I23: =BalSheet!I33 -> 5809.2657 | J23: =BalSheet!J33 -> 6354.8452 | K23: =BalSheet!K33 -> 7018.5792 | L23: =BalSheet!L33 -> 7825.2962
B24: Other current liabilities | E24: =BalSheet!E34 -> 3244.3 | F24: =BalSheet!F34 -> 3343.1448 | G24: =BalSheet!G34 -> 3543.375 | H24: =BalSheet!H34 -> 3801.1209 | I24: =BalSheet!I34 -> 4117.9366 | J24: =BalSheet!J34 -> 4504.6742 | K24: =BalSheet!K34 -> 4975.1665 | L24: =BalSheet!L34 -> 5547.0132
A25: * | B25: OWC | E25: =SUM(E19:E22)-SUM(E23:E24) -> -3517.4241 | F25: =SUM(F19:F22)-SUM(F23:F24) -> -3624.5946 | G25: =SUM(G19:G22)-SUM(G23:G24) -> -3841.6816 | H25: =SUM(H19:H22)-SUM(H23:H24) -> -4121.1264 | I25: =SUM(I19:I22)-SUM(I23:I24) -> -4464.6138 | J25: =SUM(J19:J22)-SUM(J23:J24) -> -4883.9099 | K25: =SUM(K19:K22)-SUM(K23:K24) -> -5394.0115 | L25: =SUM(L19:L22)-SUM(L23:L24) -> -6014.0003
B26: Change in OWC | F26: =E25-F25 -> 107.17054 | G26: =F25-G25 -> 217.08694 | H26: =G25-H25 -> 279.44485 | I26: =H25-I25 -> 343.48744 | J26: =I25-J25 -> 419.29602 | K26: =J25-K25 -> 510.10161 | L26: =K25-L25 -> 619.98887

Sheet Debt
A1: =CoName -> Starbucks Corp. | C1: Hist. | D1: Hist. | E1: Hist. | F1: Proj. | G1: Proj. | H1: Proj. | I1: Proj. | J1: Proj. | K1: Proj. | L1: Proj.
A2: Assumptions | C2: 2023 | D2: =C2+1 -> 2024 | E2: =D2+1 -> 2025 | F2: =E2+1 -> 2026 | G2: =F2+1 -> 2027 | H2: =G2+1 -> 2028 | I2: =H2+1 -> 2029 | J2: =I2+1 -> 2030 | K2: =J2+1 -> 2031 | L2: =K2+1 -> 2032
B4: Interest rate on revolver | F4: =Assumptions!F23 -> 0.05848 | G4: =Assumptions!G23 -> 0.05848 | H4: =Assumptions!H23 -> 0.05848 | I4: =Assumptions!I23 -> 0.05848 | J4: =Assumptions!J23 -> 0.05848 | K4: =Assumptions!K23 -> 0.05848 | L4: =Assumptions!L23 -> 0.05848
B5: Interest rate on long-term debt | F5: =Assumptions!F24 -> 0.0381 | G5: =Assumptions!G24 -> 0.0381 | H5: =Assumptions!H24 -> 0.0381 | I5: =Assumptions!I24 -> 0.0381 | J5: =Assumptions!J24 -> 0.0381 | K5: =Assumptions!K24 -> 0.0381 | L5: =Assumptions!L24 -> 0.0381
B6: Interest rate on cash | F6: =Assumptions!F25 -> 0.037368389 | G6: =Assumptions!G25 -> 0.037368389 | H6: =Assumptions!H25 -> 0.037368389 | I6: =Assumptions!I25 -> 0.037368389 | J6: =Assumptions!J25 -> 0.037368389 | K6: =Assumptions!K25 -> 0.037368389 | L6: =Assumptions!L25 -> 0.037368389
B8: Issuance of long-term debt | F8: =Assumptions!F27 -> 0 | G8: =Assumptions!G27 -> 0 | H8: =Assumptions!H27 -> 0 | I8: =Assumptions!I27 -> 0 | J8: =Assumptions!J27 -> 0 | K8: =Assumptions!K27 -> 0 | L8: =Assumptions!L27 -> 0
B9: Repayment of long-term debt | F9: =Assumptions!F28 -> 0 | G9: =Assumptions!G28 -> 0 | H9: =Assumptions!H28 -> 0 | I9: =Assumptions!I28 -> 0 | J9: =Assumptions!J28 -> 0 | K9: =Assumptions!K28 -> 0 | L9: =Assumptions!L28 -> 0
A11: Revolver | C11: =C2 -> 2023 | D11: =D2 -> 2024 | E11: =E2 -> 2025 | F11: =F2 -> 2026 | G11: =G2 -> 2027 | H11: =H2 -> 2028 | I11: =I2 -> 2029 | J11: =J2 -> 2030 | ... L11: =L2 -> 2032
B12: Balance | E12: =BalSheet!E32 -> 1248.9 | F12: =BalSheet!F32 -> 0 | G12: =BalSheet!G32 -> 0 | H12: =BalSheet!H32 -> 0 | I12: =BalSheet!I32 -> 0 | J12: =BalSheet!J32 -> 0 | K12: =BalSheet!K32 -> 0 | L12: =BalSheet!L32 -> 0
B13: Interest rate | E13: =F4 -> 0.05848 | F13: =F4 -> 0.05848 | G13: =G4 -> 0.05848 | H13: =H4 -> 0.05848 | I13: =I4 -> 0.05848 | J13: =J4 -> 0.05848 | K13: =K4 -> 0.05848 | L13: =L4 -> 0.05848
B14: Interest expense | F14: =F12*F13 -> 0 | G14: =G12*G13 -> 0 | H14: =H12*H13 -> 0 | I14: =I12*I13 -> 0 | J14: =J12*J13 -> 0 | K14: =K12*K13 -> 0 | L14: =L12*L13 -> 0
A16: Long term debt | C16: =C11 -> 2023 | D16: =D11 -> 2024 | E16: =E11 -> 2025 | F16: =F11 -> 2026 | G16: =G11 -> 2027 | H16: =H11 -> 2028 | I16: =I11 -> 2029 | J16: =J11 -> 2030 | ... L16: =L11 -> 2032
B17: Beginning balance | F17: =E20 -> 14319.5 | G17: =F20 -> 14319.5 | H17: =G20 -> 14319.5 | I17: =H20 -> 14319.5 | J17: =I20 -> 14319.5 | K17: =J20 -> 14319.5 | L17: =K20 -> 14319.5
B18: Issuance | F18: =SUM(F8) -> 0 | G18: =SUM(G8) -> 0 | H18: =SUM(H8) -> 0 | I18: =SUM(I8) -> 0 | J18: =SUM(J8) -> 0 | K18: =SUM(K8) -> 0 | L18: =SUM(L8) -> 0
B19: Repayment | F19: =SUM(F9) -> 0 | G19: =SUM(G9) -> 0 | H19: =SUM(H9) -> 0 | I19: =SUM(I9) -> 0 | J19: =SUM(J9) -> 0 | K19: =SUM(K9) -> 0 | L19: =SUM(L9) -> 0
B20: Ending balance | E20: =BalSheet!E37 -> 14319.5 | F20: =SUM(F17:F19) -> 14319.5 | G20: =SUM(G17:G19) -> 14319.5 | H20: =SUM(H17:H19) -> 14319.5 | I20: =SUM(I17:I19) -> 14319.5 | J20: =SUM(J17:J19) -> 14319.5 | K20: =SUM(K17:K19) -> 14319.5 | L20: =SUM(L17:L19) -> 14319.5
B21: Interest rate | F21: =F5 -> 0.0381 | G21: =G5 -> 0.0381 | H21: =H5 -> 0.0381 | I21: =I5 -> 0.0381 | J21: =J5 -> 0.0381 | K21: =K5 -> 0.0381 | L21: =L5 -> 0.0381
B22: Interest expense | F22: =F20*F21 -> 545.57295 | G22: =G20*G21 -> 545.57295 | H22: =H20*H21 -> 545.57295 | I22: =I20*I21 -> 545.57295 | J22: =J20*J21 -> 545.57295 | K22: =K20*K21 -> 545.57295 | L22: =L20*L21 -> 545.57295
A24: Debt summary | C24: =C16 -> 2023 | D24: =D16 -> 2024 | E24: =E16 -> 2025 | F24: =F16 -> 2026 | G24: =G16 -> 2027 | H24: =H16 -> 2028 | I24: =I16 -> 2029 | J24: =J16 -> 2030 | ... L24: =L16 -> 2032
B25: Revolver | F25: =F12 -> 0 | G25: =G12 -> 0 | H25: =H12 -> 0 | I25: =I12 -> 0 | J25: =J12 -> 0 | K25: =K12 -> 0 | L25: =L12 -> 0
B26: Total long term debt | F26: =F20 -> 14319.5 | G26: =G20 -> 14319.5 | H26: =H20 -> 14319.5 | I26: =I20 -> 14319.5 | J26: =J20 -> 14319.5 | K26: =K20 -> 14319.5 | L26: =L20 -> 14319.5
B27: Total debt | F27: =SUM(F25:F26) -> 14319.5 | G27: =SUM(G25:G26) -> 14319.5 | H27: =SUM(H25:H26) -> 14319.5 | I27: =SUM(I25:I26) -> 14319.5 | J27: =SUM(J25:J26) -> 14319.5 | K27: =SUM(K25:K26) -> 14319.5 | L27: =SUM(L25:L26) -> 14319.5
B28: Total interest expense | F28: =F22 -> 545.57295 | G28: =G22 -> 545.57295 | H28: =H22 -> 545.57295 | I28: =I22 -> 545.57295 | J28: =J22 -> 545.57295 | K28: =K22 -> 545.57295 | L28: =L22 -> 545.57295
A30: Interest income | C30: =C11 -> 2023 | D30: =D11 -> 2024 | E30: =E11 -> 2025 | F30: =F11 -> 2026 | G30: =G11 -> 2027 | H30: =H11 -> 2028 | I30: =I11 -> 2029 | J30: =J11 -> 2030 | ... L30: =L11 -> 2032
B31: Excess Cash | F31: =BalSheet!F18 -> 788.01463 | G31: =BalSheet!G18 -> 702.09195 | H31: =BalSheet!H18 -> 765.75606 | I31: =BalSheet!I18 -> 1409.6293 | J31: =BalSheet!J18 -> 2817.7132 | K31: =BalSheet!K18 -> 5174.8207 | L31: =BalSheet!L18 -> 8546.4878
B32: Interest rate | F32: =F6 -> 0.037368389 | G32: =G6 -> 0.037368389 | H32: =H6 -> 0.037368389 | I32: =I6 -> 0.037368389 | J32: =J6 -> 0.037368389 | K32: =K6 -> 0.037368389 | L32: =L6 -> 0.037368389
B33: Interest income | F33: =F31*F32 -> 29.446837 | G33: =G31*G32 -> 26.236045 | H33: =H31*H32 -> 28.61507 | I33: =I31*I32 -> 52.675577 | J33: =J31*J32 -> 105.2934 | K33: =K31*K32 -> 193.37471 | L33: =L31*L32 -> 319.36848

Sheet IncState
A1: =CoName -> Starbucks Corp. | C1: Hist. | D1: Hist. | E1: Hist. | F1: Proj. | G1: Proj. | H1: Proj. | I1: Proj. | J1: Proj. | K1: Proj. | L1: Proj.
A2: Assumptions | C2: 2023 | D2: =C2+1 -> 2024 | E2: =D2+1 -> 2025 | F2: =E2+1 -> 2026 | G2: =F2+1 -> 2027 | H2: =G2+1 -> 2028 | I2: =H2+1 -> 2029 | J2: =I2+1 -> 2030 | K2: =J2+1 -> 2031 | L2: =K2+1 -> 2032
B4: Revenue growth | F4: =Assumptions!F10 -> 0.030467227 | G4: =Assumptions!G10 -> 0.059892752 | H4: =Assumptions!H10 -> 0.072740242 | I4: =Assumptions!I10 -> 0.083347951 | J4: =Assumptions!J10 -> 0.093915406 | K4: =Assumptions!K10 -> 0.10444534 | L4: =Assumptions!L10 -> 0.11494022
B5: Cost of goods sold as % of sales | F5: =Assumptions!F11 -> 0.31403625 | G5: =Assumptions!G11 -> 0.31403625 | H5: =Assumptions!H11 -> 0.31403625 | I5: =Assumptions!I11 -> 0.31403625 | J5: =Assumptions!J11 -> 0.31403625 | K5: =Assumptions!K11 -> 0.31403625 | L5: =Assumptions!L11 -> 0.31403625
B6: SG&A % of sales | F6: =Assumptions!F12 -> 0.59114733 | G6: =Assumptions!G12 -> 0.58961719 | H6: =Assumptions!H12 -> 0.58961719 | I6: =Assumptions!I12 -> 0.57811719 | J6: =Assumptions!J12 -> 0.56661719 | K6: =Assumptions!K12 -> 0.55511719 | L6: =Assumptions!L12 -> 0.54711719
B7: Amortization amount | F7: =Assumptions!F13 -> 0 | G7: =Assumptions!G13 -> 0 | H7: =Assumptions!H13 -> 0 | I7: =Assumptions!I13 -> 0 | J7: =Assumptions!J13 -> 0 | K7: =Assumptions!K13 -> 0 | L7: =Assumptions!L13 -> 0
B8: Non recurring items, amount | F8: =Assumptions!F14 -> 0 | G8: =Assumptions!G14 -> 0 | H8: =Assumptions!H14 -> 0 | I8: =Assumptions!I14 -> 0 | J8: =Assumptions!J14 -> 0 | K8: =Assumptions!K14 -> 0 | L8: =Assumptions!L14 -> 0
B9: Other income (expense), amt | F9: =Assumptions!F15 -> 0 | G9: =Assumptions!G15 -> 0 | H9: =Assumptions!H15 -> 0 | I9: =Assumptions!I15 -> 0 | J9: =Assumptions!J15 -> 0 | K9: =Assumptions!K15 -> 0 | L9: =Assumptions!L15 -> 0
B10: Effective tax rate | F10: =Assumptions!F16 -> 0.19 | G10: =Assumptions!G16 -> 0.2 | H10: =Assumptions!H16 -> 0.21 | I10: =Assumptions!I16 -> 0.22 | J10: =Assumptions!J16 -> 0.22 | K10: =Assumptions!K16 -> 0.22 | L10: =Assumptions!L16 -> 0.22
B11: Dividend Payout Rate | F11: =Assumptions!F17 -> 2.4400755 | G11: =Assumptions!G17 -> 2.6002074 | H11: =Assumptions!H17 -> 2.7603393 | I11: =Assumptions!I17 -> 2.9204712 | J11: =Assumptions!J17 -> 3.0806031 | K11: =Assumptions!K17 -> 3.240735 | L11: =Assumptions!L17 -> 3.4008669
B12: Basic WASO | F12: =Assumptions!F18 -> 1133.8 | G12: =Assumptions!G18 -> 1133.8 | H12: =Assumptions!H18 -> 1133.8 | I12: =Assumptions!I18 -> 1133.8 | J12: =Assumptions!J18 -> 1133.8 | K12: =Assumptions!K18 -> 1133.8 | L12: =Assumptions!L18 -> 1133.8
B13: Diluted WASO | F13: =Assumptions!F19 -> 1137.3 | G13: =Assumptions!G19 -> 1137.3 | H13: =Assumptions!H19 -> 1137.3 | I13: =Assumptions!I19 -> 1137.3 | J13: =Assumptions!J19 -> 1137.3 | K13: =Assumptions!K19 -> 1137.3 | L13: =Assumptions!L19 -> 1137.3
A15: Income statement | C15: =C2 -> 2023 | D15: =D2 -> 2024 | E15: =E2 -> 2025 | F15: =F2 -> 2026 | G15: =G2 -> 2027 | H15: =H2 -> 2028 | I15: =I2 -> 2029 | J15: =J2 -> 2030 | ... L15: =L2 -> 2032
B16: Revenue | C16: ='Quarterly Projections'!L9 -> 35975.943 | D16: ='Quarterly Projections'!Q9 -> 36176.209 | E16: ='Quarterly Projections'!V9 -> 37123.797 | F16: =E16*(1+F4) -> 38254.856 | G16: =F16*(1+G4) -> 40546.044 | H16: =G16*(1+H4) -> 43495.373 | I16: =H16*(1+I4) -> 47120.624 | J16: =I16*(1+J4) -> 51545.976 | K16: =J16*(1+K4) -> 56929.713 | L16: =K16*(1+L4) -> 63473.227
B17: COGS | C17: ='Quarterly Projections'!L12 -> 11409.2 | D17: ='Quarterly Projections'!Q12 -> 11280.5 | E17: ='Quarterly Projections'!V12 -> 11658.2 | F17: =F16*F5 -> 12013.411 | G17: =G16*G5 -> 12732.928 | H17: =H16*H5 -> 13659.124 | I17: =I16*I5 -> 14797.584 | J17: =J16*J5 -> 16187.305 | K17: =K16*K5 -> 17877.993 | L17: =L16*L5 -> 19932.894
B18: SG&A | C18: =SUM('Quarterly Projections'!L14,'Quarterly Projections'!L16,'Quarterly Projections'!L18) -> 19063.6 | D18: =SUM('Quarterly Projections'!Q14,'Quarterly Projections'!Q16,'Quarterly Projections'!Q18) -> 19888.2 | E18: =SUM('Quarterly Projections'!V14,'Quarterly Projections'!V16,'Quarterly Projections'!V18) -> 21945.6 | F18: =F16*F6 -> 22614.256 | G18: =G16*G6 -> 23906.645 | H18: =H16*H6 -> 25645.62 | I18: =I16*I6 -> 27241.243 | J18: =J16*J6 -> 29206.836 | K18: =K16*K6 -> 31602.663 | L18: =L16*L6 -> 34727.294
A19: * | B19: EBIT | C19: =C16-SUM(C17:C18) -> 5503.1431 | D19: =D16-SUM(D17:D18) -> 5007.5086 | E19: =E16-SUM(E17:E18) -> 3519.9966 | F19: =F16-SUM(F17:F18) -> 3627.1886 | G19: =G16-SUM(G17:G18) -> 3906.4719 | H19: =H16-SUM(H17:H18) -> 4190.6296 | I19: =I16-SUM(I17:I18) -> 5081.7972 | J19: =J16-SUM(J17:J18) -> 6151.8349 | ... L19: =L16-SUM(L17:L18) -> 8813.0392
B21: Depreciation | C21: 1447.9 | D21: 1362.4 | E21: 1512.6 | F21: =Calcs!F8 -> 1718.6239 | G21: =Calcs!G8 -> 1831.7602 | H21: =Calcs!H8 -> 1954.5775 | I21: =Calcs!I8 -> 2091.4908 | J21: =Calcs!J8 -> 2246.8154 | K21: =Calcs!K8 -> 2425.5968 | L21: =Calcs!L8 -> 2633.8519
B22: Amortization | C22: 0 | D22: 0 | E22: 0 | F22: =F7 -> 0 | G22: =G7 -> 0 | H22: =H7 -> 0 | I22: =I7 -> 0 | J22: =J7 -> 0 | K22: =K7 -> 0 | L22: =L7 -> 0
A23: * | B23: EBITDA | C23: =SUM(C19,C21:C22) -> 6951.0431 | D23: =SUM(D19,D21:D22) -> 6369.9086 | E23: =SUM(E19,E21:E22) -> 5032.5966 | F23: =SUM(F19,F21:F22) -> 5345.8124 | G23: =SUM(G19,G21:G22) -> 5738.2321 | H23: =SUM(H19,H21:H22) -> 6145.2071 | I23: =SUM(I19,I21:I22) -> 7173.2879 | J23: =SUM(J19,J21:J22) -> 8398.6503 | ... L23: =SUM(L19,L21:L22) -> 11446.891
B25: Non-recurring items | C25: 0 | D25: 0 | E25: 0 | F25: =F8 -> 0 | G25: =G8 -> 0 | H25: =H8 -> 0 | I25: =I8 -> 0 | J25: =J8 -> 0 | K25: =K8 -> 0 | L25: =L8 -> 0
B26: Other income (expense) | C26: 0 | D26: 0 | E26: 0 | F26: =F9 -> 0 | G26: =G9 -> 0 | H26: =H9 -> 0 | I26: =I9 -> 0 | J26: =J9 -> 0 | K26: =K9 -> 0 | L26: =L9 -> 0
B28: Interest income | C28: 97 | D28: 81.2 | E28: 122.8 | F28: =IF(circ=1,Debt!F33,0) -> 0 | G28: =IF(circ=1,Debt!G33,0) -> 0 | H28: =IF(circ=1,Debt!H33,0) -> 0 | I28: =IF(circ=1,Debt!I33,0) -> 0 | J28: =IF(circ=1,Debt!J33,0) -> 0 | K28: =IF(circ=1,Debt!K33,0) -> 0 | L28: =IF(circ=1,Debt!L33,0) -> 0
B29: Interest expense | C29: -482.9 | D29: -550.1 | E29: -562 | F29: =IF(circ=1,-Debt!F22,0) -> 0 | G29: =IF(circ=1,-Debt!G22,0) -> 0 | H29: =IF(circ=1,-Debt!H22,0) -> 0 | I29: =IF(circ=1,-Debt!I22,0) -> 0 | J29: =IF(circ=1,-Debt!J22,0) -> 0 | K29: =IF(circ=1,-Debt!K22,0) -> 0 | L29: =IF(circ=1,-Debt!L22,0) -> 0
A31: * | B31: Pretax Income | C31: =C19+SUM(C26:C29) -> 5117.2431 | D31: =D19+SUM(D26:D29) -> 4538.6086 | E31: =E19+SUM(E25:E29) -> 3080.7966 | F31: =F19+SUM(F25:F29) -> 3627.1886 | G31: =G19+SUM(G25:G29) -> 3906.4719 | H31: =H19+SUM(H25:H29) -> 4190.6296 | I31: =I19+SUM(I25:I29) -> 5081.7972 | J31: =J19+SUM(J25:J29) -> 6151.8349 | K31: =K19+SUM(K25:K29) -> 7449.0571 | L31: =L19+SUM(L25:L29) -> 8813.0392
B33: Tax expense | C33: 1207.3 | D33: 1277.2 | E33: 948.5 | F33: =F31*F10 -> 689.16583 | G33: =G31*G10 -> 781.29438 | H33: =H31*H10 -> 880.03222 | I33: =I31*I10 -> 1117.9954 | J33: =J31*J10 -> 1353.4037 | K33: =K31*K10 -> 1638.7926 | L33: =L31*L10 -> 1938.8686
A34: * | B34: Net income | C34: =C31-C33 -> 3909.9431 | D34: =D31-D33 -> 3261.4086 | E34: =E31-E33 -> 2132.2966 | F34: =F31-F33 -> 2938.0227 | G34: =G31-G33 -> 3125.1775 | H34: =H31-H33 -> 3310.5974 | I34: =I31-I33 -> 3963.8018 | J34: =J31-J33 -> 4798.4313 | ... L34: =L31-L33 -> 6874.1706
B35: Dividend payout rate | C35: =C36/C38 -> 1.9621954 | D35: =D36/D38 -> 2.1198116 | E35: =E36/E38 -> 2.2799436 | F35: =F11 -> 2.4400755 | G35: =G11 -> 2.6002074 | H35: =H11 -> 2.7603393 | I35: =I11 -> 2.9204712 | J35: =J11 -> 3.0806031 | K35: =K11 -> 3.240735 | L35: =L11 -> 3.4008669
B36: Dividends | C36: 2263 | D36: 2431 | E36: 2585 | F36: =F35*F38 -> 2766.5576 | G36: =G35*G38 -> 2948.1151 | H36: =H35*H38 -> 3129.6727 | I36: =I35*I38 -> 3311.2302 | J36: =J35*J38 -> 3492.7878 | K36: =K35*K38 -> 3674.3453 | L36: =L35*L38 -> 3855.9029
A37: Shareholder information | C37: =C15 -> 2023 | D37: =D15 -> 2024 | E37: =E15 -> 2025 | F37: =F15 -> 2026 | G37: =G15 -> 2027 | H37: =H15 -> 2028 | I37: =I15 -> 2029 | J37: =J15 -> 2030 | ... L37: =L15 -> 2032
B38: Basic WASO | C38: 1153.3 | D38: 1146.8 | E38: 1133.8 | F38: =F12 -> 1133.8 | G38: =G12 -> 1133.8 | H38: =H12 -> 1133.8 | I38: =I12 -> 1133.8 | J38: =J12 -> 1133.8 | K38: =K12 -> 1133.8 | L38: =L12 -> 1133.8
B39: Diluted WASO | C39: 1158.5 | D39: 1151.3 | E39: 1137.3 | F39: =F13 -> 1137.3 | G39: =G13 -> 1137.3 | H39: =H13 -> 1137.3 | I39: =I13 -> 1137.3 | J39: =J13 -> 1137.3 | K39: =K13 -> 1137.3 | L39: =L13 -> 1137.3
B40: Basic earnings per share | C40: =C34/C38 -> 3.3902221 | D40: =D34/D38 -> 2.843921 | E40: =E34/E38 -> 1.8806638 | F40: =F34/F38 -> 2.591306 | G40: =G34/G38 -> 2.7563746 | H40: =H34/H38 -> 2.919913 | I40: =I34/I38 -> 3.4960326 | J40: =J34/J38 -> 4.2321673 | ... L40: =L34/L38 -> 6.0629481
A41: * | B41: Diluted earnings per share | C41: =C34/C39 -> 3.3750048 | D41: =D34/D39 -> 2.8328052 | E41: =E34/E39 -> 1.8748762 | F41: =F34/F39 -> 2.5833313 | G41: =G34/G39 -> 2.7478919 | H41: =H34/H39 -> 2.9109271 | I41: =I34/I39 -> 3.4852737 | J41: =J34/J39 -> 4.2191429 | ... L41: =L34/L39 -> 6.0442896

Sheet BalSheet
A1: =CoName -> Starbucks Corp. | C1: Hist. | D1: Hist. | E1: Hist. | F1: Proj. | G1: Proj. | H1: Proj. | I1: Proj. | J1: Proj. | K1: Proj. | L1: Proj.
A2: Assumptions | C2: 2023 | D2: =C2+1 -> 2024 | E2: =D2+1 -> 2025 | F2: =E2+1 -> 2026 | G2: =F2+1 -> 2027 | H2: =G2+1 -> 2028 | I2: =H2+1 -> 2029 | J2: =I2+1 -> 2030 | K2: =J2+1 -> 2031 | L2: =K2+1 -> 2032
B4: Operating Cash % of sales | F4: =Assumptions!F44 -> 0.02 | G4: =F4 -> 0.02 | H4: =G4 -> 0.02 | I4: =H4 -> 0.02 | J4: =I4 -> 0.02 | K4: =J4 -> 0.02 | L4: =K4 -> 0.02
B5: Accounts receivable % of sales | F5: =Assumptions!F45 -> 0.032696009 | G5: =Assumptions!G45 -> 0.032696009 | H5: =Assumptions!H45 -> 0.032696009 | I5: =Assumptions!I45 -> 0.032696009 | J5: =Assumptions!J45 -> 0.032696009 | K5: =Assumptions!K45 -> 0.032696009 | L5: =Assumptions!L45 -> 0.032696009
B6: Inventories % of COGS | F6: =Assumptions!F46 -> 0.15245064 | G6: =Assumptions!G46 -> 0.15245064 | H6: =Assumptions!H46 -> 0.15245064 | I6: =Assumptions!I46 -> 0.15245064 | J6: =Assumptions!J46 -> 0.15245064 | K6: =Assumptions!K46 -> 0.15245064 | L6: =Assumptions!L46 -> 0.15245064
B7: Other current assets % of sales | F7: =Assumptions!F47 -> 0.015356727 | G7: =Assumptions!G47 -> 0.015356727 | H7: =Assumptions!H47 -> 0.015356727 | I7: =Assumptions!I47 -> 0.015356727 | J7: =Assumptions!J47 -> 0.015356727 | K7: =Assumptions!K47 -> 0.015356727 | L7: =Assumptions!L47 -> 0.015356727
B9: Other long-term assets % of sales | F9: =Assumptions!F50 -> 0.064209489 | G9: =Assumptions!G50 -> 0.064209489 | H9: =Assumptions!H50 -> 0.064209489 | I9: =Assumptions!I50 -> 0.064209489 | J9: =Assumptions!J50 -> 0.064209489 | K9: =Assumptions!K50 -> 0.064209489 | L9: =Assumptions!L50 -> 0.064209489
B10: Investment in unconsolidated entities $ balance | F10: =Assumptions!F49 -> 739.9 | G10: =Assumptions!G49 -> 739.9 | H10: =Assumptions!H49 -> 739.9 | I10: =Assumptions!I49 -> 739.9 | J10: =Assumptions!J49 -> 739.9 | K10: =Assumptions!K49 -> 739.9 | L10: =Assumptions!L49 -> 739.9
B12: Accounts payable/Accural % of COGS | F12: =Assumptions!F54 -> 0.39258205 | G12: =Assumptions!G54 -> 0.39258205 | H12: =Assumptions!H54 -> 0.39258205 | I12: =Assumptions!I54 -> 0.39258205 | J12: =Assumptions!J54 -> 0.39258205 | K12: =Assumptions!K54 -> 0.39258205 | L12: =Assumptions!L54 -> 0.39258205
B13: Other current liabilities % of sales | F13: =Assumptions!F55 -> 0.087391385 | G13: =Assumptions!G55 -> 0.087391385 | H13: =Assumptions!H55 -> 0.087391385 | I13: =Assumptions!I55 -> 0.087391385 | J13: =Assumptions!J55 -> 0.087391385 | K13: =Assumptions!K55 -> 0.087391385 | L13: =Assumptions!L55 -> 0.087391385
B14: Other long-term liabilities % of sales | F14: =Assumptions!F56 -> 0.4145966 | G14: =Assumptions!G56 -> 0.4145966 | H14: =Assumptions!H56 -> 0.4145966 | I14: =Assumptions!I56 -> 0.4145966 | J14: =Assumptions!J56 -> 0.4145966 | K14: =Assumptions!K56 -> 0.4145966 | L14: =Assumptions!L56 -> 0.4145966
A16: Balance sheet | C16: =C2 -> 2023 | D16: =D2 -> 2024 | E16: =E2 -> 2025 | F16: =F2 -> 2026 | G16: =G2 -> 2027 | H16: =H2 -> 2028 | I16: =I2 -> 2029 | J16: =J2 -> 2030 | ... L16: =L2 -> 2032
B17: Operating Cash | C17: =2%*IncState!C16 -> 719.51886 | D17: =2%*IncState!D16 -> 723.52417 | E17: =2%*IncState!E16 -> 742.47593 | F17: =F4*IncState!F16 -> 765.09712 | G17: =G4*IncState!G16 -> 810.92089 | H17: =H4*IncState!H16 -> 869.90747 | I17: =I4*IncState!I16 -> 942.41247 | J17: =J4*IncState!J16 -> 1030.9195 | K17: =K4*IncState!K16 -> 1138.5943 | L17: =L4*IncState!L16 -> 1269.4645
B18: Excess cash | C18: =2818.4-C17 -> 2098.8811 | D18: =3551.5-D17 -> 2827.9758 | E18: =3286.2-E17 -> 2543.7241 | F18: =MAX(CashFlow!F23-BalSheet!E32,0) -> 788.01463 | G18: =MAX(CashFlow!G23-BalSheet!F32,0) -> 702.09195 | H18: =MAX(CashFlow!H23-BalSheet!G32,0) -> 765.75606 | I18: =MAX(CashFlow!I23-BalSheet!H32,0) -> 1409.6293 | J18: =MAX(CashFlow!J23-BalSheet!I32,0) -> 2817.7132 | K18: =MAX(CashFlow!K23-BalSheet!J32,0) -> 5174.8207 | L18: =MAX(CashFlow!L23-BalSheet!K32,0) -> 8546.4878
B19: Accounts receivable | C19: 1175.5 | D19: 1184.1 | E19: 1213.8 | F19: =F5*IncState!F16 -> 1250.7811 | G19: =G5*IncState!G16 -> 1325.6938 | H19: =H5*IncState!H16 -> 1422.1251 | I19: =I5*IncState!I16 -> 1540.6563 | J19: =J5*IncState!J16 -> 1685.3477 | K19: =K5*IncState!K16 -> 1861.3744 | L19: =L5*IncState!L16 -> 2075.3212
B20: Inventories | C20: 2176.6 | D20: 1806.4 | E20: 1777.3 | F20: =F6*IncState!F17 -> 1831.4522 | G20: =G6*IncState!G17 -> 1941.1429 | H20: =H6*IncState!H17 -> 2082.3421 | I20: =I6*IncState!I17 -> 2255.901 | J20: =J6*IncState!J17 -> 2467.7649 | K20: =K6*IncState!K17 -> 2725.5114 | L20: =L6*IncState!L17 -> 3038.7823
B21: Other current assets | C21: =483.7+364.5 -> 848.2 | D21: =359.9+401.5 -> 761.4 | E21: =313.1+257 -> 570.1 | F21: =F7*IncState!F16 -> 587.46937 | G21: =G7*IncState!G16 -> 622.65452 | H21: =H7*IncState!H16 -> 667.94656 | I21: =I7*IncState!I16 -> 723.61854 | J21: =J7*IncState!J16 -> 791.57747 | K21: =K7*IncState!K16 -> 874.25405 | L21: =L7*IncState!L16 -> 974.741
B22: Total current assets | C22: =SUM(C17:C21) -> 7018.7 | D22: =SUM(D17:D21) -> 7303.4 | E22: =SUM(E17:E21) -> 6847.4 | F22: =SUM(F17:F21) -> 5222.8144 | G22: =SUM(G17:G21) -> 5402.5041 | H22: =SUM(H17:H21) -> 5808.0773 | I22: =SUM(I17:I21) -> 6872.2177 | J22: =SUM(J17:J21) -> 8793.3228 | ... L22: =SUM(L17:L21) -> 15904.797
B24: Property, plant & equipment, net | C24: =6560.5+8015.6 -> 14576.1 | D24: =7387.1+8412.6 -> 15799.7 | E24: =8665.5+9286.2 -> 17951.7 | F24: =Calcs!F9 -> 19133.454 | G24: =Calcs!G9 -> 20416.329 | H24: =Calcs!H9 -> 21846.441 | I24: =Calcs!I9 -> 23468.868 | J24: =Calcs!J9 -> 25336.31 | K24: =Calcs!K9 -> 27511.615 | L24: =Calcs!L9 -> 30070.968
B25: Intangible assets | C25: =155.9+3283.5 -> 3439.4 | D25: =120.5+3218.3 -> 3338.8 | E25: =100.9+3315.7 -> 3416.6 | F25: =E25-IncState!F22 -> 3416.6 | G25: =F25-IncState!G22 -> 3416.6 | H25: =G25-IncState!H22 -> 3416.6 | I25: =H25-IncState!I22 -> 3416.6 | J25: =I25-IncState!J22 -> 3416.6 | K25: =J25-IncState!K22 -> 3416.6 | L25: =K25-IncState!L22 -> 3416.6
B26: Investment in unconsolidated entities | C26: =279.1+311.2 -> 590.3 | D26: =247.4+439.9 -> 687.3 | E26: =276+463.9 -> 739.9 | F26: =F10 -> 739.9 | G26: =G10 -> 739.9 | H26: =H10 -> 739.9 | I26: =I10 -> 739.9 | J26: =J10 -> 739.9 | K26: =K10 -> 739.9 | L26: =L10 -> 739.9
B27: Other assets | C27: =1799.7+554.2 -> 2353.9 | D27: =546.5+1769.8 -> 2316.3 | E27: =1766.7+617 -> 2383.7 | F27: =F9*IncState!F16 -> 2456.3247 | G27: =G9*IncState!G16 -> 2603.4408 | H27: =H9*IncState!H16 -> 2792.8157 | I27: =I9*IncState!I16 -> 3025.5912 | J27: =J9*IncState!J16 -> 3309.7408 | K27: =K9*IncState!K16 -> 3655.4278 | L27: =L9*IncState!L16 -> 4075.5834
B28: Total non-current assets | C28: =SUM(C24:C27) -> 20959.7 | D28: =SUM(D24:D27) -> 22142.1 | E28: =SUM(E24:E27) -> 24491.9 | F28: =SUM(F24:F27) -> 25746.278 | G28: =SUM(G24:G27) -> 27176.269 | H28: =SUM(H24:H27) -> 28795.757 | I28: =SUM(I24:I27) -> 30650.959 | J28: =SUM(J24:J27) -> 32802.551 | ... L28: =SUM(L24:L27) -> 38303.051
A30: * | B30: TOTAL ASSETS | C30: =SUM(C28,C22) -> 27978.4 | D30: =SUM(D28,D22) -> 29445.5 | E30: =SUM(E28,E22) -> 31339.3 | F30: =SUM(F28,F22) -> 30969.093 | G30: =SUM(G28,G22) -> 32578.774 | H30: =SUM(H28,H22) -> 34603.834 | I30: =SUM(I28,I22) -> 37523.177 | J30: =SUM(J28,J22) -> 41595.874 | ... L30: =SUM(L28,L22) -> 54207.848
B32: Revolver/Short term debt | C32: =1749+175 -> 1924 | D32: 1818.6 | E32: 1248.9 | F32: =-MIN(CashFlow!F23-BalSheet!E32,0) -> 0 | G32: =-MIN(CashFlow!G23-BalSheet!F32,0) -> 0 | H32: =-MIN(CashFlow!H23-BalSheet!G32,0) -> 0 | I32: =-MIN(CashFlow!I23-BalSheet!H32,0) -> 0 | J32: =-MIN(CashFlow!J23-BalSheet!I32,0) -> 0 | K32: =-MIN(CashFlow!K23-BalSheet!J32,0) -> 0 | L32: =-MIN(CashFlow!L23-BalSheet!K32,0) -> 0
B33: Accounts payable/Accurals | C33: =1441.4+2137.1+761.7 -> 4340.2 | D33: =1544.3+2145.1+828.3 -> 4517.7 | E33: =1595.5+2194.7+786.6 -> 4576.8 | F33: =F12*IncState!F17 -> 4716.2496 | G33: =G12*IncState!G17 -> 4998.7187 | H33: =H12*IncState!H17 -> 5362.3267 | I33: =I12*IncState!I17 -> 5809.2657 | J33: =J12*IncState!J17 -> 6354.8452 | K33: =K12*IncState!K17 -> 7018.5792 | L33: =L12*IncState!L17 -> 7825.2962
B34: Other current liabilities | C34: =1245.7+1641.9 -> 2887.6 | D34: =1275.3+1700.2+33.5 -> 3009 | E34: =1463.1+1781.2 -> 3244.3 | F34: =F13*IncState!F16 -> 3343.1448 | G34: =G13*IncState!G16 -> 3543.375 | H34: =H13*IncState!H16 -> 3801.1209 | I34: =I13*IncState!I16 -> 4117.9366 | J34: =J13*IncState!J16 -> 4504.6742 | K34: =K13*IncState!K16 -> 4975.1665 | L34: =L13*IncState!L16 -> 5547.0132
B35: Total current liabilities | C35: =SUM(C32:C34) -> 9151.8 | D35: =SUM(D32:D34) -> 9345.3 | E35: =SUM(E32:E34) -> 9070 | F35: =SUM(F32:F34) -> 8059.3944 | G35: =SUM(G32:G34) -> 8542.0937 | H35: =SUM(H32:H34) -> 9163.4477 | I35: =SUM(I32:I34) -> 9927.2022 | J35: =SUM(J32:J34) -> 10859.519 | ... L35: =SUM(L32:L34) -> 13372.309
B37: Long-term debt, including current maturities | C37: 13119.9 | D37: 13547.6 | E37: 14319.5 | F37: =Debt!F20 -> 14319.5 | G37: =Debt!G20 -> 14319.5 | H37: =Debt!H20 -> 14319.5 | I37: =Debt!I20 -> 14319.5 | J37: =Debt!J20 -> 14319.5 | K37: =Debt!K20 -> 14319.5 | L37: =Debt!L20 -> 14319.5
