Workbook
Name Ccy: MAIN!$C$6
Name circ: MAIN!$C$9
Name CoName: MAIN!$C$4
Name g: #REF!
Name IQ_CH: 110000
Name IQ_CQ: 5000
Name IQ_CY: 10000
Name IQ_DAILY: 500000
Name IQ_FH: 100000
Name IQ_FQ: 500
Name IQ_FY: 1000
Name IQ_LTM: 2000
Name IQ_MONTH: 15000
Name IQ_NTM: 6000
Name IQ_WEEK: 50000
Name IQ_YTD: 3000
Name OpCase: [1]DCF!$E$98
Name ScenarioREV: Assumptions!$D$4
Name TTS: #REF!
Name Units: MAIN!$C$7

Sheet MAIN
A1: =CoName -> Wingstop Inc
A2: Model Details
B4: Company name | C4: Wingstop Inc | E4: Current Stock Price | F4: 257.57 | H4: Operating Case One | I4: Perpetuity | J4: Terminal Mult | K4: Average
B5: Latest BS date | C5: 247.43 | E5: Diluted s/o | F5: 27786.854 | H5: Implied Price | I5: ='DCF Model'!C18 -> 143.98149 | J5: ='DCF Model'!G18 -> 214.06158 | K5: =AVERAGE(I5:J5) -> 179.02153
B6: Currency | C6: USD | E6: Mkt Cap | F6: =F5*F4 -> 7157060 | H6: Difference | I6: =I5/$F$4-1 -> -0.44100055 | J6: =J5/$F$4-1 -> -0.16891883 | K6: =K5/$F$4-1 -> -0.30495969
B7: Units | C7: m | E7: Cash | F7: =237640+25994+22476 -> 286110
B8: Analyst name | C8: Alan Chen | E8: Debt | F8: =1208358+58318 -> 1266676
B9: Circular switch | C9: 0 | E9: EV | F9: =F6-F7+F8 -> 8137626

Sheet Quarterly Projections

Sheet Assumptions
A1: =CoName -> Wingstop Inc | C1: Hist. | D1: Hist. | E1: Hist. | F1: Proj. | G1: Proj. | H1: Proj. | I1: Proj. | J1: Proj.
A2: * | B2: Income Statement | C2: 2022 | D2: =C2+1 -> 2023 | E2: =D2+1 -> 2024 | F2: =E2+1 -> 2025 | G2: =F2+1 -> 2026 | H2: =G2+1 -> 2027 | I2: =H2+1 -> 2028 | J2: =I2+1 -> 2029
B4: Operating Case | D4: 1
D5: Variance
B6: Street Case | D6: 0 | F6: 0.13 | G6: 0.2 | H6: 0.25 | I6: 0.25 | J6: 0.25
B7: Optimistic Case | D7: 0.025 | F7: =F6+$D$7 -> 0.155 | G7: =G6+$D$7 -> 0.225 | H7: =H6+$D$7 -> 0.275 | I7: =I6+$D$7 -> 0.275 | J7: =J6+$D$7 -> 0.275
B8: Pessimistic Case | D8: -0.025 | F8: =F6+$D$8 -> 0.105 | G8: =G6+$D$8 -> 0.175 | H8: =H6+$D$8 -> 0.225 | I8: =I6+$D$8 -> 0.225 | J8: =J6+$D$8 -> 0.225
B10: Revenue Growth | D10: =IncState!D16/IncState!C16-1 -> 0.28679155 | E10: =IncState!E16/IncState!D16-1 -> 0.36028736 | F10: =CHOOSE(ScenarioREV,F6,F7,F8) -> 0.13 | G10: =CHOOSE(ScenarioREV,G6,G7,G8) -> 0.2 | H10: =CHOOSE(ScenarioREV,H6,H7,H8) -> 0.25 | I10: =CHOOSE(ScenarioREV,I6,I7,I8) -> 0.25 | J10: =CHOOSE(ScenarioREV,J6,J7,J8) -> 0.25
B11: COGS % of sales | C11: =IncState!C17/IncState!C16 -> 0.17731826 | D11: =IncState!D17/IncState!D16 -> 0.13182337 | E11: =IncState!E17/IncState!E16 -> 0.14642214 | F11: =E11-0.001 -> 0.14542214 | G11: =F11-0.001 -> 0.14442214 | H11: =G11-0.001 -> 0.14342214 | I11: =H11-0.001 -> 0.14242214 | J11: =I11-0.001 -> 0.14142214
B12: SG&A % of sales | C12: =IncState!C18/IncState!C16 -> 0.5655416 | D12: =IncState!D18/IncState!D16 -> 0.62343633 | E12: =IncState!E18/IncState!E16 -> 0.58893397 | F12: =E12-0.005 -> 0.58393397 | G12: =F12-0.005 -> 0.57893397 | H12: =G12-0.005 -> 0.57393397 | I12: =H12-0.005 -> 0.56893397 | J12: =I12-0.005 -> 0.56393397
B13: Amortization $ Amt | C13: =IncState!C22 -> 0 | D13: =IncState!D22 -> 0 | E13: =IncState!E22 -> 0 | F13: =E13 -> 0 | G13: =F13 -> 0 | H13: =G13 -> 0 | I13: =H13 -> 0 | J13: =I13 -> 0
B14: Non recurring income / (expense) | C14: =IncState!C25 -> 0 | D14: =IncState!D25 -> 0 | E14: =IncState!E25 -> 0 | F14: 0 | G14: 0 | H14: 0 | I14: 0 | J14: 0
B15: Other Income / (expense) | C15: =IncState!C26 -> -573 | D15: =IncState!D26 -> -57 | E15: =IncState!E26 -> 2866 | F15: 0 | G15: 0 | H15: 0 | I15: 0 | J15: 0
B16: Effective tax rate | C16: =IncState!C33/IncState!C31 -> 0.23340938 | D16: =IncState!D33/IncState!D31 -> 0.25591136 | E16: =IncState!E33/IncState!E31 -> 0.26138325 | F16: 0.23 | G16: =F16 -> 0.23 | H16: =G16 -> 0.23 | I16: =H16 -> 0.23 | J16: =I16 -> 0.23
B17: Dividend Payout Rate | C17: =IncState!C35 -> 4.6513984 | D17: =IncState!D35 -> 0.83762765 | E17: =IncState!E35 -> 0.98781865 | F17: =E17+0.25 -> 1.2378186 | G17: =F17+0.25 -> 1.4878186 | H17: =G17+0.25 -> 1.7378186 | I17: =H17+0.25 -> 1.9878186 | J17: =I17+0.25 -> 2.2378186
B18: Basic WASO | C18: =IncState!C38 -> 30373.446 | D18: =IncState!D38 -> 29735.169 | E18: =IncState!E38 -> 29225 | F18: =E18 -> 29225 | G18: =F18 -> 29225 | H18: =G18 -> 29225 | I18: =H18 -> 29225 | J18: =I18 -> 29225
B19: Diluted WASO | C19: =IncState!C39 -> 30373.446 | D19: =IncState!D39 -> 29861.702 | E19: =IncState!E39 -> 29382.973 | F19: =E19 -> 29382.973 | G19: =F19 -> 29382.973 | H19: =G19 -> 29382.973 | I19: =H19 -> 29382.973 | J19: =I19 -> 29382.973
A21: * | B21: Debt | C21: =C2 -> 2022 | D21: =D2 -> 2023 | E21: =E2 -> 2024 | F21: =F2 -> 2025 | G21: =G2 -> 2026 | H21: =H2 -> 2027 | I21: =I2 -> 2028 | J21: =J2 -> 2029
B23: Interest rate on Revolver | E23: 0.058 | F23: =E23 -> 0.058 | G23: =F23 -> 0.058 | H23: =G23 -> 0.058 | I23: =H23 -> 0.058 | J23: =I23 -> 0.058
B24: Interest rate on long-term debt | E24: 0.04 | F24: =E24 -> 0.04 | G24: =F24 -> 0.04 | H24: =G24 -> 0.04 | I24: =H24 -> 0.04 | J24: =I24 -> 0.04
B25: Interest rate on cash | E25: 0.04 | F25: =E25 -> 0.04 | G25: =F25 -> 0.04 | H25: =G25 -> 0.04 | I25: =H25 -> 0.04 | J25: =I25 -> 0.04
B27: Issuance of long-term debt | E27: 0 | F27: 0 | G27: 0 | H27: 0 | I27: 0 | J27: 0
B28: Repayment of long-term debt | E28: 0 | F28: 0 | G28: 0 | H28: 0 | I28: 0 | J28: 0
A30: * | B30: Calcs | C30: =C21 -> 2022 | D30: =D21 -> 2023 | E30: =E21 -> 2024 | F30: =F21 -> 2025 | G30: =G21 -> 2026 | H30: =H21 -> 2027 | I30: =I21 -> 2028 | J30: =J21 -> 2029
B32: CapEx % of Sales | D32: =40833/IncState!D16 -> 0.088756779 | E32: =51929/IncState!E16 -> 0.082979257 | F32: =E32 -> 0.082979257 | G32: =F32 -> 0.082979257 | H32: =G32 -> 0.082979257 | I32: =H32 -> 0.082979257 | J32: =I32 -> 0.082979257
B33: Depreciation % of beginning PP&E | D33: =IncState!D21/BalSheet!C21 -> 0.19803743 | E33: =IncState!E21/BalSheet!D21 -> 0.17656544 | F33: =E33 -> 0.17656544 | G33: =F33 -> 0.17656544 | H33: =G33 -> 0.17656544 | I33: =H33 -> 0.17656544 | J33: =I33 -> 0.17656544
B34: Share issuance / (repurchases) | F34: 0 | G34: 0 | H34: 0 | I34: 0 | J34: 0
A36: * | B36: Shareholder information | C36: =C30 -> 2022 | D36: =D30 -> 2023 | E36: =E30 -> 2024 | F36: =F30 -> 2025 | G36: =G30 -> 2026 | H36: =H30 -> 2027 | I36: =I30 -> 2028 | J36: =J30 -> 2029
B38: =B17 -> Dividend Payout Rate | C38: =C17 -> 4.6513984 | D38: =D17 -> 0.83762765 | E38: =E17 -> 0.98781865 | F38: =F17 -> 1.2378186 | G38: =G17 -> 1.4878186 | H38: =H17 -> 1.7378186 | I38: =I17 -> 1.9878186 | J38: =J17 -> 2.2378186
B39: Basic WASO | C39: =C18 -> 30373.446 | D39: =D18 -> 29735.169 | E39: =E18 -> 29225 | F39: =F18 -> 29225 | G39: =G18 -> 29225 | H39: =H18 -> 29225 | I39: =I18 -> 29225 | J39: =J18 -> 29225
B40: Diluted WASO | C40: =C19 -> 30373.446 | D40: =D19 -> 29861.702 | E40: =E19 -> 29382.973 | F40: =F19 -> 29382.973 | G40: =G19 -> 29382.973 | H40: =H19 -> 29382.973 | I40: =I19 -> 29382.973 | J40: =J19 -> 29382.973
A42: * | B42: Balance Sheet - Assets | C42: =C36 -> 2022 | D42: =D36 -> 2023 | E42: =E36 -> 2024 | F42: =F36 -> 2025 | G42: =G36 -> 2026 | H42: =H36 -> 2027 | I42: =I36 -> 2028 | J42: =J36 -> 2029
B44: Operating Cash % of sales | C44: =BalSheet!C15/IncState!C16 -> 0.02 | D44: =BalSheet!D15/IncState!D16 -> 0.02 | E44: =BalSheet!E15/IncState!E16 -> 0.02 | F44: =E44 -> 0.02 | G44: =F44 -> 0.02 | H44: =G44 -> 0.02 | I44: =H44 -> 0.02 | J44: =I44 -> 0.02
B45: Accounts receivable % of sales | C45: =BalSheet!C17/IncState!C16 -> 0.026462781 | D45: =BalSheet!D17/IncState!D16 -> 0.026970688 | E45: =BalSheet!E17/IncState!E16 -> 0.031417034 | F45: =E45 -> 0.031417034 | G45: =F45 -> 0.031417034 | H45: =G45 -> 0.031417034 | I45: =H45 -> 0.031417034 | J45: =I45 -> 0.031417034
B46: Inventories % of COGS | C46: =BalSheet!#REF!/IncState!C17 -> #REF! | D46: =BalSheet!#REF!/IncState!D17 -> #REF! | E46: =BalSheet!#REF!/IncState!E17 -> #REF! | F46: =E46 -> #REF! | G46: =F46 -> #REF! | H46: =G46 -> #REF! | I46: =H46 -> #REF! | J46: =I46 -> #REF!
B47: Other current assets % of sales | C47: =BalSheet!C18/IncState!C16 -> 0.091505114 | D47: =BalSheet!D18/IncState!D16 -> 0.090684809 | E47: =BalSheet!E18/IncState!E16 -> 0.095951308 | F47: =E47 -> 0.095951308 | G47: =F47 -> 0.095951308 | H47: =G47 -> 0.095951308 | I47: =H47 -> 0.095951308 | J47: =I47 -> 0.095951308
B49: Investments in unconsolidated entities | C49: =BalSheet!#REF! -> #REF! | D49: =BalSheet!#REF! -> #REF! | E49: =BalSheet!#REF! -> #REF! | F49: =E49 -> #REF! | G49: =F49 -> #REF! | H49: =G49 -> #REF! | I49: =H49 -> #REF! | J49: =I49 -> #REF!
B50: Other long-term assets % of sales | C50: =BalSheet!C23/IncState!C16 -> 0.099163406 | D50: =BalSheet!D23/IncState!D16 -> 0.049318016 | E50: =BalSheet!E23/IncState!E16 -> 0.13943117 | F50: =E50 -> 0.13943117 | G50: =F50 -> 0.13943117 | H50: =G50 -> 0.13943117 | I50: =H50 -> 0.13943117 | J50: =I50 -> 0.13943117
A52: * | B52: Balance Sheet - Liabilities | C52: =C42 -> 2022 | D52: =D42 -> 2023 | E52: =E42 -> 2024 | F52: =F42 -> 2025 | G52: =G42 -> 2026 | H52: =H42 -> 2027 | I52: =I42 -> 2028 | J52: =J42 -> 2029
B54: Accounts payable % of COGS | C54: =BalSheet!C29/IncState!C17 -> 0.082325105 | D54: =BalSheet!D29/IncState!D17 -> 0.077911157 | E54: =BalSheet!E29/IncState!E17 -> 0.075770473 | F54: =E54 -> 0.075770473 | G54: =F54 -> 0.075770473 | H54: =G54 -> 0.075770473 | I54: =H54 -> 0.075770473 | J54: =I54 -> 0.075770473
...

Sheet Calcs
A1: =CoName -> Wingstop Inc | C1: Hist. | D1: Hist. | E1: Hist. | F1: Proj. | G1: Proj. | H1: Proj. | I1: Proj. | J1: Proj.
A2: Net PP&E | C2: 2022 | D2: =C2+1 -> 2023 | E2: =D2+1 -> 2024 | F2: =E2+1 -> 2025 | G2: =F2+1 -> 2026 | H2: =G2+1 -> 2027 | I2: =H2+1 -> 2028 | J2: =I2+1 -> 2029
B3: Capital expenditure % of sales | F3: =Assumptions!F32 -> 0.082979257 | G3: =Assumptions!G32 -> 0.082979257 | H3: =Assumptions!H32 -> 0.082979257 | I3: =Assumptions!I32 -> 0.082979257 | J3: =Assumptions!J32 -> 0.082979257
B4: Depreciation % of PP&E | F4: =Assumptions!F33 -> 0.17656544 | G4: =F4 -> 0.17656544 | H4: =G4 -> 0.17656544 | I4: =H4 -> 0.17656544 | J4: =I4 -> 0.17656544
B6: Beginning PP&E | F6: =E9 -> 125953 | G6: =F9 -> 162393.82 | H6: =G9 -> 204136.41 | I6: =H9 -> 256112.63 | J6: =I9 -> 320916.56
B7: Capex | F7: =F3*IncState!F16 -> 58679.77 | G7: =G3*IncState!G16 -> 70415.724 | H7: =H3*IncState!H16 -> 88019.655 | I7: =I3*IncState!I16 -> 110024.57 | J7: =J3*IncState!J16 -> 137530.71
B8: Depreciation | F8: =F6*F4 -> 22238.947 | G8: =G6*G4 -> 28673.137 | H8: =H6*H4 -> 36043.436 | I8: =I6*I4 -> 45220.64 | J8: =J6*J4 -> 56662.774
B9: Ending PP&E | E9: =BalSheet!E21 -> 125953 | F9: =F6+F7-F8 -> 162393.82 | G9: =G6+G7-G8 -> 204136.41 | H9: =H6+H7-H8 -> 256112.63 | I9: =I6+I7-I8 -> 320916.56 | J9: =J6+J7-J8 -> 401784.49
A10: Equity | C10: =C2 -> 2022 | D10: =D2 -> 2023 | E10: =E2 -> 2024 | F10: =F2 -> 2025 | G10: =G2 -> 2026 | H10: =H2 -> 2027 | I10: =I2 -> 2028 | J10: =J2 -> 2029
B11: Share issuance/(repurchases) | F11: =Assumptions!F34 -> 0 | G11: =Assumptions!G34 -> 0 | H11: =Assumptions!H34 -> 0 | I11: =Assumptions!I34 -> 0 | J11: =Assumptions!J34 -> 0
B13: Beginning balance | F13: =E17 -> -675586 | G13: =F17 -> -564391.68 | H13: =G17 -> -427109.19 | I13: =H17 -> -247041.32 | J13: =I17 -> -10440.01
B14: Net income | F14: =IncState!F34 -> 147369.57 | G14: =IncState!G34 -> 180763.99 | H14: =IncState!H34 -> 230855.62 | I14: =IncState!I34 -> 294695.31 | J14: =IncState!J34 -> 376026.38
B15: Dividends paid | F15: =-IncState!F36 -> -36175.25 | G15: =-IncState!G36 -> -43481.5 | H15: =-IncState!H36 -> -50787.75 | I15: =-IncState!I36 -> -58094 | J15: =-IncState!J36 -> -65400.25
B16: Share issuance / (repurchase) | F16: =F11 -> 0 | G16: =G11 -> 0 | H16: =H11 -> 0 | I16: =I11 -> 0 | J16: =J11 -> 0
B17: Ending balance | E17: =BalSheet!E37 -> -675586 | F17: =SUM(F13:F16) -> -564391.68 | G17: =SUM(G13:G16) -> -427109.19 | H17: =SUM(H13:H16) -> -247041.32 | I17: =SUM(I13:I16) -> -10440.01 | J17: =SUM(J13:J16) -> 300186.12
A18: OWC | C18: =C10 -> 2022 | D18: =D10 -> 2023 | E18: =E10 -> 2024 | F18: =F10 -> 2025 | G18: =G10 -> 2026 | H18: =H10 -> 2027 | I18: =I10 -> 2028 | J18: =J10 -> 2029
B19: Operating Cash | E19: =BalSheet!E15 -> 12516.14 | F19: =BalSheet!F15 -> 14143.238 | G19: =BalSheet!G15 -> 16971.886 | H19: =BalSheet!H15 -> 21214.857 | I19: =BalSheet!I15 -> 26518.572 | J19: =BalSheet!J15 -> 33148.215
B20: =BalSheet!B17 -> Accounts receivable | E20: =BalSheet!E17 -> 19661 | F20: =BalSheet!F17 -> 22216.93 | G20: =BalSheet!G17 -> 26660.316 | H20: =BalSheet!H17 -> 33325.395 | I20: =BalSheet!I17 -> 41656.744 | J20: =BalSheet!J17 -> 52070.93
B21: Other current assets | E21: =BalSheet!E18 -> 60047 | F21: =BalSheet!F18 -> 67853.11 | G21: =BalSheet!G18 -> 81423.732 | H21: =BalSheet!H18 -> 101779.66 | I21: =BalSheet!I18 -> 127224.58 | J21: =BalSheet!J18 -> 159030.73
B22: Accounts payables | E22: =BalSheet!E29 -> 6943 | F22: =BalSheet!F29 -> 7792.008 | G22: =BalSheet!G29 -> 9286.1112 | H22: =BalSheet!H29 -> 11527.266 | I22: =BalSheet!I29 -> 14308.616 | J22: =BalSheet!J29 -> 17760.188
B23: Other current liabilities | E23: =BalSheet!E30 -> 80500 | F23: =BalSheet!F30 -> 90965 | G23: =BalSheet!G30 -> 109158 | H23: =BalSheet!H30 -> 136447.5 | I23: =BalSheet!I30 -> 170559.38 | J23: =BalSheet!J30 -> 213199.22
A24: * | B24: OWC | E24: =SUM(E19:E21)-SUM(E22:E23) -> 4781.14 | F24: =SUM(F19:F21)-SUM(F22:F23) -> 5456.2702 | G24: =SUM(G19:G21)-SUM(G22:G23) -> 6611.8226 | H24: =SUM(H19:H21)-SUM(H22:H23) -> 8345.1513 | I24: =SUM(I19:I21)-SUM(I22:I23) -> 10531.905 | J24: =SUM(J19:J21)-SUM(J22:J23) -> 13290.464
B25: Change in OWC | F25: =E24-F24 -> -675.13019 | G25: =F24-G24 -> -1155.5524 | H25: =G24-H24 -> -1733.3286 | I25: =H24-I24 -> -2186.7541 | J25: =I24-J24 -> -2758.5591

Sheet Debt
A1: =CoName -> Wingstop Inc | C1: Hist. | D1: Hist. | E1: Hist. | F1: Proj. | G1: Proj. | H1: Proj. | I1: Proj. | J1: Proj.
A2: Assumptions | C2: 2022 | D2: =C2+1 -> 2023 | E2: =D2+1 -> 2024 | F2: =E2+1 -> 2025 | G2: =F2+1 -> 2026 | H2: =G2+1 -> 2027 | I2: =H2+1 -> 2028 | J2: =I2+1 -> 2029
B4: Interest rate on revolver | F4: =Assumptions!F23 -> 0.058 | G4: =Assumptions!G23 -> 0.058 | H4: =Assumptions!H23 -> 0.058 | I4: =Assumptions!I23 -> 0.058 | J4: =Assumptions!J23 -> 0.058
B5: Interest rate on long-term debt | F5: =Assumptions!F24 -> 0.04 | G5: =Assumptions!G24 -> 0.04 | H5: =Assumptions!H24 -> 0.04 | I5: =Assumptions!I24 -> 0.04 | J5: =Assumptions!J24 -> 0.04
B6: Interest rate on cash | F6: =Assumptions!F25 -> 0.04 | G6: =Assumptions!G25 -> 0.04 | H6: =Assumptions!H25 -> 0.04 | I6: =Assumptions!I25 -> 0.04 | J6: =Assumptions!J25 -> 0.04
B8: Issuance of long-term debt | F8: =Assumptions!F27 -> 0 | G8: =Assumptions!G27 -> 0 | H8: =Assumptions!H27 -> 0 | I8: =Assumptions!I27 -> 0 | J8: =Assumptions!J27 -> 0
B9: Repayment of long-term debt | F9: =Assumptions!F28 -> 0 | G9: =Assumptions!G28 -> 0 | H9: =Assumptions!H28 -> 0 | I9: =Assumptions!I28 -> 0 | J9: =Assumptions!J28 -> 0
A11: Revolver | C11: =C2 -> 2022 | D11: =D2 -> 2023 | E11: =E2 -> 2024 | F11: =F2 -> 2025 | G11: =G2 -> 2026 | H11: =H2 -> 2027 | I11: =I2 -> 2028 | J11: =J2 -> 2029
B12: Balance | F12: 0 | G12: 0 | H12: 0 | I12: 0 | J12: 0
B13: Interest rate
B14: Interest expense
A16: Long term debt | C16: =C11 -> 2022 | D16: =D11 -> 2023 | E16: =E11 -> 2024 | F16: =F11 -> 2025 | G16: =G11 -> 2026 | H16: =H11 -> 2027 | I16: =I11 -> 2028 | J16: =J11 -> 2029
B17: Beginning balance | F17: =E20 -> 1206201 | G17: =F20 -> 1206201 | H17: =G20 -> 1206201 | I17: =H20 -> 1206201 | J17: =I20 -> 1206201
B18: Issuance | F18: =F8 -> 0 | G18: =G8 -> 0 | H18: =H8 -> 0 | I18: =I8 -> 0 | J18: =J8 -> 0
B19: Repayment | F19: =F9 -> 0 | G19: =G9 -> 0 | H19: =H9 -> 0 | I19: =I9 -> 0 | J19: =J9 -> 0
B20: Ending balance | E20: =BalSheet!E33 -> 1206201 | F20: =SUM(F17:F19) -> 1206201 | G20: =SUM(G17:G19) -> 1206201 | H20: =SUM(H17:H19) -> 1206201 | I20: =SUM(I17:I19) -> 1206201 | J20: =SUM(J17:J19) -> 1206201
B21: Interest rate | F21: =F5 -> 0.04 | G21: =G5 -> 0.04 | H21: =H5 -> 0.04 | I21: =I5 -> 0.04 | J21: =J5 -> 0.04
B22: Interest expense | F22: =F20*F21 -> 48248.04 | G22: =G20*G21 -> 48248.04 | H22: =H20*H21 -> 48248.04 | I22: =I20*I21 -> 48248.04 | J22: =J20*J21 -> 48248.04
A24: Debt summary | C24: =C16 -> 2022 | D24: =D16 -> 2023 | E24: =E16 -> 2024 | F24: =F16 -> 2025 | G24: =G16 -> 2026 | H24: =H16 -> 2027 | I24: =I16 -> 2028 | J24: =J16 -> 2029
B25: Revolver | F25: 0 | G25: 0 | H25: 0 | I25: 0 | J25: 0
B26: Total long term debt | F26: =F20 -> 1206201 | G26: =G20 -> 1206201 | H26: =H20 -> 1206201 | I26: =I20 -> 1206201 | J26: =J20 -> 1206201
B27: Total debt | F27: =SUM(F25:F26) -> 1206201 | G27: =SUM(G25:G26) -> 1206201 | H27: =SUM(H25:H26) -> 1206201 | I27: =SUM(I25:I26) -> 1206201 | J27: =SUM(J25:J26) -> 1206201
B28: Total interest expense | F28: =F22 -> 48248.04 | G28: =G22 -> 48248.04 | H28: =H22 -> 48248.04 | I28: =I22 -> 48248.04 | J28: =J22 -> 48248.04
A30: Interest income | C30: =C11 -> 2022 | D30: =D11 -> 2023 | E30: =E11 -> 2024 | F30: =F11 -> 2025 | G30: =G11 -> 2026 | H30: =H11 -> 2027 | I30: =I11 -> 2028 | J30: =J11 -> 2029
B31: Excess Cash | F31: =BalSheet!F16 -> 378893.26 | G31: =BalSheet!G16 -> 475748.01 | H31: =BalSheet!H16 -> 605811.94 | I31: =BalSheet!I16 -> 780054.58 | J31: =BalSheet!J16 -> 1012844.2
B32: Interest rate | F32: =F6 -> 0.04 | G32: =G6 -> 0.04 | H32: =H6 -> 0.04 | I32: =I6 -> 0.04 | J32: =J6 -> 0.04
B33: Interest income | F33: =F31*F32 -> 15155.73 | G33: =G31*G32 -> 19029.921 | H33: =H31*H32 -> 24232.478 | I33: =I31*I32 -> 31202.183 | J33: =J31*J32 -> 40513.769

Sheet IncState
A1: =CoName -> Wingstop Inc | C1: Hist. | D1: Hist. | E1: Hist. | F1: Proj. | G1: Proj. | H1: Proj. | I1: Proj. | J1: Proj.
A2: Assumptions | C2: 2022 | D2: =C2+1 -> 2023 | E2: =D2+1 -> 2024 | F2: =E2+1 -> 2025 | G2: =F2+1 -> 2026 | H2: =G2+1 -> 2027 | I2: =H2+1 -> 2028 | J2: =I2+1 -> 2029
B4: Revenue growth | F4: =Assumptions!F10 -> 0.13 | G4: =Assumptions!G10 -> 0.2 | H4: =Assumptions!H10 -> 0.25 | I4: =Assumptions!I10 -> 0.25 | J4: =Assumptions!J10 -> 0.25
B5: Cost of goods sold as % of sales | F5: =Assumptions!F11 -> 0.14542214 | G5: =Assumptions!G11 -> 0.14442214 | H5: =Assumptions!H11 -> 0.14342214 | I5: =Assumptions!I11 -> 0.14242214 | J5: =Assumptions!J11 -> 0.14142214
B6: SG&A % of sales | F6: =Assumptions!F12 -> 0.58393397 | G6: =Assumptions!G12 -> 0.57893397 | H6: =Assumptions!H12 -> 0.57393397 | I6: =Assumptions!I12 -> 0.56893397 | J6: =Assumptions!J12 -> 0.56393397
B7: Amortization amount | F7: =Assumptions!F13 -> 0 | G7: =Assumptions!G13 -> 0 | H7: =Assumptions!H13 -> 0 | I7: =Assumptions!I13 -> 0 | J7: =Assumptions!J13 -> 0
B8: Non recurring items, amount | F8: =Assumptions!F14 -> 0 | G8: =Assumptions!G14 -> 0 | H8: =Assumptions!H14 -> 0 | I8: =Assumptions!I14 -> 0 | J8: =Assumptions!J14 -> 0
B9: Other income (expense), amt | F9: =Assumptions!F15 -> 0 | G9: =Assumptions!G15 -> 0 | H9: =Assumptions!H15 -> 0 | I9: =Assumptions!I15 -> 0 | J9: =Assumptions!J15 -> 0
B10: Effective tax rate | F10: =Assumptions!F16 -> 0.23 | G10: =Assumptions!G16 -> 0.23 | H10: =Assumptions!H16 -> 0.23 | I10: =Assumptions!I16 -> 0.23 | J10: =Assumptions!J16 -> 0.23
B11: Dividend Payout Rate | F11: =Assumptions!F17 -> 1.2378186 | G11: =Assumptions!G17 -> 1.4878186 | H11: =Assumptions!H17 -> 1.7378186 | I11: =Assumptions!I17 -> 1.9878186 | J11: =Assumptions!J17 -> 2.2378186
B12: Basic WASO | F12: =Assumptions!F18 -> 29225 | G12: =Assumptions!G18 -> 29225 | H12: =Assumptions!H18 -> 29225 | I12: =Assumptions!I18 -> 29225 | J12: =Assumptions!J18 -> 29225
B13: Diluted WASO | F13: =Assumptions!F19 -> 29382.973 | G13: =Assumptions!G19 -> 29382.973 | H13: =Assumptions!H19 -> 29382.973 | I13: =Assumptions!I19 -> 29382.973 | J13: =Assumptions!J19 -> 29382.973
A15: Income statement | C15: =C37 -> 44926 | D15: =D37 -> 45291 | E15: =E37 -> 45657 | F15: =F37 -> 46022 | G15: =G37 -> 46022 | H15: =H37 -> 46022 | I15: =I37 -> 46022 | J15: =J37 -> 46022
B16: Revenue | C16: 357521 | D16: 460055 | E16: 625807 | F16: =E16*(1+F4) -> 707161.91 | G16: =F16*(1+G4) -> 848594.29 | H16: =G16*(1+H4) -> 1060742.9 | I16: =H16*(1+I4) -> 1325928.6 | J16: =I16*(1+J4) -> 1657410.7
B17: COGS | C17: 63395 | D17: 60646 | E17: 91632 | F17: =F16*F5 -> 102837 | G17: =G16*G5 -> 122555.8 | H17: =H16*H5 -> 152134.01 | I17: =I16*I5 -> 188841.59 | J17: =J16*J5 -> 234394.57
B18: SG&A | C18: =265588-C17 -> 202193 | D18: =347461-D17 -> 286815 | E18: =460191-E17 -> 368559 | F18: =F16*F6 -> 412935.86 | G18: =G16*G6 -> 491280.06 | H18: =H16*H6 -> 608796.36 | I18: =I16*I6 -> 754365.81 | J18: =J16*J6 -> 934670.21
A19: * | B19: EBIT | C19: =C16-SUM(C17:C18) -> 91933 | D19: =D16-SUM(D17:D18) -> 112594 | E19: =E16-SUM(E17:E18) -> 165616 | F19: =F16-SUM(F17:F18) -> 191389.05 | G19: =G16-SUM(G17:G18) -> 234758.43 | H19: =H16-SUM(H17:H18) -> 299812.49 | I19: =I16-SUM(I17:I18) -> 382721.19 | J19: =J16-SUM(J17:J18) -> 488345.95
B21: Depreciation | C21: 10899 | D21: 13239 | E21: 19490 | F21: =Calcs!F8 -> 22238.947 | G21: =Calcs!G8 -> 28673.137 | H21: =Calcs!H8 -> 36043.436 | I21: =Calcs!I8 -> 45220.64 | J21: =Calcs!J8 -> 56662.774
B22: Amortization | C22: 0 | D22: 0 | E22: 0 | F22: =F7 -> 0 | G22: =G7 -> 0 | H22: =H7 -> 0 | I22: =I7 -> 0 | J22: =J7 -> 0
A23: * | B23: EBITDA | C23: =SUM(C19,C21:C22) -> 102832 | D23: =SUM(D19,D21:D22) -> 125833 | E23: =SUM(E19,E21:E22) -> 185106 | F23: =SUM(F19,F21:F22) -> 213628 | G23: =SUM(G19,G21:G22) -> 263431.56 | H23: =SUM(H19,H21:H22) -> 335855.93 | I23: =SUM(I19,I21:I22) -> 427941.83 | J23: =SUM(J19,J21:J22) -> 545008.72
B25: Non-recurring items | C25: 0 | D25: 0 | E25: 0 | F25: =F8 -> 0 | G25: =G8 -> 0 | H25: =H8 -> 0 | I25: =I8 -> 0 | J25: =J8 -> 0
B26: Other income (expense) | C26: -573 | D26: -57 | E26: 2866 | F26: =F9 -> 0 | G26: =G9 -> 0 | H26: =H9 -> 0 | I26: =I9 -> 0 | J26: =J9 -> 0
B28: Interest income | F28: =IF(circ=1,Debt!F33,0) -> 0 | G28: =IF(circ=1,Debt!G33,0) -> 0 | H28: =IF(circ=1,Debt!H33,0) -> 0 | I28: =IF(circ=1,Debt!I33,0) -> 0 | J28: =IF(circ=1,Debt!J33,0) -> 0
B29: Interest expense | C29: -21230 | D29: -18227 | E29: -21292 | F29: =IF(circ=1,-Debt!F22,0) -> 0 | G29: =IF(circ=1,-Debt!G22,0) -> 0 | H29: =IF(circ=1,-Debt!H22,0) -> 0 | I29: =IF(circ=1,-Debt!I22,0) -> 0 | J29: =IF(circ=1,-Debt!J22,0) -> 0
A31: * | B31: Pretax Income | C31: =C19+SUM(C26:C29) -> 70130 | D31: =D19+SUM(D26:D29) -> 94310 | E31: =E19+SUM(E25:E29) -> 147190 | F31: =F19+SUM(F25:F29) -> 191389.05 | G31: =G19+SUM(G25:G29) -> 234758.43 | H31: =H19+SUM(H25:H29) -> 299812.49 | I31: =I19+SUM(I25:I29) -> 382721.19 | J31: =J19+SUM(J25:J29) -> 488345.95
B33: Tax expense | C33: 16369 | D33: 24135 | E33: 38473 | F33: =F10*F31 -> 44019.482 | G33: =G10*G31 -> 53994.438 | H33: =H10*H31 -> 68956.873 | I33: =I10*I31 -> 88025.873 | J33: =J10*J31 -> 112319.57
A34: * | B34: Net income | C34: =C31-C33 -> 53761 | D34: =D31-D33 -> 70175 | E34: =E31-E33 -> 108717 | F34: =F31-F33 -> 147369.57 | G34: =G31-G33 -> 180763.99 | H34: =H31-H33 -> 230855.62 | I34: =I31-I33 -> 294695.31 | J34: =J31-J33 -> 376026.38
B35: Dividend payout rate | C35: =C36/C38 -> 4.6513984 | D35: =D36/D38 -> 0.83762765 | E35: =E36/E38 -> 0.98781865 | F35: =F11 -> 1.2378186 | G35: =G11 -> 1.4878186 | H35: =H11 -> 1.7378186 | I35: =I11 -> 1.9878186 | J35: =J11 -> 2.2378186
B36: Dividends | C36: 141279 | D36: 24907 | E36: 28869 | F36: =F35*F38 -> 36175.25 | G36: =G35*G38 -> 43481.5 | H36: =H35*H38 -> 50787.75 | I36: =I35*I38 -> 58094 | J36: =J35*J38 -> 65400.25
A37: Shareholder information | C37: 44926 | D37: 45291 | E37: 45657 | F37: 46022 | G37: 46022 | H37: 46022 | I37: 46022 | J37: 46022
B38: Basic WASO | C38: =C34/C40 -> 30373.446 | D38: =D34/D40 -> 29735.169 | E38: =E34/E40 -> 29225 | F38: =F12 -> 29225 | G38: =G12 -> 29225 | H38: =H12 -> 29225 | I38: =I12 -> 29225 | J38: =J12 -> 29225
B39: Diluted WASO | C39: =C34/C41 -> 30373.446 | D39: =D34/D41 -> 29861.702 | E39: =E34/E41 -> 29382.973 | F39: =F13 -> 29382.973 | G39: =G13 -> 29382.973 | H39: =H13 -> 29382.973 | I39: =I13 -> 29382.973 | J39: =J13 -> 29382.973
B40: Basic earnings per share | C40: 1.77 | D40: 2.36 | E40: 3.72 | F40: =F34/F38 -> 5.0425858 | G40: =G34/G38 -> 6.185252 | H40: =H34/H38 -> 7.8992513 | I40: =I34/I38 -> 10.083672 | J40: =J34/J38 -> 12.8666
A41: * | B41: Diluted earnings per share | C41: 1.77 | D41: 2.35 | E41: 3.7 | F41: =F34/F39 -> 5.0154751 | G41: =G34/G39 -> 6.1519979 | H41: =H34/H39 -> 7.8567822 | I41: =I34/I39 -> 10.029459 | J41: =J34/J39 -> 12.797425

Sheet BalSheet
A1: =CoName -> Wingstop Inc | C1: Hist. | D1: Hist. | E1: Hist. | F1: Proj. | G1: Proj. | H1: Proj. | I1: Proj. | J1: Proj.
A2: Assumptions | C2: 2022 | D2: =C2+1 -> 2023 | E2: =D2+1 -> 2024 | F2: =E2+1 -> 2025 | G2: =F2+1 -> 2026 | H2: =G2+1 -> 2027 | I2: =H2+1 -> 2028 | J2: =I2+1 -> 2029
B4: Operating Cash % of sales | F4: =Assumptions!F44 -> 0.02 | G4: =F4 -> 0.02 | H4: =G4 -> 0.02 | I4: =H4 -> 0.02 | J4: =I4 -> 0.02
B5: Accounts receivable % of sales | F5: =Assumptions!F45 -> 0.031417034 | G5: =Assumptions!G45 -> 0.031417034 | H5: =Assumptions!H45 -> 0.031417034 | I5: =Assumptions!I45 -> 0.031417034 | J5: =Assumptions!J45 -> 0.031417034
B6: Other current assets % of sales | F6: =Assumptions!F47 -> 0.095951308 | G6: =Assumptions!G47 -> 0.095951308 | H6: =Assumptions!H47 -> 0.095951308 | I6: =Assumptions!I47 -> 0.095951308 | J6: =Assumptions!J47 -> 0.095951308
B8: Other long-term assets % of sales | F8: =Assumptions!F50 -> 0.13943117 | G8: =Assumptions!G50 -> 0.13943117 | H8: =Assumptions!H50 -> 0.13943117 | I8: =Assumptions!I50 -> 0.13943117 | J8: =Assumptions!J50 -> 0.13943117
B10: Accounts payable/Accural % of COGS | F10: =Assumptions!F54 -> 0.075770473 | G10: =Assumptions!G54 -> 0.075770473 | H10: =Assumptions!H54 -> 0.075770473 | I10: =Assumptions!I54 -> 0.075770473 | J10: =Assumptions!J54 -> 0.075770473
B11: Other current liabilities % of sales | F11: =Assumptions!F55 -> 0.12863391 | G11: =Assumptions!G55 -> 0.12863391 | H11: =Assumptions!H55 -> 0.12863391 | I11: =Assumptions!I55 -> 0.12863391 | J11: =Assumptions!J55 -> 0.12863391
B12: Other long-term liabilities % of sales | F12: =Assumptions!F56 -> 0.15689821 | G12: =Assumptions!G56 -> 0.15689821 | H12: =Assumptions!H56 -> 0.15689821 | I12: =Assumptions!I56 -> 0.15689821 | J12: =Assumptions!J56 -> 0.15689821
A14: Balance sheet | C14: =C2 -> 2022 | D14: =D2 -> 2023 | E14: =E2 -> 2024 | F14: =F2 -> 2025 | G14: =G2 -> 2026 | H14: =H2 -> 2027 | I14: =I2 -> 2028 | J14: =J2 -> 2029
B15: Operating Cash | C15: =2%*IncState!C16 -> 7150.42 | D15: =2%*IncState!D16 -> 9201.1 | E15: =2%*IncState!E16 -> 12516.14 | F15: =F4*IncState!F16 -> 14143.238 | G15: =G4*IncState!G16 -> 16971.886 | H15: =H4*IncState!H16 -> 21214.857 | I15: =I4*IncState!I16 -> 26518.572 | J15: =J4*IncState!J16 -> 33148.215
B16: Excess cash | C16: =184496-C15 -> 177345.58 | D16: =90216-D15 -> 81014.9 | E16: =315910-E15 -> 303393.86 | F16: =MAX(CashFlow!F23,0) -> 378893.26 | G16: =MAX(CashFlow!G23,0) -> 475748.01 | H16: =MAX(CashFlow!H23,0) -> 605811.94 | I16: =MAX(CashFlow!I23,0) -> 780054.58 | J16: =MAX(CashFlow!J23,0) -> 1012844.2
B17: Accounts receivable | C17: 9461 | D17: =12408 -> 12408 | E17: 19661 | F17: =F5*IncState!F16 -> 22216.93 | G17: =G5*IncState!G16 -> 26660.316 | H17: =H5*IncState!H16 -> 33325.395 | I17: =I5*IncState!I16 -> 41656.744 | J17: =J5*IncState!J16 -> 52070.93
B18: Other current assets | C18: =4252+15167+13296 -> 32715 | D18: =11444+25328+4948 -> 41720 | E18: =20868+6520+32659 -> 60047 | F18: =F6*IncState!F16 -> 67853.11 | G18: =G6*IncState!G16 -> 81423.732 | H18: =H6*IncState!H16 -> 101779.66 | I18: =I6*IncState!I16 -> 127224.58 | J18: =J6*IncState!J16 -> 159030.73
B19: Total current assets | C19: =SUM(C15:C18) -> 226672 | D19: =SUM(D15:D18) -> 144344 | E19: =SUM(E15:E18) -> 395618 | F19: =SUM(F15:F18) -> 483106.54 | G19: =SUM(G15:G18) -> 600803.95 | H19: =SUM(H15:H18) -> 762131.86 | I19: =SUM(I15:I18) -> 975454.48 | J19: =SUM(J15:J18) -> 1257094.1
B21: Property, plant & equipment, net | C21: 66851 | D21: =91292+19092 -> 110384 | E21: =125953 -> 125953 | F21: =Calcs!F9 -> 162393.82 | G21: =Calcs!G9 -> 204136.41 | H21: =Calcs!H9 -> 256112.63 | I21: =Calcs!I9 -> 320916.56 | J21: =Calcs!J9 -> 401784.49
B22: Intangible assets | C22: =62514+32700 -> 95214 | D22: =67708+32700 -> 100408 | E22: =74718+32700 -> 107418 | F22: =E22-IncState!F22 -> 107418 | G22: =F22-IncState!G22 -> 107418 | H22: =G22-IncState!H22 -> 107418 | I22: =H22-IncState!I22 -> 107418 | J22: =I22-IncState!J22 -> 107418
B23: Other assets | C23: =9015+26438 -> 35453 | D23: =7740+14949 -> 22689 | E23: =6476+31735+49046 -> 87257 | F23: =F8*IncState!F16 -> 98600.41 | G23: =G8*IncState!G16 -> 118320.49 | H23: =H8*IncState!H16 -> 147900.61 | I23: =I8*IncState!I16 -> 184875.77 | J23: =J8*IncState!J16 -> 231094.71
B24: Total non-current assets | C24: =SUM(C21:C23) -> 197518 | D24: =SUM(D21:D23) -> 233481 | E24: =SUM(E21:E23) -> 320628 | F24: =SUM(F21:F23) -> 368412.23 | G24: =SUM(G21:G23) -> 429874.9 | H24: =SUM(H21:H23) -> 511431.24 | I24: =SUM(I21:I23) -> 613210.33 | J24: =SUM(J21:J23) -> 740297.2
A26: * | B26: TOTAL ASSETS | C26: =SUM(C24,C19) -> 424190 | D26: =SUM(D24,D19) -> 377825 | E26: =SUM(E24,E19) -> 716246 | F26: =SUM(F24,F19) -> 851518.77 | G26: =SUM(G24,G19) -> 1030678.8 | H26: =SUM(H24,H19) -> 1273563.1 | I26: =SUM(I24,I19) -> 1588664.8 | J26: =SUM(J24,J19) -> 1997391.3
B28: Revolver/Short term debt | C28: 0 | D28: 0 | E28: 0 | F28: =MIN(CashFlow!F23,0) -> 0 | G28: =MIN(CashFlow!G23,0) -> 0 | H28: =MIN(CashFlow!H23,0) -> 0 | I28: =MIN(CashFlow!I23,0) -> 0 | J28: =MIN(CashFlow!J23,0) -> 0
B29: Accounts payable/Accurals | C29: 5219 | D29: 4725 | E29: 6943 | F29: =F10*IncState!F17 -> 7792.008 | G29: =G10*IncState!G17 -> 9286.1112 | H29: =H10*IncState!H17 -> 11527.266 | I29: =I10*IncState!I17 -> 14308.616 | J29: =J10*IncState!J17 -> 17760.188
B30: Other current liabilities | C30: =34726+15167 -> 49893 | D30: =2380+38571+25328 -> 66279 | E30: =1059+46782+32659 -> 80500 | F30: =F11*IncState!F16 -> 90965 | G30: =G11*IncState!G16 -> 109158 | H30: =H11*IncState!H16 -> 136447.5 | I30: =I11*IncState!I16 -> 170559.38 | J30: =J11*IncState!J16 -> 213199.22
B31: Total current liabilities | C31: =SUM(C28:C30) -> 55112 | D31: =SUM(D28:D30) -> 71004 | E31: =SUM(E28:E30) -> 87443 | F31: =SUM(F28:F30) -> 98757.008 | G31: =SUM(G28:G30) -> 118444.11 | H31: =SUM(H28:H30) -> 147974.77 | I31: =SUM(I28:I30) -> 184867.99 | J31: =SUM(J28:J30) -> 230959.41
B33: Long-term debt, including current maturities | C33: =7300+706846 -> 714146 | D33: 712327 | E33: 1206201 | F33: =Debt!F20 -> 1206201 | G33: =Debt!G20 -> 1206201 | H33: =Debt!H20 -> 1206201 | I33: =Debt!I20 -> 1206201 | J33: =Debt!J20 -> 1206201
B34: Other long-term liabilities | C34: =27052+4180+14561 -> 45793 | D34: =17807+30145+3721+187 -> 51860 | E34: =58169+38877+1085+57 -> 98188 | F34: =F12*IncState!F16 -> 110952.44 | G34: =G12*IncState!G16 -> 133142.93 | H34: =H12*IncState!H16 -> 166428.66 | I34: =I12*IncState!I16 -> 208035.82 | J34: =J12*IncState!J16 -> 260044.78
B35: Total non-current liabilities | C35: =SUM(C33:C34) -> 759939 | D35: =SUM(D33:D34) -> 764187 | E35: =SUM(E33:E34) -> 1304389 | F35: =SUM(F33:F34) -> 1317153.4 | G35: =SUM(G33:G34) -> 1339343.9 | H35: =SUM(H33:H34) -> 1372629.7 | I35: =SUM(I33:I34) -> 1414236.8 | J35: =SUM(J33:J34) -> 1466245.8
B37: Equity | C37: -390861 | D37: -457366 | E37: -675586 | F37: =Calcs!F17 -> -564391.68 | G37: =Calcs!G17 -> -427109.19 | H37: =Calcs!H17 -> -247041.32 | I37: =Calcs!I17 -> -10440.01 | J37: =Calcs!J17 -> 300186.12
A38: * | B38: TOTAL LIABILITIES & EQUITY | C38: =SUM(C37,C35,C31) -> 424190 | D38: =SUM(D37,D35,D31) -> 377825 | E38: =SUM(E37,E35,E31) -> 716246 | F38: =SUM(F37,F35,F31) -> 851518.77 | G38: =SUM(G37,G35,G31) -> 1030678.8 | H38: =SUM(H37,H35,H31) -> 1273563.1 | I38: =SUM(I37,I35,I31) -> 1588664.8 | J38: =SUM(J37,J35,J31) -> 1997391.3
A40: * | B40: Balance check | C40: =C38-C26 -> 0 | D40: =D38-D26 -> 0 | E40: =E38-E26 -> 0 | F40: =F38-F26 -> 0 | G40: =G38-G26 -> 0 | H40: =H38-H26 -> 0 | I40: =I38-I26 -> 0 | J40: =J38-J26 -> 0

Sheet CashFlow
A1: =CoName -> Wingstop Inc | C1: Hist. | D1: Hist. | E1: Hist. | F1: Proj. | G1: Proj. | H1: Proj. | I1: Proj. | J1: Proj.
A2: Cash flow statement | C2: 2022 | D2: =C2+1 -> 2023 | E2: =D2+1 -> 2024 | F2: =E2+1 -> 2025 | G2: =F2+1 -> 2026 | H2: =G2+1 -> 2027 | I2: =H2+1 -> 2028 | J2: =I2+1 -> 2029
B3: Net Income | F3: =IncState!F34 -> 147369.57 | G3: =IncState!G34 -> 180763.99 | H3: =IncState!H34 -> 230855.62 | I3: =IncState!I34 -> 294695.31 | J3: =IncState!J34 -> 376026.38
B4: Depreciation | F4: =IncState!F21 -> 22238.947 | G4: =IncState!G21 -> 28673.137 | H4: =IncState!H21 -> 36043.436 | I4: =IncState!I21 -> 45220.64 | J4: =IncState!J21 -> 56662.774
B5: Amortization | F5: =IncState!F22 -> 0 | G5: =IncState!G22 -> 0 | H5: =IncState!H22 -> 0 | I5: =IncState!I22 -> 0 | J5: =IncState!J22 -> 0
B6: (inc) / dec in OWC | F6: =Calcs!F25 -> -675.13019 | G6: =Calcs!G25 -> -1155.5524 | H6: =Calcs!H25 -> -1733.3286 | I6: =Calcs!I25 -> -2186.7541 | J6: =Calcs!J25 -> -2758.5591
B7: (inc) / dec in LT assets | F7: =BalSheet!E23-BalSheet!F23 -> -11343.41 | G7: =BalSheet!F23-BalSheet!G23 -> -19720.082 | H7: =BalSheet!G23-BalSheet!H23 -> -29580.123 | I7: =BalSheet!H23-BalSheet!I23 -> -36975.154 | J7: =BalSheet!I23-BalSheet!J23 -> -46218.942
B8: inc / (dec) in LT liabilities | F8: =BalSheet!F34-BalSheet!E34 -> 12764.44 | G8: =BalSheet!G34-BalSheet!F34 -> 22190.488 | H8: =BalSheet!H34-BalSheet!G34 -> 33285.732 | I8: =BalSheet!I34-BalSheet!H34 -> 41607.165 | J8: =BalSheet!J34-BalSheet!I34 -> 52008.956
B9: CFFO | F9: =SUM(F3:F8) -> 170354.42 | G9: =SUM(G3:G8) -> 210751.98 | H9: =SUM(H3:H8) -> 268871.33 | I9: =SUM(I3:I8) -> 342361.21 | J9: =SUM(J3:J8) -> 435720.61
B11: Capex | F11: =-Calcs!F7 -> -58679.77 | G11: =-Calcs!G7 -> -70415.724 | H11: =-Calcs!H7 -> -88019.655 | I11: =-Calcs!I7 -> -110024.57 | J11: =-Calcs!J7 -> -137530.71
B12: CFFI | F12: =SUM(F11) -> -58679.77 | G12: =SUM(G11) -> -70415.724 | H12: =SUM(H11) -> -88019.655 | I12: =SUM(I11) -> -110024.57 | J12: =SUM(J11) -> -137530.71
B14: Dividends Paid | F14: =-IncState!F36 -> -36175.25 | G14: =-IncState!G36 -> -43481.5 | H14: =-IncState!H36 -> -50787.75 | I14: =-IncState!I36 -> -58094 | J14: =-IncState!J36 -> -65400.25
B15: Share issuance / (repurchases) | F15: =Calcs!F11 -> 0 | G15: =Calcs!G11 -> 0 | H15: =Calcs!H11 -> 0 | I15: =Calcs!I11 -> 0 | J15: =Calcs!J11 -> 0
B16: Debt issuance / (repayment) | F16: =SUM(Debt!F8:F9) -> 0 | G16: =SUM(Debt!G8:G9) -> 0 | H16: =SUM(Debt!H8:H9) -> 0 | I16: =SUM(Debt!I8:I9) -> 0 | J16: =SUM(Debt!J8:J9) -> 0
B17: CFFF | F17: =SUM(F14:F16) -> -36175.25 | G17: =SUM(G14:G16) -> -43481.5 | H17: =SUM(H14:H16) -> -50787.75 | I17: =SUM(I14:I16) -> -58094 | J17: =SUM(J14:J16) -> -65400.25
B19: Net changes in cash | F19: =SUM(F17,F12,F9) -> 75499.397 | G19: =SUM(G17,G12,G9) -> 96854.756 | H19: =SUM(H17,H12,H9) -> 130063.93 | I19: =SUM(I17,I12,I9) -> 174242.64 | J19: =SUM(J17,J12,J9) -> 232789.65
B21: Beginning cash | F21: =BalSheet!E16 -> 303393.86 | G21: =BalSheet!F16 -> 378893.26 | H21: =BalSheet!G16 -> 475748.01 | I21: =BalSheet!H16 -> 605811.94 | J21: =BalSheet!I16 -> 780054.58
B22: =B19 -> Net changes in cash | F22: =F19 -> 75499.397 | G22: =G19 -> 96854.756 | H22: =H19 -> 130063.93 | I22: =I19 -> 174242.64 | J22: =J19 -> 232789.65
B23: Ending cash | F23: =SUM(F21:F22) -> 378893.26 | G23: =SUM(G21:G22) -> 475748.01 | H23: =SUM(H21:H22) -> 605811.94 | I23: =SUM(I21:I22) -> 780054.58 | J23: =SUM(J21:J22) -> 1012844.2

Sheet Free Cash Flow
A1: =CoName -> Wingstop Inc | C1: Hist. | D1: Hist. | E1: Hist. | F1: Proj. | G1: Proj. | H1: Proj. | I1: Proj. | J1: Proj.
A2: Free Cash Flows | C2: 2022 | D2: =C2+1 -> 2023 | E2: =D2+1 -> 2024 | F2: =E2+1 -> 2025 | G2: =F2+1 -> 2026 | H2: =G2+1 -> 2027 | I2: =H2+1 -> 2028 | J2: =I2+1 -> 2029
A3: * | B3: Sales | F3: =IncState!F16 -> 707161.91 | G3: =IncState!G16 -> 848594.29 | H3: =IncState!H16 -> 1060742.9 | I3: =IncState!I16 -> 1325928.6 | J3: =IncState!J16 -> 1657410.7
B4: EBIT | F4: =IncState!F19 -> 191389.05 | G4: =IncState!G19 -> 234758.43 | H4: =IncState!H19 -> 299812.49 | I4: =IncState!I19 -> 382721.19 | J4: =IncState!J19 -> 488345.95
B5: Effective Tax Rate | F5: =Assumptions!F16 -> 0.23 | G5: =Assumptions!G16 -> 0.23 | H5: =Assumptions!H16 -> 0.23 | I5: =Assumptions!I16 -> 0.23 | J5: =Assumptions!J16 -> 0.23
A7: * | B7: NOPAT | F7: =F4*(1-F5) -> 147369.57 | G7: =G4*(1-G5) -> 180763.99 | H7: =H4*(1-H5) -> 230855.62 | I7: =I4*(1-I5) -> 294695.31 | J7: =J4*(1-J5) -> 376026.38
B8: Depreciation | F8: =CashFlow!F4 -> 22238.947 | G8: =CashFlow!G4 -> 28673.137 | H8: =CashFlow!H4 -> 36043.436 | I8: =CashFlow!I4 -> 45220.64 | J8: =CashFlow!J4 -> 56662.774
B9: Amortization | F9: =CashFlow!F5 -> 0 | G9: =CashFlow!G5 -> 0 | H9: =CashFlow!H5 -> 0 | I9: =CashFlow!I5 -> 0 | J9: =CashFlow!J5 -> 0
B10: (inc) / dec in OWC | F10: =CashFlow!F6 -> -675.13019 | G10: =CashFlow!G6 -> -1155.5524 | H10: =CashFlow!H6 -> -1733.3286 | I10: =CashFlow!I6 -> -2186.7541 | J10: =CashFlow!J6 -> -2758.5591
B11: (inc) / dec in other long-term assets | F11: =CashFlow!F7 -> -11343.41 | G11: =CashFlow!G7 -> -19720.082 | H11: =CashFlow!H7 -> -29580.123 | I11: =CashFlow!I7 -> -36975.154 | J11: =CashFlow!J7 -> -46218.942
B12: inc / (dec) other long-term liabilities | F12: =CashFlow!F8 -> 12764.44 | G12: =CashFlow!G8 -> 22190.488 | H12: =CashFlow!H8 -> 33285.732 | I12: =CashFlow!I8 -> 41607.165 | J12: =CashFlow!J8 -> 52008.956
B13: (Capex) | F13: =CashFlow!F12 -> -58679.77 | G13: =CashFlow!G12 -> -70415.724 | H13: =CashFlow!H12 -> -88019.655 | I13: =CashFlow!I12 -> -110024.57 | J13: =CashFlow!J12 -> -137530.71
A15: * | B15: Free Cash Flow | F15: =SUM(F7:F13) -> 111674.65 | G15: =SUM(G7:G13) -> 140336.26 | H15: =SUM(H7:H13) -> 180851.68 | I15: =SUM(I7:I13) -> 232336.64 | J15: =SUM(J7:J13) -> 298189.9

Sheet WACC
A1: =CoName -> Wingstop Inc
A3: * | B3: WACC | G3: Comp | H3: Levered beta | I3: Gross debt | J3: Market cap | K3: Debt/Mcap | L3: MTR | M3: Unlevered beta
B4: Tax Rate | E4: 0.21 | L4: =E4 -> 0.21 | M4: =H4/((1+K4*(1-L4))) -> 0
B5: Risk free rate | E5: 0.04 | L5: =L4 -> 0.21 | M5: =H5/((1+K5*(1-L5))) -> 0
B6: Market risk Premium | E6: 0.05 | L6: =L5 -> 0.21 | M6: =H6/((1+K6*(1-L6))) -> 0
B7: Beta | E7: 0.67 | L7: =L6 -> 0.21 | M7: =H7/((1+K7*(1-L7))) -> 0
B8: Cost of Equity | E8: =E5+E6*E7 -> 0.0735
B9: % Equity | E9: =1-E10 -> 0.82301727 | G9: Industry beta (average) | M9: =AVERAGE(M4:M7) -> 0
B10: % Debt | E10: =MAIN!F8/MAIN!F6 -> 0.17698273
B11: Cost of debt | E11: =Assumptions!F24 -> 0.04 | G11: Re-levered beta | M11: =M9*(1+E10*(1-E4)) -> 0
B12: Post tax cost of debt | E12: =E11*(1-E4) -> 0.0316
A13: * | B13: WACC | E13: =WACC!E8*WACC!E9+WACC!E12*WACC!E10 -> 0.066084424
B14: Long Term growth rate | E14: 0.025

Sheet DCF Model
A1: =CoName -> Wingstop Inc | D1: Proj. | E1: Proj. | F1: Proj. | G1: Proj. | H1: Proj.
A2: Discount Model Year count | D2: 0.5 | E2: =D2+1 -> 1.5 | F2: =E2+1 -> 2.5 | G2: =F2+1 -> 3.5 | H2: =G2+1 -> 4.5
B3: Discount Factor | D3: =1/(1+$K$17)^D2 -> 0.9685102 | E3: =1/(1+$K$17)^E2 -> 0.90847421 | F3: =1/(1+$K$17)^F2 -> 0.85215973 | G3: =1/(1+$K$17)^G2 -> 0.79933606 | H3: =1/(1+$K$17)^H2 -> 0.74978683
B4: PV FCF | D4: =D3*'Free Cash Flow'!F15 -> 108158.04 | E4: =E3*'Free Cash Flow'!G15 -> 127491.87 | F4: =F3*'Free Cash Flow'!H15 -> 154114.52 | G4: =G3*'Free Cash Flow'!I15 -> 185715.06 | H4: =H3*'Free Cash Flow'!J15 -> 223578.86 | I4: =(H4*(1+K18))/(K17-K18) -> 5577985.8
A6: Value Calculation | E6: Multiples Calculation
B7: Total PV of FCFs | C7: =SUM(D4:H4) -> 799058.34 | E7: Total PV of FCFs | G7: =C7 -> 799058.34
B8: PV of TV | C8: =I4*H3 -> 4182300.3 | E8: Multiple TV | G8: =G10*IncState!J23*'DCF Model'!H3 -> 6129605.4
B9: EV | C9: =SUM(C7:C8) -> 4981358.6 | E9: EV | G9: =SUM(G7:G8) -> 6928663.8
E10: Implied EBITDA multiple | G10: 15
B12: Cash & Cash Equiv | C12: =MAIN!F7 -> 286110 | E12: Cash & Cash Equiv | G12: =C12 -> 286110
B13: Debt & Claims | C13: =MAIN!F8 -> 1266676 | E13: Debt & Claims | G13: =C13 -> 1266676
B14: NCI | C14: 0 | E14: NCI | G14: =C14 -> 0
B15: Equity Value | C15: =C9+C12-SUM(C13:C14) -> 4000792.6 | E15: Equity Value | G15: =G9+G12-SUM(G13:G14) -> 5948097.8
B17: Diluted S/O | C17: =MAIN!F5 -> 27786.854 | E17: Diluted S/O | G17: =C17 -> 27786.854 | I17: WACC | K17: =WACC!E13 -> 0.066084424
A18: * | B18: Implied Share Price | C18: =C15/C17 -> 143.98149 | E18: Implied Share Price | G18: =G15/G17 -> 214.06158 | I18: Long Term growth rate | K18: 0.025
A20: Sensitivity analysis
C22: Discount rate variance | E22: 0.005 | H22: Discount rate variance | J22: 0.005
C23: Implied growth rate variance | E23: 0.0025 | H23: TV multiple variance | J23: 2
E25: LTGR | J25: Exit Mult.
C26: =C18 -> 143.98149 | D26: =E26-E23 -> 0.0225 | E26: 0.025 | F26: =E26+E23 -> 0.0275 | H26: =G18 -> 214.06158 | I26: =J26-J23 -> 13 | J26: 15 | K26: =J26+J23 -> 17
C27: =C28+$E$22 -> 0.076765855 | D27: 96.581596 | E27: 101.8667 | F27: 107.68818 | H27: =C27 -> 0.076765855 | I27: 175.45559 | J27: 203.57772 | K27: 231.69986
C28: =C29+$E$22 -> 0.071765855 | D28: 112.39805 | E28: 119.0864 | F28: 126.53023 | H28: =C28 -> 0.071765855 | I28: 179.69734 | J28: 208.4147 | K28: 237.13205
C29: 0.066765855 | D29: 131.97156 | E29: 140.62424 | F29: 150.37872 | H29: =C29 -> 0.066765855 | I29: 184.04761 | J29: 213.37566 | K29: 242.7037
C30: =C29-$E$22 -> 0.061765855 | D30: 156.75005 | E30: 168.2555 | F30: 181.43981 | H30: =C30 -> 0.061765855 | I30: 188.50972 | J30: 218.4644 | K30: 248.41908
C31: =C30-$E$22 -> 0.056765855 | D31: 189.02743 | E31: 204.87422 | F31: 223.42839 | H31: =C31 -> 0.056765855 | I31: 193.08711 | J31: 223.68486 | K31: 254.28262
