Workbook
Name Ccy: MAIN!$C$6
Name circ: MAIN!$C$9
Name CoName: MAIN!$C$4
Name g: #REF!
Name IQ_CH: 110000
Name IQ_CQ: 5000
Name IQ_CY: 10000
Name IQ_DAILY: 500000
Name IQ_FH: 100000
Name IQ_FQ: 500
Name IQ_FY: 1000
Name IQ_LTM: 2000
Name IQ_MONTH: 15000
Name IQ_NTM: 6000
Name IQ_WEEK: 50000
Name IQ_YTD: 3000
Name OpCase: [1]DCF!$E$98
Name ScenarioREV: Assumptions!$D$4
Name TTS: #REF!
Name Units: MAIN!$C$7

Sheet MAIN
A1: =CoName -> Yum Brands Inc.
A2: Model Details
B4: Company name | C4: Yum Brands Inc. | E4: Current Stock Price | F4: 144.85 | H4: Operating Case One | I4: Terminal Mult | J4: Perpetuity | K4: DDM | L4: Perpetuity
B5: Latest BS date | C5: 247.43 | E5: Diluted s/o | F5: 277.65283 | H5: Implied Price | I5: ='DCF Model'!G18 -> 169.37272 | J5: ='DCF Model'!C18 -> 146.24425 | K5: ='DCF Model'!K11 -> 93.991236 | L5: =AVERAGE(I5:K5) -> 136.53607
B6: Currency | C6: USD | E6: Mkt Cap | F6: =F5*F4 -> 40218.012 | H6: Difference | I6: =I5/$F$4-1 -> 0.16929734 | J6: =J5/$F$4-1 -> 0.0096255016 | K6: =K5/$F$4-1 -> -0.35111332 | L6: =L5/$F$4-1 -> -0.057396825
B7: Units | C7: m | E7: Cash | F7: 1045
B8: Analyst name | C8: Alan Chen | E8: Debt | F8: =1301+11506 -> 12807
B9: Circular switch | C9: 0 | E9: EV | F9: =F6-F7+F8 -> 51980.012

Sheet Quarterly Projections
A1: =CoName -> Yum Brands Inc.
A2: Dates | C2: Q122 | D2: Q222 | E2: Q322 | F2: Q422 | G2: 2022 | H2: Q123 | I2: Q223 | J2: Q323 | K2: Q423 | L2: 2023 | M2: Q124 | N2: Q224 | O2: Q324 | P2: Q424 | Q2: 2024 | R2: Q125 | S2: Q225 | T2: Q325 | U2: Q425E | V2: 2025 | W2: Q126E | X2: Q226E | Y2: Q326E | Z2: Q426E | AA2: 2026E | AB2: 2027E | AC2: 2028E | AD2: 2029E
A3: KFC
B4: Company Sales | C4: 126 | D4: 115 | E4: 112 | F4: 138 | G4: =SUM(C4:F4) -> 491 | H4: 110 | I4: 115 | J4: 117 | K4: 142 | L4: =SUM(H4:K4) -> 484 | M4: 105 | N4: 163 | O4: 220 | P4: 313 | Q4: =SUM(M4:P4) -> 801 | R4: 216 | S4: 245 | T4: 259 | V4: =SUM(R4:U4) -> 720
B5: y/y | C5: n/a | D5: n/a | E5: n/a | F5: n/a | G5: n/a | H5: =H4/C4-1 -> -0.12698413 | I5: =I4/D4-1 -> 0 | J5: =J4/E4-1 -> 0.044642857 | K5: =K4/F4-1 -> 0.028985507 | L5: =L4/G4-1 -> -0.014256619 | M5: =M4/H4-1 -> -0.045454545 | N5: =N4/I4-1 -> 0.4173913 | O5: =O4/J4-1 -> 0.88034188 | ... T5: =T4/O4-1 -> 0.17727273 | V5: =V4/Q4-1 -> -0.1011236
B6: Franchise and property revenues | C6: 383 | D6: 394 | E6: 418 | F6: 450 | G6: =SUM(C6:F6) -> 1645 | H6: 412 | I6: 416 | J6: 426 | K6: 444 | L6: =SUM(H6:K6) -> 1698 | M6: 397 | N6: 405 | O6: 417 | P6: 466 | Q6: =SUM(M6:P6) -> 1685 | R6: 407 | S6: 437 | T6: 459 | V6: =SUM(R6:U6) -> 1303
B7: y/y | C7: n/a | D7: n/a | E7: n/a | F7: n/a | G7: n/a | H7: =H6/C6-1 -> 0.075718016 | I7: =I6/D6-1 -> 0.055837563 | J7: =J6/E6-1 -> 0.019138756 | K7: =K6/F6-1 -> -0.013333333 | L7: =L6/G6-1 -> 0.032218845 | M7: =M6/H6-1 -> -0.036407767 | N7: =N6/I6-1 -> -0.026442308 | O7: =O6/J6-1 -> -0.021126761 | ... T7: =T6/O6-1 -> 0.10071942 | V7: =V6/Q6-1 -> -0.22670623
B8: other services | C8: 151 | D8: 168 | E8: 174 | F8: 205 | G8: =SUM(C8:F8) -> 698 | H8: 165 | I8: 151 | J8: 157 | K8: 175 | L8: =SUM(H8:K8) -> 648 | M8: 130 | N8: 149 | O8: 148 | P8: 186 | Q8: =SUM(M8:P8) -> 613 | R8: 149 | S8: 167 | T8: 161 | V8: =SUM(R8:U8) -> 477
B9: y/y | C9: n/a | D9: n/a | E9: n/a | F9: n/a | G9: n/a | H9: =H8/C8-1 -> 0.092715232 | I9: =I8/D8-1 -> -0.10119048 | J9: =J8/E8-1 -> -0.097701149 | K9: =K8/F8-1 -> -0.14634146 | L9: =L8/G8-1 -> -0.071633238 | M9: =M8/H8-1 -> -0.21212121 | N9: =N8/I8-1 -> -0.013245033 | O9: =O8/J8-1 -> -0.057324841 | ... T9: =T8/O8-1 -> 0.087837838 | V9: =V8/Q8-1 -> -0.22185971
A10: Revenues | C10: =SUM(C8,C6,C4) -> 660 | D10: =SUM(D8,D6,D4) -> 677 | E10: =SUM(E8,E6,E4) -> 704 | F10: =SUM(F8,F6,F4) -> 793 | G10: =SUM(G8,G6,G4) -> 2834 | H10: =SUM(H8,H6,H4) -> 687 | I10: =SUM(I8,I6,I4) -> 682 | J10: =SUM(J8,J6,J4) -> 700 | ... T10: =SUM(T8,T6,T4) -> 879 | U10: =P10*(1+U11) -> 1042.9354 | V10: =SUM(R10:U10) -> 3542.9354 | W10: =R10*(1+W11) -> 857.692 | X10: =S10*(1+X11) -> 934.749 | Y10: =T10*(1+Y11) -> 964.263 | Z10: =U10*(1+Z11) -> 1127.4132 | AA10: =SUM(W10:Z10) -> 3884.1172 | AB10: =AA10*(1+AB11) -> 4233.6877 | AC10: =AB10*(1+AC11) -> 4572.3827 | AD10: =AC10*(1+AD11) -> 4892.4495
B11: y/y | C11: n/a | D11: n/a | E11: n/a | F11: n/a | G11: n/a | H11: =H10/C10-1 -> 0.040909091 | I11: =I10/D10-1 -> 0.0073855244 | J11: =J10/E10-1 -> -0.0056818182 | K11: =K10/F10-1 -> -0.04035309 | L11: =L10/G10-1 -> -0.0014114326 | M11: =M10/H10-1 -> -0.080058224 | N11: =N10/I10-1 -> 0.051319648 | O11: =O10/J10-1 -> 0.12142857 | ... T11: =T10/O10-1 -> 0.11974522 | U11: =AVERAGE(R11:T11,M11:P11,H11:K11) -> 0.08076206 | V11: =V10/Q10-1 -> 0.14325117 | W11: 0.111 | X11: 0.101 | Y11: 0.097 | Z11: 0.081 | AA11: =AA10/V10-1 -> 0.096299178 | AB11: 0.09 | AC11: 0.08 | AD11: 0.07
B13: COGS | C13: 108 | D13: 102 | E13: 97 | F13: 119 | G13: =SUM(C13:F13) -> 426 | H13: 96 | I13: 99 | J13: 100 | K13: 122 | L13: =SUM(H13:K13) -> 417 | M13: 92 | N13: 144 | O13: 192 | P13: 275 | Q13: =SUM(M13:P13) -> 703 | R13: 196 | S13: 216 | T13: 224 | U13: =U10*U14 -> 260.73385 | V13: =SUM(R13:U13) -> 896.73385 | W13: =W10*W14 -> 214.423 | X13: =X10*X14 -> 233.68725 | Y13: =Y10*Y14 -> 241.06575 | Z13: =Z10*Z14 -> 281.85329 | AA13: =SUM(W13:Z13) -> 971.02929 | AB13: =AB10*AB14 -> 1058.4219 | AC13: =AC10*AC14 -> 1143.0957 | AD13: =AD10*AD14 -> 1223.1124
B14: Margin % | C14: =C13/C10 -> 0.16363636 | D14: =D13/D10 -> 0.1506647 | E14: =E13/E10 -> 0.13778409 | F14: =F13/F10 -> 0.15006305 | G14: =G13/G10 -> 0.15031757 | H14: =H13/H10 -> 0.13973799 | I14: =I13/I10 -> 0.14516129 | J14: =J13/J10 -> 0.14285714 | ... T14: =T13/T10 -> 0.25483504 | U14: 0.25 | V14: =V13/V10 -> 0.25310477 | W14: 0.25 | X14: 0.25 | Y14: 0.25 | Z14: 0.25 | AA14: =AA13/AA10 -> 0.25 | AB14: 0.25 | AC14: 0.25 | AD14: 0.25
B15: SG&A | C15: =84+24+151+2 -> 261 | D15: =89+14+163+16 -> 282 | E15: =96+15+166+26 -> 303 | F15: =121+16+204+23 -> 364 | G15: =SUM(C15:F15) -> 1210 | H15: =89+26+164+1 -> 280 | I15: =90+16+150+1 -> 257 | J15: =86+15+156-1 -> 256 | K15: =118+15+178-1 -> 310 | L15: =SUM(H15:K15) -> 1103 | M15: =83+17+129-2 -> 227 | N15: =84+9+147-1 -> 239 | O15: =86+20+148 -> 254 | P15: =110+17+186 -> 313 | Q15: =SUM(M15:P15) -> 1033 | R15: =80+16+149 -> 245 | S15: =86+20+162 -> 268 | T15: =88+15+160 -> 263 | U15: =U16*U10 -> 312.88062 | V15: =SUM(R15:U15) -> 1088.8806 | W15: =W16*W10 -> 257.3076 | X15: =X16*X10 -> 280.4247 | Y15: =Y16*Y10 -> 289.2789 | Z15: =Z16*Z10 -> 338.22395 | AA15: =SUM(W15:Z15) -> 1165.2351 | AB15: =AB16*AB10 -> 1270.1063 | AC15: =AC16*AC10 -> 1371.7148 | AD15: =AD16*AD10 -> 1467.7349
B16: Margin % | C16: =C15/C10 -> 0.39545455 | D16: =D15/D10 -> 0.41654357 | E16: =E15/E10 -> 0.43039773 | F16: =F15/F10 -> 0.45901639 | G16: =G15/G10 -> 0.42695836 | H16: =H15/H10 -> 0.40756914 | I16: =I15/I10 -> 0.37683284 | J16: =J15/J10 -> 0.36571429 | ... T16: =T15/T10 -> 0.29920364 | U16: 0.3 | V16: =V15/V10 -> 0.30733855 | W16: 0.3 | X16: 0.3 | Y16: 0.3 | Z16: 0.3 | AA16: =AA15/AA10 -> 0.3 | AB16: 0.3 | AC16: 0.3 | AD16: 0.3
A17: Operating income | C17: =C10-SUM(C13:C15) -> 290.83636 | D17: =D10-SUM(D13:D15) -> 292.84934 | E17: =E10-SUM(E13:E15) -> 303.86222 | F17: =F10-SUM(F13:F15) -> 309.84994 | G17: =G10-SUM(G13:G15) -> 1197.8497 | H17: =H10-SUM(H13:H15) -> 310.86026 | I17: =I10-SUM(I13:I15) -> 325.85484 | J17: =J10-SUM(J13:J15) -> 343.85714 | ... AD17: =AD10-SUM(AD13:AD15) -> 2201.3523
B18: Margin % | C18: =C17/C10 -> 0.44066116 | D18: =D17/D10 -> 0.43256918 | E18: =E17/E10 -> 0.43162247 | F18: =F17/F10 -> 0.39073132 | G18: =G17/G10 -> 0.42267102 | H18: =H17/H10 -> 0.45248946 | I18: =I17/I10 -> 0.47779302 | J18: =J17/J10 -> 0.49122449 | ... AD18: =AD17/AD10 -> 0.4499489
A19: Taco Bell
B20: Company Sales | C20: 214 | D20: 243 | E20: 234 | F20: 311 | G20: =SUM(C20:F20) -> 1002 | H20: 229 | I20: 253 | J20: 256 | K20: 331 | L20: =SUM(H20:K20) -> 1069 | M20: 240 | N20: 268 | O20: 267 | P20: 380 | Q20: =SUM(M20:P20) -> 1155 | R20: 263 | S20: 287 | T20: 298 | V20: =SUM(R20:U20) -> 848 | AA20: =SUM(W20:Z20) -> 0
B21: y/y | C21: n/a | D21: n/a | E21: n/a | F21: n/a | G21: n/a | H21: =H20/C20-1 -> 0.070093458 | I21: =I20/D20-1 -> 0.041152263 | J21: =J20/E20-1 -> 0.094017094 | K21: =K20/F20-1 -> 0.064308682 | L21: =L20/G20-1 -> 0.066866267 | M21: =M20/H20-1 -> 0.048034934 | N21: =N20/I20-1 -> 0.059288538 | O21: =O20/J20-1 -> 0.04296875 | ... T21: =T20/O20-1 -> 0.11610487 | V21: =V20/Q20-1 -> -0.26580087 | AA21: =AA20/V20-1 -> -1
B22: Franchise and property revenues | C22: 179 | D22: 199 | E22: 196 | F22: 263 | G22: =SUM(C22:F22) -> 837 | H22: 201 | I22: 218 | J22: 218 | K22: 281 | L22: =SUM(H22:K22) -> 918 | M22: 210 | N22: 234 | O22: 234 | P22: 319 | Q22: =SUM(M22:P22) -> 997 | R22: 234 | S22: 248 | T22: 254 | V22: =SUM(R22:U22) -> 736 | AA22: =SUM(W22:Z22) -> 0
B23: y/y | C23: n/a | D23: n/a | E23: n/a | F23: n/a | G23: n/a | H23: =H22/C22-1 -> 0.12290503 | I23: =I22/D22-1 -> 0.095477387 | J23: =J22/E22-1 -> 0.1122449 | K23: =K22/F22-1 -> 0.068441065 | L23: =L22/G22-1 -> 0.096774194 | M23: =M22/H22-1 -> 0.044776119 | N23: =N22/I22-1 -> 0.073394495 | O23: =O22/J22-1 -> 0.073394495 | ... T23: =T22/O22-1 -> 0.085470085 | V23: =V22/Q22-1 -> -0.26178536 | AA23: =AA22/V22-1 -> -1
B24: other services | C24: 124 | D24: 144 | E24: 138 | F24: 192 | G24: =SUM(C24:F24) -> 598 | H24: 142 | I24: 150 | J24: 155 | K24: 207 | L24: =SUM(H24:K24) -> 654 | M24: 148 | N24: 164 | O24: 165 | P24: 231 | Q24: =SUM(M24:P24) -> 708 | R24: 160 | S24: 176 | T24: 178 | V24: =SUM(R24:U24) -> 514 | AA24: =SUM(W24:Z24) -> 0
B25: y/y | C25: n/a | D25: n/a | E25: n/a | F25: n/a | G25: n/a | H25: =H24/C24-1 -> 0.14516129 | I25: =I24/D24-1 -> 0.041666667 | J25: =J24/E24-1 -> 0.12318841 | K25: =K24/F24-1 -> 0.078125 | L25: =L24/G24-1 -> 0.093645485 | M25: =M24/H24-1 -> 0.042253521 | N25: =N24/I24-1 -> 0.093333333 | O25: =O24/J24-1 -> 0.064516129 | ... T25: =T24/O24-1 -> 0.078787879 | V25: =V24/Q24-1 -> -0.2740113 | AA25: =AA24/V24-1 -> -1
A26: Revenues | C26: =SUM(C20:C24) -> 517 | D26: =SUM(D24,D22,D20) -> 586 | E26: =SUM(E24,E22,E20) -> 568 | F26: =SUM(F24,F22,F20) -> 766 | G26: =SUM(G24,G22,G20) -> 2437 | H26: =SUM(H24,H22,H20) -> 572 | I26: =SUM(I24,I22,I20) -> 621 | J26: =SUM(J24,J22,J20) -> 629 | K26: =SUM(K24,K22,K20) -> 819 | ... T26: =SUM(T24,T22,T20) -> 730 | U26: =P26*(1+U27) -> 1007.553 | V26: =SUM(R26:U26) -> 3105.553 | W26: =R26*(1+W27) -> 729.927 | X26: =S26*(1+X27) -> 782.811 | Y26: =T26*(1+Y27) -> 800.81 | Z26: =U26*(1+Z27) -> 1089.1648 | AA26: =SUM(W26:Z26) -> 3402.7128 | AB26: =AA26*(1+AB27) -> 3742.9841 | AC26: =AB26*(1+AC27) -> 4079.8527 | AD26: =AC26*(1+AD27) -> 4406.2409
B27: y/y | C27: n/a | D27: n/a | E27: n/a | F27: n/a | G27: n/a | H27: =H26/C26-1 -> 0.10638298 | I27: =I26/D26-1 -> 0.059726962 | J27: =J26/E26-1 -> 0.10739437 | K27: =K26/F26-1 -> 0.069190601 | L27: =L26/G26-1 -> 0.083709479 | M27: =M26/H26-1 -> 0.045454545 | N27: =N26/I26-1 -> 0.072463768 | O27: =O26/J26-1 -> 0.058823529 | ... T27: =T26/O26-1 -> 0.096096096 | U27: =AVERAGE(R27:T27,M27:P27,H27:K27) -> 0.083390342 | V27: =V26/Q26-1 -> 0.085857698 | W27: 0.111 | X27: 0.101 | Y27: 0.097 | Z27: 0.081 | AA27: =AA26/V26-1 -> 0.095686595 | AB27: 0.1 | AC27: 0.09 | AD27: 0.08
B29: COGS | C29: 167 | D29: 181 | E29: 177 | F29: 241 | G29: =SUM(C29:F29) -> 766 | H29: 179 | I29: 187 | J29: 195 | K29: 256 | L29: =SUM(H29:K29) -> 817 | M29: 186 | N29: 199 | O29: 205 | P29: 282 | Q29: =SUM(M29:P29) -> 872 | R29: 204 | S29: 217 | T29: 227 | U29: =U26*U30 -> 311.82577 | V29: =SUM(R29:U29) -> 959.82577 | W29: =W26*W30 -> 226.39544 | X29: =X26*X30 -> 241.48757 | Y29: =Y26*Y30 -> 246.89903 | Z29: =Z26*Z30 -> 335.50924 | AA29: =SUM(W29:Z29) -> 1050.2913 | AB29: =AB26*AB30 -> 1156.359 | AC29: =AC26*AC30 -> 1256.1711 | AD29: =AD26*AD30 -> 1357.147
B30: Margin % | C30: =C29/C26 -> 0.32301741 | D30: =D29/D26 -> 0.30887372 | E30: =E29/E26 -> 0.31161972 | F30: =F29/F26 -> 0.31462141 | G30: =G29/G26 -> 0.31432089 | H30: =H29/H26 -> 0.31293706 | I30: =I29/I26 -> 0.30112721 | J30: =J29/J26 -> 0.3100159 | ... T30: =T29/T26 -> 0.3109589 | U30: =AVERAGE(R30:T30,C30:F30,M30:P30,H30:K30) -> 0.3094882 | V30: =V29/V26 -> 0.30906759 | W30: =AVERAGE(T30:V30,E30:H30,O30:R30,J30:M30) -> 0.31016175 | X30: =AVERAGE(U30:W30,F30:I30,P30:S30,K30:N30) -> 0.30848771 | Y30: =AVERAGE(V30:X30,G30:J30,Q30:T30,L30:O30) -> 0.30831162 | Z30: =AVERAGE(W30:Y30,H30:K30,R30:U30,M30:P30) -> 0.30804267 | AA30: =AA29/AA26 -> 0.30866292 | AB30: =AVERAGE(Y30:AA30,J30:M30,T30:W30,O30:R30) -> 0.30894041 | AC30: =AVERAGE(Z30:AB30,K30:N30,U30:X30,P30:S30) -> 0.30789619 | AD30: =AVERAGE(AA30:AC30,L30:O30,V30:Y30,Q30:T30) -> 0.30800562
B31: SG&A | C31: =36+6+123 -> 165 | D31: =39+8+144-1 -> 190 | E31: =41+8+139-1 -> 187 | F31: =75+11+193 -> 279 | G31: =SUM(C31:F31) -> 821 | H31: =45+5+138+1 -> 189 | I31: =49+9+148 -> 206 | J31: =47+7+153+1 -> 208 | K31: =63+11+205-2 -> 277 | L31: =SUM(H31:K31) -> 880 | M31: =49+8+147 -> 204 | N31: =47+8+163-1 -> 217 | O31: =41+6+163 -> 210 | P31: =62+11+235 -> 308 | Q31: =SUM(M31:P31) -> 939 | R31: =49+6+157 -> 212 | S31: =49+7+176 -> 232 | T31: =50+8+177 -> 235 | U31: =U32*U26 -> 322.41697 | V31: =SUM(R31:U31) -> 1001.417 | W31: =W32*W26 -> 233.57664 | X31: =X32*X26 -> 250.49952 | Y31: =Y32*Y26 -> 256.2592 | Z31: =Z32*Z26 -> 348.53274 | AA31: =SUM(W31:Z31) -> 1088.8681 | AB31: =AB32*AB26 -> 1197.7549 | AC31: =AC32*AC26 -> 1305.5529 | AD31: =AD32*AD26 -> 1409.9971
B32: Margin % | C32: =C31/C26 -> 0.31914894 | D32: =D31/D26 -> 0.32423208 | E32: =E31/E26 -> 0.32922535 | F32: =F31/F26 -> 0.36422977 | G32: =G31/G26 -> 0.33688962 | H32: =H31/H26 -> 0.33041958 | I32: =I31/I26 -> 0.33172303 | J32: =J31/J26 -> 0.33068362 | ... T32: =T31/T26 -> 0.32191781 | U32: 0.32 | V32: =V31/V26 -> 0.32246011 | W32: 0.32 | X32: 0.32 | Y32: 0.32 | Z32: 0.32 | AA32: =AA31/AA26 -> 0.32 | AB32: 0.32 | AC32: 0.32 | AD32: 0.32
A33: Operating income | C33: =C26-SUM(C29:C31) -> 184.67698 | D33: =D26-SUM(D29:D31) -> 214.69113 | E33: =E26-SUM(E29:E31) -> 203.68838 | F33: =F26-SUM(F29:F31) -> 245.68538 | G33: =G26-SUM(G29:G31) -> 849.68568 | H33: =H26-SUM(H29:H31) -> 203.68706 | I33: =I26-SUM(I29:I31) -> 227.69887 | J33: =J26-SUM(J29:J31) -> 225.68998 | ... AD33: =AD26-SUM(AD29:AD31) -> 1638.7888
B34: Margin % | C34: =C33/C26 -> 0.35720886 | D34: =D33/D26 -> 0.36636711 | E34: =E33/E26 -> 0.3586063 | F34: =F33/F26 -> 0.32073809 | G34: =G33/G26 -> 0.34866052 | H34: =H33/H26 -> 0.35609626 | I34: =I33/I26 -> 0.36666485 | J34: =J33/J26 -> 0.35880761 | ... AD34: =AD33/AD26 -> 0.37192448
A35: Pizza Hut
B36: Franchise and property revenues | C36: 151 | D36: 142 | E36: 145 | F36: 169 | G36: =SUM(C36:F36) -> 607 | H36: 155 | I36: 149 | J36: 150 | K36: 168 | L36: =SUM(H36:K36) -> 622 | M36: 148 | N36: 148 | O36: 150 | P36: 176 | Q36: =SUM(M36:P36) -> 622 | R36: 143 | S36: 147 | T36: 146 | V36: =SUM(R36:U36) -> 436 | AA36: =SUM(W36:Z36) -> 0
B37: y/y | C37: n/a | D37: n/a | E37: n/a | F37: n/a | G37: n/a | H37: =H36/C36-1 -> 0.026490066 | I37: =I36/D36-1 -> 0.049295775 | J37: =J36/E36-1 -> 0.034482759 | K37: =K36/F36-1 -> -0.0059171598 | L37: =L36/G36-1 -> 0.024711697 | M37: =M36/H36-1 -> -0.04516129 | N37: =N36/I36-1 -> -0.0067114094 | O37: =O36/J36-1 -> 0 | ... T37: =T36/O36-1 -> -0.026666667 | V37: =V36/Q36-1 -> -0.29903537 | AA37: =AA36/V36-1 -> -1
B38: other services | C38: 88 | D38: 88 | E38: 88 | F38: 112 | G38: =SUM(C38:F38) -> 376 | H38: 94 | I38: 89 | J38: 90 | K38: 110 | L38: =SUM(H38:K38) -> 383 | M38: 88 | N38: 89 | O38: 87 | P38: 114 | Q38: =SUM(M38:P38) -> 378 | R38: 85 | S38: 85 | T38: 85 | V38: =SUM(R38:U38) -> 255 | AA38: =SUM(W38:Z38) -> 0
B39: y/y | C39: n/a | D39: n/a | E39: n/a | F39: n/a | G39: n/a | H39: =H38/C38-1 -> 0.068181818 | I39: =I38/D38-1 -> 0.011363636 | J39: =J38/E38-1 -> 0.022727273 | K39: =K38/F38-1 -> -0.017857143 | L39: =L38/G38-1 -> 0.018617021 | M39: =M38/H38-1 -> -0.063829787 | N39: =N38/I38-1 -> 0 | O39: =O38/J38-1 -> -0.033333333 | ... T39: =T38/O38-1 -> -0.022988506 | V39: =V38/Q38-1 -> -0.32539683 | AA39: =AA38/V38-1 -> -1
A40: Revenues | C40: =SUM(C34:C38) -> 239.35721 | D40: =SUM(D34:D38) -> 230.36637 | E40: =SUM(E34:E38) -> 233.35861 | F40: =SUM(F34:F38) -> 281.32074 | G40: =SUM(G34:G38) -> 983.34866 | H40: =SUM(H34:H38) -> 249.38259 | I40: =SUM(I34:I38) -> 238.41596 | J40: =SUM(J34:J38) -> 240.39329 | ... Q40: =SUM(Q34:Q38) -> 1000.3667 | R40: =SUM(R38,R36,R34) -> 228.36635 | S40: =SUM(S38,S36,S34) -> 232.36807 | T40: =SUM(T38,T36,T34) -> 231.3667 | U40: =P40*(1+U41) -> 299.12527 | V40: =SUM(R40:U40) -> 991.22638 | W40: =R40*(1+W41) -> 253.71501 | X40: =S40*(1+X41) -> 255.83724 | Y40: =T40*(1+Y41) -> 253.80927 | Z40: =U40*(1+Z41) -> 323.35442 | AA40: =SUM(W40:Z40) -> 1086.7159 | AB40: =AA40*(1+AB41) -> 1119.3174 | AC40: =AB40*(1+AC41) -> 1152.8969 | AD40: =AC40*(1+AD41) -> 1187.4838
B41: y/y | C41: n/a | D41: n/a | E41: n/a | F41: n/a | G41: n/a | H41: =H40/C40-1 -> 0.041884585 | I41: =I40/D40-1 -> 0.034942573 | J41: =J40/E40-1 -> 0.030145381 | K41: =K40/F40-1 -> -0.01058518 | L41: =L40/G40-1 -> 0.022406472 | M41: =M40/H40-1 -> -0.052451303 | N41: =N40/I40-1 -> -0.0043946106 | O41: =O40/J40-1 -> -0.01254975 | ... T41: =T40/O40-1 -> -0.025317247 | U41: 0.03 | V41: =V40/Q40-1 -> -0.009136946 | W41: 0.111 | X41: 0.101 | Y41: 0.097 | Z41: 0.081 | AA41: =AA40/V40-1 -> 0.09633476 | AB41: 0.03 | AC41: 0.03 | AD41: 0.03
B43: SG&A | C43: =50+2+87-2 -> 137 | D43: =50+1+88-3 -> 136 | E43: =45+5+91-1 -> 140 | F43: =66+4+116-4 -> 182 | G43: =SUM(C43:F43) -> 595 | H43: =51+3+93-2 -> 145 | I43: =53+6+89-1 -> 147 | J43: =51+5+91-4 -> 143 | K43: =66+1+116-4 -> 179 | L43: =SUM(H43:K43) -> 614 | M43: =52+5+90-4 -> 143 | N43: =50+5+91-3 -> 143 | O43: =51+9+89-3 -> 146 | P43: =66+15+120-6 -> 195 | Q43: =SUM(M43:P43) -> 627 | R43: =55+11+89 -> 155 | S43: =54+10+90-3 -> 151 | T43: =50+11+89-4 -> 146 | U43: =U40*U44 -> 185.44329 | V43: =SUM(R43:U43) -> 637.44329 | W43: =W40*W44 -> 158.54321 | X43: =X40*X44 -> 160.77065 | Y43: =Y40*Y44 -> 157.59959 | Z43: =Z40*Z44 -> 202.28732 | AA43: =SUM(W43:Z43) -> 679.20077 | AB43: =AB40*AB44 -> 704.14969 | AC43: =AC40*AC44 -> 728.9545 | AD43: =AD40*AD44 -> 746.01115
...

Sheet Assumptions
A1: =CoName -> Yum Brands Inc. | C1: Hist. | D1: Hist. | E1: Hist. | F1: Proj. | G1: Proj. | H1: Proj. | I1: Proj. | J1: Proj.
A2: * | B2: Income Statement | C2: 2022 | D2: =C2+1 -> 2023 | E2: =D2+1 -> 2024 | F2: =E2+1 -> 2025 | G2: =F2+1 -> 2026 | H2: =G2+1 -> 2027 | I2: =H2+1 -> 2028 | J2: =I2+1 -> 2029
B4: Operating Case | D4: 1
D5: Variance
B6: Street Case | D6: 0 | F6: ='Quarterly Projections'!V49 -> 0.097760061 | G6: ='Quarterly Projections'!AA49 -> 0.096054779 | H6: ='Quarterly Projections'!AB49 -> 0.086276867 | I6: ='Quarterly Projections'!AC49 -> 0.077962175 | J6: ='Quarterly Projections'!AD49 -> 0.069457697
B7: Optimistic Case | D7: 0.025 | F7: =F6+$D$7 -> 0.12276006 | G7: =G6+$D$7 -> 0.12105478 | H7: =H6+$D$7 -> 0.11127687 | I7: =I6+$D$7 -> 0.10296218 | J7: =J6+$D$7 -> 0.094457697
B8: Pessimistic Case | D8: -0.025 | F8: =F6+$D$8 -> 0.072760061 | G8: =G6+$D$8 -> 0.071054779 | H8: =H6+$D$8 -> 0.061276867 | I8: =I6+$D$8 -> 0.052962175 | J8: =J6+$D$8 -> 0.044457697
B10: Revenue Growth | D10: ='Quarterly Projections'!L49 -> 0.035500639 | E10: ='Quarterly Projections'!Q49 -> 0.074576305 | F10: =CHOOSE(ScenarioREV,F6,F7,F8) -> 0.097760061 | G10: =CHOOSE(ScenarioREV,G6,G7,G8) -> 0.096054779 | H10: =CHOOSE(ScenarioREV,H6,H7,H8) -> 0.086276867 | I10: =CHOOSE(ScenarioREV,I6,I7,I8) -> 0.077962175 | J10: =CHOOSE(ScenarioREV,J6,J7,J8) -> 0.069457697
B11: COGS % of sales | F11: ='Quarterly Projections'!V51 -> 0.24301426 | G11: ='Quarterly Projections'!AA51 -> 0.24139362 | H11: ='Quarterly Projections'!AB51 -> 0.24348984 | I11: ='Quarterly Projections'!AC51 -> 0.24469499 | J11: ='Quarterly Projections'!AD51 -> 0.24606299
B12: SG&A % of sales | F12: ='Quarterly Projections'!V53 -> 0.35704747 | G12: ='Quarterly Projections'!AA53 -> 0.35030608 | H12: ='Quarterly Projections'!AB53 -> 0.34872633 | I12: ='Quarterly Projections'!AC53 -> 0.34739176 | J12: ='Quarterly Projections'!AD53 -> 0.34557342
B13: Amortization $ Amt | F13: =E13 -> 0 | G13: =F13 -> 0 | H13: =G13 -> 0 | I13: =H13 -> 0 | J13: =I13 -> 0
B14: Non recurring income / (expense) | F14: 0 | G14: 0 | H14: 0 | I14: 0 | J14: 0
B15: Other Income / (expense) | F15: 0 | G15: 0 | H15: 0 | I15: 0 | J15: 0
B16: Effective tax rate | C16: =IncState!C33/IncState!C31 -> 0.17548897 | D16: =IncState!D33/IncState!D31 -> 0.10330086 | E16: =IncState!E33/IncState!E31 -> 0.17865105 | F16: =E16 -> 0.17865105 | G16: =F16 -> 0.17865105 | H16: =G16 -> 0.17865105 | I16: =H16 -> 0.17865105 | J16: =I16 -> 0.17865105
B17: Dividend Payout Rate | C17: =IncState!C35 -> 2.2692308 | D17: =IncState!D35 -> 2.4128114 | E17: =IncState!E35 -> 2.6666667 | F17: =E17+(E17-D17) -> 2.9205219 | G17: =F17+(F17-E17) -> 3.1743772 | H17: =G17+(G17-F17) -> 3.4282325 | I17: =H17+(H17-G17) -> 3.6820878 | J17: =I17+(I17-H17) -> 3.9359431
B18: Basic WASO | C18: =IncState!C38 -> 286 | D18: =IncState!D38 -> 281 | E18: =IncState!E38 -> 282 | F18: =E18 -> 282 | G18: =F18 -> 282 | H18: =G18 -> 282 | I18: =H18 -> 282 | J18: =I18 -> 282
B19: Diluted WASO | C19: =IncState!C39 -> 290 | D19: =IncState!D39 -> 285 | E19: =IncState!E39 -> 285 | F19: =E19 -> 285 | G19: =F19 -> 285 | H19: =G19 -> 285 | I19: =H19 -> 285 | J19: =I19 -> 285
A21: * | B21: Debt | C21: =C2 -> 2022 | D21: =D2 -> 2023 | E21: =E2 -> 2024 | F21: =F2 -> 2025 | G21: =G2 -> 2026 | H21: =H2 -> 2027 | I21: =I2 -> 2028 | J21: =J2 -> 2029
B23: Interest rate on Revolver | E23: =E24+2% -> 0.0648 | F23: =E23 -> 0.0648 | G23: =F23 -> 0.0648 | H23: =G23 -> 0.0648 | I23: =H23 -> 0.0648 | J23: =I23 -> 0.0648
B24: Interest rate on long-term debt | E24: 0.0448 | F24: =E24 -> 0.0448 | G24: =F24 -> 0.0448 | H24: =G24 -> 0.0448 | I24: =H24 -> 0.0448 | J24: =I24 -> 0.0448
B25: Interest rate on cash | E25: =IncState!E28/SUM(BalSheet!E16:E17) -> 0.034090909 | F25: =E25 -> 0.034090909 | G25: =F25 -> 0.034090909 | H25: =G25 -> 0.034090909 | I25: =H25 -> 0.034090909 | J25: =I25 -> 0.034090909
B27: Issuance of long-term debt | E27: 0 | F27: 0 | G27: 0 | H27: 0 | I27: 0 | J27: 0
B28: Repayment of long-term debt | E28: 0 | F28: 0 | G28: 0 | H28: 0 | I28: 0 | J28: 0
A30: * | B30: Calcs | C30: =C21 -> 2022 | D30: =D21 -> 2023 | E30: =E21 -> 2024 | F30: =F21 -> 2025 | G30: =G21 -> 2026 | H30: =H21 -> 2027 | I30: =I21 -> 2028 | J30: =J21 -> 2029
B32: CapEx % of Sales | C32: =279/IncState!C16 -> 0.044608962 | D32: =285/IncState!D16 -> 0.044006051 | E32: =257/IncState!E16 -> 0.036928648 | F32: =275/IncState!F16 -> 0.035996108 | G32: =275/IncState!G16 -> 0.032841523 | H32: =275/IncState!H16 -> 0.030233105 | I32: =275/IncState!I16 -> 0.028046536 | J32: =275/IncState!J16 -> 0.026225008
B33: Depreciation % of beginning PP&E | D33: =IncState!D21/BalSheet!C22 -> 0.011101623 | E33: =IncState!E21/BalSheet!D22 -> 0.010025063 | F33: 0.05 | G33: =F33 -> 0.05 | H33: =G33 -> 0.05 | I33: =H33 -> 0.05 | J33: =I33 -> 0.05
B34: Share issuance / (repurchases) | F34: 0 | G34: 0 | H34: 0 | I34: 0 | J34: 0
A36: * | B36: Shareholder information | C36: =C30 -> 2022 | D36: =D30 -> 2023 | E36: =E30 -> 2024 | F36: =F30 -> 2025 | G36: =G30 -> 2026 | H36: =H30 -> 2027 | I36: =I30 -> 2028 | J36: =J30 -> 2029
B38: =B17 -> Dividend Payout Rate | C38: =C17 -> 2.2692308 | D38: =D17 -> 2.4128114 | E38: =E17 -> 2.6666667 | F38: =F17 -> 2.9205219 | G38: =G17 -> 3.1743772 | H38: =H17 -> 3.4282325 | I38: =I17 -> 3.6820878 | J38: =J17 -> 3.9359431
B39: Basic WASO | C39: =C18 -> 286 | D39: =D18 -> 281 | E39: =E18 -> 282 | F39: =F18 -> 282 | G39: =G18 -> 282 | H39: =H18 -> 282 | I39: =I18 -> 282 | J39: =J18 -> 282
B40: Diluted WASO | C40: =C19 -> 290 | D40: =D19 -> 285 | E40: =E19 -> 285 | F40: =F19 -> 285 | G40: =G19 -> 285 | H40: =H19 -> 285 | I40: =I19 -> 285 | J40: =J19 -> 285
A42: * | B42: Balance Sheet - Assets | C42: =C36 -> 2022 | D42: =D36 -> 2023 | E42: =E36 -> 2024 | F42: =F36 -> 2025 | G42: =G36 -> 2026 | H42: =H36 -> 2027 | I42: =I36 -> 2028 | J42: =J36 -> 2029
B44: Operating Cash % of sales | C44: =BalSheet!C16/IncState!C16 -> 0.05 | D44: =BalSheet!D16/IncState!D16 -> 0.05 | E44: =BalSheet!E16/IncState!E16 -> 0.05 | F44: =E44 -> 0.05 | G44: =F44 -> 0.05 | H44: =G44 -> 0.05 | I44: =H44 -> 0.05 | J44: =I44 -> 0.05
B45: Accounts receivable % of sales | C45: =BalSheet!C18/IncState!C16 -> 0.10360791 | D45: =BalSheet!D18/IncState!D16 -> 0.1137981 | E45: =BalSheet!E18/IncState!E16 -> 0.11136071 | F45: =E45 -> 0.11136071 | G45: =F45 -> 0.11136071 | H45: =G45 -> 0.11136071 | I45: =H45 -> 0.11136071 | J45: =I45 -> 0.11136071
B46: Other current assets % of sales | C46: =BalSheet!C19/IncState!C16 -> 0.094973919 | D46: =BalSheet!D19/IncState!D16 -> 0.055586591 | E46: =BalSheet!E19/IncState!E16 -> 0.068971793 | F46: =E46 -> 0.068971793 | G46: =F46 -> 0.068971793 | H46: =G46 -> 0.068971793 | I46: =H46 -> 0.068971793 | J46: =I46 -> 0.068971793
B48: Investments in unconsolidated entities | C48: =BalSheet!C24 -> 0 | D48: =BalSheet!D24 -> 0 | E48: =BalSheet!E24 -> 0 | F48: =E48 -> 0 | G48: =F48 -> 0 | H48: =G48 -> 0 | I48: =H48 -> 0 | J48: =I48 -> 0
B49: Other long-term assets % of sales | C49: =BalSheet!C25/IncState!C16 -> 0.33160927 | D49: =BalSheet!D25/IncState!D16 -> 0.37150372 | E49: =BalSheet!E25/IncState!E16 -> 0.34485897 | F49: =E49 -> 0.34485897 | G49: =F49 -> 0.34485897 | H49: =G49 -> 0.34485897 | I49: =H49 -> 0.34485897 | J49: =I49 -> 0.34485897
A51: * | B51: Balance Sheet - Liabilities | C51: =C42 -> 2022 | D51: =D42 -> 2023 | E51: =E42 -> 2024 | F51: =F42 -> 2025 | G51: =G42 -> 2026 | H51: =H42 -> 2027 | I51: =I42 -> 2028 | J51: =J42 -> 2029
B53: Accounts payable % of COGS | C53: =BalSheet!C31/IncState!C17 -> 1.0494966 | D53: =BalSheet!D31/IncState!D17 -> 0.94732577 | E53: =BalSheet!E31/IncState!E17 -> 0.76888889 | F53: =E53 -> 0.76888889 | G53: =F53 -> 0.76888889 | H53: =G53 -> 0.76888889 | I53: =H53 -> 0.76888889 | J53: =I53 -> 0.76888889
B54: Other current liabilities % of sales | C54: =BalSheet!C32/IncState!C16 -> 0.00255822 | D54: =BalSheet!D32/IncState!D16 -> 0.0084923959 | E54: =BalSheet!E32/IncState!E16 -> 0.0044544283 | F54: =E54 -> 0.0044544283 | G54: =F54 -> 0.0044544283 | H54: =G54 -> 0.0044544283 | I54: =H54 -> 0.0044544283 | J54: =I54 -> 0.0044544283
...

Sheet Calcs
A1: =CoName -> Yum Brands Inc. | C1: Hist. | D1: Hist. | E1: Hist. | F1: Proj. | G1: Proj. | H1: Proj. | I1: Proj. | J1: Proj.
A2: Net PP&E | C2: 2022 | D2: =C2+1 -> 2023 | E2: =D2+1 -> 2024 | F2: =E2+1 -> 2025 | G2: =F2+1 -> 2026 | H2: =G2+1 -> 2027 | I2: =H2+1 -> 2028 | J2: =I2+1 -> 2029
B3: Capital expenditure % of sales | F3: =Assumptions!F32 -> 0.035996108 | G3: =Assumptions!G32 -> 0.032841523 | H3: =Assumptions!H32 -> 0.030233105 | I3: =Assumptions!I32 -> 0.028046536 | J3: =Assumptions!J32 -> 0.026225008
B4: Depreciation % of PP&E | F4: =Assumptions!F33 -> 0.05 | G4: =F4 -> 0.05 | H4: =G4 -> 0.05 | I4: =H4 -> 0.05 | J4: =I4 -> 0.05
B6: Beginning PP&E | F6: =E9 -> 1304 | G6: =F9 -> 1513.8 | H6: =G9 -> 1713.11 | I6: =H9 -> 1902.4545 | J6: =I9 -> 2082.3318
B7: Capex | F7: =F3*IncState!F16 -> 275 | G7: =G3*IncState!G16 -> 275 | H7: =H3*IncState!H16 -> 275 | I7: =I3*IncState!I16 -> 275 | J7: =J3*IncState!J16 -> 275
B8: Depreciation | F8: =F6*F4 -> 65.2 | G8: =G6*G4 -> 75.69 | H8: =H6*H4 -> 85.6555 | I8: =I6*I4 -> 95.122725 | J8: =J6*J4 -> 104.11659
B9: Ending PP&E | E9: =BalSheet!E22 -> 1304 | F9: =F6+F7-F8 -> 1513.8 | G9: =G6+G7-G8 -> 1713.11 | H9: =H6+H7-H8 -> 1902.4545 | I9: =I6+I7-I8 -> 2082.3318 | J9: =J6+J7-J8 -> 2253.2152
A10: Equity | C10: =C2 -> 2022 | D10: =D2 -> 2023 | E10: =E2 -> 2024 | F10: =F2 -> 2025 | G10: =G2 -> 2026 | H10: =H2 -> 2027 | I10: =I2 -> 2028 | J10: =J2 -> 2029
B11: Share issuance/(repurchases) | F11: =Assumptions!F34 -> 0 | G11: =Assumptions!G34 -> 0 | H11: =Assumptions!H34 -> 0 | I11: =Assumptions!I34 -> 0 | J11: =Assumptions!J34 -> 0
B13: Beginning balance | F13: =E17 -> -7648 | G13: =F17 -> -5962.0259 | H13: =G17 -> -4049.0728 | I13: =H17 -> -1969.2891 | J13: =I17 -> 277.46504
B14: Net income | F14: =IncState!F34 -> 2509.5613 | G14: =IncState!G34 -> 2808.1274 | H14: =IncState!H34 -> 3046.5453 | I14: =IncState!I34 -> 3285.1029 | J14: =IncState!J34 -> 3517.1573
B15: Dividends paid | F15: =-IncState!F36 -> -823.58719 | G15: =-IncState!G36 -> -895.17438 | H15: =-IncState!H36 -> -966.76157 | I15: =-IncState!I36 -> -1038.3488 | J15: =-IncState!J36 -> -1109.9359
B16: Share issuance / (repurchase) | F16: =F11 -> 0 | G16: =G11 -> 0 | H16: =H11 -> 0 | I16: =I11 -> 0 | J16: =J11 -> 0
B17: Ending balance | E17: =BalSheet!E39 -> -7648 | F17: =SUM(F13:F16) -> -5962.0259 | G17: =SUM(G13:G16) -> -4049.0728 | H17: =SUM(H13:H16) -> -1969.2891 | I17: =SUM(I13:I16) -> 277.46504 | J17: =SUM(J13:J16) -> 2684.6864
A18: OWC | C18: =C10 -> 2022 | D18: =D10 -> 2023 | E18: =E10 -> 2024 | F18: =F10 -> 2025 | G18: =G10 -> 2026 | H18: =H10 -> 2027 | I18: =I10 -> 2028 | J18: =J10 -> 2029
B19: Operating Cash | E19: =BalSheet!E16 -> 347.96833 | F19: =BalSheet!F16 -> 381.98574 | G19: =BalSheet!G16 -> 418.6773 | H19: =BalSheet!H16 -> 454.79946 | I19: =BalSheet!I16 -> 490.25662 | J19: =BalSheet!J16 -> 524.30871
B20: =BalSheet!B18 -> Accounts receivable | E20: =BalSheet!E18 -> 775 | F20: =BalSheet!F18 -> 850.76405 | G20: =BalSheet!G18 -> 932.484 | H20: =BalSheet!H18 -> 1012.9358 | I20: =BalSheet!I18 -> 1091.9065 | J20: =BalSheet!J18 -> 1167.7478
B21: Other current assets | E21: =BalSheet!E19 -> 480 | F21: =BalSheet!F19 -> 526.92483 | G21: =BalSheet!G19 -> 577.53848 | H21: =BalSheet!H19 -> 627.36669 | I21: =BalSheet!I19 -> 676.27756 | J21: =BalSheet!J19 -> 723.25024
B22: Accounts payables | E22: =BalSheet!E31 -> 1211 | F22: =BalSheet!F31 -> 1427.4881 | G22: =BalSheet!G31 -> 1554.1709 | H22: =BalSheet!H31 -> 1702.9205 | I22: =BalSheet!I31 -> 1844.7696 | J22: =BalSheet!J31 -> 1983.9327
B23: Other current liabilities | E23: =BalSheet!E32 -> 31 | F23: =BalSheet!F32 -> 34.030562 | G23: =BalSheet!G32 -> 37.29936 | H23: =BalSheet!H32 -> 40.517432 | I23: =BalSheet!I32 -> 43.676259 | J23: =BalSheet!J32 -> 46.709911
A24: * | B24: OWC | E24: =SUM(E19:E21)-SUM(E22:E23) -> 360.96833 | F24: =SUM(F19:F21)-SUM(F22:F23) -> 298.15599 | G24: =SUM(G19:G21)-SUM(G22:G23) -> 337.22949 | H24: =SUM(H19:H21)-SUM(H22:H23) -> 351.66403 | I24: =SUM(I19:I21)-SUM(I22:I23) -> 369.99484 | J24: =SUM(J19:J21)-SUM(J22:J23) -> 384.66409
B25: Change in OWC | F25: =E24-F24 -> 62.812345 | G25: =F24-G24 -> -39.073499 | H25: =G24-H24 -> -14.434545 | I25: =H24-I24 -> -18.330807 | J25: =I24-J24 -> -14.669251

Sheet Debt
A1: =CoName -> Yum Brands Inc. | C1: Hist. | D1: Hist. | E1: Hist. | F1: Proj. | G1: Proj. | H1: Proj. | I1: Proj. | J1: Proj.
A2: Assumptions | C2: 2022 | D2: =C2+1 -> 2023 | E2: =D2+1 -> 2024 | F2: =E2+1 -> 2025 | G2: =F2+1 -> 2026 | H2: =G2+1 -> 2027 | I2: =H2+1 -> 2028 | J2: =I2+1 -> 2029
B4: Interest rate on revolver | F4: =Assumptions!F23 -> 0.0648 | G4: =Assumptions!G23 -> 0.0648 | H4: =Assumptions!H23 -> 0.0648 | I4: =Assumptions!I23 -> 0.0648 | J4: =Assumptions!J23 -> 0.0648
B5: Interest rate on long-term debt | F5: =Assumptions!F24 -> 0.0448 | G5: =Assumptions!G24 -> 0.0448 | H5: =Assumptions!H24 -> 0.0448 | I5: =Assumptions!I24 -> 0.0448 | J5: =Assumptions!J24 -> 0.0448
B6: Interest rate on cash | F6: =Assumptions!F25 -> 0.034090909 | G6: =Assumptions!G25 -> 0.034090909 | H6: =Assumptions!H25 -> 0.034090909 | I6: =Assumptions!I25 -> 0.034090909 | J6: =Assumptions!J25 -> 0.034090909
B8: Issuance of long-term debt | F8: =Assumptions!F27 -> 0 | G8: =Assumptions!G27 -> 0 | H8: =Assumptions!H27 -> 0 | I8: =Assumptions!I27 -> 0 | J8: =Assumptions!J27 -> 0
B9: Repayment of long-term debt | F9: =Assumptions!F28 -> 0 | G9: =Assumptions!G28 -> 0 | H9: =Assumptions!H28 -> 0 | I9: =Assumptions!I28 -> 0 | J9: =Assumptions!J28 -> 0
A11: Revolver | C11: =C2 -> 2022 | D11: =D2 -> 2023 | E11: =E2 -> 2024 | F11: =F2 -> 2025 | G11: =G2 -> 2026 | H11: =H2 -> 2027 | I11: =I2 -> 2028 | J11: =J2 -> 2029
B12: Balance | E12: =IncState!E28 -> 21 | F12: =IncState!F28 -> 0 | G12: =IncState!G28 -> 0 | H12: =IncState!H28 -> 0 | I12: =IncState!I28 -> 0 | J12: =IncState!J28 -> 0
B13: Interest rate | F13: =F4 -> 0.0648 | G13: =G4 -> 0.0648 | H13: =H4 -> 0.0648 | I13: =I4 -> 0.0648 | J13: =J4 -> 0.0648
B14: Interest expense | F14: =F12*F13 -> 0 | G14: =G12*G13 -> 0 | H14: =H12*H13 -> 0 | I14: =I12*I13 -> 0 | J14: =J12*J13 -> 0
A16: Long term debt | C16: =C11 -> 2022 | D16: =D11 -> 2023 | E16: =E11 -> 2024 | F16: =F11 -> 2025 | G16: =G11 -> 2026 | H16: =H11 -> 2027 | I16: =I11 -> 2028 | J16: =J11 -> 2029
B17: Beginning balance | F17: =E20 -> 11306 | G17: =F20 -> 11306 | H17: =G20 -> 11306 | I17: =H20 -> 11306 | J17: =I20 -> 11306
B18: Issuance | F18: =F8 -> 0 | G18: =G8 -> 0 | H18: =H8 -> 0 | I18: =I8 -> 0 | J18: =J8 -> 0
B19: Repayment | F19: =F9 -> 0 | G19: =G9 -> 0 | H19: =H9 -> 0 | I19: =I9 -> 0 | J19: =J9 -> 0
B20: Ending balance | E20: =BalSheet!E35 -> 11306 | F20: =SUM(F17:F19) -> 11306 | G20: =SUM(G17:G19) -> 11306 | H20: =SUM(H17:H19) -> 11306 | I20: =SUM(I17:I19) -> 11306 | J20: =SUM(J17:J19) -> 11306
B21: Interest rate | F21: =F5 -> 0.0448 | G21: =G5 -> 0.0448 | H21: =H5 -> 0.0448 | I21: =I5 -> 0.0448 | J21: =J5 -> 0.0448
B22: Interest expense | F22: =F20*F21 -> 506.5088 | G22: =G20*G21 -> 506.5088 | H22: =H20*H21 -> 506.5088 | I22: =I20*I21 -> 506.5088 | J22: =J20*J21 -> 506.5088
A24: Debt summary | C24: =C16 -> 2022 | D24: =D16 -> 2023 | E24: =E16 -> 2024 | F24: =F16 -> 2025 | G24: =G16 -> 2026 | H24: =H16 -> 2027 | I24: =I16 -> 2028 | J24: =J16 -> 2029
B25: Revolver | F25: =F12 -> 0 | G25: =G12 -> 0 | H25: =H12 -> 0 | I25: =I12 -> 0 | J25: =J12 -> 0
B26: Total long term debt | F26: =F20 -> 11306 | G26: =G20 -> 11306 | H26: =H20 -> 11306 | I26: =I20 -> 11306 | J26: =J20 -> 11306
B27: Total debt | F27: =SUM(F25:F26) -> 11306 | G27: =SUM(G25:G26) -> 11306 | H27: =SUM(H25:H26) -> 11306 | I27: =SUM(I25:I26) -> 11306 | J27: =SUM(J25:J26) -> 11306
B28: Total interest expense | F28: =F22 -> 506.5088 | G28: =G22 -> 506.5088 | H28: =H22 -> 506.5088 | I28: =I22 -> 506.5088 | J28: =J22 -> 506.5088
A30: Interest income | C30: =C11 -> 2022 | D30: =D11 -> 2023 | E30: =E11 -> 2024 | F30: =F11 -> 2025 | G30: =G11 -> 2026 | H30: =H11 -> 2027 | I30: =I11 -> 2028 | J30: =J11 -> 2029
B31: Excess Cash | F31: =BalSheet!F17 -> 1721.3621 | G31: =BalSheet!G17 -> 3332.6646 | H31: =BalSheet!H17 -> 5146.384 | I31: =BalSheet!I17 -> 7133.7915 | J31: =BalSheet!J17 -> 9296.7443
B32: Interest rate | F32: =F6 -> 0.034090909 | G32: =G6 -> 0.034090909 | H32: =H6 -> 0.034090909 | I32: =I6 -> 0.034090909 | J32: =J6 -> 0.034090909
B33: Interest income | F33: =F31*F32 -> 58.682799 | G33: =G31*G32 -> 113.61357 | H33: =H31*H32 -> 175.44491 | I33: =I31*I32 -> 243.19744 | J33: =J31*J32 -> 316.93447

Sheet IncState
A1: =CoName -> Yum Brands Inc. | C1: Hist. | D1: Hist. | E1: Hist. | F1: Proj. | G1: Proj. | H1: Proj. | I1: Proj. | J1: Proj.
A2: Assumptions | C2: 2022 | D2: =C2+1 -> 2023 | E2: =D2+1 -> 2024 | F2: =E2+1 -> 2025 | G2: =F2+1 -> 2026 | H2: =G2+1 -> 2027 | I2: =H2+1 -> 2028 | J2: =I2+1 -> 2029
B4: Revenue growth | F4: =Assumptions!F10 -> 0.097760061 | G4: =Assumptions!G10 -> 0.096054779 | H4: =Assumptions!H10 -> 0.086276867 | I4: =Assumptions!I10 -> 0.077962175 | J4: =Assumptions!J10 -> 0.069457697
B5: Cost of goods sold as % of sales | F5: =Assumptions!F11 -> 0.24301426 | G5: =Assumptions!G11 -> 0.24139362 | H5: =Assumptions!H11 -> 0.24348984 | I5: =Assumptions!I11 -> 0.24469499 | J5: =Assumptions!J11 -> 0.24606299
B6: SG&A % of sales | F6: =Assumptions!F12 -> 0.35704747 | G6: =Assumptions!G12 -> 0.35030608 | H6: =Assumptions!H12 -> 0.34872633 | I6: =Assumptions!I12 -> 0.34739176 | J6: =Assumptions!J12 -> 0.34557342
B7: Amortization amount | F7: =Assumptions!F13 -> 0 | G7: =Assumptions!G13 -> 0 | H7: =Assumptions!H13 -> 0 | I7: =Assumptions!I13 -> 0 | J7: =Assumptions!J13 -> 0
B8: Non recurring items, amount | F8: =Assumptions!F14 -> 0 | G8: =Assumptions!G14 -> 0 | H8: =Assumptions!H14 -> 0 | I8: =Assumptions!I14 -> 0 | J8: =Assumptions!J14 -> 0
B9: Other income (expense), amt | F9: =Assumptions!F15 -> 0 | G9: =Assumptions!G15 -> 0 | H9: =Assumptions!H15 -> 0 | I9: =Assumptions!I15 -> 0 | J9: =Assumptions!J15 -> 0
B10: Effective tax rate | F10: =Assumptions!F16 -> 0.17865105 | G10: =Assumptions!G16 -> 0.17865105 | H10: =Assumptions!H16 -> 0.17865105 | I10: =Assumptions!I16 -> 0.17865105 | J10: =Assumptions!J16 -> 0.17865105
B11: Dividend Payout Rate | F11: =Assumptions!F17 -> 2.9205219 | G11: =Assumptions!G17 -> 3.1743772 | H11: =Assumptions!H17 -> 3.4282325 | I11: =Assumptions!I17 -> 3.6820878 | J11: =Assumptions!J17 -> 3.9359431
B12: Basic WASO | F12: =Assumptions!F18 -> 282 | G12: =Assumptions!G18 -> 282 | H12: =Assumptions!H18 -> 282 | I12: =Assumptions!I18 -> 282 | J12: =Assumptions!J18 -> 282
B13: Diluted WASO | F13: =Assumptions!F19 -> 285 | G13: =Assumptions!G19 -> 285 | H13: =Assumptions!H19 -> 285 | I13: =Assumptions!I19 -> 285 | J13: =Assumptions!J19 -> 285
A15: Income statement | C15: =C37 -> 44926 | D15: =D37 -> 45291 | E15: =E37 -> 45657 | F15: =F37 -> 46022 | G15: =G37 -> 46022 | H15: =H37 -> 46022 | I15: =I37 -> 46022 | J15: =J37 -> 46022
B16: Revenue | C16: ='Quarterly Projections'!G48 -> 6254.3487 | D16: ='Quarterly Projections'!L48 -> 6476.382 | E16: ='Quarterly Projections'!Q48 -> 6959.3667 | F16: =E16*(1+F4) -> 7639.7148 | G16: =F16*(1+G4) -> 8373.5459 | H16: =G16*(1+H4) -> 9095.9892 | I16: =H16*(1+I4) -> 9805.1323 | J16: =I16*(1+J4) -> 10486.174
B17: COGS | C17: ='Quarterly Projections'!G50 -> 1192 | D17: ='Quarterly Projections'!L50 -> 1234 | E17: ='Quarterly Projections'!Q50 -> 1575 | F17: =F16*F5 -> 1856.5596 | G17: =G16*G5 -> 2021.3206 | H17: =H16*H5 -> 2214.781 | I17: =I16*I5 -> 2399.2668 | J17: =J16*J5 -> 2580.2593
B18: SG&A | C18: ='Quarterly Projections'!G52 -> 2626 | D18: ='Quarterly Projections'!L52 -> 2597 | E18: ='Quarterly Projections'!Q52 -> 2599 | F18: =F16*F6 -> 2727.7409 | G18: =G16*G6 -> 2933.304 | H18: =H16*H6 -> 3172.0109 | I18: =I16*I6 -> 3406.2222 | J18: =J16*J6 -> 3623.7431
A19: * | B19: EBIT | C19: =C16-SUM(C17:C18) -> 2436.3487 | D19: =D16-SUM(D17:D18) -> 2645.382 | E19: =E16-SUM(E17:E18) -> 2785.3667 | F19: =F16-SUM(F17:F18) -> 3055.4143 | G19: =G16-SUM(G17:G18) -> 3418.9213 | H19: =H16-SUM(H17:H18) -> 3709.1973 | I19: =I16-SUM(I17:I18) -> 3999.6434 | J19: =J16-SUM(J17:J18) -> 4282.1718
B21: Depreciation | C21: 10 | D21: 13 | E21: 12 | F21: =Calcs!F8 -> 65.2 | G21: =Calcs!G8 -> 75.69 | H21: =Calcs!H8 -> 85.6555 | I21: =Calcs!I8 -> 95.122725 | J21: =Calcs!J8 -> 104.11659
B22: Amortization | C22: 0 | D22: 0 | E22: 0 | F22: =F7 -> 0 | G22: =G7 -> 0 | H22: =H7 -> 0 | I22: =I7 -> 0 | J22: =J7 -> 0
A23: * | B23: EBITDA | C23: =SUM(C19,C21:C22) -> 2446.3487 | D23: =SUM(D19,D21:D22) -> 2658.382 | E23: =SUM(E19,E21:E22) -> 2797.3667 | F23: =SUM(F19,F21:F22) -> 3120.6143 | G23: =SUM(G19,G21:G22) -> 3494.6113 | H23: =SUM(H19,H21:H22) -> 3794.8528 | I23: =SUM(I19,I21:I22) -> 4094.7661 | J23: =SUM(J19,J21:J22) -> 4386.2884
B25: Non-recurring items | C25: 0 | D25: 0 | E25: 0 | F25: =F8 -> 0 | G25: =G8 -> 0 | H25: =H8 -> 0 | I25: =I8 -> 0 | J25: =J8 -> 0
B26: Other income (expense) | C26: 0 | D26: 0 | E26: 0 | F26: =F9 -> 0 | G26: =G9 -> 0 | H26: =H9 -> 0 | I26: =I9 -> 0 | J26: =J9 -> 0
B28: Interest income | C28: 11 | D28: 7 | E28: 21 | F28: =IF(circ=1,Debt!F33,0) -> 0 | G28: =IF(circ=1,Debt!G33,0) -> 0 | H28: =IF(circ=1,Debt!H33,0) -> 0 | I28: =IF(circ=1,Debt!I33,0) -> 0 | J28: =IF(circ=1,Debt!J33,0) -> 0
B29: Interest expense | C29: -527 | D29: -513 | E29: -489 | F29: =IF(circ=1,Debt!F1-Debt!F28,0) -> 0 | G29: =IF(circ=1,Debt!G1-Debt!G28,0) -> 0 | H29: =IF(circ=1,Debt!H1-Debt!H28,0) -> 0 | I29: =IF(circ=1,Debt!I1-Debt!I28,0) -> 0 | J29: =IF(circ=1,Debt!J1-Debt!J28,0) -> 0
A31: * | B31: Pretax Income | C31: =C19+SUM(C26:C29) -> 1920.3487 | D31: =D19+SUM(D26:D29) -> 2139.382 | E31: =E19+SUM(E25:E29) -> 2317.3667 | F31: =F19+SUM(F25:F29) -> 3055.4143 | G31: =G19+SUM(G25:G29) -> 3418.9213 | H31: =H19+SUM(H25:H29) -> 3709.1973 | I31: =I19+SUM(I25:I29) -> 3999.6434 | J31: =J19+SUM(J25:J29) -> 4282.1718
B33: Tax expense | C33: 337 | D33: 221 | E33: 414 | F33: =F31*F10 -> 545.85298 | G33: =G31*G10 -> 610.7939 | H33: =H31*H10 -> 662.65201 | I33: =I31*I10 -> 714.54051 | J33: =J31*J10 -> 765.01451
A34: * | B34: Net income | C34: =C31-C33 -> 1583.3487 | D34: =D31-D33 -> 1918.382 | E34: =E31-E33 -> 1903.3667 | F34: =F31-F33 -> 2509.5613 | G34: =G31-G33 -> 2808.1274 | H34: =H31-H33 -> 3046.5453 | I34: =I31-I33 -> 3285.1029 | J34: =J31-J33 -> 3517.1573
B35: Dividend payout rate | C35: =C36/C38 -> 2.2692308 | D35: =D36/D38 -> 2.4128114 | E35: =E36/E38 -> 2.6666667 | F35: =F11 -> 2.9205219 | G35: =G11 -> 3.1743772 | H35: =H11 -> 3.4282325 | I35: =I11 -> 3.6820878 | J35: =J11 -> 3.9359431
B36: Dividends | C36: 649 | D36: 678 | E36: 752 | F36: =F35*(F38) -> 823.58719 | G36: =G35*(G38) -> 895.17438 | H36: =H35*(H38) -> 966.76157 | I36: =I35*(I38) -> 1038.3488 | J36: =J35*(J38) -> 1109.9359
A37: Shareholder information | C37: 44926 | D37: 45291 | E37: 45657 | F37: 46022 | G37: 46022 | H37: 46022 | I37: 46022 | J37: 46022
B38: Basic WASO | C38: 286 | D38: 281 | E38: 282 | F38: =F12 -> 282 | G38: =G12 -> 282 | H38: =H12 -> 282 | I38: =I12 -> 282 | J38: =J12 -> 282
B39: Diluted WASO | C39: 290 | D39: 285 | E39: 285 | F39: =F13 -> 285 | G39: =G13 -> 285 | H39: =H13 -> 285 | I39: =I13 -> 285 | J39: =J13 -> 285
B40: Basic earnings per share | C40: =C34/C38 -> 5.5361841 | D40: =D34/D38 -> 6.8269823 | E40: =E34/E38 -> 6.7495272 | F40: =F34/F38 -> 8.8991536 | G40: =G34/G38 -> 9.9578987 | H40: =H34/H38 -> 10.803352 | I40: =I34/I38 -> 11.649301 | J40: =J34/J38 -> 12.472189
A41: * | B41: Diluted earnings per share | C41: =C34/C39 -> 5.459823 | D41: =D34/D39 -> 6.731165 | E41: =E34/E39 -> 6.6784796 | F41: =F34/F39 -> 8.8054783 | G41: =G34/G39 -> 9.8530787 | H41: =H34/H39 -> 10.689633 | I41: =I34/I39 -> 11.526677 | J41: =J34/J39 -> 12.340903

Sheet BalSheet
A1: =CoName -> Yum Brands Inc. | C1: Hist. | D1: Hist. | E1: Hist. | F1: Proj. | G1: Proj. | H1: Proj. | I1: Proj. | J1: Proj.
A2: Assumptions | C2: 2022 | D2: =C2+1 -> 2023 | E2: =D2+1 -> 2024 | F2: =E2+1 -> 2025 | G2: =F2+1 -> 2026 | H2: =G2+1 -> 2027 | I2: =H2+1 -> 2028 | J2: =I2+1 -> 2029
B4: Operating Cash % of sales | F4: =Assumptions!F44 -> 0.05 | G4: =F4 -> 0.05 | H4: =G4 -> 0.05 | I4: =H4 -> 0.05 | J4: =I4 -> 0.05
B5: Accounts receivable % of sales | F5: =Assumptions!F45 -> 0.11136071 | G5: =Assumptions!G45 -> 0.11136071 | H5: =Assumptions!H45 -> 0.11136071 | I5: =Assumptions!I45 -> 0.11136071 | J5: =Assumptions!J45 -> 0.11136071
B6: Other current assets % of sales | F6: =Assumptions!F46 -> 0.068971793 | G6: =Assumptions!G46 -> 0.068971793 | H6: =Assumptions!H46 -> 0.068971793 | I6: =Assumptions!I46 -> 0.068971793 | J6: =Assumptions!J46 -> 0.068971793
B8: Other long-term assets % of sales | F8: =Assumptions!F49 -> 0.34485897 | G8: =Assumptions!G49 -> 0.34485897 | H8: =Assumptions!H49 -> 0.34485897 | I8: =Assumptions!I49 -> 0.34485897 | J8: =Assumptions!J49 -> 0.34485897
B9: Investment in unconsolidated entities $ balance | F9: =Assumptions!F48 -> 0 | G9: =Assumptions!G48 -> 0 | H9: =Assumptions!H48 -> 0 | I9: =Assumptions!I48 -> 0 | J9: =Assumptions!J48 -> 0
B11: Accounts payable/Accural % of COGS | F11: =Assumptions!F53 -> 0.76888889 | G11: =Assumptions!G53 -> 0.76888889 | H11: =Assumptions!H53 -> 0.76888889 | I11: =Assumptions!I53 -> 0.76888889 | J11: =Assumptions!J53 -> 0.76888889
B12: Other current liabilities % of sales | F12: =Assumptions!F54 -> 0.0044544283 | G12: =Assumptions!G54 -> 0.0044544283 | H12: =Assumptions!H54 -> 0.0044544283 | I12: =Assumptions!I54 -> 0.0044544283 | J12: =Assumptions!J54 -> 0.0044544283
B13: Other long-term liabilities % of sales | F13: =Assumptions!F55 -> 0.25864422 | G13: =Assumptions!G55 -> 0.25864422 | H13: =Assumptions!H55 -> 0.25864422 | I13: =Assumptions!I55 -> 0.25864422 | J13: =Assumptions!J55 -> 0.25864422
A15: Balance sheet | C15: =C2 -> 2022 | D15: =D2 -> 2023 | E15: =E2 -> 2024 | F15: =F2 -> 2025 | G15: =G2 -> 2026 | H15: =H2 -> 2027 | I15: =I2 -> 2028 | J15: =J2 -> 2029
B16: Operating Cash | C16: =5%*IncState!C16 -> 312.71743 | D16: =5%*IncState!D16 -> 323.8191 | E16: =5%*IncState!E16 -> 347.96833 | F16: =F4*IncState!F16 -> 381.98574 | G16: =G4*IncState!G16 -> 418.6773 | H16: =H4*IncState!H16 -> 454.79946 | I16: =I4*IncState!I16 -> 490.25662 | J16: =J4*IncState!J16 -> 524.30871
B17: Excess cash | C17: =367-C16 -> 54.282567 | D17: =512-D16 -> 188.1809 | E17: =616-E16 -> 268.03167 | F17: =MAX(CashFlow!F23,0) -> 1721.3621 | G17: =MAX(CashFlow!G23,0) -> 3332.6646 | H17: =MAX(CashFlow!H23,0) -> 5146.384 | I17: =MAX(CashFlow!I23,0) -> 7133.7915 | J17: =MAX(CashFlow!J23,0) -> 9296.7443
B18: Accounts receivable | C18: 648 | D18: 737 | E18: 775 | F18: =F5*IncState!F16 -> 850.76405 | G18: =G5*IncState!G16 -> 932.484 | H18: =H5*IncState!H16 -> 1012.9358 | I18: =I5*IncState!I16 -> 1091.9065 | J18: =J5*IncState!J16 -> 1167.7478
B19: Other current assets | C19: 594 | D19: 360 | E19: 480 | F19: =F6*IncState!F16 -> 526.92483 | G19: =G6*IncState!G16 -> 577.53848 | H19: =H6*IncState!H16 -> 627.36669 | I19: =I6*IncState!I16 -> 676.27756 | J19: =J6*IncState!J16 -> 723.25024
B20: Total current assets | C20: =SUM(C16:C19) -> 1609 | D20: =SUM(D16:D19) -> 1609 | E20: =SUM(E16:E19) -> 1871 | F20: =SUM(F16:F19) -> 3481.0367 | G20: =SUM(G16:G19) -> 5261.3644 | H20: =SUM(H16:H19) -> 7241.486 | I20: =SUM(I16:I19) -> 9392.2321 | J20: =SUM(J16:J19) -> 11712.051
B22: Property, plant & equipment, net | C22: 1171 | D22: 1197 | E22: 1304 | F22: =Calcs!F9 -> 1513.8 | G22: =Calcs!G9 -> 1713.11 | H22: =Calcs!H9 -> 1902.4545 | I22: =Calcs!I9 -> 2082.3318 | J22: =Calcs!J9 -> 2253.2152
B23: Intangible assets | C23: =638+354 -> 992 | D23: =642+377 -> 1019 | E23: =736+416 -> 1152 | F23: =E23-IncState!F22 -> 1152 | G23: =F23-IncState!G22 -> 1152 | H23: =G23-IncState!H22 -> 1152 | I23: =H23-IncState!I22 -> 1152 | J23: =I23-IncState!J22 -> 1152
B24: Investment in unconsolidated entities | C24: 0 | D24: 0 | E24: 0 | F24: =F9 -> 0 | G24: =G9 -> 0 | H24: =H9 -> 0 | I24: =I9 -> 0 | J24: =J9 -> 0
B25: Other assets | C25: =1324+750 -> 2074 | D25: =1361+1045 -> 2406 | E25: =1329+1071 -> 2400 | F25: =F8*IncState!F16 -> 2634.6241 | G25: =G8*IncState!G16 -> 2887.6924 | H25: =H8*IncState!H16 -> 3136.8334 | I25: =I8*IncState!I16 -> 3381.3878 | J25: =J8*IncState!J16 -> 3616.2512
B26: Total non-current assets | C26: =SUM(C22:C25) -> 4237 | D26: =SUM(D22:D25) -> 4622 | E26: =SUM(E22:E25) -> 4856 | F26: =SUM(F22:F25) -> 5300.4241 | G26: =SUM(G22:G25) -> 5752.8024 | H26: =SUM(H22:H25) -> 6191.2879 | I26: =SUM(I22:I25) -> 6615.7196 | J26: =SUM(J22:J25) -> 7021.4664
A28: * | B28: TOTAL ASSETS | C28: =SUM(C26,C20) -> 5846 | D28: =SUM(D26,D20) -> 6231 | E28: =SUM(E26,E20) -> 6727 | F28: =SUM(F26,F20) -> 8781.4609 | G28: =SUM(G26,G20) -> 11014.167 | H28: =SUM(H26,H20) -> 13432.774 | I28: =SUM(I26,I20) -> 16007.952 | J28: =SUM(J26,J20) -> 18733.517
B30: Revolver/Short term debt | C30: 398 | D30: 53 | E30: 27 | F30: =MIN(CashFlow!F23,0) -> 0 | G30: =MIN(CashFlow!G23,0) -> 0 | H30: =MIN(CashFlow!H23,0) -> 0 | I30: =MIN(CashFlow!I23,0) -> 0 | J30: =MIN(CashFlow!J23,0) -> 0
B31: Accounts payable/Accurals | C31: =1251 -> 1251 | D31: 1169 | E31: 1211 | F31: =F11*IncState!F17 -> 1427.4881 | G31: =G11*IncState!G17 -> 1554.1709 | H31: =H11*IncState!H17 -> 1702.9205 | I31: =I11*IncState!I17 -> 1844.7696 | J31: =J11*IncState!J17 -> 1983.9327
B32: Other current liabilities | C32: 16 | D32: 55 | E32: 31 | F32: =F12*IncState!F16 -> 34.030562 | G32: =G12*IncState!G16 -> 37.29936 | H32: =H12*IncState!H16 -> 40.517432 | I32: =I12*IncState!I16 -> 43.676259 | J32: =J12*IncState!J16 -> 46.709911
B33: Total current liabilities | C33: =SUM(C30:C32) -> 1665 | D33: =SUM(D30:D32) -> 1277 | E33: =SUM(E30:E32) -> 1269 | F33: =SUM(F30:F32) -> 1461.5186 | G33: =SUM(G30:G32) -> 1591.4703 | H33: =SUM(H30:H32) -> 1743.4379 | I33: =SUM(I30:I32) -> 1888.4458 | J33: =SUM(J30:J32) -> 2030.6426
B35: Long-term debt, including current maturities | C35: 11453 | D35: 11142 | E35: 11306 | F35: =Debt!F26 -> 11306 | G35: =Debt!G26 -> 11306 | H35: =Debt!H26 -> 11306 | I35: =Debt!I26 -> 11306 | J35: =Debt!J26 -> 11306
B36: Other long-term liabilities | C36: 1604 | D36: 1670 | E36: 1800 | F36: =F13*IncState!F16 -> 1975.9681 | G36: =G13*IncState!G16 -> 2165.7693 | H36: =H13*IncState!H16 -> 2352.6251 | I36: =I13*IncState!I16 -> 2536.0408 | J36: =J13*IncState!J16 -> 2712.1884
B37: Total non-current liabilities | C37: =SUM(C35:C36) -> 13057 | D37: =SUM(D35:D36) -> 12812 | E37: =SUM(E35:E36) -> 13106 | F37: =SUM(F35:F36) -> 13281.968 | G37: =SUM(G35:G36) -> 13471.769 | H37: =SUM(H35:H36) -> 13658.625 | I37: =SUM(I35:I36) -> 13842.041 | J37: =SUM(J35:J36) -> 14018.188
B39: Equity | C39: -8876 | D39: -7848 | E39: -7648 | F39: =Calcs!F17 -> -5962.0259 | G39: =Calcs!G17 -> -4049.0728 | H39: =Calcs!H17 -> -1969.2891 | I39: =Calcs!I17 -> 277.46504 | J39: =Calcs!J17 -> 2684.6864
A40: * | B40: TOTAL LIABILITIES & EQUITY | C40: =SUM(C39,C37,C33) -> 5846 | D40: =SUM(D39,D37,D33) -> 6241 | E40: =SUM(E39,E37,E33) -> 6727 | F40: =SUM(F39,F37,F33) -> 8781.4609 | G40: =SUM(G39,G37,G33) -> 11014.167 | H40: =SUM(H39,H37,H33) -> 13432.774 | I40: =SUM(I39,I37,I33) -> 16007.952 | J40: =SUM(J39,J37,J33) -> 18733.517
A42: * | B42: Balance check | C42: =C40-C28 -> 0 | D42: =D40-D28 -> 10 | E42: =E40-E28 -> 0 | F42: =F40-F28 -> 0 | G42: =G40-G28 -> 0 | H42: =H40-H28 -> 0 | I42: =I40-I28 -> 0 | J42: =J40-J28 -> 0

Sheet CashFlow
A1: =CoName -> Yum Brands Inc. | C1: Hist. | D1: Hist. | E1: Hist. | F1: Proj. | G1: Proj. | H1: Proj. | I1: Proj. | J1: Proj.
A2: Cash flow statement | C2: 2022 | D2: =C2+1 -> 2023 | E2: =D2+1 -> 2024 | F2: =E2+1 -> 2025 | G2: =F2+1 -> 2026 | H2: =G2+1 -> 2027 | I2: =H2+1 -> 2028 | J2: =I2+1 -> 2029
B3: Net Income | F3: =IncState!F34 -> 2509.5613 | G3: =IncState!G34 -> 2808.1274 | H3: =IncState!H34 -> 3046.5453 | I3: =IncState!I34 -> 3285.1029 | J3: =IncState!J34 -> 3517.1573
B4: Depreciation | F4: =IncState!F21 -> 65.2 | G4: =IncState!G21 -> 75.69 | H4: =IncState!H21 -> 85.6555 | I4: =IncState!I21 -> 95.122725 | J4: =IncState!J21 -> 104.11659
B5: Amortization | F5: =IncState!F22 -> 0 | G5: =IncState!G22 -> 0 | H5: =IncState!H22 -> 0 | I5: =IncState!I22 -> 0 | J5: =IncState!J22 -> 0
B6: (inc) / dec in OWC | F6: =Calcs!F25 -> 62.812345 | G6: =Calcs!G25 -> -39.073499 | H6: =Calcs!H25 -> -14.434545 | I6: =Calcs!I25 -> -18.330807 | J6: =Calcs!J25 -> -14.669251
B7: (inc) / dec in LT assets | F7: =BalSheet!E25-BalSheet!F25 -> -234.62415 | G7: =BalSheet!F25-BalSheet!G25 -> -253.06824 | H7: =BalSheet!G25-BalSheet!H25 -> -249.14105 | I7: =BalSheet!H25-BalSheet!I25 -> -244.55436 | J7: =BalSheet!I25-BalSheet!J25 -> -234.86341
B8: inc / (dec) in LT liabilities | F8: =BalSheet!F36-BalSheet!E36 -> 175.96811 | G8: =BalSheet!G36-BalSheet!F36 -> 189.80118 | H8: =BalSheet!H36-BalSheet!G36 -> 186.85579 | I8: =BalSheet!I36-BalSheet!H36 -> 183.41577 | J8: =BalSheet!J36-BalSheet!I36 -> 176.14756
B9: CFFO | F9: =SUM(F3:F8) -> 2578.9176 | G9: =SUM(G3:G8) -> 2781.4769 | H9: =SUM(H3:H8) -> 3055.481 | I9: =SUM(I3:I8) -> 3300.7562 | J9: =SUM(J3:J8) -> 3547.8888
B11: Capex | F11: =-Calcs!F7 -> -275 | G11: =-Calcs!G7 -> -275 | H11: =-Calcs!H7 -> -275 | I11: =-Calcs!I7 -> -275 | J11: =-Calcs!J7 -> -275
B12: CFFI | F12: =F11 -> -275 | G12: =G11 -> -275 | H12: =H11 -> -275 | I12: =I11 -> -275 | J12: =J11 -> -275
B14: Dividends Paid | F14: =-IncState!F36 -> -823.58719 | G14: =-IncState!G36 -> -895.17438 | H14: =-IncState!H36 -> -966.76157 | I14: =-IncState!I36 -> -1038.3488 | J14: =-IncState!J36 -> -1109.9359
B15: Debt issuance / (repayment) | F15: =SUM(Debt!F8:F9) -> 0 | G15: =SUM(Debt!G8:G9) -> 0 | H15: =SUM(Debt!H8:H9) -> 0 | I15: =SUM(Debt!I8:I9) -> 0 | J15: =SUM(Debt!J8:J9) -> 0
B16: Share issuance / (repurchases) | F16: =Calcs!F11 -> 0 | G16: =Calcs!G11 -> 0 | H16: =Calcs!H11 -> 0 | I16: =Calcs!I11 -> 0 | J16: =Calcs!J11 -> 0
B17: CFFF | F17: =SUM(F14:F16) -> -823.58719 | G17: =SUM(G14:G16) -> -895.17438 | H17: =SUM(H14:H16) -> -966.76157 | I17: =SUM(I14:I16) -> -1038.3488 | J17: =SUM(J14:J16) -> -1109.9359
B19: Net changes in cash | F19: =SUM(F17,F12,F9) -> 1480.3304 | G19: =SUM(G17,G12,G9) -> 1611.3025 | H19: =SUM(H17,H12,H9) -> 1813.7194 | I19: =SUM(I17,I12,I9) -> 1987.4075 | J19: =SUM(J17,J12,J9) -> 2162.9528
B21: Beginning cash | F21: =BalSheet!E17 -> 268.03167 | G21: =BalSheet!F17 -> 1721.3621 | H21: =BalSheet!G17 -> 3332.6646 | I21: =BalSheet!H17 -> 5146.384 | J21: =BalSheet!I17 -> 7133.7915
B22: =B19 -> Net changes in cash | F22: =F19 -> 1480.3304 | G22: =G19 -> 1611.3025 | H22: =H19 -> 1813.7194 | I22: =I19 -> 1987.4075 | J22: =J19 -> 2162.9528
B23: Ending cash | F23: =SUM(F21:F22)-BalSheet!E30 -> 1721.3621 | G23: =SUM(G21:G22)-BalSheet!F30 -> 3332.6646 | H23: =SUM(H21:H22)-BalSheet!G30 -> 5146.384 | I23: =SUM(I21:I22)-BalSheet!H30 -> 7133.7915 | J23: =SUM(J21:J22)-BalSheet!I30 -> 9296.7443

Sheet Free Cash Flow
A1: =CoName -> Yum Brands Inc. | C1: Hist. | D1: Hist. | E1: Hist. | F1: Proj. | G1: Proj. | H1: Proj. | I1: Proj. | J1: Proj.
A2: Free Cash Flows | C2: 2022 | D2: =C2+1 -> 2023 | E2: =D2+1 -> 2024 | F2: =E2+1 -> 2025 | G2: =F2+1 -> 2026 | H2: =G2+1 -> 2027 | I2: =H2+1 -> 2028 | J2: =I2+1 -> 2029
A3: * | B3: Sales | F3: =IncState!F16 -> 7639.7148 | G3: =IncState!G16 -> 8373.5459 | H3: =IncState!H16 -> 9095.9892 | I3: =IncState!I16 -> 9805.1323 | J3: =IncState!J16 -> 10486.174
B4: EBIT | F4: =IncState!F19 -> 3055.4143 | G4: =IncState!G19 -> 3418.9213 | H4: =IncState!H19 -> 3709.1973 | I4: =IncState!I19 -> 3999.6434 | J4: =IncState!J19 -> 4282.1718
B5: Effective Tax Rate | F5: =Assumptions!F16 -> 0.17865105 | G5: =Assumptions!G16 -> 0.17865105 | H5: =Assumptions!H16 -> 0.17865105 | I5: =Assumptions!I16 -> 0.17865105 | J5: =Assumptions!J16 -> 0.17865105
A7: * | B7: NOPAT | F7: =F4*(1-F5) -> 2509.5613 | G7: =G4*(1-G5) -> 2808.1274 | H7: =H4*(1-H5) -> 3046.5453 | I7: =I4*(1-I5) -> 3285.1029 | J7: =J4*(1-J5) -> 3517.1573
B8: Depreciation | F8: =CashFlow!F4 -> 65.2 | G8: =CashFlow!G4 -> 75.69 | H8: =CashFlow!H4 -> 85.6555 | I8: =CashFlow!I4 -> 95.122725 | J8: =CashFlow!J4 -> 104.11659
B9: Amortization | F9: =CashFlow!F5 -> 0 | G9: =CashFlow!G5 -> 0 | H9: =CashFlow!H5 -> 0 | I9: =CashFlow!I5 -> 0 | J9: =CashFlow!J5 -> 0
B10: (inc) / dec in OWC | F10: =CashFlow!F6 -> 62.812345 | G10: =CashFlow!G6 -> -39.073499 | H10: =CashFlow!H6 -> -14.434545 | I10: =CashFlow!I6 -> -18.330807 | J10: =CashFlow!J6 -> -14.669251
B11: (inc) / dec in other long-term assets | F11: =CashFlow!F7 -> -234.62415 | G11: =CashFlow!G7 -> -253.06824 | H11: =CashFlow!H7 -> -249.14105 | I11: =CashFlow!I7 -> -244.55436 | J11: =CashFlow!J7 -> -234.86341
B12: inc / (dec) other long-term liabilities | F12: =CashFlow!F8 -> 175.96811 | G12: =CashFlow!G8 -> 189.80118 | H12: =CashFlow!H8 -> 186.85579 | I12: =CashFlow!I8 -> 183.41577 | J12: =CashFlow!J8 -> 176.14756
B13: (Capex) | F13: =CashFlow!F12 -> -275 | G13: =CashFlow!G12 -> -275 | H13: =CashFlow!H12 -> -275 | I13: =CashFlow!I12 -> -275 | J13: =CashFlow!J12 -> -275
A15: * | B15: Free Cash Flow | F15: =SUM(F7:F13) -> 2303.9176 | G15: =SUM(G7:G13) -> 2506.4769 | H15: =SUM(H7:H13) -> 2780.481 | I15: =SUM(I7:I13) -> 3025.7562 | J15: =SUM(J7:J13) -> 3272.8888

Sheet WACC
A1: =CoName -> Yum Brands Inc.
A3: * | B3: WACC | G3: Comp | H3: Levered beta | I3: Gross debt | J3: Market cap | K3: Debt/Mcap | L3: MTR | M3: Unlevered beta
B4: Tax Rate | E4: =Assumptions!F16 -> 0.17865105 | G4: MCD | H4: 0.72 | K4: 0.186 | L4: =E4 -> 0.17865105 | M4: =H4/((1+K4*(1-L4))) -> 0.62458204
B5: Risk free rate | E5: 0.041 | G5: QSR | H5: 0.61 | I5: =116+13415 -> 13531 | J5: 33400 | K5: =I5/J5 -> 0.40511976 | L5: =L4 -> 0.17865105 | M5: =H5/((1+K5*(1-L5))) -> 0.45770207
B6: Market risk Premium | E6: 0.05 | G6: SBUX | H6: 0.98 | I6: =1498.9+14575.9 -> 16074.8 | J6: 96940 | K6: =I6/J6 -> 0.16582216 | L6: =L5 -> 0.17865105 | M6: =H6/((1+K6*(1-L6))) -> 0.86252583
B7: Beta | E7: =M10 -> 0.81782491
B8: Cost of Equity | E8: =E5+E6*E7 -> 0.081891245 | G8: Industry beta (average) | M8: =AVERAGE(M4:M6) -> 0.64826998
B9: % Equity | E9: =1-E10 -> 0.68156059
B10: % Debt | E10: =MAIN!F8/MAIN!F6 -> 0.31843941 | G10: Re-levered beta | M10: =M8*(1+E10*(1-E4)) -> 0.81782491
B11: Cost of debt | E11: =Assumptions!F24 -> 0.0448
B12: Post tax cost of debt | E12: =E11*(1-E4) -> 0.036796433
A13: * | B13: WACC | E13: =WACC!E8*WACC!E9+WACC!E12*WACC!E10 -> 0.06753128
B14: Long Term growth rate | E14: 0.025

Sheet DCF Model
A1: =CoName -> Yum Brands Inc. | D1: Proj. | E1: Proj. | F1: Proj. | G1: Proj. | H1: Proj.
A2: Discount Model Year count | D2: 1 | E2: =D2+1 -> 2 | F2: =E2+1 -> 3 | G2: =F2+1 -> 4 | H2: =G2+1 -> 5
B3: Discount Factor | D3: =1/(1+$K$17)^D2 -> 0.9367407 | E3: =1/(1+$K$17)^E2 -> 0.87748314 | F3: =1/(1+$K$17)^F2 -> 0.82197417 | G3: =1/(1+$K$17)^G2 -> 0.76997666 | H3: =1/(1+$K$17)^H2 -> 0.72126848
B4: PV FCF | D4: =D3*'Free Cash Flow'!F15 -> 2158.1734 | E4: =E3*'Free Cash Flow'!G15 -> 2199.3912 | F4: =F3*'Free Cash Flow'!H15 -> 2285.4836 | G4: =G3*'Free Cash Flow'!I15 -> 2329.7617 | H4: =H3*'Free Cash Flow'!J15 -> 2360.6315
H5: =(H4*(1+K18))/(K17-K18) -> 56891.006
A6: Value Calculation | E6: Multiples Calculation | I6: Dividend Discount Model
B7: Total PV of FCFs | C7: =SUM(D4:H4) -> 11333.441 | E7: Total PV of FCFs | G7: =C7 -> 11333.441 | I7: FY Dividends | K7: =IncState!J36 -> 1109.9359
B8: PV of TV | C8: =H5*H3 -> 41033.689 | E8: Multiple TV | G8: =H3*IncState!J23*'DCF Model'!G10 -> 47455.373 | I8: Equity Val | K8: =K7/(K17-K18) -> 26096.932
B9: EV | C9: =SUM(C7:C8) -> 52367.131 | E9: EV | G9: =SUM(G7:G8) -> 58788.815
E10: Implied EBITDA multiple | G10: 15 | I10: Diluted S/O | K10: =G17 -> 277.65283
I11: Implied Share Price | K11: =K8/K10 -> 93.991236
B12: Cash & Cash Equiv | C12: =MAIN!F7 -> 1045 | E12: Cash & Cash Equiv | G12: =C12 -> 1045
B13: Debt & Claims | C13: =MAIN!F8 -> 12807 | E13: Debt & Claims | G13: =C13 -> 12807
B14: NCI | C14: 0 | E14: NCI | G14: =C14 -> 0
B15: Equity Value | C15: =C9+C12-SUM(C13:C14) -> 40605.131 | E15: Equity Value | G15: =G9+G12-SUM(G13:G14) -> 47026.815
B17: Diluted S/O | C17: =MAIN!F5 -> 277.65283 | E17: Diluted S/O | G17: =C17 -> 277.65283 | I17: WACC | K17: =WACC!E13 -> 0.06753128
A18: * | B18: Implied Share Price | C18: =C15/C17 -> 146.24425 | E18: Implied Share Price | G18: =G15/G17 -> 169.37272 | I18: Long Term growth rate | K18: 0.025
A20: Sensitivity analysis
C22: Discount rate variance | E22: 0.0025 | G22: Discount rate variance | I22: 0.0025
C23: Implied growth rate variance | E23: 0.0025 | G23: TV multiple variance | I23: 2
E25: LTGR | I25: Exit Mult
C26: =C18 -> 146.24425 | D26: =E26-E23 -> 0.0225 | E26: 0.025 | F26: =E26+E23 -> 0.0275 | G26: =G18 -> 169.37272 | H26: =I26-I23 -> 13 | I26: 15 | J26: =I26+I23 -> 17
C27: =C28+$E$22 -> 0.07253128 | D27: 117.48578 | E27: 124.08448 | F27: 131.41585 | G27: =C27 -> 0.07253128 | H27: 142.58696 | I27: 164.84952 | J27: 187.11209
C28: =C29+$E$22 -> 0.07003128 | D28: 127.03573 | E28: 134.52272 | F28: 142.88988 | G28: =C28 -> 0.07003128 | H28: 144.57185 | I28: 167.09571 | J28: 189.61956
C29: 0.06753128 | D29: 137.69908 | E29: 146.24425 | F29: 155.85674 | G29: =C29 -> 0.06753128 | H29: 146.58389 | I29: 169.37272 | J29: 192.16155
C30: =C29-$E$22 -> 0.06503128 | D30: 149.67411 | E30: 159.49159 | F30: 170.61698 | G30: =C30 -> 0.06503128 | H30: 148.6235 | I30: 171.68106 | J30: 194.73862
C31: =C30-$E$22 -> 0.06253128 | D31: 163.20872 | E31: 174.57193 | F31: 187.55699 | G31: =C31 -> 0.06253128 | H31: 150.69115 | I31: 174.02124 | J31: 197.35133
